Workbook

Sheet Learner Usage-02-10-2026T11-12-
A1: Course Offering Id | B1: Course Offering Code | C1: Course Offering Name | D1: Parent Department Name | E1: Parent Department Code | F1: Term Id | G1: Semester Code | H1: Semester Name | I1: User Id | J1: Username | K1: Org Defined Id | L1: First Name | M1: Last Name | N1: Is Active | O1: Role Id | P1: Role Name | Q1: Content Completed | R1: Content Required | S1: Checklist Completed | T1: Quiz Completed | U1: Total Quiz Attempts | V1: Discussion Post Created | W1: Discussion Post Replies | X1: Discussion Post Read | Y1: Last Discussion Post Date | Z1: Number Of Assignment Submissions | AA1: Last Assignment Submission Date | AB1: Total Time Spent In Content | AC1: Last Visited Date | AD1: Last System Login | AE1: Number Of Logins To The System | AF1: Auditor Name | AG1: Last Quiz Attempt Date | AH1: Last SCORM Completion Date | AI1: Last SCORM Visit Date
A2: 7034 | B2: T2-25_BDSDF106 | C2: Data Structures for Data Science | D2: BS - Data Science &amp; AI | E2: dept_bs_dsai | F2: 6653 | G2: sem_trimester 2 | H2: Trimester 2 | I2: 226 | J2: 2025eb1100001@bitspilani-digital.edu.in | K2: 2025EB1100001 | L2: RUDRA SHARMA | M2: . | N2: TRUE | O2: 120 | P2: BITS Learner | Q2: 1 | R2: 154 | S2: 0 | T2: 1 | U2: 1 | V2: 0 | W2: 0 | X2: 0 | Z2: 0 | AB2: 0 | AC2: 2026-02-08T09:13:59.9530000Z | AD2: 2026-02-09T11:45:19.5500000Z | AE2: 168 | AG2: 2026-02-08T09:04:03.4030000Z
A3: 7035 | B3: T2-25_BDSDF102 | C3: Data Preprocessing (BS) | D3: BS - Data Science &amp; AI | E3: dept_bs_dsai | F3: 6653 | G3: sem_trimester 2 | H3: Trimester 2 | I3: 226 | J3: 2025eb1100001@bitspilani-digital.edu.in | K3: 2025EB1100001 | L3: RUDRA SHARMA | M3: . | N3: TRUE | O3: 120 | P3: BITS Learner | Q3: 6 | R3: 158 | S3: 0 | T3: 2 | U3: 3 | V3: 0 | W3: 0 | X3: 0 | Z3: 0 | AB3: 17096 | AC3: 2026-02-08T09:20:40.1530000Z | AD3: 2026-02-09T11:45:19.5500000Z | AE3: 168 | AG3: 2026-02-08T09:20:32.9730000Z
A4: 7032 | B4: T2-25_BDSDF107 | C4: Fundamentals of Data Science and Engineering | D4: BS - Data Science &amp; AI | E4: dept_bs_dsai | F4: 6653 | G4: sem_trimester 2 | H4: Trimester 2 | I4: 226 | J4: 2025eb1100001@bitspilani-digital.edu.in | K4: 2025EB1100001 | L4: RUDRA SHARMA | M4: . | N4: TRUE | O4: 120 | P4: BITS Learner | Q4: 45 | R4: 112 | S4: 0 | T4: 7 | U4: 8 | V4: 0 | W4: 0 | X4: 0 | Z4: 0 | AB4: 31534 | AC4: 2026-02-07T15:33:47.5000000Z | AD4: 2026-02-09T11:45:19.5500000Z | AE4: 168 | AG4: 2026-02-07T15:16:25.5370000Z
A5: 7033 | B5: T2-25_BDSDF110 | C5: Linear Algebra | D5: BS - Data Science &amp; AI | E5: dept_bs_dsai | F5: 6653 | G5: sem_trimester 2 | H5: Trimester 2 | I5: 226 | J5: 2025eb1100001@bitspilani-digital.edu.in | K5: 2025EB1100001 | L5: RUDRA SHARMA | M5: . | N5: TRUE | O5: 120 | P5: BITS Learner | Q5: 3 | R5: 86 | S5: 0 | T5: 1 | U5: 1 | V5: 0 | W5: 0 | X5: 0 | Z5: 0 | AB5: 27 | AC5: 2026-02-08T09:12:57.6770000Z | AD5: 2026-02-09T11:45:19.5500000Z | AE5: 168 | AG5: 2026-02-08T09:12:53.8070000Z | AH5: 2026-01-23T15:01:45.2470000Z | AI5: 2026-01-23T15:01:48.8770000Z
A6: 7025 | B6: T2-25_BDSDF108 | C6: Computing Systems | D6: BS - Data Science &amp; AI | E6: dept_bs_dsai | F6: 6653 | G6: sem_trimester 2 | H6: Trimester 2 | I6: 226 | J6: 2025eb1100001@bitspilani-digital.edu.in | K6: 2025EB1100001 | L6: RUDRA SHARMA | M6: . | N6: TRUE | O6: 120 | P6: BITS Learner | Q6: 105 | R6: 267 | S6: 0 | T6: 35 | U6: 57 | V6: 0 | W6: 0 | X6: 0 | Z6: 0 | AB6: 2449 | AC6: 2026-02-09T12:25:12.1930000Z | AD6: 2026-02-09T11:45:19.5500000Z | AE6: 168 | AG6: 2026-02-09T12:25:03.4370000Z | AH6: 2026-02-09T11:46:54.2770000Z | AI6: 2026-02-09T11:46:54.2730000Z
A7: 7022 | B7: T2-25_BDSDF114 | C7: Probability & Statistics | D7: BS - Data Science &amp; AI | E7: dept_bs_dsai | F7: 6653 | G7: sem_trimester 2 | H7: Trimester 2 | I7: 228 | J7: 2025eb1100003@bitspilani-digital.edu.in | K7: 2025EB1100003 | L7: AJAYACHANDRAN.E | M7: . | N7: TRUE | O7: 120 | P7: BITS Learner | Q7: 24 | R7: 326 | S7: 0 | T7: 3 | U7: 5 | V7: 2 | W7: 0 | X7: 8 | Y7: 2026-01-30T21:48:45.6800000Z | Z7: 0 | AB7: 31222 | AC7: 2026-02-09T00:39:23.1430000Z | AD7: 2026-02-08T23:02:38.0030000Z | AE7: 115 | AG7: 2026-01-31T00:24:37.8630000Z | AH7: 2026-01-24T14:45:28.7000000Z | AI7: 2026-01-31T00:25:02.4370000Z
A8: 7021 | B8: T2-25_BDSDF113 | C8: Computer Programming | D8: BS - Data Science &amp; AI | E8: dept_bs_dsai | F8: 6653 | G8: sem_trimester 2 | H8: Trimester 2 | I8: 228 | J8: 2025eb1100003@bitspilani-digital.edu.in | K8: 2025EB1100003 | L8: AJAYACHANDRAN.E | M8: . | N8: TRUE | O8: 120 | P8: BITS Learner | Q8: 44 | R8: 356 | S8: 0 | T8: 9 | U8: 18 | V8: 3 | W8: 0 | X8: 1 | Y8: 2026-01-31T00:29:49.2300000Z | Z8: 0 | AB8: 49579 | AC8: 2026-02-09T00:39:46.6630000Z | AD8: 2026-02-08T23:02:38.0030000Z | AE8: 115 | AG8: 2026-01-31T23:46:19.5000000Z | AH8: 2026-01-31T12:03:07.5170000Z | AI8: 2026-01-31T23:46:46.3370000Z
A9: 7032 | B9: T2-25_BDSDF107 | C9: Fundamentals of Data Science and Engineering | D9: BS - Data Science &amp; AI | E9: dept_bs_dsai | F9: 6653 | G9: sem_trimester 2 | H9: Trimester 2 | I9: 228 | J9: 2025eb1100003@bitspilani-digital.edu.in | K9: 2025EB1100003 | L9: AJAYACHANDRAN.E | M9: . | N9: TRUE | O9: 120 | P9: BITS Learner | Q9: 27 | R9: 112 | S9: 0 | T9: 3 | U9: 6 | V9: 0 | W9: 0 | X9: 0 | Z9: 0 | AB9: 25900 | AC9: 2026-02-09T00:37:32.1300000Z | AD9: 2026-02-08T23:02:38.0030000Z | AE9: 115 | AG9: 2026-01-30T20:33:35.5230000Z
A10: 7035 | B10: T2-25_BDSDF102 | C10: Data Preprocessing (BS) | D10: BS - Data Science &amp; AI | E10: dept_bs_dsai | F10: 6653 | G10: sem_trimester 2 | H10: Trimester 2 | I10: 228 | J10: 2025eb1100003@bitspilani-digital.edu.in | K10: 2025EB1100003 | L10: AJAYACHANDRAN.E | M10: . | N10: TRUE | O10: 120 | P10: BITS Learner | Q10: 45 | R10: 158 | S10: 0 | T10: 6 | U10: 8 | V10: 3 | W10: 0 | X10: 0 | Y10: 2026-02-07T23:08:17.5300000Z | Z10: 0 | AB10: 24234 | AC10: 2026-02-09T00:32:41.3400000Z | AD10: 2026-02-08T23:02:38.0030000Z | AE10: 115 | AG10: 2026-02-09T00:31:45.6730000Z
A11: 7035 | B11: T2-25_BDSDF102 | C11: Data Preprocessing (BS) | D11: BS - Data Science &amp; AI | E11: dept_bs_dsai | F11: 6653 | G11: sem_trimester 2 | H11: Trimester 2 | I11: 229 | J11: 2025eb1100004@bitspilani-digital.edu.in | K11: 2025EB1100004 | L11: ARUNLAL P | M11: . | N11: TRUE | O11: 120 | P11: BITS Learner | Q11: 1 | R11: 158 | S11: 0 | T11: 0 | U11: 0 | V11: 0 | W11: 0 | X11: 0 | Z11: 0 | AB11: 0 | AC11: 2026-01-19T08:25:52.9870000Z | AD11: 2026-02-08T15:52:25.5800000Z | AE11: 151
A12: 7034 | B12: T2-25_BDSDF106 | C12: Data Structures for Data Science | D12: BS - Data Science &amp; AI | E12: dept_bs_dsai | F12: 6653 | G12: sem_trimester 2 | H12: Trimester 2 | I12: 229 | J12: 2025eb1100004@bitspilani-digital.edu.in | K12: 2025EB1100004 | L12: ARUNLAL P | M12: . | N12: TRUE | O12: 120 | P12: BITS Learner | Q12: 0 | R12: 154 | S12: 0 | T12: 0 | U12: 0 | V12: 0 | W12: 0 | X12: 0 | Z12: 0 | AB12: 0 | AC12: 2026-01-17T14:38:56.5370000Z | AD12: 2026-02-08T15:52:25.5800000Z | AE12: 151
A13: 7032 | B13: T2-25_BDSDF107 | C13: Fundamentals of Data Science and Engineering | D13: BS - Data Science &amp; AI | E13: dept_bs_dsai | F13: 6653 | G13: sem_trimester 2 | H13: Trimester 2 | I13: 229 | J13: 2025eb1100004@bitspilani-digital.edu.in | K13: 2025EB1100004 | L13: ARUNLAL P | M13: . | N13: TRUE | O13: 120 | P13: BITS Learner | Q13: 1 | R13: 112 | S13: 0 | T13: 1 | U13: 1 | V13: 0 | W13: 0 | X13: 0 | Z13: 0 | AB13: 0 | AC13: 2026-02-08T15:58:42.1600000Z | AD13: 2026-02-08T15:52:25.5800000Z | AE13: 151 | AG13: 2026-02-08T15:58:35.0330000Z
A14: 7033 | B14: T2-25_BDSDF110 | C14: Linear Algebra | D14: BS - Data Science &amp; AI | E14: dept_bs_dsai | F14: 6653 | G14: sem_trimester 2 | H14: Trimester 2 | I14: 229 | J14: 2025eb1100004@bitspilani-digital.edu.in | K14: 2025EB1100004 | L14: ARUNLAL P | M14: . | N14: TRUE | O14: 120 | P14: BITS Learner | Q14: 0 | R14: 86 | S14: 0 | T14: 0 | U14: 0 | V14: 0 | W14: 0 | X14: 0 | Z14: 0 | AB14: 0 | AD14: 2026-02-08T15:52:25.5800000Z | AE14: 151
A15: 7033 | B15: T2-25_BDSDF110 | C15: Linear Algebra | D15: BS - Data Science &amp; AI | E15: dept_bs_dsai | F15: 6653 | G15: sem_trimester 2 | H15: Trimester 2 | I15: 231 | J15: 2025eb1100006@bitspilani-digital.edu.in | K15: 2025EB1100006 | L15: JAL PATEL | M15: . | N15: TRUE | O15: 120 | P15: BITS Learner | Q15: 1 | R15: 86 | S15: 0 | T15: 1 | U15: 1 | V15: 0 | W15: 0 | X15: 0 | Z15: 0 | AB15: 0 | AC15: 2026-02-08T08:16:42.7600000Z | AD15: 2026-02-08T07:51:39.3430000Z | AE15: 73 | AG15: 2026-02-08T08:12:38.5830000Z
A16: 7032 | B16: T2-25_BDSDF107 | C16: Fundamentals of Data Science and Engineering | D16: BS - Data Science &amp; AI | E16: dept_bs_dsai | F16: 6653 | G16: sem_trimester 2 | H16: Trimester 2 | I16: 231 | J16: 2025eb1100006@bitspilani-digital.edu.in | K16: 2025EB1100006 | L16: JAL PATEL | M16: . | N16: TRUE | O16: 120 | P16: BITS Learner | Q16: 2 | R16: 112 | S16: 0 | T16: 2 | U16: 2 | V16: 0 | W16: 0 | X16: 0 | Z16: 0 | AB16: 0 | AC16: 2026-02-08T08:17:07.8730000Z | AD16: 2026-02-08T07:51:39.3430000Z | AE16: 73 | AG16: 2026-02-08T08:02:33.4500000Z
A17: 7034 | B17: T2-25_BDSDF106 | C17: Data Structures for Data Science | D17: BS - Data Science &amp; AI | E17: dept_bs_dsai | F17: 6653 | G17: sem_trimester 2 | H17: Trimester 2 | I17: 231 | J17: 2025eb1100006@bitspilani-digital.edu.in | K17: 2025EB1100006 | L17: JAL PATEL | M17: . | N17: TRUE | O17: 120 | P17: BITS Learner | Q17: 1 | R17: 154 | S17: 0 | T17: 1 | U17: 1 | V17: 0 | W17: 0 | X17: 0 | Z17: 0 | AB17: 0 | AC17: 2026-02-08T08:17:33.9070000Z | AD17: 2026-02-08T07:51:39.3430000Z | AE17: 73 | AG17: 2026-02-08T08:15:45.7230000Z
A18: 7035 | B18: T2-25_BDSDF102 | C18: Data Preprocessing (BS) | D18: BS - Data Science &amp; AI | E18: dept_bs_dsai | F18: 6653 | G18: sem_trimester 2 | H18: Trimester 2 | I18: 231 | J18: 2025eb1100006@bitspilani-digital.edu.in | K18: 2025EB1100006 | L18: JAL PATEL | M18: . | N18: TRUE | O18: 120 | P18: BITS Learner | Q18: 0 | R18: 158 | S18: 0 | T18: 0 | U18: 0 | V18: 0 | W18: 0 | X18: 0 | Z18: 0 | AB18: 0 | AC18: 2026-02-08T08:16:57.8270000Z | AD18: 2026-02-08T07:51:39.3430000Z | AE18: 73
A19: 7021 | B19: T2-25_BDSDF113 | C19: Computer Programming | D19: BS - Data Science &amp; AI | E19: dept_bs_dsai | F19: 6653 | G19: sem_trimester 2 | H19: Trimester 2 | I19: 232 | J19: 2025eb1100007@bitspilani-digital.edu.in | K19: 2025EB1100007 | L19: HARSHVARDHAN SINGH | M19: . | N19: TRUE | O19: 120 | P19: BITS Learner | Q19: 10 | R19: 356 | S19: 0 | T19: 4 | U19: 4 | V19: 0 | W19: 0 | X19: 0 | Z19: 0 | AB19: 24662 | AC19: 2026-02-08T02:54:21.2930000Z | AD19: 2026-02-09T00:57:34.8670000Z | AE19: 67 | AG19: 2026-02-08T02:54:12.8470000Z | AH19: 2026-01-30T14:05:06.5370000Z | AI19: 2026-02-05T07:23:03.0770000Z
A20: 7022 | B20: T2-25_BDSDF114 | C20: Probability & Statistics | D20: BS - Data Science &amp; AI | E20: dept_bs_dsai | F20: 6653 | G20: sem_trimester 2 | H20: Trimester 2 | I20: 232 | J20: 2025eb1100007@bitspilani-digital.edu.in | K20: 2025EB1100007 | L20: HARSHVARDHAN SINGH | M20: . | N20: TRUE | O20: 120 | P20: BITS Learner | Q20: 1 | R20: 326 | S20: 0 | T20: 1 | U20: 1 | V20: 0 | W20: 0 | X20: 0 | Z20: 0 | AB20: 0 | AC20: 2026-02-08T02:56:47.4770000Z | AD20: 2026-02-09T00:57:34.8670000Z | AE20: 67 | AG20: 2026-02-08T02:56:43.8530000Z
A21: 7025 | B21: T2-25_BDSDF108 | C21: Computing Systems | D21: BS - Data Science &amp; AI | E21: dept_bs_dsai | F21: 6653 | G21: sem_trimester 2 | H21: Trimester 2 | I21: 232 | J21: 2025eb1100007@bitspilani-digital.edu.in | K21: 2025EB1100007 | L21: HARSHVARDHAN SINGH | M21: . | N21: TRUE | O21: 120 | P21: BITS Learner | Q21: 1 | R21: 267 | S21: 0 | T21: 1 | U21: 1 | V21: 0 | W21: 0 | X21: 0 | Z21: 0 | AB21: 0 | AC21: 2026-02-08T03:02:53.3470000Z | AD21: 2026-02-09T00:57:34.8670000Z | AE21: 67 | AG21: 2026-02-08T03:02:49.6200000Z
A22: 7024 | B22: T2-25_BDSDF101 | C22: Data and the World | D22: BS - Data Science &amp; AI | E22: dept_bs_dsai | F22: 6653 | G22: sem_trimester 2 | H22: Trimester 2 | I22: 232 | J22: 2025eb1100007@bitspilani-digital.edu.in | K22: 2025EB1100007 | L22: HARSHVARDHAN SINGH | M22: . | N22: TRUE | O22: 120 | P22: BITS Learner | Q22: 0 | R22: 53 | S22: 0 | T22: 0 | U22: 0 | V22: 0 | W22: 0 | X22: 0 | Z22: 0 | AB22: 0 | AD22: 2026-02-09T00:57:34.8670000Z | AE22: 67
A23: 7035 | B23: T2-25_BDSDF102 | C23: Data Preprocessing (BS) | D23: BS - Data Science &amp; AI | E23: dept_bs_dsai | F23: 6653 | G23: sem_trimester 2 | H23: Trimester 2 | I23: 233 | J23: 2025eb1100008@bitspilani-digital.edu.in | K23: 2025EB1100008 | L23: KALYANE VENKATESH NISHIKANT | M23: . | N23: TRUE | O23: 120 | P23: BITS Learner | Q23: 4 | R23: 158 | S23: 0 | T23: 0 | U23: 0 | V23: 0 | W23: 0 | X23: 0 | Z23: 0 | AB23: 6800 | AC23: 2026-02-07T15:35:16.0400000Z | AD23: 2026-02-07T15:26:57.4830000Z | AE23: 107
A24: 7034 | B24: T2-25_BDSDF106 | C24: Data Structures for Data Science | D24: BS - Data Science &amp; AI | E24: dept_bs_dsai | F24: 6653 | G24: sem_trimester 2 | H24: Trimester 2 | I24: 233 | J24: 2025eb1100008@bitspilani-digital.edu.in | K24: 2025EB1100008 | L24: KALYANE VENKATESH NISHIKANT | M24: . | N24: TRUE | O24: 120 | P24: BITS Learner | Q24: 0 | R24: 154 | S24: 0 | T24: 0 | U24: 0 | V24: 0 | W24: 0 | X24: 0 | Z24: 0 | AB24: 0 | AD24: 2026-02-07T15:26:57.4830000Z | AE24: 107
A25: 7032 | B25: T2-25_BDSDF107 | C25: Fundamentals of Data Science and Engineering | D25: BS - Data Science &amp; AI | E25: dept_bs_dsai | F25: 6653 | G25: sem_trimester 2 | H25: Trimester 2 | I25: 233 | J25: 2025eb1100008@bitspilani-digital.edu.in | K25: 2025EB1100008 | L25: KALYANE VENKATESH NISHIKANT | M25: . | N25: TRUE | O25: 120 | P25: BITS Learner | Q25: 5 | R25: 112 | S25: 0 | T25: 1 | U25: 1 | V25: 0 | W25: 0 | X25: 0 | Z25: 0 | AB25: 3889 | AC25: 2026-02-07T15:34:29.9030000Z | AD25: 2026-02-07T15:26:57.4830000Z | AE25: 107 | AG25: 2026-02-07T15:34:10.0200000Z
A26: 7033 | B26: T2-25_BDSDF110 | C26: Linear Algebra | D26: BS - Data Science &amp; AI | E26: dept_bs_dsai | F26: 6653 | G26: sem_trimester 2 | H26: Trimester 2 | I26: 233 | J26: 2025eb1100008@bitspilani-digital.edu.in | K26: 2025EB1100008 | L26: KALYANE VENKATESH NISHIKANT | M26: . | N26: TRUE | O26: 120 | P26: BITS Learner | Q26: 0 | R26: 86 | S26: 0 | T26: 0 | U26: 0 | V26: 0 | W26: 0 | X26: 0 | Z26: 0 | AB26: 0 | AD26: 2026-02-07T15:26:57.4830000Z | AE26: 107
A27: 7024 | B27: T2-25_BDSDF101 | C27: Data and the World | D27: BS - Data Science &amp; AI | E27: dept_bs_dsai | F27: 6653 | G27: sem_trimester 2 | H27: Trimester 2 | I27: 234 | J27: 2025eb1100009@bitspilani-digital.edu.in | K27: 2025EB1100009 | L27: ALI ZAFAR RIZVI | M27: . | N27: TRUE | O27: 120 | P27: BITS Learner | Q27: 0 | R27: 53 | S27: 0 | T27: 0 | U27: 0 | V27: 0 | W27: 0 | X27: 0 | Z27: 0 | AB27: 0 | AD27: 2026-02-08T17:27:11.8430000Z | AE27: 7
A28: 7025 | B28: T2-25_BDSDF108 | C28: Computing Systems | D28: BS - Data Science &amp; AI | E28: dept_bs_dsai | F28: 6653 | G28: sem_trimester 2 | H28: Trimester 2 | I28: 234 | J28: 2025eb1100009@bitspilani-digital.edu.in | K28: 2025EB1100009 | L28: ALI ZAFAR RIZVI | M28: . | N28: TRUE | O28: 120 | P28: BITS Learner | Q28: 0 | R28: 267 | S28: 0 | T28: 0 | U28: 0 | V28: 0 | W28: 0 | X28: 0 | Z28: 0 | AB28: 0 | AD28: 2026-02-08T17:27:11.8430000Z | AE28: 7
A29: 7022 | B29: T2-25_BDSDF114 | C29: Probability & Statistics | D29: BS - Data Science &amp; AI | E29: dept_bs_dsai | F29: 6653 | G29: sem_trimester 2 | H29: Trimester 2 | I29: 234 | J29: 2025eb1100009@bitspilani-digital.edu.in | K29: 2025EB1100009 | L29: ALI ZAFAR RIZVI | M29: . | N29: TRUE | O29: 120 | P29: BITS Learner | Q29: 0 | R29: 326 | S29: 0 | T29: 0 | U29: 0 | V29: 0 | W29: 0 | X29: 0 | Z29: 0 | AB29: 0 | AD29: 2026-02-08T17:27:11.8430000Z | AE29: 7
A30: 7023 | B30: T2-25_BDSDF112 | C30: Writing Practice | D30: BS - Data Science &amp; AI | E30: dept_bs_dsai | F30: 6653 | G30: sem_trimester 2 | H30: Trimester 2 | I30: 234 | J30: 2025eb1100009@bitspilani-digital.edu.in | K30: 2025EB1100009 | L30: ALI ZAFAR RIZVI | M30: . | N30: TRUE | O30: 120 | P30: BITS Learner | Q30: 0 | R30: 209 | S30: 0 | T30: 0 | U30: 0 | V30: 0 | W30: 0 | X30: 0 | Z30: 0 | AB30: 0 | AD30: 2026-02-08T17:27:11.8430000Z | AE30: 7
A31: 7021 | B31: T2-25_BDSDF113 | C31: Computer Programming | D31: BS - Data Science &amp; AI | E31: dept_bs_dsai | F31: 6653 | G31: sem_trimester 2 | H31: Trimester 2 | I31: 234 | J31: 2025eb1100009@bitspilani-digital.edu.in | K31: 2025EB1100009 | L31: ALI ZAFAR RIZVI | M31: . | N31: TRUE | O31: 120 | P31: BITS Learner | Q31: 0 | R31: 356 | S31: 0 | T31: 0 | U31: 0 | V31: 0 | W31: 0 | X31: 0 | Z31: 0 | AB31: 0 | AD31: 2026-02-08T17:27:11.8430000Z | AE31: 7
A32: 7033 | B32: T2-25_BDSDF110 | C32: Linear Algebra | D32: BS - Data Science &amp; AI | E32: dept_bs_dsai | F32: 6653 | G32: sem_trimester 2 | H32: Trimester 2 | I32: 235 | J32: 2025eb1100010@bitspilani-digital.edu.in | K32: 2025EB1100010 | L32: HARSHITA JAIN | M32: . | N32: TRUE | O32: 120 | P32: BITS Learner | Q32: 0 | R32: 86 | S32: 0 | T32: 0 | U32: 0 | V32: 0 | W32: 0 | X32: 0 | Z32: 0 | AB32: 0 | AD32: 2026-02-09T14:18:25.6470000Z | AE32: 170
A33: 7032 | B33: T2-25_BDSDF107 | C33: Fundamentals of Data Science and Engineering | D33: BS - Data Science &amp; AI | E33: dept_bs_dsai | F33: 6653 | G33: sem_trimester 2 | H33: Trimester 2 | I33: 235 | J33: 2025eb1100010@bitspilani-digital.edu.in | K33: 2025EB1100010 | L33: HARSHITA JAIN | M33: . | N33: TRUE | O33: 120 | P33: BITS Learner | Q33: 4 | R33: 112 | S33: 0 | T33: 2 | U33: 2 | V33: 0 | W33: 0 | X33: 0 | Z33: 0 | AB33: 14 | AC33: 2026-02-08T14:39:37.0530000Z | AD33: 2026-02-09T14:18:25.6470000Z | AE33: 170 | AG33: 2026-02-08T14:39:30.3800000Z
A34: 7034 | B34: T2-25_BDSDF106 | C34: Data Structures for Data Science | D34: BS - Data Science &amp; AI | E34: dept_bs_dsai | F34: 6653 | G34: sem_trimester 2 | H34: Trimester 2 | I34: 235 | J34: 2025eb1100010@bitspilani-digital.edu.in | K34: 2025EB1100010 | L34: HARSHITA JAIN | M34: . | N34: TRUE | O34: 120 | P34: BITS Learner | Q34: 3 | R34: 154 | S34: 0 | T34: 0 | U34: 0 | V34: 0 | W34: 0 | X34: 0 | Z34: 0 | AB34: 22 | AC34: 2026-02-04T14:31:35.9470000Z | AD34: 2026-02-09T14:18:25.6470000Z | AE34: 170
A35: 7035 | B35: T2-25_BDSDF102 | C35: Data Preprocessing (BS) | D35: BS - Data Science &amp; AI | E35: dept_bs_dsai | F35: 6653 | G35: sem_trimester 2 | H35: Trimester 2 | I35: 235 | J35: 2025eb1100010@bitspilani-digital.edu.in | K35: 2025EB1100010 | L35: HARSHITA JAIN | M35: . | N35: TRUE | O35: 120 | P35: BITS Learner | Q35: 10 | R35: 158 | S35: 0 | T35: 0 | U35: 0 | V35: 0 | W35: 0 | X35: 0 | Z35: 0 | AB35: 9593 | AC35: 2026-02-09T16:52:56.6300000Z | AD35: 2026-02-09T14:18:25.6470000Z | AE35: 170
A36: 7021 | B36: T2-25_BDSDF113 | C36: Computer Programming | D36: BS - Data Science &amp; AI | E36: dept_bs_dsai | F36: 6653 | G36: sem_trimester 2 | H36: Trimester 2 | I36: 237 | J36: 2025eb1100012@bitspilani-digital.edu.in | K36: 2025EB1100012 | L36: SANTOSH SHRIKHANDE | M36: . | N36: TRUE | O36: 120 | P36: BITS Learner | Q36: 0 | R36: 356 | S36: 0 | T36: 0 | U36: 0 | V36: 0 | W36: 0 | X36: 0 | Z36: 0 | AB36: 0 | AD36: 2026-02-07T05:52:24.4370000Z | AE36: 119
A37: 7022 | B37: T2-25_BDSDF114 | C37: Probability & Statistics | D37: BS - Data Science &amp; AI | E37: dept_bs_dsai | F37: 6653 | G37: sem_trimester 2 | H37: Trimester 2 | I37: 237 | J37: 2025eb1100012@bitspilani-digital.edu.in | K37: 2025EB1100012 | L37: SANTOSH SHRIKHANDE | M37: . | N37: TRUE | O37: 120 | P37: BITS Learner | Q37: 4 | R37: 326 | S37: 0 | T37: 0 | U37: 0 | V37: 0 | W37: 0 | X37: 0 | Z37: 0 | AB37: 22 | AC37: 2026-02-07T05:55:07.9530000Z | AD37: 2026-02-07T05:52:24.4370000Z | AE37: 119 | AH37: 2026-02-07T05:55:22.3570000Z | AI37: 2026-02-07T05:55:22.3570000Z
A38: 7021 | B38: T2-25_BDSDF113 | C38: Computer Programming | D38: BS - Data Science &amp; AI | E38: dept_bs_dsai | F38: 6653 | G38: sem_trimester 2 | H38: Trimester 2 | I38: 238 | J38: 2025eb1100013@bitspilani-digital.edu.in | K38: 2025EB1100013 | L38: AKSHITHA IMMACULATE A | M38: . | N38: TRUE | O38: 120 | P38: BITS Learner | Q38: 0 | R38: 356 | S38: 0 | T38: 0 | U38: 0 | V38: 0 | W38: 0 | X38: 0 | Z38: 0 | AB38: 0 | AD38: 2026-01-30T14:24:09.0330000Z | AE38: 100
A39: 7025 | B39: T2-25_BDSDF108 | C39: Computing Systems | D39: BS - Data Science &amp; AI | E39: dept_bs_dsai | F39: 6653 | G39: sem_trimester 2 | H39: Trimester 2 | I39: 238 | J39: 2025eb1100013@bitspilani-digital.edu.in | K39: 2025EB1100013 | L39: AKSHITHA IMMACULATE A | M39: . | N39: TRUE | O39: 120 | P39: BITS Learner | Q39: 0 | R39: 267 | S39: 0 | T39: 0 | U39: 0 | V39: 0 | W39: 0 | X39: 0 | Z39: 0 | AB39: 0 | AD39: 2026-01-30T14:24:09.0330000Z | AE39: 100
A40: 7032 | B40: T2-25_BDSDF107 | C40: Fundamentals of Data Science and Engineering | D40: BS - Data Science &amp; AI | E40: dept_bs_dsai | F40: 6653 | G40: sem_trimester 2 | H40: Trimester 2 | I40: 238 | J40: 2025eb1100013@bitspilani-digital.edu.in | K40: 2025EB1100013 | L40: AKSHITHA IMMACULATE A | M40: . | N40: TRUE | O40: 120 | P40: BITS Learner | Q40: 0 | R40: 112 | S40: 0 | T40: 0 | U40: 0 | V40: 0 | W40: 0 | X40: 0 | Z40: 0 | AB40: 0 | AC40: 2026-01-18T11:10:10.2200000Z | AD40: 2026-01-30T14:24:09.0330000Z | AE40: 100
...

Sheet Sheet4
A1: Org Defined ID | B1: Username | C1: FirstName | D1: LastName | E1: Score | F1: Out Of | G1: % | H1: Class Average | I1: Class Standard Deviation | J1: IsExempt | K1: Updated
A2: 2025EB1100029 | B2: 2025eb1100029@bitspilani-digital.edu.in | C2: AARUSH SHARMA | D2: . | E2: 10 | F2: 10 | G2: 100 % | H2: 98.94 % | I2: 4.39 % | J2: FALSE | K2: =_xlfn.XLOOKUP(B2,Sheet1!I:I,Sheet1!I:I) -> 2025eb1100029@bitspilani-digital.edu.in
A3: 2025EB1100157 | B3: 2025eb1100157@bitspilani-digital.edu.in | C3: ABARAJITHA RAJAGOPAL | D3: . | E3: 10 | F3: 10 | G3: 100 % | H3: 98.94 % | I3: 4.39 % | J3: FALSE | K3: =_xlfn.XLOOKUP(B3,Sheet1!I:I,Sheet1!I:I) -> 2025eb1100157@bitspilani-digital.edu.in
A4: 2025EB1100060 | B4: 2025eb1100060@bitspilani-digital.edu.in | C4: ABHIJEET MUMMITHI | D4: . | E4: 10 | F4: 10 | G4: 100 % | H4: 98.94 % | I4: 4.39 % | J4: FALSE | K4: =_xlfn.XLOOKUP(B4,Sheet1!I:I,Sheet1!I:I) -> 2025eb1100060@bitspilani-digital.edu.in
A5: 2025EB1100255 | B5: 2025eb1100255@bitspilani-digital.edu.in | C5: ABHIRAM BALARAJ | D5: . | E5: 9 | F5: 10 | G5: 90 % | H5: 98.94 % | I5: 4.39 % | J5: FALSE | K5: =_xlfn.XLOOKUP(B5,Sheet1!I:I,Sheet1!I:I) -> 2025eb1100255@bitspilani-digital.edu.in
A6: 2025EB1100059 | B6: 2025eb1100059@bitspilani-digital.edu.in | C6: ADITI CHANDALIA | D6: . | E6: 9 | F6: 10 | G6: 90 % | H6: 98.94 % | I6: 4.39 % | J6: FALSE | K6: =_xlfn.XLOOKUP(B6,Sheet1!I:I,Sheet1!I:I) -> 2025eb1100059@bitspilani-digital.edu.in
A7: 2025EB1100246 | B7: 2025eb1100246@bitspilani-digital.edu.in | C7: ADITI PAL | D7: . | E7: 10 | F7: 10 | G7: 100 % | H7: 98.94 % | I7: 4.39 % | J7: FALSE | K7: =_xlfn.XLOOKUP(B7,Sheet1!I:I,Sheet1!I:I) -> 2025eb1100246@bitspilani-digital.edu.in
A8: 2025EB1100159 | B8: 2025eb1100159@bitspilani-digital.edu.in | C8: ADRIJA CHATTERJEE | D8: . | E8: 10 | F8: 10 | G8: 100 % | H8: 98.94 % | I8: 4.39 % | J8: FALSE | K8: =_xlfn.XLOOKUP(B8,Sheet1!I:I,Sheet1!I:I) -> 2025eb1100159@bitspilani-digital.edu.in
A9: 2025EB1100231 | B9: 2025eb1100231@bitspilani-digital.edu.in | C9: AKSHIT KUMAR UPADHYAY | D9: . | E9: 10 | F9: 10 | G9: 100 % | H9: 98.94 % | I9: 4.39 % | J9: FALSE | K9: =_xlfn.XLOOKUP(B9,Sheet1!I:I,Sheet1!I:I) -> 2025eb1100231@bitspilani-digital.edu.in
A10: 2025EB1100152 | B10: 2025eb1100152@bitspilani-digital.edu.in | C10: AMAN MANJU | D10: . | E10: 10 | F10: 10 | G10: 100 % | H10: 98.94 % | I10: 4.39 % | J10: FALSE | K10: =_xlfn.XLOOKUP(B10,Sheet1!I:I,Sheet1!I:I) -> 2025eb1100152@bitspilani-digital.edu.in
A11: 2025EB1100212 | B11: 2025eb1100212@bitspilani-digital.edu.in | C11: AMAR MANI | D11: . | E11: 10 | F11: 10 | G11: 100 % | H11: 98.94 % | I11: 4.39 % | J11: FALSE | K11: =_xlfn.XLOOKUP(B11,Sheet1!I:I,Sheet1!I:I) -> 2025eb1100212@bitspilani-digital.edu.in
A12: 2025EB1100292 | B12: 2025eb1100292@bitspilani-digital.edu.in | C12: AMRIT RAJ | D12: . | E12: 10 | F12: 10 | G12: 100 % | H12: 98.94 % | I12: 4.39 % | J12: FALSE | K12: =_xlfn.XLOOKUP(B12,Sheet1!I:I,Sheet1!I:I) -> 2025eb1100292@bitspilani-digital.edu.in
A13: 2025EB1100120 | B13: 2025eb1100120@bitspilani-digital.edu.in | C13: ANKIT SINGH | D13: . | E13: 10 | F13: 10 | G13: 100 % | H13: 98.94 % | I13: 4.39 % | J13: FALSE | K13: =_xlfn.XLOOKUP(B13,Sheet1!I:I,Sheet1!I:I) -> 2025eb1100120@bitspilani-digital.edu.in
... A143: 2025EB1100166 | B143: 2025eb1100166@bitspilani-digital.edu.in | C143: YUVRAJ SINGH RATHORE | D143: . | E143: 10 | F143: 10 | G143: 100 % | H143: 98.94 % | I143: 4.39 % | J143: FALSE | K143: =_xlfn.XLOOKUP(B143,Sheet1!I:I,Sheet1!I:I) -> 2025eb1100166@bitspilani-digital.edu.in

Sheet Graded quiz 1 status
A1: Parent Department Name | B1: BS - Data Science &amp; AI | F1: Learners Progress | G1: BS | H1: MS
F2: 46061 | G2: 0.28 | H2: 0.35
A3: Row Labels | B3: Learners attempted | C3: # students | D3: % | F3: 46062 | G3: 0.37 | H3: 0.4
A4: Computer Programming | B4: 102 | C4: =_xlfn.XLOOKUP(A4,Sheet3!A:A,Sheet3!E:E) -> 170 | D4: =B4/C4 -> 0.6 | F4: 10-02-2026(11 AM) | G4: 0.54 | H4: 0.69
A5: Computing Systems | B5: 105 | C5: =_xlfn.XLOOKUP(A5,Sheet3!A:A,Sheet3!E:E) -> 193 | D5: =B5/C5 -> 0.54404145
A6: Data and the World | B6: 5 | C6: =_xlfn.XLOOKUP(A6,Sheet3!A:A,Sheet3!E:E) -> 160 | D6: =B6/C6 -> 0.03125
A7: Data Preprocessing (BS) | B7: 92 | C7: 154 | D7: =B7/C7 -> 0.5974026
A8: Data Structures for Data Science | B8: 100 | C8: =_xlfn.XLOOKUP(A8,Sheet3!A:A,Sheet3!E:E) -> 160 | D8: =B8/C8 -> 0.625
A9: Fundamentals of Data Science and Engineering | B9: 142 | C9: =_xlfn.XLOOKUP(A9,Sheet3!A:A,Sheet3!E:E) -> 176 | D9: =B9/C9 -> 0.80681818
A10: Linear Algebra | B10: 108 | C10: =_xlfn.XLOOKUP(A10,Sheet3!A:A,Sheet3!E:E) -> 188 | D10: =B10/C10 -> 0.57446809
A11: Probability & Statistics | B11: 87 | C11: =_xlfn.XLOOKUP(A11,Sheet3!A:A,Sheet3!E:E) -> 177 | D11: =B11/C11 -> 0.49152542
A12: Writing Practice | B12: 70 | C12: =_xlfn.XLOOKUP(A12,Sheet3!A:A,Sheet3!E:E) -> 134 | D12: =B12/C12 -> 0.52238806
A13: Grand Total | B13: 811 | C13: =SUM(C4:C12) -> 1512 | D13: =B13/C13 -> 0.53637566
A15: Parent Department Name | B15: MSc - Data Science &amp; AI
A17: Row Labels | B17: Learners attempted | C17: # students | D17: %
A18: Artificial Neural Networks | B18: 248 | C18: =_xlfn.XLOOKUP(A18,Sheet3!A:A,Sheet3!E:E) -> 352 | D18: =B18/C18 -> 0.70454545
A19: Cloud Services & Platforms | B19: 254 | C19: =_xlfn.XLOOKUP(A19,Sheet3!A:A,Sheet3!E:E) -> 357 | D19: =B19/C19 -> 0.71148459
A20: Data Pre-processing (MSc) | B20: 258 | C20: =_xlfn.XLOOKUP(A20,Sheet3!A:A,Sheet3!E:E) -> 389 | D20: =B20/C20 -> 0.66323907
A21: Data Stores & Pipelines | B21: 6 | C21: =_xlfn.XLOOKUP(A21,Sheet3!A:A,Sheet3!E:E) -> 17 | D21: =B21/C21 -> 0.35294118
A22: Data Visualization & Storytelling | B22: 262 | C22: =_xlfn.XLOOKUP(A22,Sheet3!A:A,Sheet3!E:E) -> 390 | D22: =B22/C22 -> 0.67179487
A23: Machine Learning | B23: 271 | C23: =_xlfn.XLOOKUP(A23,Sheet3!A:A,Sheet3!E:E) -> 350 | D23: =B23/C23 -> 0.77428571
A24: Statistical Modelling & Inferencing | B24: 259 | C24: =_xlfn.XLOOKUP(A24,Sheet3!A:A,Sheet3!E:E) -> 395 | D24: =B24/C24 -> 0.6556962
A25: Grand Total | B25: 1558 | C25: =SUM(C18:C24) -> 2250 | D25: =B25/C25 -> 0.69244444

Sheet Sheet1
A1: Course Offering Id | B1: Course Offering Code | C1: Course Offering Name | D1: Parent Department Name | E1: Parent Department Code | F1: Term Id | G1: Semester Code | H1: Semester Name | I1: Username | J1: Org Defined Id | K1: First Name | L1: Last Name | M1: Is Active | N1: Role Id | O1: Role Name | P1: Content Completed | Q1: Content Required | R1: Checklist Completed | S1: Quiz Completed | T1: Total Quiz Attempts | U1: Discussion Post Created | V1: Discussion Post Replies | W1: Discussion Post Read | X1: Last Discussion Post Date | Y1: Number Of Assignment Submissions | Z1: Last Assignment Submission Date | AA1: Total Time Spent In Content | AB1: Last Visited Date | AC1: Last System Login | AD1: Number Of Logins To The System | AE1: Auditor Name | AF1: Last Quiz Attempt Date | AG1: Last Quiz Attempt Date - custom | AH1: Last SCORM Completion Date | AI1: Last SCORM Visit Date
A2: 7034 | B2: T2-25_BDSDF106 | C2: Data Structures for Data Science | D2: BS - Data Science &amp; AI | E2: dept_bs_dsai | F2: 6653 | G2: sem_trimester 2 | H2: Trimester 2 | I2: 2025eb1100001@bitspilani-digital.edu.in | J2: 2025EB1100001 | K2: RUDRA SHARMA | L2: . | M2: TRUE | N2: 120 | O2: BITS Learner | P2: 1 | Q2: 154 | R2: 0 | S2: 1 | T2: 1 | U2: 0 | V2: 0 | W2: 0 | Y2: 0 | AA2: 0 | AB2: 2026-02-08T09:13:59.9530000Z | AC2: 2026-02-09T11:45:19.5500000Z | AD2: 168 | AF2: 2026-02-08T09:04:03.4030000Z | AG2: 2026-02-08
A3: 7035 | B3: T2-25_BDSDF102 | C3: Data Preprocessing (BS) | D3: BS - Data Science &amp; AI | E3: dept_bs_dsai | F3: 6653 | G3: sem_trimester 2 | H3: Trimester 2 | I3: 2025eb1100001@bitspilani-digital.edu.in | J3: 2025EB1100001 | K3: RUDRA SHARMA | L3: . | M3: TRUE | N3: 120 | O3: BITS Learner | P3: 6 | Q3: 158 | R3: 0 | S3: 2 | T3: 3 | U3: 0 | V3: 0 | W3: 0 | Y3: 0 | AA3: 17096 | AB3: 2026-02-08T09:20:40.1530000Z | AC3: 2026-02-09T11:45:19.5500000Z | AD3: 168 | AF3: 2026-02-08T09:20:32.9730000Z | AG3: 2026-02-08
A4: 7033 | B4: T2-25_BDSDF110 | C4: Linear Algebra | D4: BS - Data Science &amp; AI | E4: dept_bs_dsai | F4: 6653 | G4: sem_trimester 2 | H4: Trimester 2 | I4: 2025eb1100001@bitspilani-digital.edu.in | J4: 2025EB1100001 | K4: RUDRA SHARMA | L4: . | M4: TRUE | N4: 120 | O4: BITS Learner | P4: 3 | Q4: 86 | R4: 0 | S4: 1 | T4: 1 | U4: 0 | V4: 0 | W4: 0 | Y4: 0 | AA4: 27 | AB4: 2026-02-08T09:12:57.6770000Z | AC4: 2026-02-09T11:45:19.5500000Z | AD4: 168 | AF4: 2026-02-08T09:12:53.8070000Z | AG4: 2026-02-08 | AH4: 2026-01-23T15:01:45.2470000Z | AI4: 2026-01-23T15:01:48.8770000Z
A5: 7025 | B5: T2-25_BDSDF108 | C5: Computing Systems | D5: BS - Data Science &amp; AI | E5: dept_bs_dsai | F5: 6653 | G5: sem_trimester 2 | H5: Trimester 2 | I5: 2025eb1100001@bitspilani-digital.edu.in | J5: 2025EB1100001 | K5: RUDRA SHARMA | L5: . | M5: TRUE | N5: 120 | O5: BITS Learner | P5: 105 | Q5: 267 | R5: 0 | S5: 35 | T5: 57 | U5: 0 | V5: 0 | W5: 0 | Y5: 0 | AA5: 2449 | AB5: 2026-02-09T12:25:12.1930000Z | AC5: 2026-02-09T11:45:19.5500000Z | AD5: 168 | AF5: 2026-02-09T12:25:03.4370000Z | AG5: 2026-02-09 | AH5: 2026-02-09T11:46:54.2770000Z | AI5: 2026-02-09T11:46:54.2730000Z
A6: 7035 | B6: T2-25_BDSDF102 | C6: Data Preprocessing (BS) | D6: BS - Data Science &amp; AI | E6: dept_bs_dsai | F6: 6653 | G6: sem_trimester 2 | H6: Trimester 2 | I6: 2025eb1100003@bitspilani-digital.edu.in | J6: 2025EB1100003 | K6: AJAYACHANDRAN.E | L6: . | M6: TRUE | N6: 120 | O6: BITS Learner | P6: 45 | Q6: 158 | R6: 0 | S6: 6 | T6: 8 | U6: 3 | V6: 0 | W6: 0 | X6: 2026-02-07T23:08:17.5300000Z | Y6: 0 | AA6: 24234 | AB6: 2026-02-09T00:32:41.3400000Z | AC6: 2026-02-08T23:02:38.0030000Z | AD6: 115 | AF6: 2026-02-09T00:31:45.6730000Z | AG6: 2026-02-09
A7: 7033 | B7: T2-25_BDSDF110 | C7: Linear Algebra | D7: BS - Data Science &amp; AI | E7: dept_bs_dsai | F7: 6653 | G7: sem_trimester 2 | H7: Trimester 2 | I7: 2025eb1100006@bitspilani-digital.edu.in | J7: 2025EB1100006 | K7: JAL PATEL | L7: . | M7: TRUE | N7: 120 | O7: BITS Learner | P7: 1 | Q7: 86 | R7: 0 | S7: 1 | T7: 1 | U7: 0 | V7: 0 | W7: 0 | Y7: 0 | AA7: 0 | AB7: 2026-02-08T08:16:42.7600000Z | AC7: 2026-02-08T07:51:39.3430000Z | AD7: 73 | AF7: 2026-02-08T08:12:38.5830000Z | AG7: 2026-02-08
A8: 7034 | B8: T2-25_BDSDF106 | C8: Data Structures for Data Science | D8: BS - Data Science &amp; AI | E8: dept_bs_dsai | F8: 6653 | G8: sem_trimester 2 | H8: Trimester 2 | I8: 2025eb1100006@bitspilani-digital.edu.in | J8: 2025EB1100006 | K8: JAL PATEL | L8: . | M8: TRUE | N8: 120 | O8: BITS Learner | P8: 1 | Q8: 154 | R8: 0 | S8: 1 | T8: 1 | U8: 0 | V8: 0 | W8: 0 | Y8: 0 | AA8: 0 | AB8: 2026-02-08T08:17:33.9070000Z | AC8: 2026-02-08T07:51:39.3430000Z | AD8: 73 | AF8: 2026-02-08T08:15:45.7230000Z | AG8: 2026-02-08
A9: 7021 | B9: T2-25_BDSDF113 | C9: Computer Programming | D9: BS - Data Science &amp; AI | E9: dept_bs_dsai | F9: 6653 | G9: sem_trimester 2 | H9: Trimester 2 | I9: 2025eb1100007@bitspilani-digital.edu.in | J9: 2025EB1100007 | K9: HARSHVARDHAN SINGH | L9: . | M9: TRUE | N9: 120 | O9: BITS Learner | P9: 10 | Q9: 356 | R9: 0 | S9: 4 | T9: 4 | U9: 0 | V9: 0 | W9: 0 | Y9: 0 | AA9: 24662 | AB9: 2026-02-08T02:54:21.2930000Z | AC9: 2026-02-09T00:57:34.8670000Z | AD9: 67 | AF9: 2026-02-08T02:54:12.8470000Z | AG9: 2026-02-08 | AH9: 2026-01-30T14:05:06.5370000Z | AI9: 2026-02-05T07:23:03.0770000Z
A10: 7022 | B10: T2-25_BDSDF114 | C10: Probability & Statistics | D10: BS - Data Science &amp; AI | E10: dept_bs_dsai | F10: 6653 | G10: sem_trimester 2 | H10: Trimester 2 | I10: 2025eb1100007@bitspilani-digital.edu.in | J10: 2025EB1100007 | K10: HARSHVARDHAN SINGH | L10: . | M10: TRUE | N10: 120 | O10: BITS Learner | P10: 1 | Q10: 326 | R10: 0 | S10: 1 | T10: 1 | U10: 0 | V10: 0 | W10: 0 | Y10: 0 | AA10: 0 | AB10: 2026-02-08T02:56:47.4770000Z | AC10: 2026-02-09T00:57:34.8670000Z | AD10: 67 | AF10: 2026-02-08T02:56:43.8530000Z | AG10: 2026-02-08
A11: 7025 | B11: T2-25_BDSDF108 | C11: Computing Systems | D11: BS - Data Science &amp; AI | E11: dept_bs_dsai | F11: 6653 | G11: sem_trimester 2 | H11: Trimester 2 | I11: 2025eb1100007@bitspilani-digital.edu.in | J11: 2025EB1100007 | K11: HARSHVARDHAN SINGH | L11: . | M11: TRUE | N11: 120 | O11: BITS Learner | P11: 1 | Q11: 267 | R11: 0 | S11: 1 | T11: 1 | U11: 0 | V11: 0 | W11: 0 | Y11: 0 | AA11: 0 | AB11: 2026-02-08T03:02:53.3470000Z | AC11: 2026-02-09T00:57:34.8670000Z | AD11: 67 | AF11: 2026-02-08T03:02:49.6200000Z | AG11: 2026-02-08
A12: 7034 | B12: T2-25_BDSDF106 | C12: Data Structures for Data Science | D12: BS - Data Science &amp; AI | E12: dept_bs_dsai | F12: 6653 | G12: sem_trimester 2 | H12: Trimester 2 | I12: 2025eb1100014@bitspilani-digital.edu.in | J12: 2025EB1100014 | K12: SURYA A | L12: . | M12: TRUE | N12: 120 | O12: BITS Learner | P12: 61 | Q12: 154 | R12: 0 | S12: 8 | T12: 8 | U12: 0 | V12: 0 | W12: 0 | Y12: 0 | AA12: 52849 | AB12: 2026-02-09T15:46:33.2500000Z | AC12: 2026-02-09T15:44:09.7300000Z | AD12: 200 | AF12: 2026-02-09T15:46:22.7570000Z | AG12: 2026-02-09 | AH12: 2026-01-19T09:41:03.9430000Z | AI12: 2026-01-28T20:04:48.0130000Z
A13: 7022 | B13: T2-25_BDSDF114 | C13: Probability & Statistics | D13: BS - Data Science &amp; AI | E13: dept_bs_dsai | F13: 6653 | G13: sem_trimester 2 | H13: Trimester 2 | I13: 2025eb1100014@bitspilani-digital.edu.in | J13: 2025EB1100014 | K13: SURYA A | L13: . | M13: TRUE | N13: 120 | O13: BITS Learner | P13: 13 | Q13: 326 | R13: 0 | S13: 2 | T13: 3 | U13: 0 | V13: 0 | W13: 0 | Y13: 0 | AA13: 7223 | AB13: 2026-02-09T15:49:52.3800000Z | AC13: 2026-02-09T15:44:09.7300000Z | AD13: 200 | AF13: 2026-02-09T15:49:48.9800000Z | AG13: 2026-02-09 | AH13: 2026-01-21T10:07:30.9030000Z | AI13: 2026-01-21T10:07:30.9130000Z
A14: 7034 | B14: T2-25_BDSDF106 | C14: Data Structures for Data Science | D14: BS - Data Science &amp; AI | E14: dept_bs_dsai | F14: 6653 | G14: sem_trimester 2 | H14: Trimester 2 | I14: 2025eb1100015@bitspilani-digital.edu.in | J14: 2025EB1100015 | K14: TADIMALLA ADITI | L14: . | M14: TRUE | N14: 120 | O14: BITS Learner | P14: 13 | Q14: 154 | R14: 0 | S14: 4 | T14: 4 | U14: 0 | V14: 0 | W14: 0 | Y14: 0 | AA14: 43739 | AB14: 2026-02-10T03:06:34.9530000Z | AC14: 2026-02-10T03:06:30.3670000Z | AD14: 239 | AF14: 2026-02-08T17:30:39.1400000Z | AG14: 2026-02-08 | AH14: 2026-02-10T03:20:58.8370000Z | AI14: 2026-02-10T03:20:58.8400000Z
A15: 7033 | B15: T2-25_BDSDF110 | C15: Linear Algebra | D15: BS - Data Science &amp; AI | E15: dept_bs_dsai | F15: 6653 | G15: sem_trimester 2 | H15: Trimester 2 | I15: 2025eb1100015@bitspilani-digital.edu.in | J15: 2025EB1100015 | K15: TADIMALLA ADITI | L15: . | M15: TRUE | N15: 120 | O15: BITS Learner | P15: 41 | Q15: 86 | R15: 0 | S15: 12 | T15: 12 | U15: 0 | V15: 0 | W15: 0 | Y15: 0 | AA15: 7515 | AB15: 2026-02-09T14:17:22.6930000Z | AC15: 2026-02-10T03:06:30.3670000Z | AD15: 239 | AF15: 2026-02-09T14:16:46.7530000Z | AG15: 2026-02-09 | AH15: 2026-02-09T03:13:18.3970000Z | AI15: 2026-02-09T03:13:18.3930000Z
A16: 7033 | B16: T2-25_BDSDF110 | C16: Linear Algebra | D16: BS - Data Science &amp; AI | E16: dept_bs_dsai | F16: 6653 | G16: sem_trimester 2 | H16: Trimester 2 | I16: 2025eb1100018@bitspilani-digital.edu.in | J16: 2025EB1100018 | K16: NIMMAGANTI SUMAHE | L16: . | M16: TRUE | N16: 120 | O16: BITS Learner | P16: 61 | Q16: 86 | R16: 0 | S16: 16 | T16: 17 | U16: 4 | V16: 0 | W16: 0 | X16: 2026-02-08T20:09:50.6830000Z | Y16: 0 | AA16: 25463 | AB16: 2026-02-09T12:51:37.3100000Z | AC16: 2026-02-09T12:50:53.0830000Z | AD16: 322 | AF16: 2026-02-08T20:01:37.7070000Z | AG16: 2026-02-08 | AH16: 2026-02-08T20:01:57.0970000Z | AI16: 2026-02-08T20:01:57.0970000Z
A17: 7035 | B17: T2-25_BDSDF102 | C17: Data Preprocessing (BS) | D17: BS - Data Science &amp; AI | E17: dept_bs_dsai | F17: 6653 | G17: sem_trimester 2 | H17: Trimester 2 | I17: 2025eb1100018@bitspilani-digital.edu.in | J17: 2025EB1100018 | K17: NIMMAGANTI SUMAHE | L17: . | M17: TRUE | N17: 120 | O17: BITS Learner | P17: 81 | Q17: 158 | R17: 0 | S17: 27 | T17: 27 | U17: 0 | V17: 0 | W17: 0 | Y17: 0 | AA17: 28046 | AB17: 2026-02-08T20:10:27.6930000Z | AC17: 2026-02-09T12:50:53.0830000Z | AD17: 322 | AF17: 2026-02-08T14:32:46.4930000Z | AG17: 2026-02-08
A18: 7034 | B18: T2-25_BDSDF106 | C18: Data Structures for Data Science | D18: BS - Data Science &amp; AI | E18: dept_bs_dsai | F18: 6653 | G18: sem_trimester 2 | H18: Trimester 2 | I18: 2025eb1100018@bitspilani-digital.edu.in | J18: 2025EB1100018 | K18: NIMMAGANTI SUMAHE | L18: . | M18: TRUE | N18: 120 | O18: BITS Learner | P18: 91 | Q18: 154 | R18: 0 | S18: 30 | T18: 30 | U18: 0 | V18: 0 | W18: 0 | Y18: 0 | AA18: 29105 | AB18: 2026-02-09T12:52:05.5470000Z | AC18: 2026-02-09T12:50:53.0830000Z | AD18: 322 | AF18: 2026-02-08T14:26:36.0170000Z | AG18: 2026-02-08 | AH18: 2026-02-05T18:26:03.1070000Z | AI18: 2026-02-05T18:36:20.5400000Z
A19: 7022 | B19: T2-25_BDSDF114 | C19: Probability & Statistics | D19: BS - Data Science &amp; AI | E19: dept_bs_dsai | F19: 6653 | G19: sem_trimester 2 | H19: Trimester 2 | I19: 2025eb1100019@bitspilani-digital.edu.in | J19: 2025EB1100019 | K19: NITISH KUMAR | L19: . | M19: TRUE | N19: 120 | O19: BITS Learner | P19: 6 | Q19: 326 | R19: 0 | S19: 1 | T19: 1 | U19: 0 | V19: 0 | W19: 0 | Y19: 0 | AA19: 763 | AB19: 2026-02-08T15:01:55.8400000Z | AC19: 2026-02-09T18:25:38.1170000Z | AD19: 124 | AF19: 2026-02-08T15:01:36.1370000Z | AG19: 2026-02-08
A20: 7025 | B20: T2-25_BDSDF108 | C20: Computing Systems | D20: BS - Data Science &amp; AI | E20: dept_bs_dsai | F20: 6653 | G20: sem_trimester 2 | H20: Trimester 2 | I20: 2025eb1100019@bitspilani-digital.edu.in | J20: 2025EB1100019 | K20: NITISH KUMAR | L20: . | M20: TRUE | N20: 120 | O20: BITS Learner | P20: 15 | Q20: 267 | R20: 0 | S20: 4 | T20: 4 | U20: 0 | V20: 0 | W20: 0 | Y20: 0 | AA20: 9984 | AB20: 2026-02-09T20:04:12.7870000Z | AC20: 2026-02-09T18:25:38.1170000Z | AD20: 124 | AF20: 2026-02-09T20:04:02.3630000Z | AG20: 2026-02-09 | AH20: 2026-02-09T20:04:23.7470000Z | AI20: 2026-02-09T20:04:23.7400000Z
A21: 7025 | B21: T2-25_BDSDF108 | C21: Computing Systems | D21: BS - Data Science &amp; AI | E21: dept_bs_dsai | F21: 6653 | G21: sem_trimester 2 | H21: Trimester 2 | I21: 2025eb1100020@bitspilani-digital.edu.in | J21: 2025EB1100020 | K21: AYUSH JHA | L21: . | M21: TRUE | N21: 120 | O21: BITS Learner | P21: 5 | Q21: 267 | R21: 0 | S21: 1 | T21: 1 | U21: 0 | V21: 0 | W21: 0 | Y21: 0 | AA21: 66 | AB21: 2026-02-08T13:56:05.5670000Z | AC21: 2026-02-09T07:21:41.8230000Z | AD21: 77 | AF21: 2026-02-08T13:55:34.7400000Z | AG21: 2026-02-08 | AH21: 2026-01-24T15:44:23.2600000Z | AI21: 2026-01-24T15:44:23.2670000Z
A22: 7022 | B22: T2-25_BDSDF114 | C22: Probability & Statistics | D22: BS - Data Science &amp; AI | E22: dept_bs_dsai | F22: 6653 | G22: sem_trimester 2 | H22: Trimester 2 | I22: 2025eb1100020@bitspilani-digital.edu.in | J22: 2025EB1100020 | K22: AYUSH JHA | L22: . | M22: TRUE | N22: 120 | O22: BITS Learner | P22: 1 | Q22: 326 | R22: 0 | S22: 1 | T22: 1 | U22: 0 | V22: 0 | W22: 0 | Y22: 0 | AA22: 0 | AB22: 2026-02-08T13:45:37.9530000Z | AC22: 2026-02-09T07:21:41.8230000Z | AD22: 77 | AF22: 2026-02-08T13:45:25.1370000Z | AG22: 2026-02-08
A23: 7021 | B23: T2-25_BDSDF113 | C23: Computer Programming | D23: BS - Data Science &amp; AI | E23: dept_bs_dsai | F23: 6653 | G23: sem_trimester 2 | H23: Trimester 2 | I23: 2025eb1100020@bitspilani-digital.edu.in | J23: 2025EB1100020 | K23: AYUSH JHA | L23: . | M23: TRUE | N23: 120 | O23: BITS Learner | P23: 21 | Q23: 356 | R23: 0 | S23: 6 | T23: 8 | U23: 0 | V23: 0 | W23: 0 | Y23: 0 | AA23: 4646 | AB23: 2026-02-09T07:22:11.7630000Z | AC23: 2026-02-09T07:21:41.8230000Z | AD23: 77 | AF23: 2026-02-08T13:37:04.5700000Z | AG23: 2026-02-08 | AH23: 2026-02-09T07:41:28.0400000Z | AI23: 2026-02-09T07:41:28.0400000Z
A24: 7034 | B24: T2-25_BDSDF106 | C24: Data Structures for Data Science | D24: BS - Data Science &amp; AI | E24: dept_bs_dsai | F24: 6653 | G24: sem_trimester 2 | H24: Trimester 2 | I24: 2025eb1100021@bitspilani-digital.edu.in | J24: 2025EB1100021 | K24: R KUSHAL MEHTA | L24: . | M24: TRUE | N24: 120 | O24: BITS Learner | P24: 23 | Q24: 154 | R24: 0 | S24: 6 | T24: 7 | U24: 0 | V24: 0 | W24: 0 | Y24: 0 | AA24: 7042 | AB24: 2026-02-10T05:22:24.8300000Z | AC24: 2026-02-10T05:04:12.6300000Z | AD24: 274 | AF24: 2026-02-10T05:22:18.0230000Z | AG24: 2026-02-10 | AH24: 2026-02-04T11:22:17.7870000Z | AI24: 2026-02-05T12:29:06.3170000Z
A25: 7035 | B25: T2-25_BDSDF102 | C25: Data Preprocessing (BS) | D25: BS - Data Science &amp; AI | E25: dept_bs_dsai | F25: 6653 | G25: sem_trimester 2 | H25: Trimester 2 | I25: 2025eb1100021@bitspilani-digital.edu.in | J25: 2025EB1100021 | K25: R KUSHAL MEHTA | L25: . | M25: TRUE | N25: 120 | O25: BITS Learner | P25: 29 | Q25: 158 | R25: 0 | S25: 8 | T25: 10 | U25: 0 | V25: 0 | W25: 0 | Y25: 0 | AA25: 13207 | AB25: 2026-02-10T05:27:57.6630000Z | AC25: 2026-02-10T05:04:12.6300000Z | AD25: 274 | AF25: 2026-02-10T05:27:09.6830000Z | AG25: 2026-02-10
A26: 7033 | B26: T2-25_BDSDF110 | C26: Linear Algebra | D26: BS - Data Science &amp; AI | E26: dept_bs_dsai | F26: 6653 | G26: sem_trimester 2 | H26: Trimester 2 | I26: 2025eb1100021@bitspilani-digital.edu.in | J26: 2025EB1100021 | K26: R KUSHAL MEHTA | L26: . | M26: TRUE | N26: 120 | O26: BITS Learner | P26: 7 | Q26: 86 | R26: 0 | S26: 1 | T26: 1 | U26: 0 | V26: 0 | W26: 0 | Y26: 0 | AA26: 1150 | AB26: 2026-02-10T05:18:21.8000000Z | AC26: 2026-02-10T05:04:12.6300000Z | AD26: 274 | AF26: 2026-02-10T05:18:16.5670000Z | AG26: 2026-02-10 | AH26: 2026-01-29T13:05:35.3030000Z | AI26: 2026-01-29T13:05:35.3030000Z
A27: 7021 | B27: T2-25_BDSDF113 | C27: Computer Programming | D27: BS - Data Science &amp; AI | E27: dept_bs_dsai | F27: 6653 | G27: sem_trimester 2 | H27: Trimester 2 | I27: 2025eb1100024@bitspilani-digital.edu.in | J27: 2025EB1100024 | K27: SHOORSEN THIRUNAVUKKARASU K | L27: . | M27: TRUE | N27: 120 | O27: BITS Learner | P27: 13 | Q27: 356 | R27: 0 | S27: 4 | T27: 8 | U27: 0 | V27: 0 | W27: 0 | Y27: 0 | AA27: 1785 | AB27: 2026-02-08T06:56:25.9930000Z | AC27: 2026-02-08T06:51:55.3800000Z | AD27: 112 | AF27: 2026-02-08T06:55:52.9500000Z | AG27: 2026-02-08 | AH27: 2026-01-29T14:37:14.7270000Z | AI27: 2026-01-29T14:37:14.7370000Z
A28: 7033 | B28: T2-25_BDSDF110 | C28: Linear Algebra | D28: BS - Data Science &amp; AI | E28: dept_bs_dsai | F28: 6653 | G28: sem_trimester 2 | H28: Trimester 2 | I28: 2025eb1100024@bitspilani-digital.edu.in | J28: 2025EB1100024 | K28: SHOORSEN THIRUNAVUKKARASU K | L28: . | M28: TRUE | N28: 120 | O28: BITS Learner | P28: 9 | Q28: 86 | R28: 0 | S28: 3 | T28: 3 | U28: 0 | V28: 0 | W28: 0 | Y28: 0 | AA28: 4129 | AB28: 2026-02-08T06:59:50.3870000Z | AC28: 2026-02-08T06:51:55.3800000Z | AD28: 112 | AF28: 2026-02-08T06:59:45.8830000Z | AG28: 2026-02-08 | AH28: 2026-01-27T13:34:45.6630000Z | AI28: 2026-01-27T13:34:45.6730000Z
A29: 7035 | B29: T2-25_BDSDF102 | C29: Data Preprocessing (BS) | D29: BS - Data Science &amp; AI | E29: dept_bs_dsai | F29: 6653 | G29: sem_trimester 2 | H29: Trimester 2 | I29: 2025eb1100026@bitspilani-digital.edu.in | J29: 2025EB1100026 | K29: SWARUP KUMAR PRADHAN | L29: . | M29: TRUE | N29: 120 | O29: BITS Learner | P29: 11 | Q29: 158 | R29: 0 | S29: 4 | T29: 4 | U29: 0 | V29: 0 | W29: 0 | Y29: 0 | AA29: 1740 | AB29: 2026-02-09T14:14:51.3630000Z | AC29: 2026-02-10T03:49:59.1170000Z | AD29: 264 | AF29: 2026-02-08T03:31:43.2300000Z | AG29: 2026-02-08
A30: 7034 | B30: T2-25_BDSDF106 | C30: Data Structures for Data Science | D30: BS - Data Science &amp; AI | E30: dept_bs_dsai | F30: 6653 | G30: sem_trimester 2 | H30: Trimester 2 | I30: 2025eb1100026@bitspilani-digital.edu.in | J30: 2025EB1100026 | K30: SWARUP KUMAR PRADHAN | L30: . | M30: TRUE | N30: 120 | O30: BITS Learner | P30: 1 | Q30: 154 | R30: 0 | S30: 1 | T30: 1 | U30: 0 | V30: 0 | W30: 0 | Y30: 0 | AA30: 0 | AB30: 2026-02-09T14:05:27.6470000Z | AC30: 2026-02-10T03:49:59.1170000Z | AD30: 264 | AF30: 2026-02-08T03:21:54.7530000Z | AG30: 2026-02-08
A31: 7033 | B31: T2-25_BDSDF110 | C31: Linear Algebra | D31: BS - Data Science &amp; AI | E31: dept_bs_dsai | F31: 6653 | G31: sem_trimester 2 | H31: Trimester 2 | I31: 2025eb1100026@bitspilani-digital.edu.in | J31: 2025EB1100026 | K31: SWARUP KUMAR PRADHAN | L31: . | M31: TRUE | N31: 120 | O31: BITS Learner | P31: 2 | Q31: 86 | R31: 0 | S31: 2 | T31: 2 | U31: 0 | V31: 0 | W31: 0 | Y31: 0 | AA31: 31 | AB31: 2026-02-09T14:06:20.6100000Z | AC31: 2026-02-10T03:49:59.1170000Z | AD31: 264 | AF31: 2026-02-08T04:14:05.3230000Z | AG31: 2026-02-08
A32: 7035 | B32: T2-25_BDSDF102 | C32: Data Preprocessing (BS) | D32: BS - Data Science &amp; AI | E32: dept_bs_dsai | F32: 6653 | G32: sem_trimester 2 | H32: Trimester 2 | I32: 2025eb1100030@bitspilani-digital.edu.in | J32: 2025EB1100030 | K32: KAYITHOJU PRAVARAKYA | L32: . | M32: TRUE | N32: 120 | O32: BITS Learner | P32: 6 | Q32: 158 | R32: 0 | S32: 1 | T32: 1 | U32: 0 | V32: 0 | W32: 0 | Y32: 0 | AA32: 10984 | AB32: 2026-02-09T20:38:48.6800000Z | AC32: 2026-02-09T16:10:18.7430000Z | AD32: 208 | AF32: 2026-02-09T20:38:41.0670000Z | AG32: 2026-02-09
A33: 7034 | B33: T2-25_BDSDF106 | C33: Data Structures for Data Science | D33: BS - Data Science &amp; AI | E33: dept_bs_dsai | F33: 6653 | G33: sem_trimester 2 | H33: Trimester 2 | I33: 2025eb1100030@bitspilani-digital.edu.in | J33: 2025EB1100030 | K33: KAYITHOJU PRAVARAKYA | L33: . | M33: TRUE | N33: 120 | O33: BITS Learner | P33: 3 | Q33: 154 | R33: 0 | S33: 1 | T33: 1 | U33: 0 | V33: 0 | W33: 0 | Y33: 0 | AA33: 0 | AB33: 2026-02-09T13:57:00.1600000Z | AC33: 2026-02-09T16:10:18.7430000Z | AD33: 208 | AF33: 2026-02-09T13:56:51.3730000Z | AG33: 2026-02-09
A34: 7033 | B34: T2-25_BDSDF110 | C34: Linear Algebra | D34: BS - Data Science &amp; AI | E34: dept_bs_dsai | F34: 6653 | G34: sem_trimester 2 | H34: Trimester 2 | I34: 2025eb1100030@bitspilani-digital.edu.in | J34: 2025EB1100030 | K34: KAYITHOJU PRAVARAKYA | L34: . | M34: TRUE | N34: 120 | O34: BITS Learner | P34: 4 | Q34: 86 | R34: 0 | S34: 1 | T34: 1 | U34: 0 | V34: 0 | W34: 0 | Y34: 0 | AA34: 152 | AB34: 2026-02-09T20:38:58.8900000Z | AC34: 2026-02-09T16:10:18.7430000Z | AD34: 208 | AF34: 2026-02-09T13:34:51.6500000Z | AG34: 2026-02-09 | AH34: 2026-01-18T15:51:45.8970000Z | AI34: 2026-01-18T15:51:45.8830000Z
A35: 7033 | B35: T2-25_BDSDF110 | C35: Linear Algebra | D35: BS - Data Science &amp; AI | E35: dept_bs_dsai | F35: 6653 | G35: sem_trimester 2 | H35: Trimester 2 | I35: 2025eb1100031@bitspilani-digital.edu.in | J35: 2025EB1100031 | K35: KUCHI SAMANVI | L35: . | M35: TRUE | N35: 120 | O35: BITS Learner | P35: 22 | Q35: 86 | R35: 0 | S35: 5 | T35: 6 | U35: 0 | V35: 0 | W35: 0 | Y35: 0 | AA35: 6741 | AB35: 2026-02-09T08:44:26.2100000Z | AC35: 2026-02-09T08:34:26.3900000Z | AD35: 89 | AF35: 2026-02-09T08:44:21.7200000Z | AG35: 2026-02-09 | AH35: 2026-01-19T20:46:39.0970000Z | AI35: 2026-01-19T20:56:27.9530000Z
A36: 7034 | B36: T2-25_BDSDF106 | C36: Data Structures for Data Science | D36: BS - Data Science &amp; AI | E36: dept_bs_dsai | F36: 6653 | G36: sem_trimester 2 | H36: Trimester 2 | I36: 2025eb1100031@bitspilani-digital.edu.in | J36: 2025EB1100031 | K36: KUCHI SAMANVI | L36: . | M36: TRUE | N36: 120 | O36: BITS Learner | P36: 3 | Q36: 154 | R36: 0 | S36: 1 | T36: 1 | U36: 0 | V36: 0 | W36: 0 | Y36: 0 | AA36: 34 | AB36: 2026-02-09T08:48:24.4200000Z | AC36: 2026-02-09T08:34:26.3900000Z | AD36: 89 | AF36: 2026-02-09T08:48:23.4270000Z | AG36: 2026-02-09
A37: 7035 | B37: T2-25_BDSDF102 | C37: Data Preprocessing (BS) | D37: BS - Data Science &amp; AI | E37: dept_bs_dsai | F37: 6653 | G37: sem_trimester 2 | H37: Trimester 2 | I37: 2025eb1100031@bitspilani-digital.edu.in | J37: 2025EB1100031 | K37: KUCHI SAMANVI | L37: . | M37: TRUE | N37: 120 | O37: BITS Learner | P37: 26 | Q37: 158 | R37: 0 | S37: 6 | T37: 6 | U37: 0 | V37: 0 | W37: 0 | Y37: 0 | AA37: 20009 | AB37: 2026-02-09T08:53:00.2300000Z | AC37: 2026-02-09T08:34:26.3900000Z | AD37: 89 | AF37: 2026-02-09T08:52:52.3970000Z | AG37: 2026-02-09
A38: 7035 | B38: T2-25_BDSDF102 | C38: Data Preprocessing (BS) | D38: BS - Data Science &amp; AI | E38: dept_bs_dsai | F38: 6653 | G38: sem_trimester 2 | H38: Trimester 2 | I38: 2025eb1100032@bitspilani-digital.edu.in | J38: 2025EB1100032 | K38: GANESH ANKIT | L38: . | M38: TRUE | N38: 120 | O38: BITS Learner | P38: 68 | Q38: 158 | R38: 0 | S38: 18 | T38: 19 | U38: 0 | V38: 0 | W38: 0 | Y38: 0 | AA38: 354 | AB38: 2026-02-08T11:58:58.7570000Z | AC38: 2026-02-08T11:36:33.8600000Z | AD38: 126 | AF38: 2026-02-08T11:57:40.1230000Z | AG38: 2026-02-08
A39: 7034 | B39: T2-25_BDSDF106 | C39: Data Structures for Data Science | D39: BS - Data Science &amp; AI | E39: dept_bs_dsai | F39: 6653 | G39: sem_trimester 2 | H39: Trimester 2 | I39: 2025eb1100032@bitspilani-digital.edu.in | J39: 2025EB1100032 | K39: GANESH ANKIT | L39: . | M39: TRUE | N39: 120 | O39: BITS Learner | P39: 98 | Q39: 154 | R39: 0 | S39: 20 | T39: 20 | U39: 1 | V39: 0 | W39: 0 | X39: 2026-02-08T11:45:58.0400000Z | Y39: 0 | AA39: 2827 | AB39: 2026-02-08T11:51:35.5700000Z | AC39: 2026-02-08T11:36:33.8600000Z | AD39: 126 | AF39: 2026-02-08T11:51:25.2600000Z | AG39: 2026-02-08 | AH39: 2026-01-24T06:46:47.5170000Z | AI39: 2026-01-24T06:46:49.3930000Z
A40: 7033 | B40: T2-25_BDSDF110 | C40: Linear Algebra | D40: BS - Data Science &amp; AI | E40: dept_bs_dsai | F40: 6653 | G40: sem_trimester 2 | H40: Trimester 2 | I40: 2025eb1100032@bitspilani-digital.edu.in | J40: 2025EB1100032 | K40: GANESH ANKIT | L40: . | M40: TRUE | N40: 120 | O40: BITS Learner | P40: 45 | Q40: 86 | R40: 0 | S40: 5 | T40: 5 | U40: 1 | V40: 0 | W40: 0 | X40: 2026-02-08T11:38:55.9270000Z | Y40: 0 | AA40: 505 | AB40: 2026-02-08T11:43:24.0200000Z | AC40: 2026-02-08T11:36:33.8600000Z | AD40: 126 | AF40: 2026-02-08T11:43:07.4570000Z | AG40: 2026-02-08 | AH40: 2026-01-24T06:48:02.5530000Z | AI40: 2026-01-24T06:48:05.0470000Z
...

Sheet Sheet3
A1: LIVE SESSION ATTENDANCE
A2: BS (T-2 C-1) & (T-1 C-2) | C2: Trimester-1 (C-2 Jan-2026) (New) | D2: Trimester-2 (C-1 Sep-2025) (Old) | E2: Total
A3: Course | B3: Faculty
A4: Probability & Statistics | B4: Dr. Pushpendra | C4: 109 | D4: 68 | E4: 177
A5: Computer Programming | B5: Dr. Jagat Sesh Challa | C5: 109 | D5: 61 | E5: 170
A6: Writing Practice | B6: Solanki chakraborty | C6: 109 | D6: 25 | E6: 134
A7: Data and the World | B7: Deepankar Garg | C7: 109 | D7: 51 | E7: 160
A8: Computing Systems | B8: Prof. SUNIL KUMAR TEGGIHALLU | C8: 109 | D8: 84 | E8: 193
A11: BS (T-2 C-1) | D11: Trimester-2 (C-1 Sep-2025) (Old) | E11: Total
A12: Course | B12: Faculty
A13: Linear Algebra | B13: Vaibhav Mehandiratta (Goa campus) | D13: 188 | E13: 188
A14: Fundamentals of Data Science and Engineering | B14: Priyanka Banerjee | D14: 176 | E14: 176
A15: Data Structures for Data Science | B15: Jagat Sesh Challa | D15: 160 | E15: 160
A16: Data Preprocessing | B16: Swapnil Saurav | D16: 154 | E16: 154
A19: MSc (T-2 C-1) & (T-1 C-2) | C19: Trimester-1 (C-2 Jan-2026) (New) | D19: Trimester-2 (C-1 Sep-2025) (Old) | E19: Total
A20: Course | B20: Faculty
A21: Statistical Modelling & Inferencing | B21: Dr. Pushpendra Gupta | C21: 356 | D21: 39 | E21: 395
A22: Data Pre-processing (MSc) | B22: Dr. Hemant Rathore | C22: 356 | D22: 33 | E22: 389
A23: Data Visualization & Storytelling | B23: ACV Subrahmaniam | C23: 356 | D23: 34 | E23: 390
A24: Feature Engineering | B24: Prof Naga | C24: 356 | D24: 33 | E24: 389
A26: MSc (T-2 C-1) | C26: Trimester-2 (C-1 Sep-2025) (New courses) | D26: Trimester-2 (C-1 Sep-2025) (Old Courses) | E26: Total
A27: Course | B27: Faculty
A28: Machine Learning | B28: Dr. Hemant Rathore | C28: 350 | E28: 350
A29: Artificial Neural Networks | B29: Deepanshi Seth | C29: 352 | E29: 352
A30: Data Stores & Pipelines | B30: Prof. Praveen | D30: 17 | E30: 17
A31: Cloud Services & Platforms | B31: Mohammad Anees Alam | C31: 357 | E31: 357
A32: Data Annotations and Labelling | B32: Utkarsh Khare | C32: 0 | D32: 0
A34: MATHS | C34: (C-2 Jan-2026) (New)
A35: Course | B35: Faculty
A36: Basic Mathematics | B36: Rahul Dhakad | C36: 77 | E36: 77
A38: Python | C38: (C-2 Jan-2026) (New)
A39: Course | B39: Faculty
A40: Python Programming | B40: MAHIPAL SINGH | C40: 35 | E40: 35
A42: Professional Certificate in AI Engg. and MLOps | C42: (C-2 Jan-2026) (New)
A43: Course | B43: Faculty
A44: Applied AI Engineering Foundations | B44: Prof. Prasad and Ms. Ankita | C44: 99 | E44: 99
