Workbook
Name Slicer_CP_Quiz___Assignment_Status: #N/A
Name Slicer_CS_Quiz___Assignment_Status: #N/A
Name Slicer_DPP_Quiz___Assignment_Status: #N/A
Name Slicer_DSP_Quiz___Assignment_Status: #N/A
Name Slicer_DVS_Quiz___Assignment_Status: #N/A
Name Slicer_FE_Quiz___Assignment_Status: #N/A
Name Slicer_PS_Quiz___Assignment_Status: #N/A
Name Slicer_SMI_Quiz___Assignment_Status: #N/A
Name Slicer_WP_Quiz___Assignment_Status: #N/A

Sheet Main Dashboard
B3: Examination Partcipation (BS-MSc) | C3: BS | D3: %age | E3: MSc | F3: %age | G3: Total Students | H3: Total %age | I3: Remarks
B4: Total Students | C4: 322 | E4: 488 | G4: =SUM(C4+E4) -> 810
B5: Present in All Written Exams | C5: 184 | D5: =$C5/$C$4 -> 0.57142857 | E5: 361 | F5: =$E5/$E$4 -> 0.7397541 | G5: =SUM(C5+E5) -> 545 | H5: =G5/$G$4 -> 0.67283951 | I5: 49 out of 184 have completed all Assignments and Quizzes in BS 168 out of 361 have completed all Assignments and Quizzes in MSc Total-217
B6: Present in 5 Exams | C6: - | D6: - | E6: 361 | F6: =$E6/$E$4 -> 0.7397541 | G6: =E6 -> 361 | H6: =G6/$G$4 -> 0.44567901
B7: Present in 4 Exams | C7: 184 | D7: =$C7/$C$4 -> 0.57142857 | E7: 13 | F7: =$E7/$E$4 -> 0.026639344 | G7: =SUM(C7+E7) -> 197 | H7: =G7/$G$4 -> 0.24320988
B8: Present in 3 Exams | C8: 30 | D8: =$C8/$C$4 -> 0.093167702 | E8: 4 | F8: =$E8/$E$4 -> 0.0081967213 | G8: =SUM(C8+E8) -> 34 | H8: =G8/$G$4 -> 0.041975309
B9: Present in 2 Exams | C9: 14 | D9: =$C9/$C$4 -> 0.043478261 | E9: 7 | F9: =$E9/$E$4 -> 0.014344262 | G9: =SUM(C9+E9) -> 21 | H9: =G9/$G$4 -> 0.025925926
B10: Present in 1 Exam | C10: 21 | D10: =$C10/$C$4 -> 0.065217391 | E10: 10 | F10: =$E10/$E$4 -> 0.020491803 | G10: =SUM(C10+E10) -> 31 | H10: =G10/$G$4 -> 0.038271605
B11: Atleast Present in 1 Exam | C11: =SUM(C7:C10) -> 249 | D11: =$C11/$C$4 -> 0.77329193 | E11: =SUM(E6:E10) -> 395 | F11: =$E11/$E$4 -> 0.80942623 | G11: =SUM(C11+E11) -> 644 | H11: =G11/$G$4 -> 0.79506173
B12: Not Present in Any Written Exam | C12: 73 | D12: =$C12/$C$4 -> 0.22670807 | E12: 93 | F12: =$E12/$E$4 -> 0.19057377 | G12: =SUM(C12+E12) -> 166 | H12: =G12/$G$4 -> 0.20493827
B18: Bifurcation of Absent Students | C18: BS | D18: MSc | E18: Total | H18: =49+14+21 -> 84
B19: Not Appeared in Exam | C19: 29 | D19: 31 | E19: =SUM(C19:D19) -> 60
B20: Slot Preference Not Given | C20: 15 | D20: 7 | E20: =SUM(C20:D20) -> 22
B21: Account not Activated | C21: 29 | D21: 55 | E21: =SUM(C21:D21) -> 84
B22: Total | C22: =SUM(C19:C21) -> 73 | D22: =SUM(D19:D21) -> 93 | E22: =SUM(C22:D22) -> 166

Sheet BS-Dashboard
A1: BS-322 | B1: (Multiple Items)
A2: 73/166 | B2: (All)
A3: Present/Absent/No Data | B3: (All)
A5: Row Labels | B5: Count of BITS ID
A6: Q-0 A-0 || Q Total-4, A Total-1 | B6: 2
A7: Q-1 A-0 || Q Total-4, A Total-1 | B7: 75
A8: Q-1 A-1 || Q Total-4, A Total-1 | B8: 7
A9: Q-2 A-0 || Q Total-4, A Total-1 | B9: 35
A10: Q-2 A-1 || Q Total-4, A Total-1 | B10: 9
A11: Q-3 A-0 || Q Total-4, A Total-1 | B11: 21
A12: Q-3 A-1 || Q Total-4, A Total-1 | B12: 34
A13: Q-4 A-0 || Q Total-4, A Total-1 | B13: 22
A14: Q-4 A-1 || Q Total-4, A Total-1 | B14: 117
A15: Grand Total | B15: 322

Sheet MSc Dashboard
A1: MSc-488 | B1: (Multiple Items)
A2: 93/166 | B2: (All)
A3: Present/Absent/No Data | B3: (All)
A5: Row Labels | B5: Count of ID No.
A6: Q-0 A-0 || Q Total-3, A Total-1 | B6: 40
A7: Q-0 A-1 || Q Total-3, A Total-1 | B7: 2
A8: Q-1 A-0 || Q Total-3, A Total-1 | B8: 26
A9: Q-1 A-1 || Q Total-3, A Total-1 | B9: 14
A10: Q-2 A-0 || Q Total-3, A Total-1 | B10: 25
A11: Q-2 A-1 || Q Total-3, A Total-1 | B11: 57
A12: Q-3 A-0 || Q Total-3, A Total-1 | B12: 14
A13: Q-3 A-1 || Q Total-3, A Total-1 | B13: 310
A14: Grand Total | B14: 488

Sheet BS Attendance
H1: Computer Programming | AH1: Computer Systems | BH1: Probability & Statistics | CG1: Writing Practice | DH1: Data and The World
H2: Graded Quiz | L2: Graded Assignment | M2: BDS DF113-Computer Programming (# Quiz-4, # A-1) | AA2: Computer Programming | AB2: BDSDF113 | AF2: CP-Exam Attendance | AG2: CP-Exam Attendance | AH2: Graded Assignment | AJ2: Graded Quiz | AM2: BDS DF108-Computer Systems (# Quiz-2, # A-2) | BA2: Computer Systems | BB2: BDSDF108 | BF2: CS-Exam Attendance | BG2: CS-Exam Attendance | BH2: Graded Quiz | BK2: Graded Assignment | BL2: BDS DF114-Probability & Statistics (# Quiz-3 # A-1) | BZ2: Probability & Statistics | CA2: BDSDF114 | CE2: PS-Exam Attendance | CF2: PS-Exam Attendance | CG2: Graded Quiz | CI2: Graded Assignment | CK2: Practice Quizes | CL2: Discussion Forums | CM2: BDS DF112-Writing Practice (# Quiz-2, # A-2) | DA2: Writing Practice | DB2: BDSDF112 | DF2: WP-Exam Attendance | DG2: WP-Exam Attendance | DH2: Graded Assignment | DK2: Total Present/Absent/No Data | DM2: Attendance Slot-1/2 Exams - 20/21/27/28 December 2025
A3: Sr. No. | B3: Course | C3: BITS ID | D3: BITS Email ID | E3: First Name | F3: Gender | G3: Phone Number | H3: 1 (8) | I3: 2 (8) | J3: 3 (8) | K3: 4 (8) | L3: 1 (28) | M3: Final Grade Numerator | N3: Final Grade Denominator | O3: Subject | P3: Subject code | Q3: BITS ID + Course Code | R3: Count_of_A_Q | S3: Count_of_A_A | T3: Quiz_Completed | U3: Assignment_Completed | V3: Quiz_Attendance % | W3: Assignment_Attendance % | X3: Count_of_Absent | Y3: Component_Completed | Z3: Attendance % | AA3: CP-Quiz & Assignment Status | AB3: CP-Exam-Slot-1 | AC3: CP-Exam-Slot-2 | AD3: Written Exam Marks | AE3: Total Marks Written | AF3: CP-Present/Absent/No Data | AG3: CP-Status/Slot/Exam Mode | AH3: 1 (15) | AI3: 2 (15) | AJ3: 1 (10) | AK3: 2 (10) | AL3: 3 (10) | AM3: Final Grade Numerator | AN3: Final Grade Denominator | AO3: Subject | AP3: Subject code | AQ3: BITS ID + Course Code | AR3: Count_of_A_Q | AS3: Count_of_A_A | AT3: Quiz_Completed | AU3: Assignment_Completed | AV3: Quiz_Attendance % | AW3: Assignment_Attendance % | AX3: Count_of_Absent | AY3: Component_Completed | AZ3: Attendance % | BA3: CS-Quiz & Assignment Status | BB3: CS-Exam-Slot-1 | BC3: CS-Exam-Slot-2 | BD3: Written Exam Marks | BE3: Total Marks Written | BF3: CS-Present/Absent/No Data | BG3: CS-Status/Slot/Exam Mode | BH3: 1 (10) | BI3: 2 (15) | BJ3: 3 (15) | BK3: 1 (20) | BL3: Final Grade Numerator | BM3: Final Grade Denominator | BN3: Subject | BO3: Subject code | BP3: BITS ID + Course Code | BQ3: Count_of_A_Q | BR3: Count_of_A_A | BS3: Quiz_Completed | BT3: Assignment_Completed | BU3: Quiz_Attendance % | BV3: Assignment_Attendance % | BW3: Count_of_Absent | BX3: Component_Completed | BY3: Attendance % | BZ3: PS-Quiz & Assignment Status | CA3: PS-Slot-1 | CB3: PS-Slot-2 | CC3: Written Exam Marks | CD3: Total Marks Written | CE3: PS-Present/Absent/No Data | CF3: PS-Status/Slot/Exam Mode | CG3: 1 (5) | CH3: 2 (5) | CI3: 1 (10) | CJ3: 2 (10) | CK3: 1 (10) | CL3: 1 (10) | CM3: Calculated Final Grade Numerator | CN3: Calculated Final Grade Denominator | CO3: Subject | CP3: Subject code | CQ3: BITS ID + Course Code | CR3: Count_of_A_Q | CS3: Count_of_A_A | CT3: Quiz_Completed | CU3: Assignment_Completed | CV3: Quiz_Attendance % | CW3: Assignment_Attendance % | CX3: Count_of_A | CY3: Component_Completed | CZ3: Attendance % | DA3: WP-Quiz & Assignment Status | DB3: WP-Slot-1 | DC3: WP-Slot-2 | DD3: Written Exam Marks | DE3: Total Marks Written | DF3: WP-Present/Absent/No Data | DG3: WP-Status-Slot-Exam Mode | DH3: 1 (100) | DI3: Calculated Final Grade Numerator | DJ3: Calculated Final Grade Denominator | DK3: Total Exam Slot-1 | DL3: Total Exam Slot-2 | DM3: BDSDF113 | DN3: BDSDF112 | DO3: BDSDF108 | DP3: BDSDF114 | DQ3: Present/Absent/No Data | DR3: Quiz+Assignment | DS3: Account Status | DT3: Final Status | DU3: BS-322 | DV3: 73/166
A4: 1 | B4: BS DS-AI | C4: 2025EB1100001 | D4: 2025eb1100001@bitspilani-digital.edu.in | E4: RUDRA SHARMA | F4: MALE | G4: `+91-6376182075 | H4: 8 | I4: 7.2 | J4: A | K4: A | L4: A | M4: 15.2 | N4: 60 | O4: Computer Programming | P4: BDSDF113 | Q4: =CONCATENATE($C4,"-",$P4) -> 2025EB1100001-BDSDF113 | R4: =COUNTIF($H4:$K4,"A") & " " & "missed" -> 2 missed | S4: =COUNTIF(L4,"A") & " " & "missed" -> 1 missed | T4: =4-COUNTIF($H4:$K4,"A") -> 2 | U4: =1-COUNTIF($L4,"A") -> 0 | V4: =$T4/4 -> 0.5 | W4: =$U4/1 -> 0 | X4: =COUNTIF($H4:$L4, "A") & " " &"missed" -> 3 missed | Y4: =5- COUNTIF($H4:$L4, "A") -> 2 | Z4: =$Y4/5 -> 0.4 | AA4: =CONCATENATE("Q-",$T4," A-",$U4," || Q Total-4, A Total-1") -> Q-2 A-0 || Q Total-4, A Total-1 | AB4: {=IFERROR(INDEX('Attendance-Slot-1'!$Q$2:$Q$1112,MATCH(1,('Attendance-Slot-1'!$A$2:$A$1112=$C4)*('Attendance-Slot-1'!$G$2:$G$1112=AB$2),0)),"No Data")} -> No Data | AC4: {=IFERROR(INDEX('Attendance-Slot-2'!$Q$2:$Q$2595,MATCH(1,('Attendance-Slot-2'!$A$2:$A$2595=$C4)*('Attendance-Slot-2'!$G$2:$G$2595=AB$2),0)),"No Data")} -> P-S2_Onsite | AD4: =VLOOKUP($Q4,'Written Exam Marks'!$H:$Q,10,FALSE) -> 40 | AE4: =VLOOKUP($Q4,'Written Exam Marks'!$H:$Q,9,FALSE) -> 40 | AF4: =IF(COUNTIF($AB4:$AC4,"P-*")>0,"Present", IF(COUNTIF($AB4:$AC4,"A-*")>0,"Absent", IF(COUNTIF($AB4:$AC4,"No Data")>0,"No Data",""))) -> Present | AG4: =IF(LEFT($AB4,2)="P-",$AB4,IF(LEFT($AC4,2)="P-",$AC4,IF(LEFT($AB4,2)="A-",$AB4,IF(LEFT($AC4,2)="A-",$AC4,IF($AB4="No Data",$AB4,IF($AC4="No Data",$AC4,"")))))) -> P-S2_Onsite | AH4: A | AI4: A | AJ4: A | AK4: A | AL4: A | AM4: 0 | AN4: 60 | AO4: 60 | AP4: 60 | AQ4: 60 | AR4: 60 | AS4: 60 | AT4: 60 | AU4: 60 | AV4: 60 | AW4: 60 | AX4: 60 | AY4: 60 | AZ4: 60 | BA4: =CONCATENATE("Q-",$AT4," A-",$AU4," || Q Total-3, A Total-2") -> Q-60 A-60 || Q Total-3, A Total-2 | BB4: {=IFERROR(INDEX('Attendance-Slot-1'!$Q$2:$Q$1112,MATCH(1,('Attendance-Slot-1'!$A$2:$A$1112=$C4)*('Attendance-Slot-1'!$G$2:$G$1112=BB$2),0)),"No Data")} -> No Data | BC4: {=IFERROR(INDEX('Attendance-Slot-2'!$Q$2:$Q$2595,MATCH(1,('Attendance-Slot-2'!$A$2:$A$2595=$C4)*('Attendance-Slot-2'!$G$2:$G$2595=BB$2),0)),"No Data")} -> P-S2_Onsite | BD4: =VLOOKUP($AQ4,'Written Exam Marks'!$H:$Q,10,FALSE) -> #N/A | BE4: =VLOOKUP($AQ4,'Written Exam Marks'!$H:$Q,9,FALSE) -> #N/A | BF4: =IF(COUNTIF($BB4:$BC4,"P-*")>0,"Present", IF(COUNTIF($BB4:$BC4,"A-*")>0,"Absent", IF(COUNTIF($BB4:$BC4,"No Data")>0,"No Data",""))) -> Present | BG4: =IF(LEFT($BB4,2)="P-",$BB4,IF(LEFT($BC4,2)="P-",$BC4,IF(LEFT($BB4,2)="A-",$BB4,IF(LEFT($BC4,2)="A-",$BC4,IF($BB4="No Data",$BB4,IF($BC4="No Data",$BC4,"")))))) -> P-S2_Onsite | BH4: 9 | BI4: 12 | BJ4: A | BK4: A | BL4: 21 | BM4: 60 | BN4: Probability & Statistics | BO4: BDSDF114 | BP4: =CONCATENATE($C4,"-",$BO4) -> 2025EB1100001-BDSDF114 | BQ4: =COUNTIF($BH4:$BJ4,"A") & " " & "missed" -> 1 missed | BR4: =COUNTIF($BK4,"A") & " " & "missed" -> 1 missed | BS4: =3-COUNTIF($BH4:$BJ4,"A") -> 2 | BT4: =1-COUNTIF($BK4,"A") -> 0 | BU4: =$BS4/3 -> 0.66666667 | BV4: =$BT4/1 -> 0 | BW4: =COUNTIF($BH4:$BK4, "A") & " " &"missed" -> 2 missed | BX4: =4- COUNTIF(BH4:BK4, "A") -> 2 | BY4: =$BX4/4 -> 0.5 | BZ4: =CONCATENATE("Q-",$BS4," A-",$BT4," || Q Total-3, A Total-1") -> Q-2 A-0 || Q Total-3, A Total-1 | CA4: {=IFERROR(INDEX('Attendance-Slot-1'!$Q$2:$Q$1112,MATCH(1,('Attendance-Slot-1'!$A$2:$A$1112=$C4)*('Attendance-Slot-1'!$G$2:$G$1112=CA$2),0)),"No Data")} -> No Data | CB4: {=IFERROR(INDEX('Attendance-Slot-2'!$Q$2:$Q$2595,MATCH(1,('Attendance-Slot-2'!$A$2:$A$2595=$C4)*('Attendance-Slot-2'!$G$2:$G$2595=CA$2),0)),"No Data")} -> P-S2_Onsite | CC4: =VLOOKUP($BP4,'Written Exam Marks'!$H:$Q,10,FALSE) -> 32 | CD4: =VLOOKUP($BP4,'Written Exam Marks'!$H:$Q,9,FALSE) -> 40 | CE4: =IF(COUNTIF($CA4:$CB4,"P-*")>0,"Present", IF(COUNTIF($CA4:$CB4,"A-*")>0,"Absent", IF(COUNTIF($CA4:$CB4,"No Data")>0,"No Data",""))) -> Present | CF4: =IF(LEFT($CA4,2)="P-",$CA4,IF(LEFT($CB4,2)="P-",$CB4,IF(LEFT($CA4,2)="A-",$CA4,IF(LEFT($CB4,2)="A-",$CB4,IF($CA4="No Data",$CA4,IF($CB4="No Data",$CB4,"")))))) -> P-S2_Onsite | CG4: 5 | CH4: 4 | CI4: A | CJ4: A | CK4: A | CL4: A | CM4: 9 | CN4: 50 | CO4: Writing Practice | CP4: BDSDF112 | CQ4: =CONCATENATE($C4,"-",$CP4) -> 2025EB1100001-BDSDF112 | CR4: =COUNTIF($CG4:$CH4,"A") & " " & "missed" -> 0 missed | CS4: =COUNTIF($CI4:$CJ4,"A") & " " & "missed" -> 2 missed | CT4: =2-COUNTIF($CG4:$CH4,"A") -> 2 | CU4: =2-COUNTIF($CI4:$CJ4,"A") -> 0 | CV4: =$CT4/2 -> 1 | CW4: =$CU4/2 -> 0 | CX4: =COUNTIF($CG4:$CJ4, "A") & " " &"missed" -> 2 missed | CY4: =4- COUNTIF($CG4:$CJ4, "A") -> 2 | CZ4: =$CY4/4 -> 0.5 | DA4: =CONCATENATE("Q-",$CT4," A-",$CU4," || Q Total-2, A Total-2") -> Q-2 A-0 || Q Total-2, A Total-2 | DB4: {=IFERROR(INDEX('Attendance-Slot-1'!$Q$2:$Q$1112,MATCH(1,('Attendance-Slot-1'!$A$2:$A$1112=$C4)*('Attendance-Slot-1'!$G$2:$G$1112=DB$2),0)),"No Data")} -> No Data | DC4: {=IFERROR(INDEX('Attendance-Slot-2'!$Q$2:$Q$2595,MATCH(1,('Attendance-Slot-2'!$A$2:$A$2595=$C4)*('Attendance-Slot-2'!$G$2:$G$2595=DB$2),0)),"No Data")} -> P-S2_Onsite | DD4: =VLOOKUP($CQ4,'Written Exam Marks'!$H:$Q,10,FALSE) -> 25 | DE4: =VLOOKUP($CQ4,'Written Exam Marks'!$H:$Q,9,FALSE) -> 50 | DF4: =IF(COUNTIF($DB4:$DC4,"P-*")>0,"Present", IF(COUNTIF($DB4:$DC4,"A-*")>0,"Absent", IF(COUNTIF($DB4:$DC4,"No Data")>0,"No Data",""))) -> Present | DG4: =IF(LEFT($DB4,2)="P-",$DB4,IF(LEFT($DC4,2)="P-",$DC4,IF(LEFT($DB4,2)="A-",$DB4,IF(LEFT($DC4,2)="A-",$DC4,IF($DB4="No Data",$DB4,IF($DC4="No Data",$DC4,"")))))) -> P-S2_Onsite | DH4: 90 | DI4: 90 | DJ4: 100 | DK4: ="P-"&(COUNTIF($AB4,"P-*")+COUNTIF($BB4,"P-*")+COUNTIF($CA4,"P-*")+COUNTIF($DB4,"P-*"))&", A-"&(COUNTIF($AB4,"A-*")+COUNTIF($BB4,"A-*")+COUNTIF($CA4,"A-*")+COUNTIF($DB4,"A-*"))&", No Data-"&(COUNTIF($AB4,"No Data")+COUNTIF($BB4,"No Data")+COUNTIF($CA4,"No Data")+COUNTIF($DB4,"No Data")) -> P-0, A-0, No Data-4 | DL4: ="P-"&(COUNTIF($AC4,"P-*")+COUNTIF($BC4,"P-*")+COUNTIF($CB4,"P-*")+COUNTIF($DC4,"P-*"))&", A-"&(COUNTIF($AC4,"A-*")+COUNTIF($BC4,"A-*")+COUNTIF($CB4,"A-*")+COUNTIF($DC4,"A-*"))&", No Data-"&(COUNTIF($AC4,"No Data")+COUNTIF($BC4,"No Data")+COUNTIF($CB4,"No Data")+COUNTIF($DC4,"No Data")) -> P-4, A-0, No Data-0 | DM4: =IF(LEFT($AB4,2)="P-",$AB4, IF(LEFT($AC4,2)="P-",$AC4, IF(LEFT($AB4,2)="A-",$AB4, IF(LEFT($AC4,2)="A-",$AC4, IF($AB4="No Data",$AB4, IF($AC4="No Data",$AC4,"")))))) -> P-S2_Onsite | DN4: =IF(LEFT($DB4,2)="P-",$DB4, IF(LEFT($DC4,2)="P-",$DC4, IF(LEFT($DB4,2)="A-",$DB4, IF(LEFT($DC4,2)="A-",$DC4, IF($DB4="No Data",$DB4, IF($DC4="No Data",$DC4,"")))))) -> P-S2_Onsite | DO4: =IF(LEFT($BB4,2)="P-",$BB4, IF(LEFT($BC4,2)="P-",$BC4, IF(LEFT($BB4,2)="A-",$BB4, IF(LEFT($BC4,2)="A-",$BC4, IF($BB4="No Data",$BB4, IF($BC4="No Data",$BC4,"")))))) -> P-S2_Onsite | DP4: =IF(LEFT($CA4,2)="P-",$CA4, IF(LEFT($CB4,2)="P-",$CB4, IF(LEFT($CA4,2)="A-",$CA4, IF(LEFT($CB4,2)="A-",$CB4, IF($CA4="No Data",$CA4, IF($CB4="No Data",$CB4,"")))))) -> P-S2_Onsite | DQ4: ="P-"&COUNTIF($DM4:$DP4,"P-*")&", A-"&COUNTIF($DM4:$DP4,"A-*")&", No Data-"&COUNTIF($DM4:$DP4,"No Data") -> P-4, A-0, No Data-0 | DR4: =IF( AND( $AA4="Q-4 A-1 || Q Total-4, A Total-1", $BA4="Q-3 A-2 || Q Total-3, A Total-2", $BZ4="Q-3 A-1 || Q Total-3, A Total-1", $DA4="Q-2 A-2 || Q Total-2, A Total-2" ), 1, 0 ) -> 0 | DS4: Activated | DT4: Exam Given | DU4: 2025EB1100001
A5: 2 | B5: BS DS-AI | C5: 2025EB1100002 | D5: 2025eb1100002@bitspilani-digital.edu.in | E5: BANDREDDY BHAWIN SAI KOUSHIK | F5: MALE | G5: `+91-8790640060 | H5: 8 | I5: 4.8 | J5: 6.4 | K5: A | L5: A | M5: 19.2 | N5: 60 | O5: Computer Programming | P5: BDSDF113 | Q5: =CONCATENATE($C5,"-",$P5) -> 2025EB1100002-BDSDF113 | R5: =COUNTIF($H5:$K5,"A") & " " & "missed" -> 1 missed | S5: =COUNTIF(L5,"A") & " " & "missed" -> 1 missed | T5: =4-COUNTIF($H5:$K5,"A") -> 3 | U5: =1-COUNTIF($L5,"A") -> 0 | V5: =$T5/4 -> 0.75 | W5: =$U5/1 -> 0 | X5: =COUNTIF($H5:$L5, "A") & " " &"missed" -> 2 missed | Y5: =5- COUNTIF($H5:$L5, "A") -> 3 | Z5: =$Y5/5 -> 0.6 | AA5: =CONCATENATE("Q-",$T5," A-",$U5," || Q Total-4, A Total-1") -> Q-3 A-0 || Q Total-4, A Total-1 | AB5: {=IFERROR(INDEX('Attendance-Slot-1'!$Q$2:$Q$1112,MATCH(1,('Attendance-Slot-1'!$A$2:$A$1112=$C5)*('Attendance-Slot-1'!$G$2:$G$1112=AB$2),0)),"No Data")} -> No Data | AC5: {=IFERROR(INDEX('Attendance-Slot-2'!$Q$2:$Q$2595,MATCH(1,('Attendance-Slot-2'!$A$2:$A$2595=$C5)*('Attendance-Slot-2'!$G$2:$G$2595=AB$2),0)),"No Data")} -> A-S2_Onsite | AD5: =VLOOKUP($Q5,'Written Exam Marks'!$H:$Q,10,FALSE) -> #N/A | AE5: =VLOOKUP($Q5,'Written Exam Marks'!$H:$Q,9,FALSE) -> #N/A | AF5: =IF(COUNTIF($AB5:$AC5,"P-*")>0,"Present", IF(COUNTIF($AB5:$AC5,"A-*")>0,"Absent", IF(COUNTIF($AB5:$AC5,"No Data")>0,"No Data",""))) -> Absent | AG5: =IF(LEFT($AB5,2)="P-",$AB5,IF(LEFT($AC5,2)="P-",$AC5,IF(LEFT($AB5,2)="A-",$AB5,IF(LEFT($AC5,2)="A-",$AC5,IF($AB5="No Data",$AB5,IF($AC5="No Data",$AC5,"")))))) -> A-S2_Onsite | AH5: A | AI5: A | AJ5: A | AK5: A | AL5: A | AM5: 0 | AN5: 60 | AO5: Computer Systems | AP5: BDSDF108 | AQ5: =CONCATENATE($C5,"-",$AP5) -> 2025EB1100002-BDSDF108 | AR5: =COUNTIF($AJ5:$AL5,"A") & " " & "missed" -> 3 missed | AS5: =COUNTIF($AH5:$AI5,"A") & " " & "missed" -> 2 missed | AT5: =3-COUNTIF(AJ5:AL5,"A") -> 0 | AU5: =2-COUNTIF($AH5:$AI5,"A") -> 0 | AV5: =$AT5/3 -> 0 | AW5: =$AU5/2 -> 0 | AX5: =COUNTIF($AH5:$AL5, "A") & " " &"missed" -> 5 missed | AY5: =5- COUNTIF($AH5:$AL5, "A") -> 0 | AZ5: =$AY5/5 -> 0 | BA5: =CONCATENATE("Q-",$AT5," A-",$AU5," || Q Total-3, A Total-2") -> Q-0 A-0 || Q Total-3, A Total-2 | BB5: {=IFERROR(INDEX('Attendance-Slot-1'!$Q$2:$Q$1112,MATCH(1,('Attendance-Slot-1'!$A$2:$A$1112=$C5)*('Attendance-Slot-1'!$G$2:$G$1112=BB$2),0)),"No Data")} -> No Data | BC5: {=IFERROR(INDEX('Attendance-Slot-2'!$Q$2:$Q$2595,MATCH(1,('Attendance-Slot-2'!$A$2:$A$2595=$C5)*('Attendance-Slot-2'!$G$2:$G$2595=BB$2),0)),"No Data")} -> A-S2_Onsite | BD5: =VLOOKUP($AQ5,'Written Exam Marks'!$H:$Q,10,FALSE) -> #N/A | BE5: =VLOOKUP($AQ5,'Written Exam Marks'!$H:$Q,9,FALSE) -> #N/A | BF5: =IF(COUNTIF($BB5:$BC5,"P-*")>0,"Present", IF(COUNTIF($BB5:$BC5,"A-*")>0,"Absent", IF(COUNTIF($BB5:$BC5,"No Data")>0,"No Data",""))) -> Absent | BG5: =IF(LEFT($BB5,2)="P-",$BB5,IF(LEFT($BC5,2)="P-",$BC5,IF(LEFT($BB5,2)="A-",$BB5,IF(LEFT($BC5,2)="A-",$BC5,IF($BB5="No Data",$BB5,IF($BC5="No Data",$BC5,"")))))) -> A-S2_Onsite | BH5: A | BI5: A | BJ5: A | BK5: A | BL5: 0 | BM5: 60 | BN5: Probability & Statistics | BO5: BDSDF114 | BP5: =CONCATENATE($C5,"-",$BO5) -> 2025EB1100002-BDSDF114 | BQ5: =COUNTIF($BH5:$BJ5,"A") & " " & "missed" -> 3 missed | BR5: =COUNTIF($BK5,"A") & " " & "missed" -> 1 missed | BS5: =3-COUNTIF($BH5:$BJ5,"A") -> 0 | BT5: =1-COUNTIF($BK5,"A") -> 0 | BU5: =$BS5/3 -> 0 | BV5: =$BT5/1 -> 0 | BW5: =COUNTIF($BH5:$BK5, "A") & " " &"missed" -> 4 missed | BX5: =4- COUNTIF(BH5:BK5, "A") -> 0 | BY5: =$BX5/4 -> 0 | BZ5: =CONCATENATE("Q-",$BS5," A-",$BT5," || Q Total-3, A Total-1") -> Q-0 A-0 || Q Total-3, A Total-1 | CA5: {=IFERROR(INDEX('Attendance-Slot-1'!$Q$2:$Q$1112,MATCH(1,('Attendance-Slot-1'!$A$2:$A$1112=$C5)*('Attendance-Slot-1'!$G$2:$G$1112=CA$2),0)),"No Data")} -> No Data | CB5: {=IFERROR(INDEX('Attendance-Slot-2'!$Q$2:$Q$2595,MATCH(1,('Attendance-Slot-2'!$A$2:$A$2595=$C5)*('Attendance-Slot-2'!$G$2:$G$2595=CA$2),0)),"No Data")} -> A-S2_Onsite | CC5: =VLOOKUP($BP5,'Written Exam Marks'!$H:$Q,10,FALSE) -> #N/A | CD5: =VLOOKUP($BP5,'Written Exam Marks'!$H:$Q,9,FALSE) -> #N/A | CE5: =IF(COUNTIF($CA5:$CB5,"P-*")>0,"Present", IF(COUNTIF($CA5:$CB5,"A-*")>0,"Absent", IF(COUNTIF($CA5:$CB5,"No Data")>0,"No Data",""))) -> Absent | CF5: =IF(LEFT($CA5,2)="P-",$CA5,IF(LEFT($CB5,2)="P-",$CB5,IF(LEFT($CA5,2)="A-",$CA5,IF(LEFT($CB5,2)="A-",$CB5,IF($CA5="No Data",$CA5,IF($CB5="No Data",$CB5,"")))))) -> A-S2_Onsite | CG5: 4.5 | CH5: A | CI5: A | CJ5: A | CK5: A | CL5: A | CM5: 4.5 | CN5: 50 | CO5: Writing Practice | CP5: BDSDF112 | CQ5: =CONCATENATE($C5,"-",$CP5) -> 2025EB1100002-BDSDF112 | CR5: =COUNTIF($CG5:$CH5,"A") & " " & "missed" -> 1 missed | CS5: =COUNTIF($CI5:$CJ5,"A") & " " & "missed" -> 2 missed | CT5: =2-COUNTIF($CG5:$CH5,"A") -> 1 | CU5: =2-COUNTIF($CI5:$CJ5,"A") -> 0 | CV5: =$CT5/2 -> 0.5 | CW5: =$CU5/2 -> 0 | CX5: =COUNTIF($CG5:$CJ5, "A") & " " &"missed" -> 3 missed | CY5: =4- COUNTIF($CG5:$CJ5, "A") -> 1 | CZ5: =$CY5/4 -> 0.25 | DA5: =CONCATENATE("Q-",$CT5," A-",$CU5," || Q Total-2, A Total-2") -> Q-1 A-0 || Q Total-2, A Total-2 | DB5: {=IFERROR(INDEX('Attendance-Slot-1'!$Q$2:$Q$1112,MATCH(1,('Attendance-Slot-1'!$A$2:$A$1112=$C5)*('Attendance-Slot-1'!$G$2:$G$1112=DB$2),0)),"No Data")} -> No Data | DC5: {=IFERROR(INDEX('Attendance-Slot-2'!$Q$2:$Q$2595,MATCH(1,('Attendance-Slot-2'!$A$2:$A$2595=$C5)*('Attendance-Slot-2'!$G$2:$G$2595=DB$2),0)),"No Data")} -> A-S2_Onsite | DD5: =VLOOKUP($CQ5,'Written Exam Marks'!$H:$Q,10,FALSE) -> #N/A | DE5: =VLOOKUP($CQ5,'Written Exam Marks'!$H:$Q,9,FALSE) -> #N/A | DF5: =IF(COUNTIF($DB5:$DC5,"P-*")>0,"Present", IF(COUNTIF($DB5:$DC5,"A-*")>0,"Absent", IF(COUNTIF($DB5:$DC5,"No Data")>0,"No Data",""))) -> Absent | DG5: =IF(LEFT($DB5,2)="P-",$DB5,IF(LEFT($DC5,2)="P-",$DC5,IF(LEFT($DB5,2)="A-",$DB5,IF(LEFT($DC5,2)="A-",$DC5,IF($DB5="No Data",$DB5,IF($DC5="No Data",$DC5,"")))))) -> A-S2_Onsite | DH5: 85 | DI5: 85 | DJ5: 100 | DK5: ="P-"&(COUNTIF($AB5,"P-*")+COUNTIF($BB5,"P-*")+COUNTIF($CA5,"P-*")+COUNTIF($DB5,"P-*"))&", A-"&(COUNTIF($AB5,"A-*")+COUNTIF($BB5,"A-*")+COUNTIF($CA5,"A-*")+COUNTIF($DB5,"A-*"))&", No Data-"&(COUNTIF($AB5,"No Data")+COUNTIF($BB5,"No Data")+COUNTIF($CA5,"No Data")+COUNTIF($DB5,"No Data")) -> P-0, A-0, No Data-4 | DL5: ="P-"&(COUNTIF($AC5,"P-*")+COUNTIF($BC5,"P-*")+COUNTIF($CB5,"P-*")+COUNTIF($DC5,"P-*"))&", A-"&(COUNTIF($AC5,"A-*")+COUNTIF($BC5,"A-*")+COUNTIF($CB5,"A-*")+COUNTIF($DC5,"A-*"))&", No Data-"&(COUNTIF($AC5,"No Data")+COUNTIF($BC5,"No Data")+COUNTIF($CB5,"No Data")+COUNTIF($DC5,"No Data")) -> P-0, A-4, No Data-0 | DM5: =IF(LEFT($AB5,2)="P-",$AB5, IF(LEFT($AC5,2)="P-",$AC5, IF(LEFT($AB5,2)="A-",$AB5, IF(LEFT($AC5,2)="A-",$AC5, IF($AB5="No Data",$AB5, IF($AC5="No Data",$AC5,"")))))) -> A-S2_Onsite | DN5: =IF(LEFT($DB5,2)="P-",$DB5, IF(LEFT($DC5,2)="P-",$DC5, IF(LEFT($DB5,2)="A-",$DB5, IF(LEFT($DC5,2)="A-",$DC5, IF($DB5="No Data",$DB5, IF($DC5="No Data",$DC5,"")))))) -> A-S2_Onsite | DO5: =IF(LEFT($BB5,2)="P-",$BB5, IF(LEFT($BC5,2)="P-",$BC5, IF(LEFT($BB5,2)="A-",$BB5, IF(LEFT($BC5,2)="A-",$BC5, IF($BB5="No Data",$BB5, IF($BC5="No Data",$BC5,"")))))) -> A-S2_Onsite | DP5: =IF(LEFT($CA5,2)="P-",$CA5, IF(LEFT($CB5,2)="P-",$CB5, IF(LEFT($CA5,2)="A-",$CA5, IF(LEFT($CB5,2)="A-",$CB5, IF($CA5="No Data",$CA5, IF($CB5="No Data",$CB5,"")))))) -> A-S2_Onsite | DQ5: ="P-"&COUNTIF($DM5:$DP5,"P-*")&", A-"&COUNTIF($DM5:$DP5,"A-*")&", No Data-"&COUNTIF($DM5:$DP5,"No Data") -> P-0, A-4, No Data-0 | DR5: =IF( AND( $AA5="Q-4 A-1 || Q Total-4, A Total-1", $BA5="Q-3 A-2 || Q Total-3, A Total-2", $BZ5="Q-3 A-1 || Q Total-3, A Total-1", $DA5="Q-2 A-2 || Q Total-2, A Total-2" ), 1, 0 ) -> 0 | DS5: Activated | DT5: Absent | DU5: 2025EB1100002 | DV5: Absent
A6: 3 | B6: BS DS-AI | C6: 2025EB1100003 | D6: 2025eb1100003@bitspilani-digital.edu.in | E6: AJAYACHANDRAN.E | F6: MALE | G6: `+971-521052060 | H6: 7.2 | I6: A | J6: A | K6: A | L6: A | M6: 7.2 | N6: 60 | O6: Computer Programming | P6: BDSDF113 | Q6: =CONCATENATE($C6,"-",$P6) -> 2025EB1100003-BDSDF113 | R6: =COUNTIF($H6:$K6,"A") & " " & "missed" -> 3 missed | S6: =COUNTIF(L6,"A") & " " & "missed" -> 1 missed | T6: =4-COUNTIF($H6:$K6,"A") -> 1 | U6: =1-COUNTIF($L6,"A") -> 0 | V6: =$T6/4 -> 0.25 | W6: =$U6/1 -> 0 | X6: =COUNTIF($H6:$L6, "A") & " " &"missed" -> 4 missed | Y6: =5- COUNTIF($H6:$L6, "A") -> 1 | Z6: =$Y6/5 -> 0.2 | AA6: =CONCATENATE("Q-",$T6," A-",$U6," || Q Total-4, A Total-1") -> Q-1 A-0 || Q Total-4, A Total-1 | AB6: {=IFERROR(INDEX('Attendance-Slot-1'!$Q$2:$Q$1112,MATCH(1,('Attendance-Slot-1'!$A$2:$A$1112=$C6)*('Attendance-Slot-1'!$G$2:$G$1112=AB$2),0)),"No Data")} -> P-S1_Online | AC6: {=IFERROR(INDEX('Attendance-Slot-2'!$Q$2:$Q$2595,MATCH(1,('Attendance-Slot-2'!$A$2:$A$2595=$C6)*('Attendance-Slot-2'!$G$2:$G$2595=AB$2),0)),"No Data")} -> No Data | AD6: =VLOOKUP($Q6,'Written Exam Marks'!$H:$Q,10,FALSE) -> 0 | AE6: =VLOOKUP($Q6,'Written Exam Marks'!$H:$Q,9,FALSE) -> 40 | AF6: =IF(COUNTIF($AB6:$AC6,"P-*")>0,"Present", IF(COUNTIF($AB6:$AC6,"A-*")>0,"Absent", IF(COUNTIF($AB6:$AC6,"No Data")>0,"No Data",""))) -> Present | AG6: =IF(LEFT($AB6,2)="P-",$AB6,IF(LEFT($AC6,2)="P-",$AC6,IF(LEFT($AB6,2)="A-",$AB6,IF(LEFT($AC6,2)="A-",$AC6,IF($AB6="No Data",$AB6,IF($AC6="No Data",$AC6,"")))))) -> P-S1_Online | AH6: 14 | AI6: 12 | AJ6: 8 | AK6: A | AL6: A | AM6: 34 | AN6: 60 | AO6: Computer Systems | AP6: BDSDF108 | AQ6: =CONCATENATE($C6,"-",$AP6) -> 2025EB1100003-BDSDF108 | AR6: =COUNTIF($AJ6:$AL6,"A") & " " & "missed" -> 2 missed | AS6: =COUNTIF($AH6:$AI6,"A") & " " & "missed" -> 0 missed | AT6: =3-COUNTIF(AJ6:AL6,"A") -> 1 | AU6: =2-COUNTIF($AH6:$AI6,"A") -> 2 | AV6: =$AT6/3 -> 0.33333333 | AW6: =$AU6/2 -> 1 | AX6: =COUNTIF($AH6:$AL6, "A") & " " &"missed" -> 2 missed | AY6: =5- COUNTIF($AH6:$AL6, "A") -> 3 | AZ6: =$AY6/5 -> 0.6 | BA6: =CONCATENATE("Q-",$AT6," A-",$AU6," || Q Total-3, A Total-2") -> Q-1 A-2 || Q Total-3, A Total-2 | BB6: {=IFERROR(INDEX('Attendance-Slot-1'!$Q$2:$Q$1112,MATCH(1,('Attendance-Slot-1'!$A$2:$A$1112=$C6)*('Attendance-Slot-1'!$G$2:$G$1112=BB$2),0)),"No Data")} -> P-S1_Online | BC6: {=IFERROR(INDEX('Attendance-Slot-2'!$Q$2:$Q$2595,MATCH(1,('Attendance-Slot-2'!$A$2:$A$2595=$C6)*('Attendance-Slot-2'!$G$2:$G$2595=BB$2),0)),"No Data")} -> No Data | BD6: =VLOOKUP($AQ6,'Written Exam Marks'!$H:$Q,10,FALSE) -> 3.5 | BE6: =VLOOKUP($AQ6,'Written Exam Marks'!$H:$Q,9,FALSE) -> 40 | BF6: =IF(COUNTIF($BB6:$BC6,"P-*")>0,"Present", IF(COUNTIF($BB6:$BC6,"A-*")>0,"Absent", IF(COUNTIF($BB6:$BC6,"No Data")>0,"No Data",""))) -> Present | BG6: =IF(LEFT($BB6,2)="P-",$BB6,IF(LEFT($BC6,2)="P-",$BC6,IF(LEFT($BB6,2)="A-",$BB6,IF(LEFT($BC6,2)="A-",$BC6,IF($BB6="No Data",$BB6,IF($BC6="No Data",$BC6,"")))))) -> P-S1_Online | BH6: 10 | BI6: A | BJ6: 15 | BK6: A | BL6: 25 | BM6: 60 | BN6: Probability & Statistics | BO6: BDSDF114 | BP6: =CONCATENATE($C6,"-",$BO6) -> 2025EB1100003-BDSDF114 | BQ6: =COUNTIF($BH6:$BJ6,"A") & " " & "missed" -> 1 missed | BR6: =COUNTIF($BK6,"A") & " " & "missed" -> 1 missed | BS6: =3-COUNTIF($BH6:$BJ6,"A") -> 2 | BT6: =1-COUNTIF($BK6,"A") -> 0 | BU6: =$BS6/3 -> 0.66666667 | BV6: =$BT6/1 -> 0 | BW6: =COUNTIF($BH6:$BK6, "A") & " " &"missed" -> 2 missed | BX6: =4- COUNTIF(BH6:BK6, "A") -> 2 | BY6: =$BX6/4 -> 0.5 | BZ6: =CONCATENATE("Q-",$BS6," A-",$BT6," || Q Total-3, A Total-1") -> Q-2 A-0 || Q Total-3, A Total-1 | CA6: {=IFERROR(INDEX('Attendance-Slot-1'!$Q$2:$Q$1112,MATCH(1,('Attendance-Slot-1'!$A$2:$A$1112=$C6)*('Attendance-Slot-1'!$G$2:$G$1112=CA$2),0)),"No Data")} -> No Data | CB6: {=IFERROR(INDEX('Attendance-Slot-2'!$Q$2:$Q$2595,MATCH(1,('Attendance-Slot-2'!$A$2:$A$2595=$C6)*('Attendance-Slot-2'!$G$2:$G$2595=CA$2),0)),"No Data")} -> A-S2_Online | CC6: =VLOOKUP($BP6,'Written Exam Marks'!$H:$Q,10,FALSE) -> #N/A | CD6: =VLOOKUP($BP6,'Written Exam Marks'!$H:$Q,9,FALSE) -> #N/A | CE6: =IF(COUNTIF($CA6:$CB6,"P-*")>0,"Present", IF(COUNTIF($CA6:$CB6,"A-*")>0,"Absent", IF(COUNTIF($CA6:$CB6,"No Data")>0,"No Data",""))) -> Absent | CF6: =IF(LEFT($CA6,2)="P-",$CA6,IF(LEFT($CB6,2)="P-",$CB6,IF(LEFT($CA6,2)="A-",$CA6,IF(LEFT($CB6,2)="A-",$CB6,IF($CA6="No Data",$CA6,IF($CB6="No Data",$CB6,"")))))) -> A-S2_Online | CG6: 5 | CH6: 4.5 | CI6: A | CJ6: A | CK6: A | CL6: A | CM6: 9.5 | CN6: 50 | CO6: Writing Practice | CP6: BDSDF112 | CQ6: =CONCATENATE($C6,"-",$CP6) -> 2025EB1100003-BDSDF112 | CR6: =COUNTIF($CG6:$CH6,"A") & " " & "missed" -> 0 missed | CS6: =COUNTIF($CI6:$CJ6,"A") & " " & "missed" -> 2 missed | CT6: =2-COUNTIF($CG6:$CH6,"A") -> 2 | CU6: =2-COUNTIF($CI6:$CJ6,"A") -> 0 | CV6: =$CT6/2 -> 1 | CW6: =$CU6/2 -> 0 | CX6: =COUNTIF($CG6:$CJ6, "A") & " " &"missed" -> 2 missed | CY6: =4- COUNTIF($CG6:$CJ6, "A") -> 2 | CZ6: =$CY6/4 -> 0.5 | DA6: =CONCATENATE("Q-",$CT6," A-",$CU6," || Q Total-2, A Total-2") -> Q-2 A-0 || Q Total-2, A Total-2 | DB6: {=IFERROR(INDEX('Attendance-Slot-1'!$Q$2:$Q$1112,MATCH(1,('Attendance-Slot-1'!$A$2:$A$1112=$C6)*('Attendance-Slot-1'!$G$2:$G$1112=DB$2),0)),"No Data")} -> P-S1_Online | DC6: {=IFERROR(INDEX('Attendance-Slot-2'!$Q$2:$Q$2595,MATCH(1,('Attendance-Slot-2'!$A$2:$A$2595=$C6)*('Attendance-Slot-2'!$G$2:$G$2595=DB$2),0)),"No Data")} -> No Data | DD6: =VLOOKUP($CQ6,'Written Exam Marks'!$H:$Q,10,FALSE) -> 16 | DE6: =VLOOKUP($CQ6,'Written Exam Marks'!$H:$Q,9,FALSE) -> 50 | DF6: =IF(COUNTIF($DB6:$DC6,"P-*")>0,"Present", IF(COUNTIF($DB6:$DC6,"A-*")>0,"Absent", IF(COUNTIF($DB6:$DC6,"No Data")>0,"No Data",""))) -> Present | DG6: =IF(LEFT($DB6,2)="P-",$DB6,IF(LEFT($DC6,2)="P-",$DC6,IF(LEFT($DB6,2)="A-",$DB6,IF(LEFT($DC6,2)="A-",$DC6,IF($DB6="No Data",$DB6,IF($DC6="No Data",$DC6,"")))))) -> P-S1_Online | DH6: 95 | DI6: 95 | DJ6: 100 | DK6: ="P-"&(COUNTIF($AB6,"P-*")+COUNTIF($BB6,"P-*")+COUNTIF($CA6,"P-*")+COUNTIF($DB6,"P-*"))&", A-"&(COUNTIF($AB6,"A-*")+COUNTIF($BB6,"A-*")+COUNTIF($CA6,"A-*")+COUNTIF($DB6,"A-*"))&", No Data-"&(COUNTIF($AB6,"No Data")+COUNTIF($BB6,"No Data")+COUNTIF($CA6,"No Data")+COUNTIF($DB6,"No Data")) -> P-3, A-0, No Data-1 | DL6: ="P-"&(COUNTIF($AC6,"P-*")+COUNTIF($BC6,"P-*")+COUNTIF($CB6,"P-*")+COUNTIF($DC6,"P-*"))&", A-"&(COUNTIF($AC6,"A-*")+COUNTIF($BC6,"A-*")+COUNTIF($CB6,"A-*")+COUNTIF($DC6,"A-*"))&", No Data-"&(COUNTIF($AC6,"No Data")+COUNTIF($BC6,"No Data")+COUNTIF($CB6,"No Data")+COUNTIF($DC6,"No Data")) -> P-0, A-1, No Data-3 | DM6: =IF(LEFT($AB6,2)="P-",$AB6, IF(LEFT($AC6,2)="P-",$AC6, IF(LEFT($AB6,2)="A-",$AB6, IF(LEFT($AC6,2)="A-",$AC6, IF($AB6="No Data",$AB6, IF($AC6="No Data",$AC6,"")))))) -> P-S1_Online | DN6: =IF(LEFT($DB6,2)="P-",$DB6, IF(LEFT($DC6,2)="P-",$DC6, IF(LEFT($DB6,2)="A-",$DB6, IF(LEFT($DC6,2)="A-",$DC6, IF($DB6="No Data",$DB6, IF($DC6="No Data",$DC6,"")))))) -> P-S1_Online | DO6: =IF(LEFT($BB6,2)="P-",$BB6, IF(LEFT($BC6,2)="P-",$BC6, IF(LEFT($BB6,2)="A-",$BB6, IF(LEFT($BC6,2)="A-",$BC6, IF($BB6="No Data",$BB6, IF($BC6="No Data",$BC6,"")))))) -> P-S1_Online | DP6: =IF(LEFT($CA6,2)="P-",$CA6, IF(LEFT($CB6,2)="P-",$CB6, IF(LEFT($CA6,2)="A-",$CA6, IF(LEFT($CB6,2)="A-",$CB6, IF($CA6="No Data",$CA6, IF($CB6="No Data",$CB6,"")))))) -> A-S2_Online | DQ6: ="P-"&COUNTIF($DM6:$DP6,"P-*")&", A-"&COUNTIF($DM6:$DP6,"A-*")&", No Data-"&COUNTIF($DM6:$DP6,"No Data") -> P-3, A-1, No Data-0 | DR6: =IF( AND( $AA6="Q-4 A-1 || Q Total-4, A Total-1", $BA6="Q-3 A-2 || Q Total-3, A Total-2", $BZ6="Q-3 A-1 || Q Total-3, A Total-1", $DA6="Q-2 A-2 || Q Total-2, A Total-2" ), 1, 0 ) -> 0 | DS6: Activated | DT6: Exam Given | DU6: 2025EB1100003
A7: 4 | B7: BS DS-AI | C7: 2025EB1100004 | D7: 2025eb1100004@bitspilani-digital.edu.in | E7: ARUNLAL P | F7: MALE | G7: `+91-9444088435 | H7: 8 | I7: 6.4 | J7: A | K7: 7.2 | L7: 28 | M7: 49.6 | N7: 60 | O7: Computer Programming | P7: BDSDF113 | Q7: =CONCATENATE($C7,"-",$P7) -> 2025EB1100004-BDSDF113 | R7: =COUNTIF($H7:$K7,"A") & " " & "missed" -> 1 missed | S7: =COUNTIF(L7,"A") & " " & "missed" -> 0 missed | T7: =4-COUNTIF($H7:$K7,"A") -> 3 | U7: =1-COUNTIF($L7,"A") -> 1 | V7: =$T7/4 -> 0.75 | W7: =$U7/1 -> 1 | X7: =COUNTIF($H7:$L7, "A") & " " &"missed" -> 1 missed | Y7: =5- COUNTIF($H7:$L7, "A") -> 4 | Z7: =$Y7/5 -> 0.8 | AA7: =CONCATENATE("Q-",$T7," A-",$U7," || Q Total-4, A Total-1") -> Q-3 A-1 || Q Total-4, A Total-1 | AB7: {=IFERROR(INDEX('Attendance-Slot-1'!$Q$2:$Q$1112,MATCH(1,('Attendance-Slot-1'!$A$2:$A$1112=$C7)*('Attendance-Slot-1'!$G$2:$G$1112=AB$2),0)),"No Data")} -> No Data | AC7: {=IFERROR(INDEX('Attendance-Slot-2'!$Q$2:$Q$2595,MATCH(1,('Attendance-Slot-2'!$A$2:$A$2595=$C7)*('Attendance-Slot-2'!$G$2:$G$2595=AB$2),0)),"No Data")} -> P-S2_Onsite | AD7: =VLOOKUP($Q7,'Written Exam Marks'!$H:$Q,10,FALSE) -> 6 | AE7: =VLOOKUP($Q7,'Written Exam Marks'!$H:$Q,9,FALSE) -> 40 | AF7: =IF(COUNTIF($AB7:$AC7,"P-*")>0,"Present", IF(COUNTIF($AB7:$AC7,"A-*")>0,"Absent", IF(COUNTIF($AB7:$AC7,"No Data")>0,"No Data",""))) -> Present | AG7: =IF(LEFT($AB7,2)="P-",$AB7,IF(LEFT($AC7,2)="P-",$AC7,IF(LEFT($AB7,2)="A-",$AB7,IF(LEFT($AC7,2)="A-",$AC7,IF($AB7="No Data",$AB7,IF($AC7="No Data",$AC7,"")))))) -> P-S2_Onsite | AH7: 15 | AI7: 6 | AJ7: 8 | AK7: A | AL7: 8 | AM7: 37 | AN7: 60 | AO7: Computer Systems | AP7: BDSDF108 | AQ7: =CONCATENATE($C7,"-",$AP7) -> 2025EB1100004-BDSDF108 | AR7: =COUNTIF($AJ7:$AL7,"A") & " " & "missed" -> 1 missed | AS7: =COUNTIF($AH7:$AI7,"A") & " " & "missed" -> 0 missed | AT7: =3-COUNTIF(AJ7:AL7,"A") -> 2 | AU7: =2-COUNTIF($AH7:$AI7,"A") -> 2 | AV7: =$AT7/3 -> 0.66666667 | AW7: =$AU7/2 -> 1 | AX7: =COUNTIF($AH7:$AL7, "A") & " " &"missed" -> 1 missed | AY7: =5- COUNTIF($AH7:$AL7, "A") -> 4 | AZ7: =$AY7/5 -> 0.8 | BA7: =CONCATENATE("Q-",$AT7," A-",$AU7," || Q Total-3, A Total-2") -> Q-2 A-2 || Q Total-3, A Total-2 | BB7: {=IFERROR(INDEX('Attendance-Slot-1'!$Q$2:$Q$1112,MATCH(1,('Attendance-Slot-1'!$A$2:$A$1112=$C7)*('Attendance-Slot-1'!$G$2:$G$1112=BB$2),0)),"No Data")} -> No Data | BC7: {=IFERROR(INDEX('Attendance-Slot-2'!$Q$2:$Q$2595,MATCH(1,('Attendance-Slot-2'!$A$2:$A$2595=$C7)*('Attendance-Slot-2'!$G$2:$G$2595=BB$2),0)),"No Data")} -> P-S2_Onsite | BD7: =VLOOKUP($AQ7,'Written Exam Marks'!$H:$Q,10,FALSE) -> 12 | BE7: =VLOOKUP($AQ7,'Written Exam Marks'!$H:$Q,9,FALSE) -> 40 | BF7: =IF(COUNTIF($BB7:$BC7,"P-*")>0,"Present", IF(COUNTIF($BB7:$BC7,"A-*")>0,"Absent", IF(COUNTIF($BB7:$BC7,"No Data")>0,"No Data",""))) -> Present | BG7: =IF(LEFT($BB7,2)="P-",$BB7,IF(LEFT($BC7,2)="P-",$BC7,IF(LEFT($BB7,2)="A-",$BB7,IF(LEFT($BC7,2)="A-",$BC7,IF($BB7="No Data",$BB7,IF($BC7="No Data",$BC7,"")))))) -> P-S2_Onsite | BH7: 10 | BI7: 15 | BJ7: 15 | BK7: 20 | BL7: 60 | BM7: 60 | BN7: Probability & Statistics | BO7: BDSDF114 | BP7: =CONCATENATE($C7,"-",$BO7) -> 2025EB1100004-BDSDF114 | BQ7: =COUNTIF($BH7:$BJ7,"A") & " " & "missed" -> 0 missed | BR7: =COUNTIF($BK7,"A") & " " & "missed" -> 0 missed | BS7: =3-COUNTIF($BH7:$BJ7,"A") -> 3 | BT7: =1-COUNTIF($BK7,"A") -> 1 | BU7: =$BS7/3 -> 1 | BV7: =$BT7/1 -> 1 | BW7: =COUNTIF($BH7:$BK7, "A") & " " &"missed" -> 0 missed | BX7: =4- COUNTIF(BH7:BK7, "A") -> 4 | BY7: =$BX7/4 -> 1 | BZ7: =CONCATENATE("Q-",$BS7," A-",$BT7," || Q Total-3, A Total-1") -> Q-3 A-1 || Q Total-3, A Total-1 | CA7: {=IFERROR(INDEX('Attendance-Slot-1'!$Q$2:$Q$1112,MATCH(1,('Attendance-Slot-1'!$A$2:$A$1112=$C7)*('Attendance-Slot-1'!$G$2:$G$1112=CA$2),0)),"No Data")} -> P-S1_Onsite | CB7: {=IFERROR(INDEX('Attendance-Slot-2'!$Q$2:$Q$2595,MATCH(1,('Attendance-Slot-2'!$A$2:$A$2595=$C7)*('Attendance-Slot-2'!$G$2:$G$2595=CA$2),0)),"No Data")} -> No Data | CC7: =VLOOKUP($BP7,'Written Exam Marks'!$H:$Q,10,FALSE) -> 14 | CD7: =VLOOKUP($BP7,'Written Exam Marks'!$H:$Q,9,FALSE) -> 40 | CE7: =IF(COUNTIF($CA7:$CB7,"P-*")>0,"Present", IF(COUNTIF($CA7:$CB7,"A-*")>0,"Absent", IF(COUNTIF($CA7:$CB7,"No Data")>0,"No Data",""))) -> Present | CF7: =IF(LEFT($CA7,2)="P-",$CA7,IF(LEFT($CB7,2)="P-",$CB7,IF(LEFT($CA7,2)="A-",$CA7,IF(LEFT($CB7,2)="A-",$CB7,IF($CA7="No Data",$CA7,IF($CB7="No Data",$CB7,"")))))) -> P-S1_Onsite | CG7: 5 | CH7: 4.5 | CI7: 8.5 | CJ7: A | CK7: 10 | CL7: A | CM7: 28 | CN7: 50 | CO7: Writing Practice | CP7: BDSDF112 | CQ7: =CONCATENATE($C7,"-",$CP7) -> 2025EB1100004-BDSDF112 | CR7: =COUNTIF($CG7:$CH7,"A") & " " & "missed" -> 0 missed | CS7: =COUNTIF($CI7:$CJ7,"A") & " " & "missed" -> 1 missed | CT7: =2-COUNTIF($CG7:$CH7,"A") -> 2 | CU7: =2-COUNTIF($CI7:$CJ7,"A") -> 1 | CV7: =$CT7/2 -> 1 | CW7: =$CU7/2 -> 0.5 | CX7: =COUNTIF($CG7:$CJ7, "A") & " " &"missed" -> 1 missed | CY7: =4- COUNTIF($CG7:$CJ7, "A") -> 3 | CZ7: =$CY7/4 -> 0.75 | DA7: =CONCATENATE("Q-",$CT7," A-",$CU7," || Q Total-2, A Total-2") -> Q-2 A-1 || Q Total-2, A Total-2 | DB7: {=IFERROR(INDEX('Attendance-Slot-1'!$Q$2:$Q$1112,MATCH(1,('Attendance-Slot-1'!$A$2:$A$1112=$C7)*('Attendance-Slot-1'!$G$2:$G$1112=DB$2),0)),"No Data")} -> P-S1_Onsite | DC7: {=IFERROR(INDEX('Attendance-Slot-2'!$Q$2:$Q$2595,MATCH(1,('Attendance-Slot-2'!$A$2:$A$2595=$C7)*('Attendance-Slot-2'!$G$2:$G$2595=DB$2),0)),"No Data")} -> No Data | DD7: =VLOOKUP($CQ7,'Written Exam Marks'!$H:$Q,10,FALSE) -> 29 | DE7: =VLOOKUP($CQ7,'Written Exam Marks'!$H:$Q,9,FALSE) -> 50 | DF7: =IF(COUNTIF($DB7:$DC7,"P-*")>0,"Present", IF(COUNTIF($DB7:$DC7,"A-*")>0,"Absent", IF(COUNTIF($DB7:$DC7,"No Data")>0,"No Data",""))) -> Present | DG7: =IF(LEFT($DB7,2)="P-",$DB7,IF(LEFT($DC7,2)="P-",$DC7,IF(LEFT($DB7,2)="A-",$DB7,IF(LEFT($DC7,2)="A-",$DC7,IF($DB7="No Data",$DB7,IF($DC7="No Data",$DC7,"")))))) -> P-S1_Onsite | DH7: 90 | DI7: 90 | DJ7: 100 | DK7: ="P-"&(COUNTIF($AB7,"P-*")+COUNTIF($BB7,"P-*")+COUNTIF($CA7,"P-*")+COUNTIF($DB7,"P-*"))&", A-"&(COUNTIF($AB7,"A-*")+COUNTIF($BB7,"A-*")+COUNTIF($CA7,"A-*")+COUNTIF($DB7,"A-*"))&", No Data-"&(COUNTIF($AB7,"No Data")+COUNTIF($BB7,"No Data")+COUNTIF($CA7,"No Data")+COUNTIF($DB7,"No Data")) -> P-2, A-0, No Data-2 | DL7: ="P-"&(COUNTIF($AC7,"P-*")+COUNTIF($BC7,"P-*")+COUNTIF($CB7,"P-*")+COUNTIF($DC7,"P-*"))&", A-"&(COUNTIF($AC7,"A-*")+COUNTIF($BC7,"A-*")+COUNTIF($CB7,"A-*")+COUNTIF($DC7,"A-*"))&", No Data-"&(COUNTIF($AC7,"No Data")+COUNTIF($BC7,"No Data")+COUNTIF($CB7,"No Data")+COUNTIF($DC7,"No Data")) -> P-2, A-0, No Data-2 | DM7: =IF(LEFT($AB7,2)="P-",$AB7, IF(LEFT($AC7,2)="P-",$AC7, IF(LEFT($AB7,2)="A-",$AB7, IF(LEFT($AC7,2)="A-",$AC7, IF($AB7="No Data",$AB7, IF($AC7="No Data",$AC7,"")))))) -> P-S2_Onsite | DN7: =IF(LEFT($DB7,2)="P-",$DB7, IF(LEFT($DC7,2)="P-",$DC7, IF(LEFT($DB7,2)="A-",$DB7, IF(LEFT($DC7,2)="A-",$DC7, IF($DB7="No Data",$DB7, IF($DC7="No Data",$DC7,"")))))) -> P-S1_Onsite | DO7: =IF(LEFT($BB7,2)="P-",$BB7, IF(LEFT($BC7,2)="P-",$BC7, IF(LEFT($BB7,2)="A-",$BB7, IF(LEFT($BC7,2)="A-",$BC7, IF($BB7="No Data",$BB7, IF($BC7="No Data",$BC7,"")))))) -> P-S2_Onsite | DP7: =IF(LEFT($CA7,2)="P-",$CA7, IF(LEFT($CB7,2)="P-",$CB7, IF(LEFT($CA7,2)="A-",$CA7, IF(LEFT($CB7,2)="A-",$CB7, IF($CA7="No Data",$CA7, IF($CB7="No Data",$CB7,"")))))) -> P-S1_Onsite | DQ7: ="P-"&COUNTIF($DM7:$DP7,"P-*")&", A-"&COUNTIF($DM7:$DP7,"A-*")&", No Data-"&COUNTIF($DM7:$DP7,"No Data") -> P-4, A-0, No Data-0 | DR7: =IF( AND( $AA7="Q-4 A-1 || Q Total-4, A Total-1", $BA7="Q-3 A-2 || Q Total-3, A Total-2", $BZ7="Q-3 A-1 || Q Total-3, A Total-1", $DA7="Q-2 A-2 || Q Total-2, A Total-2" ), 1, 0 ) -> 0 | DS7: Activated | DT7: Exam Given | DU7: 2025EB1100004
A8: 5 | B8: BS DS-AI | C8: 2025EB1100005 | D8: 2025eb1100005@bitspilani-digital.edu.in | E8: RUPEN TAK | F8: MALE | G8: `+91-9729809711 | H8: A | I8: A | J8: A | K8: A | L8: A | M8: 1.6 | N8: 60 | O8: Computer Programming | P8: BDSDF113 | Q8: =CONCATENATE($C8,"-",$P8) -> 2025EB1100005-BDSDF113 | R8: =COUNTIF($H8:$K8,"A") & " " & "missed" -> 4 missed | S8: =COUNTIF(L8,"A") & " " & "missed" -> 1 missed | T8: =4-COUNTIF($H8:$K8,"A") -> 0 | U8: =1-COUNTIF($L8,"A") -> 0 | V8: =$T8/4 -> 0 | W8: =$U8/1 -> 0 | X8: =COUNTIF($H8:$L8, "A") & " " &"missed" -> 5 missed | Y8: =5- COUNTIF($H8:$L8, "A") -> 0 | Z8: =$Y8/5 -> 0 | AA8: =CONCATENATE("Q-",$T8," A-",$U8," || Q Total-4, A Total-1") -> Q-0 A-0 || Q Total-4, A Total-1 | AB8: {=IFERROR(INDEX('Attendance-Slot-1'!$Q$2:$Q$1112,MATCH(1,('Attendance-Slot-1'!$A$2:$A$1112=$C8)*('Attendance-Slot-1'!$G$2:$G$1112=AB$2),0)),"No Data")} -> No Data | AC8: {=IFERROR(INDEX('Attendance-Slot-2'!$Q$2:$Q$2595,MATCH(1,('Attendance-Slot-2'!$A$2:$A$2595=$C8)*('Attendance-Slot-2'!$G$2:$G$2595=AB$2),0)),"No Data")} -> P-S2_Onsite | AD8: =VLOOKUP($Q8,'Written Exam Marks'!$H:$Q,10,FALSE) -> 3 | AE8: =VLOOKUP($Q8,'Written Exam Marks'!$H:$Q,9,FALSE) -> 40 | AF8: =IF(COUNTIF($AB8:$AC8,"P-*")>0,"Present", IF(COUNTIF($AB8:$AC8,"A-*")>0,"Absent", IF(COUNTIF($AB8:$AC8,"No Data")>0,"No Data",""))) -> Present | AG8: =IF(LEFT($AB8,2)="P-",$AB8,IF(LEFT($AC8,2)="P-",$AC8,IF(LEFT($AB8,2)="A-",$AB8,IF(LEFT($AC8,2)="A-",$AC8,IF($AB8="No Data",$AB8,IF($AC8="No Data",$AC8,"")))))) -> P-S2_Onsite | AH8: A | AI8: A | AJ8: A | AK8: A | AL8: 7 | AM8: 7 | AN8: 60 | AO8: Computer Systems | AP8: BDSDF108 | AQ8: =CONCATENATE($C8,"-",$AP8) -> 2025EB1100005-BDSDF108 | AR8: =COUNTIF($AJ8:$AL8,"A") & " " & "missed" -> 2 missed | AS8: =COUNTIF($AH8:$AI8,"A") & " " & "missed" -> 2 missed | AT8: =3-COUNTIF(AJ8:AL8,"A") -> 1 | AU8: =2-COUNTIF($AH8:$AI8,"A") -> 0 | AV8: =$AT8/3 -> 0.33333333 | AW8: =$AU8/2 -> 0 | AX8: =COUNTIF($AH8:$AL8, "A") & " " &"missed" -> 4 missed | AY8: =5- COUNTIF($AH8:$AL8, "A") -> 1 | AZ8: =$AY8/5 -> 0.2 | BA8: =CONCATENATE("Q-",$AT8," A-",$AU8," || Q Total-3, A Total-2") -> Q-1 A-0 || Q Total-3, A Total-2 | BB8: {=IFERROR(INDEX('Attendance-Slot-1'!$Q$2:$Q$1112,MATCH(1,('Attendance-Slot-1'!$A$2:$A$1112=$C8)*('Attendance-Slot-1'!$G$2:$G$1112=BB$2),0)),"No Data")} -> P-S1_Onsite | BC8: {=IFERROR(INDEX('Attendance-Slot-2'!$Q$2:$Q$2595,MATCH(1,('Attendance-Slot-2'!$A$2:$A$2595=$C8)*('Attendance-Slot-2'!$G$2:$G$2595=BB$2),0)),"No Data")} -> No Data | BD8: =VLOOKUP($AQ8,'Written Exam Marks'!$H:$Q,10,FALSE) -> 14 | BE8: =VLOOKUP($AQ8,'Written Exam Marks'!$H:$Q,9,FALSE) -> 40 | BF8: =IF(COUNTIF($BB8:$BC8,"P-*")>0,"Present", IF(COUNTIF($BB8:$BC8,"A-*")>0,"Absent", IF(COUNTIF($BB8:$BC8,"No Data")>0,"No Data",""))) -> Present | BG8: =IF(LEFT($BB8,2)="P-",$BB8,IF(LEFT($BC8,2)="P-",$BC8,IF(LEFT($BB8,2)="A-",$BB8,IF(LEFT($BC8,2)="A-",$BC8,IF($BB8="No Data",$BB8,IF($BC8="No Data",$BC8,"")))))) -> P-S1_Onsite | BH8: 5 | BI8: A | BJ8: A | BK8: A | BL8: 5 | BM8: 60 | BN8: Probability & Statistics | BO8: BDSDF114 | BP8: =CONCATENATE($C8,"-",$BO8) -> 2025EB1100005-BDSDF114 | BQ8: =COUNTIF($BH8:$BJ8,"A") & " " & "missed" -> 2 missed | BR8: =COUNTIF($BK8,"A") & " " & "missed" -> 1 missed | BS8: =3-COUNTIF($BH8:$BJ8,"A") -> 1 | BT8: =1-COUNTIF($BK8,"A") -> 0 | BU8: =$BS8/3 -> 0.33333333 | BV8: =$BT8/1 -> 0 | BW8: =COUNTIF($BH8:$BK8, "A") & " " &"missed" -> 3 missed | BX8: =4- COUNTIF(BH8:BK8, "A") -> 1 | BY8: =$BX8/4 -> 0.25 | BZ8: =CONCATENATE("Q-",$BS8," A-",$BT8," || Q Total-3, A Total-1") -> Q-1 A-0 || Q Total-3, A Total-1 | CA8: {=IFERROR(INDEX('Attendance-Slot-1'!$Q$2:$Q$1112,MATCH(1,('Attendance-Slot-1'!$A$2:$A$1112=$C8)*('Attendance-Slot-1'!$G$2:$G$1112=CA$2),0)),"No Data")} -> No Data | CB8: {=IFERROR(INDEX('Attendance-Slot-2'!$Q$2:$Q$2595,MATCH(1,('Attendance-Slot-2'!$A$2:$A$2595=$C8)*('Attendance-Slot-2'!$G$2:$G$2595=CA$2),0)),"No Data")} -> P-S2_Onsite | CC8: =VLOOKUP($BP8,'Written Exam Marks'!$H:$Q,10,FALSE) -> 4 | CD8: =VLOOKUP($BP8,'Written Exam Marks'!$H:$Q,9,FALSE) -> 40 | CE8: =IF(COUNTIF($CA8:$CB8,"P-*")>0,"Present", IF(COUNTIF($CA8:$CB8,"A-*")>0,"Absent", IF(COUNTIF($CA8:$CB8,"No Data")>0,"No Data",""))) -> Present | CF8: =IF(LEFT($CA8,2)="P-",$CA8,IF(LEFT($CB8,2)="P-",$CB8,IF(LEFT($CA8,2)="A-",$CA8,IF(LEFT($CB8,2)="A-",$CB8,IF($CA8="No Data",$CA8,IF($CB8="No Data",$CB8,"")))))) -> P-S2_Onsite | CG8: 1.5 | CH8: A | CI8: A | CJ8: A | CK8: A | CL8: A | CM8: 1.5 | CN8: 50 | CO8: Writing Practice | CP8: BDSDF112 | CQ8: =CONCATENATE($C8,"-",$CP8) -> 2025EB1100005-BDSDF112 | CR8: =COUNTIF($CG8:$CH8,"A") & " " & "missed" -> 1 missed | CS8: =COUNTIF($CI8:$CJ8,"A") & " " & "missed" -> 2 missed | CT8: =2-COUNTIF($CG8:$CH8,"A") -> 1 | CU8: =2-COUNTIF($CI8:$CJ8,"A") -> 0 | CV8: =$CT8/2 -> 0.5 | CW8: =$CU8/2 -> 0 | CX8: =COUNTIF($CG8:$CJ8, "A") & " " &"missed" -> 3 missed | CY8: =4- COUNTIF($CG8:$CJ8, "A") -> 1 | CZ8: =$CY8/4 -> 0.25 | DA8: =CONCATENATE("Q-",$CT8," A-",$CU8," || Q Total-2, A Total-2") -> Q-1 A-0 || Q Total-2, A Total-2 | DB8: {=IFERROR(INDEX('Attendance-Slot-1'!$Q$2:$Q$1112,MATCH(1,('Attendance-Slot-1'!$A$2:$A$1112=$C8)*('Attendance-Slot-1'!$G$2:$G$1112=DB$2),0)),"No Data")} -> P-S1_Onsite | DC8: {=IFERROR(INDEX('Attendance-Slot-2'!$Q$2:$Q$2595,MATCH(1,('Attendance-Slot-2'!$A$2:$A$2595=$C8)*('Attendance-Slot-2'!$G$2:$G$2595=DB$2),0)),"No Data")} -> No Data | DD8: =VLOOKUP($CQ8,'Written Exam Marks'!$H:$Q,10,FALSE) -> 24 | DE8: =VLOOKUP($CQ8,'Written Exam Marks'!$H:$Q,9,FALSE) -> 50 | DF8: =IF(COUNTIF($DB8:$DC8,"P-*")>0,"Present", IF(COUNTIF($DB8:$DC8,"A-*")>0,"Absent", IF(COUNTIF($DB8:$DC8,"No Data")>0,"No Data",""))) -> Present | DG8: =IF(LEFT($DB8,2)="P-",$DB8,IF(LEFT($DC8,2)="P-",$DC8,IF(LEFT($DB8,2)="A-",$DB8,IF(LEFT($DC8,2)="A-",$DC8,IF($DB8="No Data",$DB8,IF($DC8="No Data",$DC8,"")))))) -> P-S1_Onsite | DH8: 90 | DI8: 90 | DJ8: 100 | DK8: ="P-"&(COUNTIF($AB8,"P-*")+COUNTIF($BB8,"P-*")+COUNTIF($CA8,"P-*")+COUNTIF($DB8,"P-*"))&", A-"&(COUNTIF($AB8,"A-*")+COUNTIF($BB8,"A-*")+COUNTIF($CA8,"A-*")+COUNTIF($DB8,"A-*"))&", No Data-"&(COUNTIF($AB8,"No Data")+COUNTIF($BB8,"No Data")+COUNTIF($CA8,"No Data")+COUNTIF($DB8,"No Data")) -> P-2, A-0, No Data-2 | DL8: ="P-"&(COUNTIF($AC8,"P-*")+COUNTIF($BC8,"P-*")+COUNTIF($CB8,"P-*")+COUNTIF($DC8,"P-*"))&", A-"&(COUNTIF($AC8,"A-*")+COUNTIF($BC8,"A-*")+COUNTIF($CB8,"A-*")+COUNTIF($DC8,"A-*"))&", No Data-"&(COUNTIF($AC8,"No Data")+COUNTIF($BC8,"No Data")+COUNTIF($CB8,"No Data")+COUNTIF($DC8,"No Data")) -> P-2, A-0, No Data-2 | DM8: =IF(LEFT($AB8,2)="P-",$AB8, IF(LEFT($AC8,2)="P-",$AC8, IF(LEFT($AB8,2)="A-",$AB8, IF(LEFT($AC8,2)="A-",$AC8, IF($AB8="No Data",$AB8, IF($AC8="No Data",$AC8,"")))))) -> P-S2_Onsite | DN8: =IF(LEFT($DB8,2)="P-",$DB8, IF(LEFT($DC8,2)="P-",$DC8, IF(LEFT($DB8,2)="A-",$DB8, IF(LEFT($DC8,2)="A-",$DC8, IF($DB8="No Data",$DB8, IF($DC8="No Data",$DC8,"")))))) -> P-S1_Onsite | DO8: =IF(LEFT($BB8,2)="P-",$BB8, IF(LEFT($BC8,2)="P-",$BC8, IF(LEFT($BB8,2)="A-",$BB8, IF(LEFT($BC8,2)="A-",$BC8, IF($BB8="No Data",$BB8, IF($BC8="No Data",$BC8,"")))))) -> P-S1_Onsite | DP8: =IF(LEFT($CA8,2)="P-",$CA8, IF(LEFT($CB8,2)="P-",$CB8, IF(LEFT($CA8,2)="A-",$CA8, IF(LEFT($CB8,2)="A-",$CB8, IF($CA8="No Data",$CA8, IF($CB8="No Data",$CB8,"")))))) -> P-S2_Onsite | DQ8: ="P-"&COUNTIF($DM8:$DP8,"P-*")&", A-"&COUNTIF($DM8:$DP8,"A-*")&", No Data-"&COUNTIF($DM8:$DP8,"No Data") -> P-4, A-0, No Data-0 | DR8: =IF( AND( $AA8="Q-4 A-1 || Q Total-4, A Total-1", $BA8="Q-3 A-2 || Q Total-3, A Total-2", $BZ8="Q-3 A-1 || Q Total-3, A Total-1", $DA8="Q-2 A-2 || Q Total-2, A Total-2" ), 1, 0 ) -> 0 | DS8: Activated | DT8: Exam Given | DU8: 2025EB1100005
A9: 6 | B9: BS DS-AI | C9: 2025EB1100006 | D9: 2025eb1100006@bitspilani-digital.edu.in | E9: JAL PATEL | F9: MALE | G9: `+91-6356170830 | H9: 5.6 | I9: A | J9: 8 | K9: 8 | L9: 28 | M9: 49.6 | N9: 60 | O9: Computer Programming | P9: BDSDF113 | Q9: =CONCATENATE($C9,"-",$P9) -> 2025EB1100006-BDSDF113 | R9: =COUNTIF($H9:$K9,"A") & " " & "missed" -> 1 missed | S9: =COUNTIF(L9,"A") & " " & "missed" -> 0 missed | T9: =4-COUNTIF($H9:$K9,"A") -> 3 | U9: =1-COUNTIF($L9,"A") -> 1 | V9: =$T9/4 -> 0.75 | W9: =$U9/1 -> 1 | X9: =COUNTIF($H9:$L9, "A") & " " &"missed" -> 1 missed | Y9: =5- COUNTIF($H9:$L9, "A") -> 4 | Z9: =$Y9/5 -> 0.8 | AA9: =CONCATENATE("Q-",$T9," A-",$U9," || Q Total-4, A Total-1") -> Q-3 A-1 || Q Total-4, A Total-1 | AB9: {=IFERROR(INDEX('Attendance-Slot-1'!$Q$2:$Q$1112,MATCH(1,('Attendance-Slot-1'!$A$2:$A$1112=$C9)*('Attendance-Slot-1'!$G$2:$G$1112=AB$2),0)),"No Data")} -> P-S1_Onsite | AC9: {=IFERROR(INDEX('Attendance-Slot-2'!$Q$2:$Q$2595,MATCH(1,('Attendance-Slot-2'!$A$2:$A$2595=$C9)*('Attendance-Slot-2'!$G$2:$G$2595=AB$2),0)),"No Data")} -> No Data | AD9: =VLOOKUP($Q9,'Written Exam Marks'!$H:$Q,10,FALSE) -> 10 | AE9: =VLOOKUP($Q9,'Written Exam Marks'!$H:$Q,9,FALSE) -> 40 | AF9: =IF(COUNTIF($AB9:$AC9,"P-*")>0,"Present", IF(COUNTIF($AB9:$AC9,"A-*")>0,"Absent", IF(COUNTIF($AB9:$AC9,"No Data")>0,"No Data",""))) -> Present | AG9: =IF(LEFT($AB9,2)="P-",$AB9,IF(LEFT($AC9,2)="P-",$AC9,IF(LEFT($AB9,2)="A-",$AB9,IF(LEFT($AC9,2)="A-",$AC9,IF($AB9="No Data",$AB9,IF($AC9="No Data",$AC9,"")))))) -> P-S1_Onsite | AH9: 14 | AI9: 13 | AJ9: 9.3333333 | AK9: 10 | AL9: 10 | AM9: 56.333333 | AN9: 60 | AO9: Computer Systems | AP9: BDSDF108 | AQ9: =CONCATENATE($C9,"-",$AP9) -> 2025EB1100006-BDSDF108 | AR9: =COUNTIF($AJ9:$AL9,"A") & " " & "missed" -> 0 missed | AS9: =COUNTIF($AH9:$AI9,"A") & " " & "missed" -> 0 missed | AT9: =3-COUNTIF(AJ9:AL9,"A") -> 3 | AU9: =2-COUNTIF($AH9:$AI9,"A") -> 2 | AV9: =$AT9/3 -> 1 | AW9: =$AU9/2 -> 1 | AX9: =COUNTIF($AH9:$AL9, "A") & " " &"missed" -> 0 missed | AY9: =5- COUNTIF($AH9:$AL9, "A") -> 5 | AZ9: =$AY9/5 -> 1 | BA9: =CONCATENATE("Q-",$AT9," A-",$AU9," || Q Total-3, A Total-2") -> Q-3 A-2 || Q Total-3, A Total-2 | BB9: {=IFERROR(INDEX('Attendance-Slot-1'!$Q$2:$Q$1112,MATCH(1,('Attendance-Slot-1'!$A$2:$A$1112=$C9)*('Attendance-Slot-1'!$G$2:$G$1112=BB$2),0)),"No Data")} -> P-S1_Onsite | BC9: {=IFERROR(INDEX('Attendance-Slot-2'!$Q$2:$Q$2595,MATCH(1,('Attendance-Slot-2'!$A$2:$A$2595=$C9)*('Attendance-Slot-2'!$G$2:$G$2595=BB$2),0)),"No Data")} -> No Data | BD9: =VLOOKUP($AQ9,'Written Exam Marks'!$H:$Q,10,FALSE) -> 10.5 | BE9: =VLOOKUP($AQ9,'Written Exam Marks'!$H:$Q,9,FALSE) -> 40 | BF9: =IF(COUNTIF($BB9:$BC9,"P-*")>0,"Present", IF(COUNTIF($BB9:$BC9,"A-*")>0,"Absent", IF(COUNTIF($BB9:$BC9,"No Data")>0,"No Data",""))) -> Present | BG9: =IF(LEFT($BB9,2)="P-",$BB9,IF(LEFT($BC9,2)="P-",$BC9,IF(LEFT($BB9,2)="A-",$BB9,IF(LEFT($BC9,2)="A-",$BC9,IF($BB9="No Data",$BB9,IF($BC9="No Data",$BC9,"")))))) -> P-S1_Onsite | BH9: 10 | BI9: 15 | BJ9: 15 | BK9: 17 | BL9: 57 | BM9: 60 | BN9: Probability & Statistics | BO9: BDSDF114 | BP9: =CONCATENATE($C9,"-",$BO9) -> 2025EB1100006-BDSDF114 | BQ9: =COUNTIF($BH9:$BJ9,"A") & " " & "missed" -> 0 missed | BR9: =COUNTIF($BK9,"A") & " " & "missed" -> 0 missed | BS9: =3-COUNTIF($BH9:$BJ9,"A") -> 3 | BT9: =1-COUNTIF($BK9,"A") -> 1 | BU9: =$BS9/3 -> 1 | BV9: =$BT9/1 -> 1 | BW9: =COUNTIF($BH9:$BK9, "A") & " " &"missed" -> 0 missed | BX9: =4- COUNTIF(BH9:BK9, "A") -> 4 | BY9: =$BX9/4 -> 1 | BZ9: =CONCATENATE("Q-",$BS9," A-",$BT9," || Q Total-3, A Total-1") -> Q-3 A-1 || Q Total-3, A Total-1 | CA9: {=IFERROR(INDEX('Attendance-Slot-1'!$Q$2:$Q$1112,MATCH(1,('Attendance-Slot-1'!$A$2:$A$1112=$C9)*('Attendance-Slot-1'!$G$2:$G$1112=CA$2),0)),"No Data")} -> P-S1_Onsite | CB9: {=IFERROR(INDEX('Attendance-Slot-2'!$Q$2:$Q$2595,MATCH(1,('Attendance-Slot-2'!$A$2:$A$2595=$C9)*('Attendance-Slot-2'!$G$2:$G$2595=CA$2),0)),"No Data")} -> No Data | CC9: =VLOOKUP($BP9,'Written Exam Marks'!$H:$Q,10,FALSE) -> 19.5 | CD9: =VLOOKUP($BP9,'Written Exam Marks'!$H:$Q,9,FALSE) -> 40 | CE9: =IF(COUNTIF($CA9:$CB9,"P-*")>0,"Present", IF(COUNTIF($CA9:$CB9,"A-*")>0,"Absent", IF(COUNTIF($CA9:$CB9,"No Data")>0,"No Data",""))) -> Present | CF9: =IF(LEFT($CA9,2)="P-",$CA9,IF(LEFT($CB9,2)="P-",$CB9,IF(LEFT($CA9,2)="A-",$CA9,IF(LEFT($CB9,2)="A-",$CB9,IF($CA9="No Data",$CA9,IF($CB9="No Data",$CB9,"")))))) -> P-S1_Onsite | CG9: 4.5 | CH9: 4 | CI9: 7 | CJ9: 8 | CK9: A | CL9: A | CM9: 23.5 | CN9: 50 | CO9: Writing Practice | CP9: BDSDF112 | CQ9: =CONCATENATE($C9,"-",$CP9) -> 2025EB1100006-BDSDF112 | CR9: =COUNTIF($CG9:$CH9,"A") & " " & "missed" -> 0 missed | CS9: =COUNTIF($CI9:$CJ9,"A") & " " & "missed" -> 0 missed | CT9: =2-COUNTIF($CG9:$CH9,"A") -> 2 | CU9: =2-COUNTIF($CI9:$CJ9,"A") -> 2 | CV9: =$CT9/2 -> 1 | CW9: =$CU9/2 -> 1 | CX9: =COUNTIF($CG9:$CJ9, "A") & " " &"missed" -> 0 missed | CY9: =4- COUNTIF($CG9:$CJ9, "A") -> 4 | CZ9: =$CY9/4 -> 1 | DA9: =CONCATENATE("Q-",$CT9," A-",$CU9," || Q Total-2, A Total-2") -> Q-2 A-2 || Q Total-2, A Total-2 | DB9: {=IFERROR(INDEX('Attendance-Slot-1'!$Q$2:$Q$1112,MATCH(1,('Attendance-Slot-1'!$A$2:$A$1112=$C9)*('Attendance-Slot-1'!$G$2:$G$1112=DB$2),0)),"No Data")} -> P-S1_Onsite | DC9: {=IFERROR(INDEX('Attendance-Slot-2'!$Q$2:$Q$2595,MATCH(1,('Attendance-Slot-2'!$A$2:$A$2595=$C9)*('Attendance-Slot-2'!$G$2:$G$2595=DB$2),0)),"No Data")} -> No Data | DD9: =VLOOKUP($CQ9,'Written Exam Marks'!$H:$Q,10,FALSE) -> 30 | DE9: =VLOOKUP($CQ9,'Written Exam Marks'!$H:$Q,9,FALSE) -> 50 | DF9: =IF(COUNTIF($DB9:$DC9,"P-*")>0,"Present", IF(COUNTIF($DB9:$DC9,"A-*")>0,"Absent", IF(COUNTIF($DB9:$DC9,"No Data")>0,"No Data",""))) -> Present | DG9: =IF(LEFT($DB9,2)="P-",$DB9,IF(LEFT($DC9,2)="P-",$DC9,IF(LEFT($DB9,2)="A-",$DB9,IF(LEFT($DC9,2)="A-",$DC9,IF($DB9="No Data",$DB9,IF($DC9="No Data",$DC9,"")))))) -> P-S1_Onsite | DH9: 90 | DI9: 90 | DJ9: 100 | DK9: ="P-"&(COUNTIF($AB9,"P-*")+COUNTIF($BB9,"P-*")+COUNTIF($CA9,"P-*")+COUNTIF($DB9,"P-*"))&", A-"&(COUNTIF($AB9,"A-*")+COUNTIF($BB9,"A-*")+COUNTIF($CA9,"A-*")+COUNTIF($DB9,"A-*"))&", No Data-"&(COUNTIF($AB9,"No Data")+COUNTIF($BB9,"No Data")+COUNTIF($CA9,"No Data")+COUNTIF($DB9,"No Data")) -> P-4, A-0, No Data-0 | DL9: ="P-"&(COUNTIF($AC9,"P-*")+COUNTIF($BC9,"P-*")+COUNTIF($CB9,"P-*")+COUNTIF($DC9,"P-*"))&", A-"&(COUNTIF($AC9,"A-*")+COUNTIF($BC9,"A-*")+COUNTIF($CB9,"A-*")+COUNTIF($DC9,"A-*"))&", No Data-"&(COUNTIF($AC9,"No Data")+COUNTIF($BC9,"No Data")+COUNTIF($CB9,"No Data")+COUNTIF($DC9,"No Data")) -> P-0, A-0, No Data-4 | DM9: =IF(LEFT($AB9,2)="P-",$AB9, IF(LEFT($AC9,2)="P-",$AC9, IF(LEFT($AB9,2)="A-",$AB9, IF(LEFT($AC9,2)="A-",$AC9, IF($AB9="No Data",$AB9, IF($AC9="No Data",$AC9,"")))))) -> P-S1_Onsite | DN9: =IF(LEFT($DB9,2)="P-",$DB9, IF(LEFT($DC9,2)="P-",$DC9, IF(LEFT($DB9,2)="A-",$DB9, IF(LEFT($DC9,2)="A-",$DC9, IF($DB9="No Data",$DB9, IF($DC9="No Data",$DC9,"")))))) -> P-S1_Onsite | DO9: =IF(LEFT($BB9,2)="P-",$BB9, IF(LEFT($BC9,2)="P-",$BC9, IF(LEFT($BB9,2)="A-",$BB9, IF(LEFT($BC9,2)="A-",$BC9, IF($BB9="No Data",$BB9, IF($BC9="No Data",$BC9,"")))))) -> P-S1_Onsite | DP9: =IF(LEFT($CA9,2)="P-",$CA9, IF(LEFT($CB9,2)="P-",$CB9, IF(LEFT($CA9,2)="A-",$CA9, IF(LEFT($CB9,2)="A-",$CB9, IF($CA9="No Data",$CA9, IF($CB9="No Data",$CB9,"")))))) -> P-S1_Onsite | DQ9: ="P-"&COUNTIF($DM9:$DP9,"P-*")&", A-"&COUNTIF($DM9:$DP9,"A-*")&", No Data-"&COUNTIF($DM9:$DP9,"No Data") -> P-4, A-0, No Data-0 | DR9: =IF( AND( $AA9="Q-4 A-1 || Q Total-4, A Total-1", $BA9="Q-3 A-2 || Q Total-3, A Total-2", $BZ9="Q-3 A-1 || Q Total-3, A Total-1", $DA9="Q-2 A-2 || Q Total-2, A Total-2" ), 1, 0 ) -> 0 | DS9: Activated | DT9: Exam Given | DU9: 2025EB1100006
