Workbook

Sheet Graded Quiz 1 Status
A1: Parent Department Name | B1: BS
A3: Count of Username | B3: Column Labels
A4: Row Labels | B4: 2026-02-08 | C4: 2026-02-09 | D4: Grand Total | E4: Total no. of students | F4: %
A5: Computer Programming | B5: 50 | C5: 20 | D5: 70 | E5: =_xlfn.XLOOKUP(A5,Courses!A:A,Courses!E:E) -> 170 | F5: =D5/E5 -> 0.41176471
A6: Computing Systems | B6: 44 | C6: 22 | D6: 66 | E6: =_xlfn.XLOOKUP(A6,Courses!A:A,Courses!E:E) -> 193 | F6: =D6/E6 -> 0.34196891
A7: Data and the World | B7: 2 | C7: 1 | D7: 3 | E7: =_xlfn.XLOOKUP(A7,Courses!A:A,Courses!E:E) -> 160 | F7: =D7/E7 -> 0.01875
A8: Data Preprocessing (BS) | B8: 53 | C8: 18 | D8: 71 | E8: 154 | F8: =D8/E8 -> 0.46103896
A9: Data Structures for Data Science | B9: 62 | C9: 17 | D9: 79 | E9: =_xlfn.XLOOKUP(A9,Courses!A:A,Courses!E:E) -> 160 | F9: =D9/E9 -> 0.49375
A10: Fundamentals of Data Science and Engineering | B10: 75 | C10: 1 | D10: 76 | E10: =_xlfn.XLOOKUP(A10,Courses!A:A,Courses!E:E) -> 176 | F10: =D10/E10 -> 0.43181818
A11: Linear Algebra | B11: 68 | C11: 17 | D11: 85 | E11: =_xlfn.XLOOKUP(A11,Courses!A:A,Courses!E:E) -> 188 | F11: =D11/E11 -> 0.45212766
A12: Probability & Statistics | B12: 42 | C12: 15 | D12: 57 | E12: 177 | F12: =D12/E12 -> 0.3220339
A13: Writing Practice | B13: 31 | C13: 17 | D13: 48 | E13: =_xlfn.XLOOKUP(A13,Courses!A:A,Courses!E:E) -> 134 | F13: =D13/E13 -> 0.35820896
A14: Grand Total | B14: 427 | C14: 128 | D14: 555 | E14: =SUM(E5:E13) -> 1512 | F14: =D14/E14 -> 0.36706349
A16: Parent Department Name | B16: MS
A18: Count of Username | B18: Column Labels
A19: Row Labels | B19: 2026-02-08 | C19: 2026-02-09 | D19: Grand Total | E19: Total no. of students | F19: %
A20: Artificial Neural Networks | B20: 127 | C20: 35 | D20: 162 | E20: =_xlfn.XLOOKUP(A20,Courses!A:A,Courses!E:E) -> 352 | F20: =D20/E20 -> 0.46022727
A21: Cloud Services & Platforms | B21: 128 | C21: 39 | D21: 167 | E21: =_xlfn.XLOOKUP(A21,Courses!A:A,Courses!E:E) -> 357 | F21: =D21/E21 -> 0.46778711
A22: Data Pre-processing (MSc) | B22: 138 | C22: 42 | D22: 180 | E22: 389 | F22: =D22/E22 -> 0.46272494
A23: Data Stores & Pipelines | B23: 2 | C23: 1 | D23: 3 | E23: =_xlfn.XLOOKUP(A23,Courses!A:A,Courses!E:E) -> 17 | F23: =D23/E23 -> 0.17647059
A24: Data Visualization & Storytelling | B24: 126 | C24: 51 | D24: 177 | E24: =_xlfn.XLOOKUP(A24,Courses!A:A,Courses!E:E) -> 390 | F24: =D24/E24 -> 0.45384615
A25: Feature Engineering | B25: 4 | C25: 1 | D25: 5 | E25: =_xlfn.XLOOKUP(A25,Courses!A:A,Courses!E:E) -> 389 | F25: =D25/E25 -> 0.01285347
A26: Machine Learning | B26: 142 | C26: 48 | D26: 190 | E26: =_xlfn.XLOOKUP(A26,Courses!A:A,Courses!E:E) -> 350 | F26: =D26/E26 -> 0.54285714
A27: Statistical Modelling & Inferencing | B27: 128 | C27: 49 | D27: 177 | E27: =_xlfn.XLOOKUP(A27,Courses!A:A,Courses!E:E) -> 395 | F27: =D27/E27 -> 0.44810127
A28: Grand Total | B28: 795 | C28: 266 | D28: 1061 | E28: =SUM(E20:E27) -> 2639 | F28: =D28/E28 -> 0.40204623

Sheet Analysis Data
A1: Course Offering Name | B1: Parent Department Name | C1: Semester Name | D1: Username | E1: Username_for verification | F1: Org Defined Id | G1: First Name | H1: Is Active | I1: Content Completed | J1: Content Required | K1: Checklist Completed | L1: Quiz Completed | M1: Total Quiz Attempts | N1: Discussion Post Created | O1: Discussion Post Replies | P1: Discussion Post Read | Q1: Last Discussion Post Date | R1: Number Of Assignment Submissions | S1: Last Assignment Submission Date | T1: Total Time Spent In Content | U1: Last Visited Date | V1: Last System Login | W1: Number Of Logins To The System | X1: Auditor Name | Y1: Last Quiz Attempt Date | Z1: Last graded Quiz Attempt Date | AA1: Last SCORM Completion Date | AB1: Last SCORM Visit Date
A2: Data Structures for Data Science | B2: BS | C2: Trimester 2 | D2: 2025eb1100001@bitspilani-digital.edu.in | E2: =_xlfn.XLOOKUP(D2,Total_Enrolled!C:C,Total_Enrolled!C:C) -> 2025eb1100001@bitspilani-digital.edu.in | F2: 2025EB1100001 | G2: RUDRA SHARMA | H2: TRUE | I2: 1 | J2: 154 | K2: 0 | L2: 1 | M2: 1 | N2: 0 | O2: 0 | P2: 0 | R2: 0 | T2: 0 | U2: 2026-02-08T09:13:59.9530000Z | V2: 2026-02-08T08:54:36.2970000Z | W2: 166 | Y2: 2026-02-08T09:04:03.4030000Z | Z2: =LEFT(Y2,10) -> 2026-02-08
A3: Data Preprocessing (BS) | B3: BS | C3: Trimester 2 | D3: 2025eb1100001@bitspilani-digital.edu.in | E3: =_xlfn.XLOOKUP(D3,Total_Enrolled!C:C,Total_Enrolled!C:C) -> 2025eb1100001@bitspilani-digital.edu.in | F3: 2025EB1100001 | G3: RUDRA SHARMA | H3: TRUE | I3: 6 | J3: 158 | K3: 0 | L3: 2 | M3: 3 | N3: 0 | O3: 0 | P3: 0 | R3: 0 | T3: 17096 | U3: 2026-02-08T09:20:40.1530000Z | V3: 2026-02-08T08:54:36.2970000Z | W3: 166 | Y3: 2026-02-08T09:20:32.9730000Z | Z3: =LEFT(Y3,10) -> 2026-02-08
A4: Linear Algebra | B4: BS | C4: Trimester 2 | D4: 2025eb1100001@bitspilani-digital.edu.in | E4: =_xlfn.XLOOKUP(D4,Total_Enrolled!C:C,Total_Enrolled!C:C) -> 2025eb1100001@bitspilani-digital.edu.in | F4: 2025EB1100001 | G4: RUDRA SHARMA | H4: TRUE | I4: 3 | J4: 86 | K4: 0 | L4: 1 | M4: 1 | N4: 0 | O4: 0 | P4: 0 | R4: 0 | T4: 27 | U4: 2026-02-08T09:12:57.6770000Z | V4: 2026-02-08T08:54:36.2970000Z | W4: 166 | Y4: 2026-02-08T09:12:53.8070000Z | Z4: =LEFT(Y4,10) -> 2026-02-08 | AA4: 2026-01-23T15:01:45.2470000Z | AB4: 2026-01-23T15:01:48.8770000Z
A5: Computing Systems | B5: BS | C5: Trimester 2 | D5: 2025eb1100001@bitspilani-digital.edu.in | E5: =_xlfn.XLOOKUP(D5,Total_Enrolled!C:C,Total_Enrolled!C:C) -> 2025eb1100001@bitspilani-digital.edu.in | F5: 2025EB1100001 | G5: RUDRA SHARMA | H5: TRUE | I5: 92 | J5: 267 | K5: 0 | L5: 34 | M5: 56 | N5: 0 | O5: 0 | P5: 0 | R5: 0 | T5: 1027 | U5: 2026-02-08T08:57:34.8130000Z | V5: 2026-02-08T08:54:36.2970000Z | W5: 166 | Y5: 2026-02-08T08:57:30.2130000Z | Z5: =LEFT(Y5,10) -> 2026-02-08 | AA5: 2026-01-23T14:59:58.6570000Z | AB5: 2026-01-23T15:00:20.6770000Z
A6: Fundamentals of Data Science and Engineering | B6: BS | C6: Trimester 2 | D6: 2025eb1100004@bitspilani-digital.edu.in | E6: =_xlfn.XLOOKUP(D6,Total_Enrolled!C:C,Total_Enrolled!C:C) -> 2025eb1100004@bitspilani-digital.edu.in | F6: 2025EB1100004 | G6: ARUNLAL P | H6: TRUE | I6: 1 | J6: 112 | K6: 0 | L6: 1 | M6: 1 | N6: 0 | O6: 0 | P6: 0 | R6: 0 | T6: 0 | U6: 2026-02-08T15:58:42.1600000Z | V6: 2026-02-08T15:52:25.5800000Z | W6: 151 | Y6: 2026-02-08T15:58:35.0330000Z | Z6: =LEFT(Y6,10) -> 2026-02-08
A7: Linear Algebra | B7: BS | C7: Trimester 2 | D7: 2025eb1100006@bitspilani-digital.edu.in | E7: =_xlfn.XLOOKUP(D7,Total_Enrolled!C:C,Total_Enrolled!C:C) -> 2025eb1100006@bitspilani-digital.edu.in | F7: 2025EB1100006 | G7: JAL PATEL | H7: TRUE | I7: 1 | J7: 86 | K7: 0 | L7: 1 | M7: 1 | N7: 0 | O7: 0 | P7: 0 | R7: 0 | T7: 0 | U7: 2026-02-08T08:16:42.7600000Z | V7: 2026-02-08T07:51:39.3430000Z | W7: 73 | Y7: 2026-02-08T08:12:38.5830000Z | Z7: =LEFT(Y7,10) -> 2026-02-08
A8: Fundamentals of Data Science and Engineering | B8: BS | C8: Trimester 2 | D8: 2025eb1100006@bitspilani-digital.edu.in | E8: =_xlfn.XLOOKUP(D8,Total_Enrolled!C:C,Total_Enrolled!C:C) -> 2025eb1100006@bitspilani-digital.edu.in | F8: 2025EB1100006 | G8: JAL PATEL | H8: TRUE | I8: 2 | J8: 112 | K8: 0 | L8: 2 | M8: 2 | N8: 0 | O8: 0 | P8: 0 | R8: 0 | T8: 0 | U8: 2026-02-08T08:17:07.8730000Z | V8: 2026-02-08T07:51:39.3430000Z | W8: 73 | Y8: 2026-02-08T08:02:33.4500000Z | Z8: =LEFT(Y8,10) -> 2026-02-08
A9: Data Structures for Data Science | B9: BS | C9: Trimester 2 | D9: 2025eb1100006@bitspilani-digital.edu.in | E9: =_xlfn.XLOOKUP(D9,Total_Enrolled!C:C,Total_Enrolled!C:C) -> 2025eb1100006@bitspilani-digital.edu.in | F9: 2025EB1100006 | G9: JAL PATEL | H9: TRUE | I9: 1 | J9: 154 | K9: 0 | L9: 1 | M9: 1 | N9: 0 | O9: 0 | P9: 0 | R9: 0 | T9: 0 | U9: 2026-02-08T08:17:33.9070000Z | V9: 2026-02-08T07:51:39.3430000Z | W9: 73 | Y9: 2026-02-08T08:15:45.7230000Z | Z9: =LEFT(Y9,10) -> 2026-02-08
A10: Computer Programming | B10: BS | C10: Trimester 2 | D10: 2025eb1100007@bitspilani-digital.edu.in | E10: =_xlfn.XLOOKUP(D10,Total_Enrolled!C:C,Total_Enrolled!C:C) -> 2025eb1100007@bitspilani-digital.edu.in | F10: 2025EB1100007 | G10: HARSHVARDHAN SINGH | H10: TRUE | I10: 10 | J10: 356 | K10: 0 | L10: 4 | M10: 4 | N10: 0 | O10: 0 | P10: 0 | R10: 0 | T10: 24662 | U10: 2026-02-08T02:54:21.2930000Z | V10: 2026-02-09T00:57:34.8670000Z | W10: 67 | Y10: 2026-02-08T02:54:12.8470000Z | Z10: =LEFT(Y10,10) -> 2026-02-08 | AA10: 2026-01-30T14:05:06.5370000Z | AB10: 2026-02-05T07:23:03.0770000Z
A11: Probability & Statistics | B11: BS | C11: Trimester 2 | D11: 2025eb1100007@bitspilani-digital.edu.in | E11: =_xlfn.XLOOKUP(D11,Total_Enrolled!C:C,Total_Enrolled!C:C) -> 2025eb1100007@bitspilani-digital.edu.in | F11: 2025EB1100007 | G11: HARSHVARDHAN SINGH | H11: TRUE | I11: 1 | J11: 326 | K11: 0 | L11: 1 | M11: 1 | N11: 0 | O11: 0 | P11: 0 | R11: 0 | T11: 0 | U11: 2026-02-08T02:56:47.4770000Z | V11: 2026-02-09T00:57:34.8670000Z | W11: 67 | Y11: 2026-02-08T02:56:43.8530000Z | Z11: =LEFT(Y11,10) -> 2026-02-08
A12: Computing Systems | B12: BS | C12: Trimester 2 | D12: 2025eb1100007@bitspilani-digital.edu.in | E12: =_xlfn.XLOOKUP(D12,Total_Enrolled!C:C,Total_Enrolled!C:C) -> 2025eb1100007@bitspilani-digital.edu.in | F12: 2025EB1100007 | G12: HARSHVARDHAN SINGH | H12: TRUE | I12: 1 | J12: 267 | K12: 0 | L12: 1 | M12: 1 | N12: 0 | O12: 0 | P12: 0 | R12: 0 | T12: 0 | U12: 2026-02-08T03:02:53.3470000Z | V12: 2026-02-09T00:57:34.8670000Z | W12: 67 | Y12: 2026-02-08T03:02:49.6200000Z | Z12: =LEFT(Y12,10) -> 2026-02-08
A13: Fundamentals of Data Science and Engineering | B13: BS | C13: Trimester 2 | D13: 2025eb1100010@bitspilani-digital.edu.in | E13: =_xlfn.XLOOKUP(D13,Total_Enrolled!C:C,Total_Enrolled!C:C) -> 2025eb1100010@bitspilani-digital.edu.in | F13: 2025EB1100010 | G13: HARSHITA JAIN | H13: TRUE | I13: 4 | J13: 112 | K13: 0 | L13: 2 | M13: 2 | N13: 0 | O13: 0 | P13: 0 | R13: 0 | T13: 14 | U13: 2026-02-08T14:39:37.0530000Z | V13: 2026-02-08T14:34:30.4630000Z | W13: 169 | Y13: 2026-02-08T14:39:30.3800000Z | Z13: =LEFT(Y13,10) -> 2026-02-08
A14: Data Structures for Data Science | B14: BS | C14: Trimester 2 | D14: 2025eb1100015@bitspilani-digital.edu.in | E14: =_xlfn.XLOOKUP(D14,Total_Enrolled!C:C,Total_Enrolled!C:C) -> 2025eb1100015@bitspilani-digital.edu.in | F14: 2025EB1100015 | G14: TADIMALLA ADITI | H14: TRUE | I14: 12 | J14: 154 | K14: 0 | L14: 4 | M14: 4 | N14: 0 | O14: 0 | P14: 0 | R14: 0 | T14: 42049 | U14: 2026-02-08T17:30:42.8230000Z | V14: 2026-02-09T03:14:20.9130000Z | W14: 233 | Y14: 2026-02-08T17:30:39.1400000Z | Z14: =LEFT(Y14,10) -> 2026-02-08 | AA14: 2026-02-08T17:30:46.8530000Z | AB14: 2026-02-08T17:30:46.8530000Z
A15: Fundamentals of Data Science and Engineering | B15: BS | C15: Trimester 2 | D15: 2025eb1100018@bitspilani-digital.edu.in | E15: =_xlfn.XLOOKUP(D15,Total_Enrolled!C:C,Total_Enrolled!C:C) -> 2025eb1100018@bitspilani-digital.edu.in | F15: 2025EB1100018 | G15: NIMMAGANTI SUMAHE | H15: TRUE | I15: 52 | J15: 112 | K15: 0 | L15: 7 | M15: 7 | N15: 0 | O15: 0 | P15: 0 | R15: 0 | T15: 14750 | U15: 2026-02-08T21:41:02.6170000Z | V15: 2026-02-09T09:46:13.1530000Z | W15: 321 | Y15: 2026-02-08T21:40:36.1730000Z | Z15: =LEFT(Y15,10) -> 2026-02-08
A16: Linear Algebra | B16: BS | C16: Trimester 2 | D16: 2025eb1100018@bitspilani-digital.edu.in | E16: =_xlfn.XLOOKUP(D16,Total_Enrolled!C:C,Total_Enrolled!C:C) -> 2025eb1100018@bitspilani-digital.edu.in | F16: 2025EB1100018 | G16: NIMMAGANTI SUMAHE | H16: TRUE | I16: 61 | J16: 86 | K16: 0 | L16: 16 | M16: 17 | N16: 4 | O16: 0 | P16: 0 | Q16: 2026-02-08T20:09:50.6830000Z | R16: 0 | T16: 25463 | U16: 2026-02-08T20:10:03.7700000Z | V16: 2026-02-09T09:46:13.1530000Z | W16: 321 | Y16: 2026-02-08T20:01:37.7070000Z | Z16: =LEFT(Y16,10) -> 2026-02-08 | AA16: 2026-02-08T20:01:57.0970000Z | AB16: 2026-02-08T20:01:57.0970000Z
A17: Data Preprocessing (BS) | B17: BS | C17: Trimester 2 | D17: 2025eb1100018@bitspilani-digital.edu.in | E17: =_xlfn.XLOOKUP(D17,Total_Enrolled!C:C,Total_Enrolled!C:C) -> 2025eb1100018@bitspilani-digital.edu.in | F17: 2025EB1100018 | G17: NIMMAGANTI SUMAHE | H17: TRUE | I17: 81 | J17: 158 | K17: 0 | L17: 27 | M17: 27 | N17: 0 | O17: 0 | P17: 0 | R17: 0 | T17: 28046 | U17: 2026-02-08T20:10:27.6930000Z | V17: 2026-02-09T09:46:13.1530000Z | W17: 321 | Y17: 2026-02-08T14:32:46.4930000Z | Z17: =LEFT(Y17,10) -> 2026-02-08
A18: Data Structures for Data Science | B18: BS | C18: Trimester 2 | D18: 2025eb1100018@bitspilani-digital.edu.in | E18: =_xlfn.XLOOKUP(D18,Total_Enrolled!C:C,Total_Enrolled!C:C) -> 2025eb1100018@bitspilani-digital.edu.in | F18: 2025EB1100018 | G18: NIMMAGANTI SUMAHE | H18: TRUE | I18: 91 | J18: 154 | K18: 0 | L18: 30 | M18: 30 | N18: 0 | O18: 0 | P18: 0 | R18: 0 | T18: 29105 | U18: 2026-02-08T14:26:43.0470000Z | V18: 2026-02-09T09:46:13.1530000Z | W18: 321 | Y18: 2026-02-08T14:26:36.0170000Z | Z18: =LEFT(Y18,10) -> 2026-02-08 | AA18: 2026-02-05T18:26:03.1070000Z | AB18: 2026-02-05T18:36:20.5400000Z
A19: Probability & Statistics | B19: BS | C19: Trimester 2 | D19: 2025eb1100019@bitspilani-digital.edu.in | E19: =_xlfn.XLOOKUP(D19,Total_Enrolled!C:C,Total_Enrolled!C:C) -> 2025eb1100019@bitspilani-digital.edu.in | F19: 2025EB1100019 | G19: NITISH KUMAR | H19: TRUE | I19: 6 | J19: 326 | K19: 0 | L19: 1 | M19: 1 | N19: 0 | O19: 0 | P19: 0 | R19: 0 | T19: 763 | U19: 2026-02-08T15:01:55.8400000Z | V19: 2026-02-08T14:49:38.8730000Z | W19: 123 | Y19: 2026-02-08T15:01:36.1370000Z | Z19: =LEFT(Y19,10) -> 2026-02-08
A20: Computing Systems | B20: BS | C20: Trimester 2 | D20: 2025eb1100019@bitspilani-digital.edu.in | E20: =_xlfn.XLOOKUP(D20,Total_Enrolled!C:C,Total_Enrolled!C:C) -> 2025eb1100019@bitspilani-digital.edu.in | F20: 2025EB1100019 | G20: NITISH KUMAR | H20: TRUE | I20: 13 | J20: 267 | K20: 0 | L20: 3 | M20: 3 | N20: 0 | O20: 0 | P20: 0 | R20: 0 | T20: 5897 | U20: 2026-02-08T14:54:15.1670000Z | V20: 2026-02-08T14:49:38.8730000Z | W20: 123 | Y20: 2026-02-08T14:54:11.7000000Z | Z20: =LEFT(Y20,10) -> 2026-02-08 | AA20: 2026-01-23T15:27:29.7470000Z | AB20: 2026-02-06T07:59:20.1730000Z
A21: Computing Systems | B21: BS | C21: Trimester 2 | D21: 2025eb1100020@bitspilani-digital.edu.in | E21: =_xlfn.XLOOKUP(D21,Total_Enrolled!C:C,Total_Enrolled!C:C) -> 2025eb1100020@bitspilani-digital.edu.in | F21: 2025EB1100020 | G21: AYUSH JHA | H21: TRUE | I21: 5 | J21: 267 | K21: 0 | L21: 1 | M21: 1 | N21: 0 | O21: 0 | P21: 0 | R21: 0 | T21: 66 | U21: 2026-02-08T13:56:05.5670000Z | V21: 2026-02-09T07:21:41.8230000Z | W21: 77 | Y21: 2026-02-08T13:55:34.7400000Z | Z21: =LEFT(Y21,10) -> 2026-02-08 | AA21: 2026-01-24T15:44:23.2600000Z | AB21: 2026-01-24T15:44:23.2670000Z
A22: Probability & Statistics | B22: BS | C22: Trimester 2 | D22: 2025eb1100020@bitspilani-digital.edu.in | E22: =_xlfn.XLOOKUP(D22,Total_Enrolled!C:C,Total_Enrolled!C:C) -> 2025eb1100020@bitspilani-digital.edu.in | F22: 2025EB1100020 | G22: AYUSH JHA | H22: TRUE | I22: 1 | J22: 326 | K22: 0 | L22: 1 | M22: 1 | N22: 0 | O22: 0 | P22: 0 | R22: 0 | T22: 0 | U22: 2026-02-08T13:45:37.9530000Z | V22: 2026-02-09T07:21:41.8230000Z | W22: 77 | Y22: 2026-02-08T13:45:25.1370000Z | Z22: =LEFT(Y22,10) -> 2026-02-08
A23: Computer Programming | B23: BS | C23: Trimester 2 | D23: 2025eb1100020@bitspilani-digital.edu.in | E23: =_xlfn.XLOOKUP(D23,Total_Enrolled!C:C,Total_Enrolled!C:C) -> 2025eb1100020@bitspilani-digital.edu.in | F23: 2025EB1100020 | G23: AYUSH JHA | H23: TRUE | I23: 21 | J23: 356 | K23: 0 | L23: 6 | M23: 8 | N23: 0 | O23: 0 | P23: 0 | R23: 0 | T23: 4646 | U23: 2026-02-09T07:22:11.7630000Z | V23: 2026-02-09T07:21:41.8230000Z | W23: 77 | Y23: 2026-02-08T13:37:04.5700000Z | Z23: =LEFT(Y23,10) -> 2026-02-08 | AA23: 2026-02-09T07:41:28.0400000Z | AB23: 2026-02-09T07:41:28.0400000Z
A24: Computer Programming | B24: BS | C24: Trimester 2 | D24: 2025eb1100024@bitspilani-digital.edu.in | E24: =_xlfn.XLOOKUP(D24,Total_Enrolled!C:C,Total_Enrolled!C:C) -> 2025eb1100024@bitspilani-digital.edu.in | F24: 2025EB1100024 | G24: SHOORSEN THIRUNAVUKKARASU K | H24: TRUE | I24: 13 | J24: 356 | K24: 0 | L24: 4 | M24: 8 | N24: 0 | O24: 0 | P24: 0 | R24: 0 | T24: 1785 | U24: 2026-02-08T06:56:25.9930000Z | V24: 2026-02-08T06:51:55.3800000Z | W24: 112 | Y24: 2026-02-08T06:55:52.9500000Z | Z24: =LEFT(Y24,10) -> 2026-02-08 | AA24: 2026-01-29T14:37:14.7270000Z | AB24: 2026-01-29T14:37:14.7370000Z
A25: Linear Algebra | B25: BS | C25: Trimester 2 | D25: 2025eb1100024@bitspilani-digital.edu.in | E25: =_xlfn.XLOOKUP(D25,Total_Enrolled!C:C,Total_Enrolled!C:C) -> 2025eb1100024@bitspilani-digital.edu.in | F25: 2025EB1100024 | G25: SHOORSEN THIRUNAVUKKARASU K | H25: TRUE | I25: 9 | J25: 86 | K25: 0 | L25: 3 | M25: 3 | N25: 0 | O25: 0 | P25: 0 | R25: 0 | T25: 4129 | U25: 2026-02-08T06:59:50.3870000Z | V25: 2026-02-08T06:51:55.3800000Z | W25: 112 | Y25: 2026-02-08T06:59:45.8830000Z | Z25: =LEFT(Y25,10) -> 2026-02-08 | AA25: 2026-01-27T13:34:45.6630000Z | AB25: 2026-01-27T13:34:45.6730000Z
A26: Data Preprocessing (BS) | B26: BS | C26: Trimester 2 | D26: 2025eb1100026@bitspilani-digital.edu.in | E26: =_xlfn.XLOOKUP(D26,Total_Enrolled!C:C,Total_Enrolled!C:C) -> 2025eb1100026@bitspilani-digital.edu.in | F26: 2025EB1100026 | G26: SWARUP KUMAR PRADHAN | H26: TRUE | I26: 11 | J26: 158 | K26: 0 | L26: 4 | M26: 4 | N26: 0 | O26: 0 | P26: 0 | R26: 0 | T26: 1740 | U26: 2026-02-08T03:31:50.7270000Z | V26: 2026-02-09T01:09:56.6170000Z | W26: 262 | Y26: 2026-02-08T03:31:43.2300000Z | Z26: =LEFT(Y26,10) -> 2026-02-08
A27: Data Structures for Data Science | B27: BS | C27: Trimester 2 | D27: 2025eb1100026@bitspilani-digital.edu.in | E27: =_xlfn.XLOOKUP(D27,Total_Enrolled!C:C,Total_Enrolled!C:C) -> 2025eb1100026@bitspilani-digital.edu.in | F27: 2025EB1100026 | G27: SWARUP KUMAR PRADHAN | H27: TRUE | I27: 1 | J27: 154 | K27: 0 | L27: 1 | M27: 1 | N27: 0 | O27: 0 | P27: 0 | R27: 0 | T27: 0 | U27: 2026-02-08T03:22:01.9270000Z | V27: 2026-02-09T01:09:56.6170000Z | W27: 262 | Y27: 2026-02-08T03:21:54.7530000Z | Z27: =LEFT(Y27,10) -> 2026-02-08
A28: Linear Algebra | B28: BS | C28: Trimester 2 | D28: 2025eb1100026@bitspilani-digital.edu.in | E28: =_xlfn.XLOOKUP(D28,Total_Enrolled!C:C,Total_Enrolled!C:C) -> 2025eb1100026@bitspilani-digital.edu.in | F28: 2025EB1100026 | G28: SWARUP KUMAR PRADHAN | H28: TRUE | I28: 2 | J28: 86 | K28: 0 | L28: 2 | M28: 2 | N28: 0 | O28: 0 | P28: 0 | R28: 0 | T28: 31 | U28: 2026-02-08T04:14:09.4170000Z | V28: 2026-02-09T01:09:56.6170000Z | W28: 262 | Y28: 2026-02-08T04:14:05.3230000Z | Z28: =LEFT(Y28,10) -> 2026-02-08
A29: Data Preprocessing (BS) | B29: BS | C29: Trimester 2 | D29: 2025eb1100032@bitspilani-digital.edu.in | E29: =_xlfn.XLOOKUP(D29,Total_Enrolled!C:C,Total_Enrolled!C:C) -> 2025eb1100032@bitspilani-digital.edu.in | F29: 2025EB1100032 | G29: GANESH ANKIT | H29: TRUE | I29: 68 | J29: 158 | K29: 0 | L29: 18 | M29: 19 | N29: 0 | O29: 0 | P29: 0 | R29: 0 | T29: 354 | U29: 2026-02-08T11:58:58.7570000Z | V29: 2026-02-08T11:36:33.8600000Z | W29: 126 | Y29: 2026-02-08T11:57:40.1230000Z | Z29: =LEFT(Y29,10) -> 2026-02-08
A30: Data Structures for Data Science | B30: BS | C30: Trimester 2 | D30: 2025eb1100032@bitspilani-digital.edu.in | E30: =_xlfn.XLOOKUP(D30,Total_Enrolled!C:C,Total_Enrolled!C:C) -> 2025eb1100032@bitspilani-digital.edu.in | F30: 2025EB1100032 | G30: GANESH ANKIT | H30: TRUE | I30: 98 | J30: 154 | K30: 0 | L30: 20 | M30: 20 | N30: 1 | O30: 0 | P30: 0 | Q30: 2026-02-08T11:45:58.0400000Z | R30: 0 | T30: 2827 | U30: 2026-02-08T11:51:35.5700000Z | V30: 2026-02-08T11:36:33.8600000Z | W30: 126 | Y30: 2026-02-08T11:51:25.2600000Z | Z30: =LEFT(Y30,10) -> 2026-02-08 | AA30: 2026-01-24T06:46:47.5170000Z | AB30: 2026-01-24T06:46:49.3930000Z
A31: Fundamentals of Data Science and Engineering | B31: BS | C31: Trimester 2 | D31: 2025eb1100032@bitspilani-digital.edu.in | E31: =_xlfn.XLOOKUP(D31,Total_Enrolled!C:C,Total_Enrolled!C:C) -> 2025eb1100032@bitspilani-digital.edu.in | F31: 2025EB1100032 | G31: GANESH ANKIT | H31: TRUE | I31: 44 | J31: 112 | K31: 0 | L31: 6 | M31: 6 | N31: 0 | O31: 0 | P31: 0 | R31: 0 | T31: 302 | U31: 2026-02-08T11:53:18.9700000Z | V31: 2026-02-08T11:36:33.8600000Z | W31: 126 | Y31: 2026-02-08T11:53:02.1830000Z | Z31: =LEFT(Y31,10) -> 2026-02-08
A32: Linear Algebra | B32: BS | C32: Trimester 2 | D32: 2025eb1100032@bitspilani-digital.edu.in | E32: =_xlfn.XLOOKUP(D32,Total_Enrolled!C:C,Total_Enrolled!C:C) -> 2025eb1100032@bitspilani-digital.edu.in | F32: 2025EB1100032 | G32: GANESH ANKIT | H32: TRUE | I32: 45 | J32: 86 | K32: 0 | L32: 5 | M32: 5 | N32: 1 | O32: 0 | P32: 0 | Q32: 2026-02-08T11:38:55.9270000Z | R32: 0 | T32: 505 | U32: 2026-02-08T11:43:24.0200000Z | V32: 2026-02-08T11:36:33.8600000Z | W32: 126 | Y32: 2026-02-08T11:43:07.4570000Z | Z32: =LEFT(Y32,10) -> 2026-02-08 | AA32: 2026-01-24T06:48:02.5530000Z | AB32: 2026-01-24T06:48:05.0470000Z
A33: Fundamentals of Data Science and Engineering | B33: BS | C33: Trimester 2 | D33: 2025eb1100033@bitspilani-digital.edu.in | E33: =_xlfn.XLOOKUP(D33,Total_Enrolled!C:C,Total_Enrolled!C:C) -> 2025eb1100033@bitspilani-digital.edu.in | F33: 2025EB1100033 | G33: JHANVI KOTHARI | H33: TRUE | I33: 22 | J33: 112 | K33: 0 | L33: 2 | M33: 2 | N33: 0 | O33: 0 | P33: 0 | R33: 0 | T33: 9360 | U33: 2026-02-08T11:36:17.8130000Z | V33: 2026-02-08T11:27:45.0830000Z | W33: 127 | Y33: 2026-02-08T11:36:05.1730000Z | Z33: =LEFT(Y33,10) -> 2026-02-08
A34: Data Structures for Data Science | B34: BS | C34: Trimester 2 | D34: 2025eb1100033@bitspilani-digital.edu.in | E34: =_xlfn.XLOOKUP(D34,Total_Enrolled!C:C,Total_Enrolled!C:C) -> 2025eb1100033@bitspilani-digital.edu.in | F34: 2025EB1100033 | G34: JHANVI KOTHARI | H34: TRUE | I34: 23 | J34: 154 | K34: 0 | L34: 6 | M34: 6 | N34: 0 | O34: 0 | P34: 0 | R34: 0 | T34: 23162 | U34: 2026-02-08T13:25:48.7430000Z | V34: 2026-02-08T11:27:45.0830000Z | W34: 127 | Y34: 2026-02-08T13:25:40.8400000Z | Z34: =LEFT(Y34,10) -> 2026-02-08 | AA34: 2026-02-08T13:26:40.7170000Z | AB34: 2026-02-08T13:26:40.7200000Z
A35: Linear Algebra | B35: BS | C35: Trimester 2 | D35: 2025eb1100034@bitspilani-digital.edu.in | E35: =_xlfn.XLOOKUP(D35,Total_Enrolled!C:C,Total_Enrolled!C:C) -> 2025eb1100034@bitspilani-digital.edu.in | F35: 2025EB1100034 | G35: MEHTA PREET NIRAVKUMAR | H35: TRUE | I35: 19 | J35: 86 | K35: 0 | L35: 9 | M35: 9 | N35: 0 | O35: 0 | P35: 0 | R35: 0 | T35: 6532 | U35: 2026-02-08T18:40:28.5000000Z | V35: 2026-02-08T17:31:21.6330000Z | W35: 416 | Y35: 2026-02-08T05:36:49.9470000Z | Z35: =LEFT(Y35,10) -> 2026-02-08 | AA35: 2026-02-02T13:35:13.8030000Z | AB35: 2026-02-02T13:35:13.8030000Z
A36: Linear Algebra | B36: BS | C36: Trimester 2 | D36: 2025eb1100037@bitspilani-digital.edu.in | E36: =_xlfn.XLOOKUP(D36,Total_Enrolled!C:C,Total_Enrolled!C:C) -> 2025eb1100037@bitspilani-digital.edu.in | F36: 2025EB1100037 | G36: SHIVAM KUMAR | H36: TRUE | I36: 19 | J36: 86 | K36: 0 | L36: 1 | M36: 1 | N36: 0 | O36: 0 | P36: 0 | R36: 0 | T36: 2532 | U36: 2026-02-08T04:21:18.8170000Z | V36: 2026-02-09T09:24:49.1770000Z | W36: 114 | Y36: 2026-02-08T04:21:12.9030000Z | Z36: =LEFT(Y36,10) -> 2026-02-08 | AA36: 2026-02-02T14:58:20.9370000Z | AB36: 2026-02-02T14:58:20.9400000Z
A37: Fundamentals of Data Science and Engineering | B37: BS | C37: Trimester 2 | D37: 2025eb1100037@bitspilani-digital.edu.in | E37: =_xlfn.XLOOKUP(D37,Total_Enrolled!C:C,Total_Enrolled!C:C) -> 2025eb1100037@bitspilani-digital.edu.in | F37: 2025EB1100037 | G37: SHIVAM KUMAR | H37: TRUE | I37: 16 | J37: 112 | K37: 0 | L37: 2 | M37: 2 | N37: 0 | O37: 0 | P37: 0 | R37: 0 | T37: 7709 | U37: 2026-02-09T09:32:56.1670000Z | V37: 2026-02-09T09:24:49.1770000Z | W37: 114 | Y37: 2026-02-08T04:29:18.7800000Z | Z37: =LEFT(Y37,10) -> 2026-02-08
A38: Data Structures for Data Science | B38: BS | C38: Trimester 2 | D38: 2025eb1100037@bitspilani-digital.edu.in | E38: =_xlfn.XLOOKUP(D38,Total_Enrolled!C:C,Total_Enrolled!C:C) -> 2025eb1100037@bitspilani-digital.edu.in | F38: 2025EB1100037 | G38: SHIVAM KUMAR | H38: TRUE | I38: 23 | J38: 154 | K38: 0 | L38: 1 | M38: 1 | N38: 0 | O38: 0 | P38: 0 | R38: 0 | T38: 2909 | U38: 2026-02-08T04:25:23.6400000Z | V38: 2026-02-09T09:24:49.1770000Z | W38: 114 | Y38: 2026-02-08T04:25:12.7330000Z | Z38: =LEFT(Y38,10) -> 2026-02-08 | AA38: 2026-02-02T15:24:46.8500000Z | AB38: 2026-02-02T15:24:46.8500000Z
A39: Linear Algebra | B39: BS | C39: Trimester 2 | D39: 2025eb1100038@bitspilani-digital.edu.in | E39: =_xlfn.XLOOKUP(D39,Total_Enrolled!C:C,Total_Enrolled!C:C) -> 2025eb1100038@bitspilani-digital.edu.in | F39: 2025EB1100038 | G39: JAANVI KHANNA | H39: TRUE | I39: 7 | J39: 86 | K39: 0 | L39: 2 | M39: 2 | N39: 0 | O39: 0 | P39: 0 | R39: 0 | T39: 8580 | U39: 2026-02-08T14:46:37.1600000Z | V39: 2026-02-09T04:15:36.3270000Z | W39: 219 | Y39: 2026-02-08T14:46:12.7800000Z | Z39: =LEFT(Y39,10) -> 2026-02-08 | AA39: 2026-01-21T14:39:34.3430000Z | AB39: 2026-01-23T06:16:48.8470000Z
A40: Computing Systems | B40: BS | C40: Trimester 2 | D40: 2025eb1100038@bitspilani-digital.edu.in | E40: =_xlfn.XLOOKUP(D40,Total_Enrolled!C:C,Total_Enrolled!C:C) -> 2025eb1100038@bitspilani-digital.edu.in | F40: 2025EB1100038 | G40: JAANVI KHANNA | H40: TRUE | I40: 20 | J40: 267 | K40: 0 | L40: 3 | M40: 3 | N40: 0 | O40: 0 | P40: 0 | R40: 0 | T40: 25315 | U40: 2026-02-09T04:22:08.4230000Z | V40: 2026-02-09T04:15:36.3270000Z | W40: 219 | Y40: 2026-02-08T14:52:49.2770000Z | Z40: =LEFT(Y40,10) -> 2026-02-08 | AA40: 2026-02-09T04:30:24.7870000Z | AB40: 2026-02-09T04:30:24.7870000Z
...

Sheet Total_Enrolled
A1: PersonalEmailB3 | B1: IDB3 | C1: EmailB3 | D1: NameB3 | E1: passwordb3 | F1: Welcome Email Status
A2: JANCYJTG@GMAIL.COM | B2: 2025EM1200001 | C2: 2025em1200001@bitspilani-digital.edu.in | D2: JANCY C JOSHWA | E2: Ep$23012001 | F2: Sent
A3: OHILESWAR@GMAIL.COM | B3: 2025EM1200002 | C3: 2025em1200002@bitspilani-digital.edu.in | D3: OHILESWAR M N | E3: Ep$08061975 | F3: Sent
A4: TEJASLIMAYE37@GMAIL.COM | B4: 2025EM1200003 | C4: 2025em1200003@bitspilani-digital.edu.in | D4: TEJAS PRATAP LIMAYE | E4: Ep$19022002 | F4: Sent
A5: RAJANIDASTHRICE@YAHOO.CO.IN | B5: 2025EM1200005 | C5: 2025em1200005@bitspilani-digital.edu.in | D5: RAJANI DAS | E5: Ep$08091984 | F5: Sent
A6: ANEES.ASLAM.AI@GMAIL.COM | B6: 2025EM1200006 | C6: 2025em1200006@bitspilani-digital.edu.in | D6: ANEES A | E6: Ep$24102001 | F6: Sent
A7: GAURAVDATASCIENCE4438@GMAIL.COM | B7: 2025EM1200007 | C7: 2025em1200007@bitspilani-digital.edu.in | D7: GAURAV KUMAR SINGH | E7: Ep$23021993 | F7: Sent
A8: SAHI.VISTA@GMAIL.COM | B8: 2025EM1200008 | C8: 2025em1200008@bitspilani-digital.edu.in | D8: MOTUPALLI SURENDRA SAHI | E8: Ep$27051992 | F8: Sent
A9: ANASBISWAS@HOTMAIL.COM | B9: 2025EM1200009 | C9: 2025em1200009@bitspilani-digital.edu.in | D9: MD. ANAS BISWAS | E9: Ep$30081992 | F9: Sent
A10: SSK2410@GMAIL.COM | B10: 2025EM1200010 | C10: 2025em1200010@bitspilani-digital.edu.in | D10: KAMBLI SAURABH SANDEEP SWAPNA | E10: Ep$24101992 | F10: Sent
A11: ANKITA.SRIVASTAVA.01.09@GMAIL.COM | B11: 2025EM1200011 | C11: 2025em1200011@bitspilani-digital.edu.in | D11: ANKITA SRIVASTAVA | E11: Ep$27041995 | F11: Sent
A12: AMANABD98@GMAIL.COM | B12: 2025EM1200012 | C12: 2025em1200012@bitspilani-digital.edu.in | D12: AMAN ABDULLA | E12: Ep$16081998 | F12: Sent
... A1304: KHIMANSHU9953@GMAIL.COM | B1304: 2025EM1100509 | C1304: 2025em1100509@bitspilani-digital.edu.in | D1304: HIMANSHU PANDEY | E1304: Ep$19041999 | F1304: SENT

Sheet Courses
A1: LIVE SESSION ATTENDANCE
A2: BS (T-2 C-1) & (T-1 C-2) | C2: Trimester-1 (C-2 Jan-2026) (New) | D2: Trimester-2 (C-1 Sep-2025) (Old) | E2: Total
A3: Course | B3: Faculty
A4: Probability and Statistics | B4: Dr. Pushpendra | C4: 109 | D4: 68 | E4: 177
A5: Computer Programming | B5: Dr. Jagat Sesh Challa | C5: 109 | D5: 61 | E5: 170
A6: Writing Practice | B6: Solanki chakraborty | C6: 109 | D6: 25 | E6: 134
A7: Data and the World | B7: Deepankar Garg | C7: 109 | D7: 51 | E7: 160
A8: Computing Systems | B8: Prof. SUNIL KUMAR TEGGIHALLU | C8: 109 | D8: 84 | E8: 193
A11: BS (T-2 C-1) | D11: Trimester-2 (C-1 Sep-2025) (Old) | E11: Total
A12: Course | B12: Faculty
A13: Linear Algebra | B13: Vaibhav Mehandiratta (Goa campus) | D13: 188 | E13: 188
A14: Fundamentals of Data Science and Engineering | B14: Priyanka Banerjee | D14: 176 | E14: 176
A15: Data Structures for Data Science | B15: Jagat Sesh Challa | D15: 160 | E15: 160
A16: Data Preprocessing | B16: Swapnil Saurav | D16: 154 | E16: 154
A19: MSc (T-2 C-1) & (T-1 C-2) | C19: Trimester-1 (C-2 Jan-2026) (New) | D19: Trimester-2 (C-1 Sep-2025) (Old) | E19: Total
A20: Course | B20: Faculty
A21: Statistical Modelling & Inferencing | B21: Dr. Pushpendra Gupta | C21: 356 | D21: 39 | E21: 395
A22: Data Pre-processing | B22: Dr. Hemant Rathore | C22: 356 | D22: 33 | E22: 389
A23: Data Visualization & Storytelling | B23: ACV Subrahmaniam | C23: 356 | D23: 34 | E23: 390
A24: Feature Engineering | B24: Prof Naga | C24: 356 | D24: 33 | E24: 389
A26: MSc (T-2 C-1) | C26: Trimester-2 (C-1 Sep-2025) (New courses) | D26: Trimester-2 (C-1 Sep-2025) (Old Courses) | E26: Total
A27: Course | B27: Faculty
A28: Machine Learning | B28: Dr. Hemant Rathore | C28: 350 | E28: 350
A29: Artificial Neural Networks | B29: Deepanshi Seth | C29: 352 | E29: 352
A30: Data Stores & Pipelines | B30: Prof. Praveen | D30: 17 | E30: 17
A31: Cloud Services & Platforms | B31: Mohammad Anees Alam | C31: 357 | E31: 357
A32: Data Annotations and Labelling | B32: Utkarsh Khare | C32: 0 | D32: 0
A34: MATHS | C34: (C-2 Jan-2026) (New)
A35: Course | B35: Faculty
A36: Basic Mathematics | B36: Rahul Dhakad | C36: 77 | E36: 77
A38: Python | C38: (C-2 Jan-2026) (New)
A39: Course | B39: Faculty
A40: Python Programming | B40: MAHIPAL SINGH | C40: 35 | E40: 35
A42: Professional Certificate in AI Engg. and MLOps | C42: (C-2 Jan-2026) (New)
A43: Course | B43: Faculty
A44: Applied AI Engineering Foundations | B44: Prof. Prasad and Ms. Ankita | C44: 99 | E44: 99

Sheet Data Dump - Learner Usage
A1: Course Offering Name | B1: Parent Department Name | C1: Semester Name | D1: Username | E1: Org Defined Id | F1: First Name | G1: Is Active | H1: Content Completed | I1: Content Required | J1: Checklist Completed | K1: Quiz Completed | L1: Total Quiz Attempts | M1: Discussion Post Created | N1: Discussion Post Replies | O1: Discussion Post Read | P1: Last Discussion Post Date | Q1: Number Of Assignment Submissions | R1: Last Assignment Submission Date | S1: Total Time Spent In Content | T1: Last Visited Date | U1: Last System Login | V1: Number Of Logins To The System | W1: Auditor Name | X1: Last Quiz Attempt Date | Y1: Last SCORM Completion Date | Z1: Last SCORM Visit Date
A2: Data Structures for Data Science | B2: BS | C2: Trimester 2 | D2: 2025eb1100001@bitspilani-digital.edu.in | E2: 2025EB1100001 | F2: RUDRA SHARMA | G2: TRUE | H2: 1 | I2: 154 | J2: 0 | K2: 1 | L2: 1 | M2: 0 | N2: 0 | O2: 0 | Q2: 0 | S2: 0 | T2: 2026-02-08T09:13:59.9530000Z | U2: 2026-02-08T08:54:36.2970000Z | V2: 166 | X2: 2026-02-08T09:04:03.4030000Z
A3: Data Preprocessing (BS) | B3: BS | C3: Trimester 2 | D3: 2025eb1100001@bitspilani-digital.edu.in | E3: 2025EB1100001 | F3: RUDRA SHARMA | G3: TRUE | H3: 6 | I3: 158 | J3: 0 | K3: 2 | L3: 3 | M3: 0 | N3: 0 | O3: 0 | Q3: 0 | S3: 17096 | T3: 2026-02-08T09:20:40.1530000Z | U3: 2026-02-08T08:54:36.2970000Z | V3: 166 | X3: 2026-02-08T09:20:32.9730000Z
A4: Fundamentals of Data Science and Engineering | B4: BS | C4: Trimester 2 | D4: 2025eb1100001@bitspilani-digital.edu.in | E4: 2025EB1100001 | F4: RUDRA SHARMA | G4: TRUE | H4: 45 | I4: 112 | J4: 0 | K4: 7 | L4: 8 | M4: 0 | N4: 0 | O4: 0 | Q4: 0 | S4: 31534 | T4: 2026-02-07T15:33:47.5000000Z | U4: 2026-02-08T08:54:36.2970000Z | V4: 166 | X4: 2026-02-07T15:16:25.5370000Z
A5: Linear Algebra | B5: BS | C5: Trimester 2 | D5: 2025eb1100001@bitspilani-digital.edu.in | E5: 2025EB1100001 | F5: RUDRA SHARMA | G5: TRUE | H5: 3 | I5: 86 | J5: 0 | K5: 1 | L5: 1 | M5: 0 | N5: 0 | O5: 0 | Q5: 0 | S5: 27 | T5: 2026-02-08T09:12:57.6770000Z | U5: 2026-02-08T08:54:36.2970000Z | V5: 166 | X5: 2026-02-08T09:12:53.8070000Z | Y5: 2026-01-23T15:01:45.2470000Z | Z5: 2026-01-23T15:01:48.8770000Z
A6: Computing Systems | B6: BS | C6: Trimester 2 | D6: 2025eb1100001@bitspilani-digital.edu.in | E6: 2025EB1100001 | F6: RUDRA SHARMA | G6: TRUE | H6: 92 | I6: 267 | J6: 0 | K6: 34 | L6: 56 | M6: 0 | N6: 0 | O6: 0 | Q6: 0 | S6: 1027 | T6: 2026-02-08T08:57:34.8130000Z | U6: 2026-02-08T08:54:36.2970000Z | V6: 166 | X6: 2026-02-08T08:57:30.2130000Z | Y6: 2026-01-23T14:59:58.6570000Z | Z6: 2026-01-23T15:00:20.6770000Z
A7: Probability & Statistics | B7: BS | C7: Trimester 2 | D7: 2025eb1100003@bitspilani-digital.edu.in | E7: 2025EB1100003 | F7: AJAYACHANDRAN.E | G7: TRUE | H7: 24 | I7: 326 | J7: 0 | K7: 3 | L7: 5 | M7: 2 | N7: 0 | O7: 8 | P7: 2026-01-30T21:48:45.6800000Z | Q7: 0 | S7: 31222 | T7: 2026-02-09T00:39:23.1430000Z | U7: 2026-02-08T23:02:38.0030000Z | V7: 115 | X7: 2026-01-31T00:24:37.8630000Z | Y7: 2026-01-24T14:45:28.7000000Z | Z7: 2026-01-31T00:25:02.4370000Z
A8: Computer Programming | B8: BS | C8: Trimester 2 | D8: 2025eb1100003@bitspilani-digital.edu.in | E8: 2025EB1100003 | F8: AJAYACHANDRAN.E | G8: TRUE | H8: 44 | I8: 356 | J8: 0 | K8: 9 | L8: 18 | M8: 3 | N8: 0 | O8: 1 | P8: 2026-01-31T00:29:49.2300000Z | Q8: 0 | S8: 49579 | T8: 2026-02-09T00:39:46.6630000Z | U8: 2026-02-08T23:02:38.0030000Z | V8: 115 | X8: 2026-01-31T23:46:19.5000000Z | Y8: 2026-01-31T12:03:07.5170000Z | Z8: 2026-01-31T23:46:46.3370000Z
A9: Fundamentals of Data Science and Engineering | B9: BS | C9: Trimester 2 | D9: 2025eb1100003@bitspilani-digital.edu.in | E9: 2025EB1100003 | F9: AJAYACHANDRAN.E | G9: TRUE | H9: 27 | I9: 112 | J9: 0 | K9: 3 | L9: 6 | M9: 0 | N9: 0 | O9: 0 | Q9: 0 | S9: 25900 | T9: 2026-02-09T00:37:32.1300000Z | U9: 2026-02-08T23:02:38.0030000Z | V9: 115 | X9: 2026-01-30T20:33:35.5230000Z
A10: Data Preprocessing (BS) | B10: BS | C10: Trimester 2 | D10: 2025eb1100003@bitspilani-digital.edu.in | E10: 2025EB1100003 | F10: AJAYACHANDRAN.E | G10: TRUE | H10: 45 | I10: 158 | J10: 0 | K10: 6 | L10: 8 | M10: 3 | N10: 0 | O10: 0 | P10: 2026-02-07T23:08:17.5300000Z | Q10: 0 | S10: 24234 | T10: 2026-02-09T00:32:41.3400000Z | U10: 2026-02-08T23:02:38.0030000Z | V10: 115 | X10: 2026-02-09T00:31:45.6730000Z
A11: Data Preprocessing (BS) | B11: BS | C11: Trimester 2 | D11: 2025eb1100004@bitspilani-digital.edu.in | E11: 2025EB1100004 | F11: ARUNLAL P | G11: TRUE | H11: 1 | I11: 158 | J11: 0 | K11: 0 | L11: 0 | M11: 0 | N11: 0 | O11: 0 | Q11: 0 | S11: 0 | T11: 2026-01-19T08:25:52.9870000Z | U11: 2026-02-08T15:52:25.5800000Z | V11: 151
A12: Data Structures for Data Science | B12: BS | C12: Trimester 2 | D12: 2025eb1100004@bitspilani-digital.edu.in | E12: 2025EB1100004 | F12: ARUNLAL P | G12: TRUE | H12: 0 | I12: 154 | J12: 0 | K12: 0 | L12: 0 | M12: 0 | N12: 0 | O12: 0 | Q12: 0 | S12: 0 | T12: 2026-01-17T14:38:56.5370000Z | U12: 2026-02-08T15:52:25.5800000Z | V12: 151
A13: Fundamentals of Data Science and Engineering | B13: BS | C13: Trimester 2 | D13: 2025eb1100004@bitspilani-digital.edu.in | E13: 2025EB1100004 | F13: ARUNLAL P | G13: TRUE | H13: 1 | I13: 112 | J13: 0 | K13: 1 | L13: 1 | M13: 0 | N13: 0 | O13: 0 | Q13: 0 | S13: 0 | T13: 2026-02-08T15:58:42.1600000Z | U13: 2026-02-08T15:52:25.5800000Z | V13: 151 | X13: 2026-02-08T15:58:35.0330000Z
A14: Linear Algebra | B14: BS | C14: Trimester 2 | D14: 2025eb1100004@bitspilani-digital.edu.in | E14: 2025EB1100004 | F14: ARUNLAL P | G14: TRUE | H14: 0 | I14: 86 | J14: 0 | K14: 0 | L14: 0 | M14: 0 | N14: 0 | O14: 0 | Q14: 0 | S14: 0 | U14: 2026-02-08T15:52:25.5800000Z | V14: 151
A15: Linear Algebra | B15: BS | C15: Trimester 2 | D15: 2025eb1100006@bitspilani-digital.edu.in | E15: 2025EB1100006 | F15: JAL PATEL | G15: TRUE | H15: 1 | I15: 86 | J15: 0 | K15: 1 | L15: 1 | M15: 0 | N15: 0 | O15: 0 | Q15: 0 | S15: 0 | T15: 2026-02-08T08:16:42.7600000Z | U15: 2026-02-08T07:51:39.3430000Z | V15: 73 | X15: 2026-02-08T08:12:38.5830000Z
A16: Fundamentals of Data Science and Engineering | B16: BS | C16: Trimester 2 | D16: 2025eb1100006@bitspilani-digital.edu.in | E16: 2025EB1100006 | F16: JAL PATEL | G16: TRUE | H16: 2 | I16: 112 | J16: 0 | K16: 2 | L16: 2 | M16: 0 | N16: 0 | O16: 0 | Q16: 0 | S16: 0 | T16: 2026-02-08T08:17:07.8730000Z | U16: 2026-02-08T07:51:39.3430000Z | V16: 73 | X16: 2026-02-08T08:02:33.4500000Z
A17: Data Structures for Data Science | B17: BS | C17: Trimester 2 | D17: 2025eb1100006@bitspilani-digital.edu.in | E17: 2025EB1100006 | F17: JAL PATEL | G17: TRUE | H17: 1 | I17: 154 | J17: 0 | K17: 1 | L17: 1 | M17: 0 | N17: 0 | O17: 0 | Q17: 0 | S17: 0 | T17: 2026-02-08T08:17:33.9070000Z | U17: 2026-02-08T07:51:39.3430000Z | V17: 73 | X17: 2026-02-08T08:15:45.7230000Z
A18: Data Preprocessing (BS) | B18: BS | C18: Trimester 2 | D18: 2025eb1100006@bitspilani-digital.edu.in | E18: 2025EB1100006 | F18: JAL PATEL | G18: TRUE | H18: 0 | I18: 158 | J18: 0 | K18: 0 | L18: 0 | M18: 0 | N18: 0 | O18: 0 | Q18: 0 | S18: 0 | T18: 2026-02-08T08:16:57.8270000Z | U18: 2026-02-08T07:51:39.3430000Z | V18: 73
A19: Computer Programming | B19: BS | C19: Trimester 2 | D19: 2025eb1100007@bitspilani-digital.edu.in | E19: 2025EB1100007 | F19: HARSHVARDHAN SINGH | G19: TRUE | H19: 10 | I19: 356 | J19: 0 | K19: 4 | L19: 4 | M19: 0 | N19: 0 | O19: 0 | Q19: 0 | S19: 24662 | T19: 2026-02-08T02:54:21.2930000Z | U19: 2026-02-09T00:57:34.8670000Z | V19: 67 | X19: 2026-02-08T02:54:12.8470000Z | Y19: 2026-01-30T14:05:06.5370000Z | Z19: 2026-02-05T07:23:03.0770000Z
A20: Probability & Statistics | B20: BS | C20: Trimester 2 | D20: 2025eb1100007@bitspilani-digital.edu.in | E20: 2025EB1100007 | F20: HARSHVARDHAN SINGH | G20: TRUE | H20: 1 | I20: 326 | J20: 0 | K20: 1 | L20: 1 | M20: 0 | N20: 0 | O20: 0 | Q20: 0 | S20: 0 | T20: 2026-02-08T02:56:47.4770000Z | U20: 2026-02-09T00:57:34.8670000Z | V20: 67 | X20: 2026-02-08T02:56:43.8530000Z
A21: Computing Systems | B21: BS | C21: Trimester 2 | D21: 2025eb1100007@bitspilani-digital.edu.in | E21: 2025EB1100007 | F21: HARSHVARDHAN SINGH | G21: TRUE | H21: 1 | I21: 267 | J21: 0 | K21: 1 | L21: 1 | M21: 0 | N21: 0 | O21: 0 | Q21: 0 | S21: 0 | T21: 2026-02-08T03:02:53.3470000Z | U21: 2026-02-09T00:57:34.8670000Z | V21: 67 | X21: 2026-02-08T03:02:49.6200000Z
A22: Data and the World | B22: BS | C22: Trimester 2 | D22: 2025eb1100007@bitspilani-digital.edu.in | E22: 2025EB1100007 | F22: HARSHVARDHAN SINGH | G22: TRUE | H22: 0 | I22: 53 | J22: 0 | K22: 0 | L22: 0 | M22: 0 | N22: 0 | O22: 0 | Q22: 0 | S22: 0 | U22: 2026-02-09T00:57:34.8670000Z | V22: 67
A23: Data Preprocessing (BS) | B23: BS | C23: Trimester 2 | D23: 2025eb1100008@bitspilani-digital.edu.in | E23: 2025EB1100008 | F23: KALYANE VENKATESH NISHIKANT | G23: TRUE | H23: 4 | I23: 158 | J23: 0 | K23: 0 | L23: 0 | M23: 0 | N23: 0 | O23: 0 | Q23: 0 | S23: 6800 | T23: 2026-02-07T15:35:16.0400000Z | U23: 2026-02-07T15:26:57.4830000Z | V23: 107
A24: Data Structures for Data Science | B24: BS | C24: Trimester 2 | D24: 2025eb1100008@bitspilani-digital.edu.in | E24: 2025EB1100008 | F24: KALYANE VENKATESH NISHIKANT | G24: TRUE | H24: 0 | I24: 154 | J24: 0 | K24: 0 | L24: 0 | M24: 0 | N24: 0 | O24: 0 | Q24: 0 | S24: 0 | U24: 2026-02-07T15:26:57.4830000Z | V24: 107
A25: Fundamentals of Data Science and Engineering | B25: BS | C25: Trimester 2 | D25: 2025eb1100008@bitspilani-digital.edu.in | E25: 2025EB1100008 | F25: KALYANE VENKATESH NISHIKANT | G25: TRUE | H25: 5 | I25: 112 | J25: 0 | K25: 1 | L25: 1 | M25: 0 | N25: 0 | O25: 0 | Q25: 0 | S25: 3889 | T25: 2026-02-07T15:34:29.9030000Z | U25: 2026-02-07T15:26:57.4830000Z | V25: 107 | X25: 2026-02-07T15:34:10.0200000Z
A26: Linear Algebra | B26: BS | C26: Trimester 2 | D26: 2025eb1100008@bitspilani-digital.edu.in | E26: 2025EB1100008 | F26: KALYANE VENKATESH NISHIKANT | G26: TRUE | H26: 0 | I26: 86 | J26: 0 | K26: 0 | L26: 0 | M26: 0 | N26: 0 | O26: 0 | Q26: 0 | S26: 0 | U26: 2026-02-07T15:26:57.4830000Z | V26: 107
A27: Data and the World | B27: BS | C27: Trimester 2 | D27: 2025eb1100009@bitspilani-digital.edu.in | E27: 2025EB1100009 | F27: ALI ZAFAR RIZVI | G27: TRUE | H27: 0 | I27: 53 | J27: 0 | K27: 0 | L27: 0 | M27: 0 | N27: 0 | O27: 0 | Q27: 0 | S27: 0 | U27: 2026-02-08T17:27:11.8430000Z | V27: 7
A28: Computing Systems | B28: BS | C28: Trimester 2 | D28: 2025eb1100009@bitspilani-digital.edu.in | E28: 2025EB1100009 | F28: ALI ZAFAR RIZVI | G28: TRUE | H28: 0 | I28: 267 | J28: 0 | K28: 0 | L28: 0 | M28: 0 | N28: 0 | O28: 0 | Q28: 0 | S28: 0 | U28: 2026-02-08T17:27:11.8430000Z | V28: 7
A29: Probability & Statistics | B29: BS | C29: Trimester 2 | D29: 2025eb1100009@bitspilani-digital.edu.in | E29: 2025EB1100009 | F29: ALI ZAFAR RIZVI | G29: TRUE | H29: 0 | I29: 326 | J29: 0 | K29: 0 | L29: 0 | M29: 0 | N29: 0 | O29: 0 | Q29: 0 | S29: 0 | U29: 2026-02-08T17:27:11.8430000Z | V29: 7
A30: Writing Practice | B30: BS | C30: Trimester 2 | D30: 2025eb1100009@bitspilani-digital.edu.in | E30: 2025EB1100009 | F30: ALI ZAFAR RIZVI | G30: TRUE | H30: 0 | I30: 208 | J30: 0 | K30: 0 | L30: 0 | M30: 0 | N30: 0 | O30: 0 | Q30: 0 | S30: 0 | U30: 2026-02-08T17:27:11.8430000Z | V30: 7
A31: Computer Programming | B31: BS | C31: Trimester 2 | D31: 2025eb1100009@bitspilani-digital.edu.in | E31: 2025EB1100009 | F31: ALI ZAFAR RIZVI | G31: TRUE | H31: 0 | I31: 356 | J31: 0 | K31: 0 | L31: 0 | M31: 0 | N31: 0 | O31: 0 | Q31: 0 | S31: 0 | U31: 2026-02-08T17:27:11.8430000Z | V31: 7
A32: Linear Algebra | B32: BS | C32: Trimester 2 | D32: 2025eb1100010@bitspilani-digital.edu.in | E32: 2025EB1100010 | F32: HARSHITA JAIN | G32: TRUE | H32: 0 | I32: 86 | J32: 0 | K32: 0 | L32: 0 | M32: 0 | N32: 0 | O32: 0 | Q32: 0 | S32: 0 | U32: 2026-02-08T14:34:30.4630000Z | V32: 169
A33: Fundamentals of Data Science and Engineering | B33: BS | C33: Trimester 2 | D33: 2025eb1100010@bitspilani-digital.edu.in | E33: 2025EB1100010 | F33: HARSHITA JAIN | G33: TRUE | H33: 4 | I33: 112 | J33: 0 | K33: 2 | L33: 2 | M33: 0 | N33: 0 | O33: 0 | Q33: 0 | S33: 14 | T33: 2026-02-08T14:39:37.0530000Z | U33: 2026-02-08T14:34:30.4630000Z | V33: 169 | X33: 2026-02-08T14:39:30.3800000Z
A34: Data Structures for Data Science | B34: BS | C34: Trimester 2 | D34: 2025eb1100010@bitspilani-digital.edu.in | E34: 2025EB1100010 | F34: HARSHITA JAIN | G34: TRUE | H34: 3 | I34: 154 | J34: 0 | K34: 0 | L34: 0 | M34: 0 | N34: 0 | O34: 0 | Q34: 0 | S34: 22 | T34: 2026-02-04T14:31:35.9470000Z | U34: 2026-02-08T14:34:30.4630000Z | V34: 169
A35: Data Preprocessing (BS) | B35: BS | C35: Trimester 2 | D35: 2025eb1100010@bitspilani-digital.edu.in | E35: 2025EB1100010 | F35: HARSHITA JAIN | G35: TRUE | H35: 10 | I35: 158 | J35: 0 | K35: 0 | L35: 0 | M35: 0 | N35: 0 | O35: 0 | Q35: 0 | S35: 9593 | T35: 2026-02-04T14:32:10.0600000Z | U35: 2026-02-08T14:34:30.4630000Z | V35: 169
A36: Computer Programming | B36: BS | C36: Trimester 2 | D36: 2025eb1100012@bitspilani-digital.edu.in | E36: 2025EB1100012 | F36: SANTOSH SHRIKHANDE | G36: TRUE | H36: 0 | I36: 356 | J36: 0 | K36: 0 | L36: 0 | M36: 0 | N36: 0 | O36: 0 | Q36: 0 | S36: 0 | U36: 2026-02-07T05:52:24.4370000Z | V36: 119
A37: Probability & Statistics | B37: BS | C37: Trimester 2 | D37: 2025eb1100012@bitspilani-digital.edu.in | E37: 2025EB1100012 | F37: SANTOSH SHRIKHANDE | G37: TRUE | H37: 4 | I37: 326 | J37: 0 | K37: 0 | L37: 0 | M37: 0 | N37: 0 | O37: 0 | Q37: 0 | S37: 22 | T37: 2026-02-07T05:55:07.9530000Z | U37: 2026-02-07T05:52:24.4370000Z | V37: 119 | Y37: 2026-02-07T05:55:22.3570000Z | Z37: 2026-02-07T05:55:22.3570000Z
A38: Computer Programming | B38: BS | C38: Trimester 2 | D38: 2025eb1100013@bitspilani-digital.edu.in | E38: 2025EB1100013 | F38: AKSHITHA IMMACULATE A | G38: TRUE | H38: 0 | I38: 356 | J38: 0 | K38: 0 | L38: 0 | M38: 0 | N38: 0 | O38: 0 | Q38: 0 | S38: 0 | U38: 2026-01-30T14:24:09.0330000Z | V38: 100
A39: Computing Systems | B39: BS | C39: Trimester 2 | D39: 2025eb1100013@bitspilani-digital.edu.in | E39: 2025EB1100013 | F39: AKSHITHA IMMACULATE A | G39: TRUE | H39: 0 | I39: 267 | J39: 0 | K39: 0 | L39: 0 | M39: 0 | N39: 0 | O39: 0 | Q39: 0 | S39: 0 | U39: 2026-01-30T14:24:09.0330000Z | V39: 100
A40: Fundamentals of Data Science and Engineering | B40: BS | C40: Trimester 2 | D40: 2025eb1100013@bitspilani-digital.edu.in | E40: 2025EB1100013 | F40: AKSHITHA IMMACULATE A | G40: TRUE | H40: 0 | I40: 112 | J40: 0 | K40: 0 | L40: 0 | M40: 0 | N40: 0 | O40: 0 | Q40: 0 | S40: 0 | T40: 2026-01-18T11:10:10.2200000Z | U40: 2026-01-30T14:24:09.0330000Z | V40: 100
...
