Workbook

Sheet Learner Usage
A1: Course Offering Id | B1: Course Offering Code | C1: Course Offering Name | D1: Parent Department Name | E1: Parent Department Code | F1: Term Id | G1: Semester Name | H1: User Id | I1: Username | J1: Org Defined Id | K1: First Name | L1: Content Completed | M1: Content Required | N1: Checklist Completed | O1: Quiz Completed | P1: Total Quiz Attempts | Q1: Discussion Post Created | R1: Discussion Post Replies | S1: Discussion Post Read | T1: Last Discussion Post Date | U1: Number Of Assignment Submissions | V1: Last Assignment Submission Date | W1: Total Time Spent In Content | X1: Last Visited Date | Y1: Last System Login | Z1: Number Of Logins To The System | AA1: Auditor Name | AB1: Last Quiz Attempt Date | AC1: Last SCORM Completion Date | AD1: Last SCORM Visit Date
A2: 7034 | B2: T2-25_BDSDF106 | C2: Data Structures for Data Science | D2: BS - Data Science &amp; AI | E2: dept_bs_dsai | F2: 6653 | G2: Trimester 2 | H2: 226 | I2: 2025eb1100001@bitspilani-digital.edu.in | J2: 2025EB1100001 | K2: RUDRA SHARMA | L2: 1 | M2: 154 | N2: 0 | O2: 1 | P2: 1 | Q2: 0 | R2: 0 | S2: 0 | U2: 0 | W2: 0 | X2: 2026-02-08T09:13:59.9530000Z | Y2: 2026-02-09T11:45:19.5500000Z | Z2: 168 | AB2: 2026-02-08T09:04:03.4030000Z
A3: 7035 | B3: T2-25_BDSDF102 | C3: Data Preprocessing (BS) | D3: BS - Data Science &amp; AI | E3: dept_bs_dsai | F3: 6653 | G3: Trimester 2 | H3: 226 | I3: 2025eb1100001@bitspilani-digital.edu.in | J3: 2025EB1100001 | K3: RUDRA SHARMA | L3: 6 | M3: 158 | N3: 0 | O3: 2 | P3: 3 | Q3: 0 | R3: 0 | S3: 0 | U3: 0 | W3: 17096 | X3: 2026-02-08T09:20:40.1530000Z | Y3: 2026-02-09T11:45:19.5500000Z | Z3: 168 | AB3: 2026-02-08T09:20:32.9730000Z
A4: 7032 | B4: T2-25_BDSDF107 | C4: Fundamentals of Data Science and Engineering | D4: BS - Data Science &amp; AI | E4: dept_bs_dsai | F4: 6653 | G4: Trimester 2 | H4: 226 | I4: 2025eb1100001@bitspilani-digital.edu.in | J4: 2025EB1100001 | K4: RUDRA SHARMA | L4: 45 | M4: 112 | N4: 0 | O4: 7 | P4: 8 | Q4: 0 | R4: 0 | S4: 0 | U4: 0 | W4: 31534 | X4: 2026-02-07T15:33:47.5000000Z | Y4: 2026-02-09T11:45:19.5500000Z | Z4: 168 | AB4: 2026-02-07T15:16:25.5370000Z
A5: 7033 | B5: T2-25_BDSDF110 | C5: Linear Algebra | D5: BS - Data Science &amp; AI | E5: dept_bs_dsai | F5: 6653 | G5: Trimester 2 | H5: 226 | I5: 2025eb1100001@bitspilani-digital.edu.in | J5: 2025EB1100001 | K5: RUDRA SHARMA | L5: 3 | M5: 86 | N5: 0 | O5: 1 | P5: 1 | Q5: 0 | R5: 0 | S5: 0 | U5: 0 | W5: 27 | X5: 2026-02-08T09:12:57.6770000Z | Y5: 2026-02-09T11:45:19.5500000Z | Z5: 168 | AB5: 2026-02-08T09:12:53.8070000Z | AC5: 2026-01-23T15:01:45.2470000Z | AD5: 2026-01-23T15:01:48.8770000Z
A6: 7025 | B6: T2-25_BDSDF108 | C6: Computing Systems | D6: BS - Data Science &amp; AI | E6: dept_bs_dsai | F6: 6653 | G6: Trimester 2 | H6: 226 | I6: 2025eb1100001@bitspilani-digital.edu.in | J6: 2025EB1100001 | K6: RUDRA SHARMA | L6: 105 | M6: 267 | N6: 0 | O6: 35 | P6: 57 | Q6: 0 | R6: 0 | S6: 0 | U6: 0 | W6: 2449 | X6: 2026-02-09T12:25:12.1930000Z | Y6: 2026-02-09T11:45:19.5500000Z | Z6: 168 | AB6: 2026-02-09T12:25:03.4370000Z | AC6: 2026-02-09T11:46:54.2770000Z | AD6: 2026-02-09T11:46:54.2730000Z
A7: 7022 | B7: T2-25_BDSDF114 | C7: Probability & Statistics | D7: BS - Data Science &amp; AI | E7: dept_bs_dsai | F7: 6653 | G7: Trimester 2 | H7: 228 | I7: 2025eb1100003@bitspilani-digital.edu.in | J7: 2025EB1100003 | K7: AJAYACHANDRAN.E | L7: 24 | M7: 326 | N7: 0 | O7: 3 | P7: 5 | Q7: 2 | R7: 0 | S7: 8 | T7: 2026-01-30T21:48:45.6800000Z | U7: 0 | W7: 31222 | X7: 2026-02-09T00:39:23.1430000Z | Y7: 2026-02-08T23:02:38.0030000Z | Z7: 115 | AB7: 2026-01-31T00:24:37.8630000Z | AC7: 2026-01-24T14:45:28.7000000Z | AD7: 2026-01-31T00:25:02.4370000Z
A8: 7021 | B8: T2-25_BDSDF113 | C8: Computer Programming | D8: BS - Data Science &amp; AI | E8: dept_bs_dsai | F8: 6653 | G8: Trimester 2 | H8: 228 | I8: 2025eb1100003@bitspilani-digital.edu.in | J8: 2025EB1100003 | K8: AJAYACHANDRAN.E | L8: 44 | M8: 356 | N8: 0 | O8: 9 | P8: 18 | Q8: 3 | R8: 0 | S8: 1 | T8: 2026-01-31T00:29:49.2300000Z | U8: 0 | W8: 49579 | X8: 2026-02-09T00:39:46.6630000Z | Y8: 2026-02-08T23:02:38.0030000Z | Z8: 115 | AB8: 2026-01-31T23:46:19.5000000Z | AC8: 2026-01-31T12:03:07.5170000Z | AD8: 2026-01-31T23:46:46.3370000Z
A9: 7032 | B9: T2-25_BDSDF107 | C9: Fundamentals of Data Science and Engineering | D9: BS - Data Science &amp; AI | E9: dept_bs_dsai | F9: 6653 | G9: Trimester 2 | H9: 228 | I9: 2025eb1100003@bitspilani-digital.edu.in | J9: 2025EB1100003 | K9: AJAYACHANDRAN.E | L9: 27 | M9: 112 | N9: 0 | O9: 3 | P9: 6 | Q9: 0 | R9: 0 | S9: 0 | U9: 0 | W9: 25900 | X9: 2026-02-09T00:37:32.1300000Z | Y9: 2026-02-08T23:02:38.0030000Z | Z9: 115 | AB9: 2026-01-30T20:33:35.5230000Z
A10: 7035 | B10: T2-25_BDSDF102 | C10: Data Preprocessing (BS) | D10: BS - Data Science &amp; AI | E10: dept_bs_dsai | F10: 6653 | G10: Trimester 2 | H10: 228 | I10: 2025eb1100003@bitspilani-digital.edu.in | J10: 2025EB1100003 | K10: AJAYACHANDRAN.E | L10: 45 | M10: 158 | N10: 0 | O10: 6 | P10: 8 | Q10: 3 | R10: 0 | S10: 0 | T10: 2026-02-07T23:08:17.5300000Z | U10: 0 | W10: 24234 | X10: 2026-02-09T00:32:41.3400000Z | Y10: 2026-02-08T23:02:38.0030000Z | Z10: 115 | AB10: 2026-02-09T00:31:45.6730000Z
A11: 7035 | B11: T2-25_BDSDF102 | C11: Data Preprocessing (BS) | D11: BS - Data Science &amp; AI | E11: dept_bs_dsai | F11: 6653 | G11: Trimester 2 | H11: 229 | I11: 2025eb1100004@bitspilani-digital.edu.in | J11: 2025EB1100004 | K11: ARUNLAL P | L11: 1 | M11: 158 | N11: 0 | O11: 0 | P11: 0 | Q11: 0 | R11: 0 | S11: 0 | U11: 0 | W11: 0 | X11: 2026-01-19T08:25:52.9870000Z | Y11: 2026-02-08T15:52:25.5800000Z | Z11: 151
A12: 7034 | B12: T2-25_BDSDF106 | C12: Data Structures for Data Science | D12: BS - Data Science &amp; AI | E12: dept_bs_dsai | F12: 6653 | G12: Trimester 2 | H12: 229 | I12: 2025eb1100004@bitspilani-digital.edu.in | J12: 2025EB1100004 | K12: ARUNLAL P | L12: 0 | M12: 154 | N12: 0 | O12: 0 | P12: 0 | Q12: 0 | R12: 0 | S12: 0 | U12: 0 | W12: 0 | X12: 2026-01-17T14:38:56.5370000Z | Y12: 2026-02-08T15:52:25.5800000Z | Z12: 151
A13: 7032 | B13: T2-25_BDSDF107 | C13: Fundamentals of Data Science and Engineering | D13: BS - Data Science &amp; AI | E13: dept_bs_dsai | F13: 6653 | G13: Trimester 2 | H13: 229 | I13: 2025eb1100004@bitspilani-digital.edu.in | J13: 2025EB1100004 | K13: ARUNLAL P | L13: 1 | M13: 112 | N13: 0 | O13: 1 | P13: 1 | Q13: 0 | R13: 0 | S13: 0 | U13: 0 | W13: 0 | X13: 2026-02-08T15:58:42.1600000Z | Y13: 2026-02-08T15:52:25.5800000Z | Z13: 151 | AB13: 2026-02-08T15:58:35.0330000Z
A14: 7033 | B14: T2-25_BDSDF110 | C14: Linear Algebra | D14: BS - Data Science &amp; AI | E14: dept_bs_dsai | F14: 6653 | G14: Trimester 2 | H14: 229 | I14: 2025eb1100004@bitspilani-digital.edu.in | J14: 2025EB1100004 | K14: ARUNLAL P | L14: 0 | M14: 86 | N14: 0 | O14: 0 | P14: 0 | Q14: 0 | R14: 0 | S14: 0 | U14: 0 | W14: 0 | Y14: 2026-02-08T15:52:25.5800000Z | Z14: 151
A15: 7033 | B15: T2-25_BDSDF110 | C15: Linear Algebra | D15: BS - Data Science &amp; AI | E15: dept_bs_dsai | F15: 6653 | G15: Trimester 2 | H15: 231 | I15: 2025eb1100006@bitspilani-digital.edu.in | J15: 2025EB1100006 | K15: JAL PATEL | L15: 1 | M15: 86 | N15: 0 | O15: 1 | P15: 1 | Q15: 0 | R15: 0 | S15: 0 | U15: 0 | W15: 0 | X15: 2026-02-08T08:16:42.7600000Z | Y15: 2026-02-08T07:51:39.3430000Z | Z15: 73 | AB15: 2026-02-08T08:12:38.5830000Z
A16: 7032 | B16: T2-25_BDSDF107 | C16: Fundamentals of Data Science and Engineering | D16: BS - Data Science &amp; AI | E16: dept_bs_dsai | F16: 6653 | G16: Trimester 2 | H16: 231 | I16: 2025eb1100006@bitspilani-digital.edu.in | J16: 2025EB1100006 | K16: JAL PATEL | L16: 2 | M16: 112 | N16: 0 | O16: 2 | P16: 2 | Q16: 0 | R16: 0 | S16: 0 | U16: 0 | W16: 0 | X16: 2026-02-08T08:17:07.8730000Z | Y16: 2026-02-08T07:51:39.3430000Z | Z16: 73 | AB16: 2026-02-08T08:02:33.4500000Z
A17: 7034 | B17: T2-25_BDSDF106 | C17: Data Structures for Data Science | D17: BS - Data Science &amp; AI | E17: dept_bs_dsai | F17: 6653 | G17: Trimester 2 | H17: 231 | I17: 2025eb1100006@bitspilani-digital.edu.in | J17: 2025EB1100006 | K17: JAL PATEL | L17: 1 | M17: 154 | N17: 0 | O17: 1 | P17: 1 | Q17: 0 | R17: 0 | S17: 0 | U17: 0 | W17: 0 | X17: 2026-02-08T08:17:33.9070000Z | Y17: 2026-02-08T07:51:39.3430000Z | Z17: 73 | AB17: 2026-02-08T08:15:45.7230000Z
A18: 7035 | B18: T2-25_BDSDF102 | C18: Data Preprocessing (BS) | D18: BS - Data Science &amp; AI | E18: dept_bs_dsai | F18: 6653 | G18: Trimester 2 | H18: 231 | I18: 2025eb1100006@bitspilani-digital.edu.in | J18: 2025EB1100006 | K18: JAL PATEL | L18: 0 | M18: 158 | N18: 0 | O18: 0 | P18: 0 | Q18: 0 | R18: 0 | S18: 0 | U18: 0 | W18: 0 | X18: 2026-02-08T08:16:57.8270000Z | Y18: 2026-02-08T07:51:39.3430000Z | Z18: 73
A19: 7021 | B19: T2-25_BDSDF113 | C19: Computer Programming | D19: BS - Data Science &amp; AI | E19: dept_bs_dsai | F19: 6653 | G19: Trimester 2 | H19: 232 | I19: 2025eb1100007@bitspilani-digital.edu.in | J19: 2025EB1100007 | K19: HARSHVARDHAN SINGH | L19: 10 | M19: 356 | N19: 0 | O19: 4 | P19: 4 | Q19: 0 | R19: 0 | S19: 0 | U19: 0 | W19: 24662 | X19: 2026-02-08T02:54:21.2930000Z | Y19: 2026-02-10T09:45:44.0430000Z | Z19: 68 | AB19: 2026-02-08T02:54:12.8470000Z | AC19: 2026-01-30T14:05:06.5370000Z | AD19: 2026-02-05T07:23:03.0770000Z
A20: 7022 | B20: T2-25_BDSDF114 | C20: Probability & Statistics | D20: BS - Data Science &amp; AI | E20: dept_bs_dsai | F20: 6653 | G20: Trimester 2 | H20: 232 | I20: 2025eb1100007@bitspilani-digital.edu.in | J20: 2025EB1100007 | K20: HARSHVARDHAN SINGH | L20: 1 | M20: 326 | N20: 0 | O20: 1 | P20: 1 | Q20: 0 | R20: 0 | S20: 0 | U20: 0 | W20: 0 | X20: 2026-02-08T02:56:47.4770000Z | Y20: 2026-02-10T09:45:44.0430000Z | Z20: 68 | AB20: 2026-02-08T02:56:43.8530000Z
A21: 7025 | B21: T2-25_BDSDF108 | C21: Computing Systems | D21: BS - Data Science &amp; AI | E21: dept_bs_dsai | F21: 6653 | G21: Trimester 2 | H21: 232 | I21: 2025eb1100007@bitspilani-digital.edu.in | J21: 2025EB1100007 | K21: HARSHVARDHAN SINGH | L21: 1 | M21: 267 | N21: 0 | O21: 1 | P21: 1 | Q21: 0 | R21: 0 | S21: 0 | U21: 0 | W21: 0 | X21: 2026-02-08T03:02:53.3470000Z | Y21: 2026-02-10T09:45:44.0430000Z | Z21: 68 | AB21: 2026-02-08T03:02:49.6200000Z
A22: 7024 | B22: T2-25_BDSDF101 | C22: Data and the World | D22: BS - Data Science &amp; AI | E22: dept_bs_dsai | F22: 6653 | G22: Trimester 2 | H22: 232 | I22: 2025eb1100007@bitspilani-digital.edu.in | J22: 2025EB1100007 | K22: HARSHVARDHAN SINGH | L22: 0 | M22: 53 | N22: 0 | O22: 0 | P22: 0 | Q22: 0 | R22: 0 | S22: 0 | U22: 0 | W22: 0 | Y22: 2026-02-10T09:45:44.0430000Z | Z22: 68
A23: 7035 | B23: T2-25_BDSDF102 | C23: Data Preprocessing (BS) | D23: BS - Data Science &amp; AI | E23: dept_bs_dsai | F23: 6653 | G23: Trimester 2 | H23: 233 | I23: 2025eb1100008@bitspilani-digital.edu.in | J23: 2025EB1100008 | K23: KALYANE VENKATESH NISHIKANT | L23: 5 | M23: 158 | N23: 0 | O23: 1 | P23: 1 | Q23: 0 | R23: 0 | S23: 0 | U23: 0 | W23: 6803 | X23: 2026-02-10T10:37:54.0070000Z | Y23: 2026-02-10T10:33:24.8730000Z | Z23: 109 | AB23: 2026-02-10T10:37:42.3600000Z
A24: 7034 | B24: T2-25_BDSDF106 | C24: Data Structures for Data Science | D24: BS - Data Science &amp; AI | E24: dept_bs_dsai | F24: 6653 | G24: Trimester 2 | H24: 233 | I24: 2025eb1100008@bitspilani-digital.edu.in | J24: 2025EB1100008 | K24: KALYANE VENKATESH NISHIKANT | L24: 1 | M24: 154 | N24: 0 | O24: 1 | P24: 1 | Q24: 0 | R24: 0 | S24: 0 | U24: 0 | W24: 0 | X24: 2026-02-10T10:50:08.8370000Z | Y24: 2026-02-10T10:33:24.8730000Z | Z24: 109 | AB24: 2026-02-10T10:49:31.4930000Z
A25: 7032 | B25: T2-25_BDSDF107 | C25: Fundamentals of Data Science and Engineering | D25: BS - Data Science &amp; AI | E25: dept_bs_dsai | F25: 6653 | G25: Trimester 2 | H25: 233 | I25: 2025eb1100008@bitspilani-digital.edu.in | J25: 2025EB1100008 | K25: KALYANE VENKATESH NISHIKANT | L25: 5 | M25: 112 | N25: 0 | O25: 1 | P25: 1 | Q25: 0 | R25: 0 | S25: 0 | U25: 0 | W25: 3889 | X25: 2026-02-07T15:34:29.9030000Z | Y25: 2026-02-10T10:33:24.8730000Z | Z25: 109 | AB25: 2026-02-07T15:34:10.0200000Z
A26: 7033 | B26: T2-25_BDSDF110 | C26: Linear Algebra | D26: BS - Data Science &amp; AI | E26: dept_bs_dsai | F26: 6653 | G26: Trimester 2 | H26: 233 | I26: 2025eb1100008@bitspilani-digital.edu.in | J26: 2025EB1100008 | K26: KALYANE VENKATESH NISHIKANT | L26: 1 | M26: 86 | N26: 0 | O26: 1 | P26: 1 | Q26: 0 | R26: 0 | S26: 0 | U26: 0 | W26: 0 | X26: 2026-02-10T11:11:09.2670000Z | Y26: 2026-02-10T10:33:24.8730000Z | Z26: 109 | AB26: 2026-02-10T11:11:01.2030000Z
A27: 7024 | B27: T2-25_BDSDF101 | C27: Data and the World | D27: BS - Data Science &amp; AI | E27: dept_bs_dsai | F27: 6653 | G27: Trimester 2 | H27: 234 | I27: 2025eb1100009@bitspilani-digital.edu.in | J27: 2025EB1100009 | K27: ALI ZAFAR RIZVI | L27: 0 | M27: 53 | N27: 0 | O27: 0 | P27: 0 | Q27: 0 | R27: 0 | S27: 0 | U27: 0 | W27: 0 | Y27: 2026-02-08T17:27:11.8430000Z | Z27: 7
A28: 7025 | B28: T2-25_BDSDF108 | C28: Computing Systems | D28: BS - Data Science &amp; AI | E28: dept_bs_dsai | F28: 6653 | G28: Trimester 2 | H28: 234 | I28: 2025eb1100009@bitspilani-digital.edu.in | J28: 2025EB1100009 | K28: ALI ZAFAR RIZVI | L28: 0 | M28: 267 | N28: 0 | O28: 0 | P28: 0 | Q28: 0 | R28: 0 | S28: 0 | U28: 0 | W28: 0 | Y28: 2026-02-08T17:27:11.8430000Z | Z28: 7
A29: 7022 | B29: T2-25_BDSDF114 | C29: Probability & Statistics | D29: BS - Data Science &amp; AI | E29: dept_bs_dsai | F29: 6653 | G29: Trimester 2 | H29: 234 | I29: 2025eb1100009@bitspilani-digital.edu.in | J29: 2025EB1100009 | K29: ALI ZAFAR RIZVI | L29: 0 | M29: 326 | N29: 0 | O29: 0 | P29: 0 | Q29: 0 | R29: 0 | S29: 0 | U29: 0 | W29: 0 | Y29: 2026-02-08T17:27:11.8430000Z | Z29: 7
A30: 7023 | B30: T2-25_BDSDF112 | C30: Writing Practice | D30: BS - Data Science &amp; AI | E30: dept_bs_dsai | F30: 6653 | G30: Trimester 2 | H30: 234 | I30: 2025eb1100009@bitspilani-digital.edu.in | J30: 2025EB1100009 | K30: ALI ZAFAR RIZVI | L30: 0 | M30: 209 | N30: 0 | O30: 0 | P30: 0 | Q30: 0 | R30: 0 | S30: 0 | U30: 0 | W30: 0 | Y30: 2026-02-08T17:27:11.8430000Z | Z30: 7
A31: 7021 | B31: T2-25_BDSDF113 | C31: Computer Programming | D31: BS - Data Science &amp; AI | E31: dept_bs_dsai | F31: 6653 | G31: Trimester 2 | H31: 234 | I31: 2025eb1100009@bitspilani-digital.edu.in | J31: 2025EB1100009 | K31: ALI ZAFAR RIZVI | L31: 0 | M31: 356 | N31: 0 | O31: 0 | P31: 0 | Q31: 0 | R31: 0 | S31: 0 | U31: 0 | W31: 0 | Y31: 2026-02-08T17:27:11.8430000Z | Z31: 7
A32: 7033 | B32: T2-25_BDSDF110 | C32: Linear Algebra | D32: BS - Data Science &amp; AI | E32: dept_bs_dsai | F32: 6653 | G32: Trimester 2 | H32: 235 | I32: 2025eb1100010@bitspilani-digital.edu.in | J32: 2025EB1100010 | K32: HARSHITA JAIN | L32: 0 | M32: 86 | N32: 0 | O32: 0 | P32: 0 | Q32: 0 | R32: 0 | S32: 0 | U32: 0 | W32: 0 | X32: 2026-02-10T08:06:10.0870000Z | Y32: 2026-02-10T08:06:02.6430000Z | Z32: 171
A33: 7032 | B33: T2-25_BDSDF107 | C33: Fundamentals of Data Science and Engineering | D33: BS - Data Science &amp; AI | E33: dept_bs_dsai | F33: 6653 | G33: Trimester 2 | H33: 235 | I33: 2025eb1100010@bitspilani-digital.edu.in | J33: 2025EB1100010 | K33: HARSHITA JAIN | L33: 4 | M33: 112 | N33: 0 | O33: 2 | P33: 2 | Q33: 0 | R33: 0 | S33: 0 | U33: 0 | W33: 14 | X33: 2026-02-08T14:39:37.0530000Z | Y33: 2026-02-10T08:06:02.6430000Z | Z33: 171 | AB33: 2026-02-08T14:39:30.3800000Z
A34: 7034 | B34: T2-25_BDSDF106 | C34: Data Structures for Data Science | D34: BS - Data Science &amp; AI | E34: dept_bs_dsai | F34: 6653 | G34: Trimester 2 | H34: 235 | I34: 2025eb1100010@bitspilani-digital.edu.in | J34: 2025EB1100010 | K34: HARSHITA JAIN | L34: 3 | M34: 154 | N34: 0 | O34: 0 | P34: 0 | Q34: 0 | R34: 0 | S34: 0 | U34: 0 | W34: 22 | X34: 2026-02-10T08:06:16.2930000Z | Y34: 2026-02-10T08:06:02.6430000Z | Z34: 171
A35: 7035 | B35: T2-25_BDSDF102 | C35: Data Preprocessing (BS) | D35: BS - Data Science &amp; AI | E35: dept_bs_dsai | F35: 6653 | G35: Trimester 2 | H35: 235 | I35: 2025eb1100010@bitspilani-digital.edu.in | J35: 2025EB1100010 | K35: HARSHITA JAIN | L35: 10 | M35: 158 | N35: 0 | O35: 0 | P35: 0 | Q35: 0 | R35: 0 | S35: 0 | U35: 0 | W35: 9593 | X35: 2026-02-10T08:06:21.8130000Z | Y35: 2026-02-10T08:06:02.6430000Z | Z35: 171
A36: 7021 | B36: T2-25_BDSDF113 | C36: Computer Programming | D36: BS - Data Science &amp; AI | E36: dept_bs_dsai | F36: 6653 | G36: Trimester 2 | H36: 237 | I36: 2025eb1100012@bitspilani-digital.edu.in | J36: 2025EB1100012 | K36: SANTOSH SHRIKHANDE | L36: 0 | M36: 356 | N36: 0 | O36: 0 | P36: 0 | Q36: 0 | R36: 0 | S36: 0 | U36: 0 | W36: 0 | Y36: 2026-02-10T09:17:06.8000000Z | Z36: 120
A37: 7022 | B37: T2-25_BDSDF114 | C37: Probability & Statistics | D37: BS - Data Science &amp; AI | E37: dept_bs_dsai | F37: 6653 | G37: Trimester 2 | H37: 237 | I37: 2025eb1100012@bitspilani-digital.edu.in | J37: 2025EB1100012 | K37: SANTOSH SHRIKHANDE | L37: 17 | M37: 326 | N37: 0 | O37: 4 | P37: 5 | Q37: 0 | R37: 0 | S37: 0 | U37: 0 | W37: 3443 | X37: 2026-02-10T10:48:13.0130000Z | Y37: 2026-02-10T09:17:06.8000000Z | Z37: 120 | AB37: 2026-02-10T10:48:04.4030000Z | AC37: 2026-02-10T10:48:19.7300000Z | AD37: 2026-02-10T10:48:19.7270000Z
A38: 7021 | B38: T2-25_BDSDF113 | C38: Computer Programming | D38: BS - Data Science &amp; AI | E38: dept_bs_dsai | F38: 6653 | G38: Trimester 2 | H38: 238 | I38: 2025eb1100013@bitspilani-digital.edu.in | J38: 2025EB1100013 | K38: AKSHITHA IMMACULATE A | L38: 0 | M38: 356 | N38: 0 | O38: 0 | P38: 0 | Q38: 0 | R38: 0 | S38: 0 | U38: 0 | W38: 0 | Y38: 2026-01-30T14:24:09.0330000Z | Z38: 100
A39: 7025 | B39: T2-25_BDSDF108 | C39: Computing Systems | D39: BS - Data Science &amp; AI | E39: dept_bs_dsai | F39: 6653 | G39: Trimester 2 | H39: 238 | I39: 2025eb1100013@bitspilani-digital.edu.in | J39: 2025EB1100013 | K39: AKSHITHA IMMACULATE A | L39: 0 | M39: 267 | N39: 0 | O39: 0 | P39: 0 | Q39: 0 | R39: 0 | S39: 0 | U39: 0 | W39: 0 | Y39: 2026-01-30T14:24:09.0330000Z | Z39: 100
A40: 7032 | B40: T2-25_BDSDF107 | C40: Fundamentals of Data Science and Engineering | D40: BS - Data Science &amp; AI | E40: dept_bs_dsai | F40: 6653 | G40: Trimester 2 | H40: 238 | I40: 2025eb1100013@bitspilani-digital.edu.in | J40: 2025EB1100013 | K40: AKSHITHA IMMACULATE A | L40: 0 | M40: 112 | N40: 0 | O40: 0 | P40: 0 | Q40: 0 | R40: 0 | S40: 0 | U40: 0 | W40: 0 | X40: 2026-01-18T11:10:10.2200000Z | Y40: 2026-01-30T14:24:09.0330000Z | Z40: 100
...

Sheet graded quiz 1 status
A1: Parent Department Name | B1: BS - Data Science &amp; AI | F1: Learners Progress | G1: BS | H1: MS
F2: 46061 | G2: 0.28 | H2: 0.35
A3: Row Labels | B3: Count of Username | C3: # students | D3: % | F3: 46062 | G3: 0.37 | H3: 0.4
A4: Computer Programming | B4: 116 | C4: =_xlfn.XLOOKUP(A4,courses!A:A,courses!E:E) -> 170 | D4: =B4/C4 -> 0.68235294 | F4: 10-02-2026(11:15 AM) | G4: 0.54 | H4: 0.69
A5: Computing Systems | B5: 123 | C5: =_xlfn.XLOOKUP(A5,courses!A:A,courses!E:E) -> 193 | D5: =B5/C5 -> 0.6373057 | F5: 10-02-2026(4:51 PM) | G5: 0.69 | H5: 0.8
A6: Data Preprocessing (BS) | B6: 107 | C6: 154 | D6: =B6/C6 -> 0.69480519
A7: Data Structures for Data Science | B7: 115 | C7: =_xlfn.XLOOKUP(A7,courses!A:A,courses!E:E) -> 160 | D7: =B7/C7 -> 0.71875
A8: Fundamentals of Data Science and Engineering | B8: 149 | C8: =_xlfn.XLOOKUP(A8,courses!A:A,courses!E:E) -> 176 | D8: =B8/C8 -> 0.84659091
A9: Linear Algebra | B9: 123 | C9: =_xlfn.XLOOKUP(A9,courses!A:A,courses!E:E) -> 188 | D9: =B9/C9 -> 0.65425532
A10: Probability & Statistics | B10: 112 | C10: 177 | D10: =B10/C10 -> 0.63276836
A11: Writing Practice | B11: 89 | C11: =_xlfn.XLOOKUP(A11,courses!A:A,courses!E:E) -> 134 | D11: =B11/C11 -> 0.6641791
A12: Grand Total | B12: 934 | C12: =SUM(C4:C11) -> 1352 | D12: =B12/C12 -> 0.6908284
A14: Parent Department Name | B14: MSc - Data Science &amp; AI
A16: Row Labels | B16: Count of Username | C16: # students | D16: %
A17: Artificial Neural Networks | B17: 284 | C17: =_xlfn.XLOOKUP(A17,courses!A:A,courses!E:E) -> 352 | D17: =B17/C17 -> 0.80681818
A18: Cloud Services & Platforms | B18: 292 | C18: =_xlfn.XLOOKUP(A18,courses!A:A,courses!E:E) -> 357 | D18: =B18/C18 -> 0.81792717
A19: Data Pre-processing (MSc) | B19: 303 | C19: 389 | D19: =B19/C19 -> 0.77892031
A20: Data Stores & Pipelines | B20: 7 | C20: =_xlfn.XLOOKUP(A20,courses!A:A,courses!E:E) -> 17 | D20: =B20/C20 -> 0.41176471
A21: Data Visualization & Storytelling | B21: 306 | C21: =_xlfn.XLOOKUP(A21,courses!A:A,courses!E:E) -> 390 | D21: =B21/C21 -> 0.78461538
A22: Machine Learning | B22: 304 | C22: =_xlfn.XLOOKUP(A22,courses!A:A,courses!E:E) -> 350 | D22: =B22/C22 -> 0.86857143
A23: Statistical Modelling & Inferencing | B23: 305 | C23: =_xlfn.XLOOKUP(A23,courses!A:A,courses!E:E) -> 395 | D23: =B23/C23 -> 0.7721519
A24: Grand Total | B24: 1801 | C24: =SUM(C17:C23) -> 2250 | D24: =B24/C24 -> 0.80044444

Sheet courses
A1: LIVE SESSION ATTENDANCE
A2: BS (T-2 C-1) & (T-1 C-2) | C2: Trimester-1 (C-2 Jan-2026) (New) | D2: Trimester-2 (C-1 Sep-2025) (Old) | E2: Total
A3: Course | B3: Faculty
A4: Probability and Statistics | B4: Dr. Pushpendra | C4: 109 | D4: 68 | E4: 177
A5: Computer Programming | B5: Dr. Jagat Sesh Challa | C5: 109 | D5: 61 | E5: 170
A6: Writing Practice | B6: Solanki chakraborty | C6: 109 | D6: 25 | E6: 134
A7: Data and the World | B7: Deepankar Garg | C7: 109 | D7: 51 | E7: 160
A8: Computing Systems | B8: Prof. SUNIL KUMAR TEGGIHALLU | C8: 109 | D8: 84 | E8: 193
A11: BS (T-2 C-1) | D11: Trimester-2 (C-1 Sep-2025) (Old) | E11: Total
A12: Course | B12: Faculty
A13: Linear Algebra | B13: Vaibhav Mehandiratta (Goa campus) | D13: 188 | E13: 188
A14: Fundamentals of Data Science and Engineering | B14: Priyanka Banerjee | D14: 176 | E14: 176
A15: Data Structures for Data Science | B15: Jagat Sesh Challa | D15: 160 | E15: 160
A16: Data Preprocessing | B16: Swapnil Saurav | D16: 154 | E16: 154
A19: MSc (T-2 C-1) & (T-1 C-2) | C19: Trimester-1 (C-2 Jan-2026) (New) | D19: Trimester-2 (C-1 Sep-2025) (Old) | E19: Total
A20: Course | B20: Faculty
A21: Statistical Modelling & Inferencing | B21: Dr. Pushpendra Gupta | C21: 356 | D21: 39 | E21: 395
A22: Data Pre-processing | B22: Dr. Hemant Rathore | C22: 356 | D22: 33 | E22: 389
A23: Data Visualization & Storytelling | B23: ACV Subrahmaniam | C23: 356 | D23: 34 | E23: 390
A24: Feature Engineering | B24: Prof Naga | C24: 356 | D24: 33 | E24: 389
A26: MSc (T-2 C-1) | C26: Trimester-2 (C-1 Sep-2025) (New courses) | D26: Trimester-2 (C-1 Sep-2025) (Old Courses) | E26: Total
A27: Course | B27: Faculty
A28: Machine Learning | B28: Dr. Hemant Rathore | C28: 350 | E28: 350
A29: Artificial Neural Networks | B29: Deepanshi Seth | C29: 352 | E29: 352
A30: Data Stores & Pipelines | B30: Prof. Praveen | D30: 17 | E30: 17
A31: Cloud Services & Platforms | B31: Mohammad Anees Alam | C31: 357 | E31: 357
A32: Data Annotations and Labelling | B32: Utkarsh Khare | C32: 0 | D32: 0
A34: MATHS | C34: (C-2 Jan-2026) (New)
A35: Course | B35: Faculty
A36: Basic Mathematics | B36: Rahul Dhakad | C36: 77 | E36: 77
A38: Python | C38: (C-2 Jan-2026) (New)
A39: Course | B39: Faculty
A40: Python Programming | B40: MAHIPAL SINGH | C40: 35 | E40: 35
A42: Professional Certificate in AI Engg. and MLOps | C42: (C-2 Jan-2026) (New)
A43: Course | B43: Faculty
A44: Applied AI Engineering Foundations | B44: Prof. Prasad and Ms. Ankita | C44: 99 | E44: 99

Sheet Sheet1
A1: Course Offering Id | B1: Course Offering Code | C1: Course Offering Name | D1: Parent Department Name | E1: Parent Department Code | F1: Term Id | G1: Semester Name | H1: User Id | I1: Username | J1: Org Defined Id | K1: First Name | L1: Content Completed | M1: Content Required | N1: Checklist Completed | O1: Quiz Completed | P1: Total Quiz Attempts | Q1: Discussion Post Created | R1: Discussion Post Replies | S1: Discussion Post Read | T1: Last Discussion Post Date | U1: Number Of Assignment Submissions | V1: Last Assignment Submission Date | W1: Total Time Spent In Content | X1: Last Visited Date | Y1: Last System Login | Z1: Number Of Logins To The System | AA1: Auditor Name | AB1: Last Quiz Attempt Date | AC1: Last Quiz Attempt Date updated | AD1: Last SCORM Completion Date | AE1: Last SCORM Visit Date
A2: 7034 | B2: T2-25_BDSDF106 | C2: Data Structures for Data Science | D2: BS - Data Science &amp; AI | E2: dept_bs_dsai | F2: 6653 | G2: Trimester 2 | H2: 226 | I2: 2025eb1100001@bitspilani-digital.edu.in | J2: 2025EB1100001 | K2: RUDRA SHARMA | L2: 1 | M2: 154 | N2: 0 | O2: 1 | P2: 1 | Q2: 0 | R2: 0 | S2: 0 | U2: 0 | W2: 0 | X2: 2026-02-08T09:13:59.9530000Z | Y2: 2026-02-09T11:45:19.5500000Z | Z2: 168 | AB2: 2026-02-08T09:04:03.4030000Z | AC2: =LEFT(AB2,10) -> 2026-02-08
A3: 7035 | B3: T2-25_BDSDF102 | C3: Data Preprocessing (BS) | D3: BS - Data Science &amp; AI | E3: dept_bs_dsai | F3: 6653 | G3: Trimester 2 | H3: 226 | I3: 2025eb1100001@bitspilani-digital.edu.in | J3: 2025EB1100001 | K3: RUDRA SHARMA | L3: 6 | M3: 158 | N3: 0 | O3: 2 | P3: 3 | Q3: 0 | R3: 0 | S3: 0 | U3: 0 | W3: 17096 | X3: 2026-02-08T09:20:40.1530000Z | Y3: 2026-02-09T11:45:19.5500000Z | Z3: 168 | AB3: 2026-02-08T09:20:32.9730000Z | AC3: =LEFT(AB3,10) -> 2026-02-08
A4: 7032 | B4: T2-25_BDSDF107 | C4: Fundamentals of Data Science and Engineering | D4: BS - Data Science &amp; AI | E4: dept_bs_dsai | F4: 6653 | G4: Trimester 2 | H4: 226 | I4: 2025eb1100001@bitspilani-digital.edu.in | J4: 2025EB1100001 | K4: RUDRA SHARMA | L4: 45 | M4: 112 | N4: 0 | O4: 7 | P4: 8 | Q4: 0 | R4: 0 | S4: 0 | U4: 0 | W4: 31534 | X4: 2026-02-07T15:33:47.5000000Z | Y4: 2026-02-09T11:45:19.5500000Z | Z4: 168 | AB4: 2026-02-07T15:16:25.5370000Z | AC4: =LEFT(AB4,10) -> 2026-02-07
A5: 7033 | B5: T2-25_BDSDF110 | C5: Linear Algebra | D5: BS - Data Science &amp; AI | E5: dept_bs_dsai | F5: 6653 | G5: Trimester 2 | H5: 226 | I5: 2025eb1100001@bitspilani-digital.edu.in | J5: 2025EB1100001 | K5: RUDRA SHARMA | L5: 3 | M5: 86 | N5: 0 | O5: 1 | P5: 1 | Q5: 0 | R5: 0 | S5: 0 | U5: 0 | W5: 27 | X5: 2026-02-08T09:12:57.6770000Z | Y5: 2026-02-09T11:45:19.5500000Z | Z5: 168 | AB5: 2026-02-08T09:12:53.8070000Z | AC5: =LEFT(AB5,10) -> 2026-02-08 | AD5: 2026-01-23T15:01:45.2470000Z | AE5: 2026-01-23T15:01:48.8770000Z
A6: 7025 | B6: T2-25_BDSDF108 | C6: Computing Systems | D6: BS - Data Science &amp; AI | E6: dept_bs_dsai | F6: 6653 | G6: Trimester 2 | H6: 226 | I6: 2025eb1100001@bitspilani-digital.edu.in | J6: 2025EB1100001 | K6: RUDRA SHARMA | L6: 105 | M6: 267 | N6: 0 | O6: 35 | P6: 57 | Q6: 0 | R6: 0 | S6: 0 | U6: 0 | W6: 2449 | X6: 2026-02-09T12:25:12.1930000Z | Y6: 2026-02-09T11:45:19.5500000Z | Z6: 168 | AB6: 2026-02-09T12:25:03.4370000Z | AC6: =LEFT(AB6,10) -> 2026-02-09 | AD6: 2026-02-09T11:46:54.2770000Z | AE6: 2026-02-09T11:46:54.2730000Z
A7: 7035 | B7: T2-25_BDSDF102 | C7: Data Preprocessing (BS) | D7: BS - Data Science &amp; AI | E7: dept_bs_dsai | F7: 6653 | G7: Trimester 2 | H7: 228 | I7: 2025eb1100003@bitspilani-digital.edu.in | J7: 2025EB1100003 | K7: AJAYACHANDRAN.E | L7: 45 | M7: 158 | N7: 0 | O7: 6 | P7: 8 | Q7: 3 | R7: 0 | S7: 0 | T7: 2026-02-07T23:08:17.5300000Z | U7: 0 | W7: 24234 | X7: 2026-02-09T00:32:41.3400000Z | Y7: 2026-02-08T23:02:38.0030000Z | Z7: 115 | AB7: 2026-02-09T00:31:45.6730000Z | AC7: =LEFT(AB7,10) -> 2026-02-09
A8: 7032 | B8: T2-25_BDSDF107 | C8: Fundamentals of Data Science and Engineering | D8: BS - Data Science &amp; AI | E8: dept_bs_dsai | F8: 6653 | G8: Trimester 2 | H8: 229 | I8: 2025eb1100004@bitspilani-digital.edu.in | J8: 2025EB1100004 | K8: ARUNLAL P | L8: 1 | M8: 112 | N8: 0 | O8: 1 | P8: 1 | Q8: 0 | R8: 0 | S8: 0 | U8: 0 | W8: 0 | X8: 2026-02-08T15:58:42.1600000Z | Y8: 2026-02-08T15:52:25.5800000Z | Z8: 151 | AB8: 2026-02-08T15:58:35.0330000Z | AC8: =LEFT(AB8,10) -> 2026-02-08
A9: 7033 | B9: T2-25_BDSDF110 | C9: Linear Algebra | D9: BS - Data Science &amp; AI | E9: dept_bs_dsai | F9: 6653 | G9: Trimester 2 | H9: 231 | I9: 2025eb1100006@bitspilani-digital.edu.in | J9: 2025EB1100006 | K9: JAL PATEL | L9: 1 | M9: 86 | N9: 0 | O9: 1 | P9: 1 | Q9: 0 | R9: 0 | S9: 0 | U9: 0 | W9: 0 | X9: 2026-02-08T08:16:42.7600000Z | Y9: 2026-02-08T07:51:39.3430000Z | Z9: 73 | AB9: 2026-02-08T08:12:38.5830000Z | AC9: =LEFT(AB9,10) -> 2026-02-08
A10: 7032 | B10: T2-25_BDSDF107 | C10: Fundamentals of Data Science and Engineering | D10: BS - Data Science &amp; AI | E10: dept_bs_dsai | F10: 6653 | G10: Trimester 2 | H10: 231 | I10: 2025eb1100006@bitspilani-digital.edu.in | J10: 2025EB1100006 | K10: JAL PATEL | L10: 2 | M10: 112 | N10: 0 | O10: 2 | P10: 2 | Q10: 0 | R10: 0 | S10: 0 | U10: 0 | W10: 0 | X10: 2026-02-08T08:17:07.8730000Z | Y10: 2026-02-08T07:51:39.3430000Z | Z10: 73 | AB10: 2026-02-08T08:02:33.4500000Z | AC10: =LEFT(AB10,10) -> 2026-02-08
A11: 7034 | B11: T2-25_BDSDF106 | C11: Data Structures for Data Science | D11: BS - Data Science &amp; AI | E11: dept_bs_dsai | F11: 6653 | G11: Trimester 2 | H11: 231 | I11: 2025eb1100006@bitspilani-digital.edu.in | J11: 2025EB1100006 | K11: JAL PATEL | L11: 1 | M11: 154 | N11: 0 | O11: 1 | P11: 1 | Q11: 0 | R11: 0 | S11: 0 | U11: 0 | W11: 0 | X11: 2026-02-08T08:17:33.9070000Z | Y11: 2026-02-08T07:51:39.3430000Z | Z11: 73 | AB11: 2026-02-08T08:15:45.7230000Z | AC11: =LEFT(AB11,10) -> 2026-02-08
A12: 7021 | B12: T2-25_BDSDF113 | C12: Computer Programming | D12: BS - Data Science &amp; AI | E12: dept_bs_dsai | F12: 6653 | G12: Trimester 2 | H12: 232 | I12: 2025eb1100007@bitspilani-digital.edu.in | J12: 2025EB1100007 | K12: HARSHVARDHAN SINGH | L12: 10 | M12: 356 | N12: 0 | O12: 4 | P12: 4 | Q12: 0 | R12: 0 | S12: 0 | U12: 0 | W12: 24662 | X12: 2026-02-08T02:54:21.2930000Z | Y12: 2026-02-10T09:45:44.0430000Z | Z12: 68 | AB12: 2026-02-08T02:54:12.8470000Z | AC12: =LEFT(AB12,10) -> 2026-02-08 | AD12: 2026-01-30T14:05:06.5370000Z | AE12: 2026-02-05T07:23:03.0770000Z
A13: 7022 | B13: T2-25_BDSDF114 | C13: Probability & Statistics | D13: BS - Data Science &amp; AI | E13: dept_bs_dsai | F13: 6653 | G13: Trimester 2 | H13: 232 | I13: 2025eb1100007@bitspilani-digital.edu.in | J13: 2025EB1100007 | K13: HARSHVARDHAN SINGH | L13: 1 | M13: 326 | N13: 0 | O13: 1 | P13: 1 | Q13: 0 | R13: 0 | S13: 0 | U13: 0 | W13: 0 | X13: 2026-02-08T02:56:47.4770000Z | Y13: 2026-02-10T09:45:44.0430000Z | Z13: 68 | AB13: 2026-02-08T02:56:43.8530000Z | AC13: =LEFT(AB13,10) -> 2026-02-08
A14: 7025 | B14: T2-25_BDSDF108 | C14: Computing Systems | D14: BS - Data Science &amp; AI | E14: dept_bs_dsai | F14: 6653 | G14: Trimester 2 | H14: 232 | I14: 2025eb1100007@bitspilani-digital.edu.in | J14: 2025EB1100007 | K14: HARSHVARDHAN SINGH | L14: 1 | M14: 267 | N14: 0 | O14: 1 | P14: 1 | Q14: 0 | R14: 0 | S14: 0 | U14: 0 | W14: 0 | X14: 2026-02-08T03:02:53.3470000Z | Y14: 2026-02-10T09:45:44.0430000Z | Z14: 68 | AB14: 2026-02-08T03:02:49.6200000Z | AC14: =LEFT(AB14,10) -> 2026-02-08
A15: 7035 | B15: T2-25_BDSDF102 | C15: Data Preprocessing (BS) | D15: BS - Data Science &amp; AI | E15: dept_bs_dsai | F15: 6653 | G15: Trimester 2 | H15: 233 | I15: 2025eb1100008@bitspilani-digital.edu.in | J15: 2025EB1100008 | K15: KALYANE VENKATESH NISHIKANT | L15: 5 | M15: 158 | N15: 0 | O15: 1 | P15: 1 | Q15: 0 | R15: 0 | S15: 0 | U15: 0 | W15: 6803 | X15: 2026-02-10T10:37:54.0070000Z | Y15: 2026-02-10T10:33:24.8730000Z | Z15: 109 | AB15: 2026-02-10T10:37:42.3600000Z | AC15: =LEFT(AB15,10) -> 2026-02-10
A16: 7034 | B16: T2-25_BDSDF106 | C16: Data Structures for Data Science | D16: BS - Data Science &amp; AI | E16: dept_bs_dsai | F16: 6653 | G16: Trimester 2 | H16: 233 | I16: 2025eb1100008@bitspilani-digital.edu.in | J16: 2025EB1100008 | K16: KALYANE VENKATESH NISHIKANT | L16: 1 | M16: 154 | N16: 0 | O16: 1 | P16: 1 | Q16: 0 | R16: 0 | S16: 0 | U16: 0 | W16: 0 | X16: 2026-02-10T10:50:08.8370000Z | Y16: 2026-02-10T10:33:24.8730000Z | Z16: 109 | AB16: 2026-02-10T10:49:31.4930000Z | AC16: =LEFT(AB16,10) -> 2026-02-10
A17: 7032 | B17: T2-25_BDSDF107 | C17: Fundamentals of Data Science and Engineering | D17: BS - Data Science &amp; AI | E17: dept_bs_dsai | F17: 6653 | G17: Trimester 2 | H17: 233 | I17: 2025eb1100008@bitspilani-digital.edu.in | J17: 2025EB1100008 | K17: KALYANE VENKATESH NISHIKANT | L17: 5 | M17: 112 | N17: 0 | O17: 1 | P17: 1 | Q17: 0 | R17: 0 | S17: 0 | U17: 0 | W17: 3889 | X17: 2026-02-07T15:34:29.9030000Z | Y17: 2026-02-10T10:33:24.8730000Z | Z17: 109 | AB17: 2026-02-07T15:34:10.0200000Z | AC17: =LEFT(AB17,10) -> 2026-02-07
A18: 7033 | B18: T2-25_BDSDF110 | C18: Linear Algebra | D18: BS - Data Science &amp; AI | E18: dept_bs_dsai | F18: 6653 | G18: Trimester 2 | H18: 233 | I18: 2025eb1100008@bitspilani-digital.edu.in | J18: 2025EB1100008 | K18: KALYANE VENKATESH NISHIKANT | L18: 1 | M18: 86 | N18: 0 | O18: 1 | P18: 1 | Q18: 0 | R18: 0 | S18: 0 | U18: 0 | W18: 0 | X18: 2026-02-10T11:11:09.2670000Z | Y18: 2026-02-10T10:33:24.8730000Z | Z18: 109 | AB18: 2026-02-10T11:11:01.2030000Z | AC18: =LEFT(AB18,10) -> 2026-02-10
A19: 7032 | B19: T2-25_BDSDF107 | C19: Fundamentals of Data Science and Engineering | D19: BS - Data Science &amp; AI | E19: dept_bs_dsai | F19: 6653 | G19: Trimester 2 | H19: 235 | I19: 2025eb1100010@bitspilani-digital.edu.in | J19: 2025EB1100010 | K19: HARSHITA JAIN | L19: 4 | M19: 112 | N19: 0 | O19: 2 | P19: 2 | Q19: 0 | R19: 0 | S19: 0 | U19: 0 | W19: 14 | X19: 2026-02-08T14:39:37.0530000Z | Y19: 2026-02-10T08:06:02.6430000Z | Z19: 171 | AB19: 2026-02-08T14:39:30.3800000Z | AC19: =LEFT(AB19,10) -> 2026-02-08
A20: 7022 | B20: T2-25_BDSDF114 | C20: Probability & Statistics | D20: BS - Data Science &amp; AI | E20: dept_bs_dsai | F20: 6653 | G20: Trimester 2 | H20: 237 | I20: 2025eb1100012@bitspilani-digital.edu.in | J20: 2025EB1100012 | K20: SANTOSH SHRIKHANDE | L20: 17 | M20: 326 | N20: 0 | O20: 4 | P20: 5 | Q20: 0 | R20: 0 | S20: 0 | U20: 0 | W20: 3443 | X20: 2026-02-10T10:48:13.0130000Z | Y20: 2026-02-10T09:17:06.8000000Z | Z20: 120 | AB20: 2026-02-10T10:48:04.4030000Z | AC20: =LEFT(AB20,10) -> 2026-02-10 | AD20: 2026-02-10T10:48:19.7300000Z | AE20: 2026-02-10T10:48:19.7270000Z
A21: 7034 | B21: T2-25_BDSDF106 | C21: Data Structures for Data Science | D21: BS - Data Science &amp; AI | E21: dept_bs_dsai | F21: 6653 | G21: Trimester 2 | H21: 239 | I21: 2025eb1100014@bitspilani-digital.edu.in | J21: 2025EB1100014 | K21: SURYA A | L21: 61 | M21: 154 | N21: 0 | O21: 8 | P21: 8 | Q21: 0 | R21: 0 | S21: 0 | U21: 0 | W21: 52849 | X21: 2026-02-09T15:46:33.2500000Z | Y21: 2026-02-09T15:44:09.7300000Z | Z21: 200 | AB21: 2026-02-09T15:46:22.7570000Z | AC21: =LEFT(AB21,10) -> 2026-02-09 | AD21: 2026-01-19T09:41:03.9430000Z | AE21: 2026-01-28T20:04:48.0130000Z
A22: 7022 | B22: T2-25_BDSDF114 | C22: Probability & Statistics | D22: BS - Data Science &amp; AI | E22: dept_bs_dsai | F22: 6653 | G22: Trimester 2 | H22: 239 | I22: 2025eb1100014@bitspilani-digital.edu.in | J22: 2025EB1100014 | K22: SURYA A | L22: 13 | M22: 326 | N22: 0 | O22: 2 | P22: 3 | Q22: 0 | R22: 0 | S22: 0 | U22: 0 | W22: 7223 | X22: 2026-02-09T15:49:52.3800000Z | Y22: 2026-02-09T15:44:09.7300000Z | Z22: 200 | AB22: 2026-02-09T15:49:48.9800000Z | AC22: =LEFT(AB22,10) -> 2026-02-09 | AD22: 2026-01-21T10:07:30.9030000Z | AE22: 2026-01-21T10:07:30.9130000Z
A23: 7034 | B23: T2-25_BDSDF106 | C23: Data Structures for Data Science | D23: BS - Data Science &amp; AI | E23: dept_bs_dsai | F23: 6653 | G23: Trimester 2 | H23: 240 | I23: 2025eb1100015@bitspilani-digital.edu.in | J23: 2025EB1100015 | K23: TADIMALLA ADITI | L23: 13 | M23: 154 | N23: 0 | O23: 4 | P23: 4 | Q23: 0 | R23: 0 | S23: 0 | U23: 0 | W23: 43739 | X23: 2026-02-10T03:06:34.9530000Z | Y23: 2026-02-10T03:06:30.3670000Z | Z23: 239 | AB23: 2026-02-08T17:30:39.1400000Z | AC23: =LEFT(AB23,10) -> 2026-02-08 | AD23: 2026-02-10T03:20:58.8370000Z | AE23: 2026-02-10T03:20:58.8400000Z
A24: 7033 | B24: T2-25_BDSDF110 | C24: Linear Algebra | D24: BS - Data Science &amp; AI | E24: dept_bs_dsai | F24: 6653 | G24: Trimester 2 | H24: 240 | I24: 2025eb1100015@bitspilani-digital.edu.in | J24: 2025EB1100015 | K24: TADIMALLA ADITI | L24: 41 | M24: 86 | N24: 0 | O24: 12 | P24: 12 | Q24: 0 | R24: 0 | S24: 0 | U24: 0 | W24: 7515 | X24: 2026-02-09T14:17:22.6930000Z | Y24: 2026-02-10T03:06:30.3670000Z | Z24: 239 | AB24: 2026-02-09T14:16:46.7530000Z | AC24: =LEFT(AB24,10) -> 2026-02-09 | AD24: 2026-02-09T03:13:18.3970000Z | AE24: 2026-02-09T03:13:18.3930000Z
A25: 7032 | B25: T2-25_BDSDF107 | C25: Fundamentals of Data Science and Engineering | D25: BS - Data Science &amp; AI | E25: dept_bs_dsai | F25: 6653 | G25: Trimester 2 | H25: 240 | I25: 2025eb1100015@bitspilani-digital.edu.in | J25: 2025EB1100015 | K25: TADIMALLA ADITI | L25: 37 | M25: 112 | N25: 0 | O25: 6 | P25: 6 | Q25: 0 | R25: 0 | S25: 0 | U25: 0 | W25: 46448 | X25: 2026-02-07T16:43:43.8370000Z | Y25: 2026-02-10T03:06:30.3670000Z | Z25: 239 | AB25: 2026-02-07T16:43:37.4230000Z | AC25: =LEFT(AB25,10) -> 2026-02-07
A26: 7032 | B26: T2-25_BDSDF107 | C26: Fundamentals of Data Science and Engineering | D26: BS - Data Science &amp; AI | E26: dept_bs_dsai | F26: 6653 | G26: Trimester 2 | H26: 243 | I26: 2025eb1100018@bitspilani-digital.edu.in | J26: 2025EB1100018 | K26: NIMMAGANTI SUMAHE | L26: 52 | M26: 112 | N26: 0 | O26: 7 | P26: 7 | Q26: 0 | R26: 0 | S26: 0 | U26: 0 | W26: 14750 | X26: 2026-02-08T21:41:02.6170000Z | Y26: 2026-02-10T10:32:31.4130000Z | Z26: 324 | AB26: 2026-02-08T21:40:36.1730000Z | AC26: =LEFT(AB26,10) -> 2026-02-08
A27: 7033 | B27: T2-25_BDSDF110 | C27: Linear Algebra | D27: BS - Data Science &amp; AI | E27: dept_bs_dsai | F27: 6653 | G27: Trimester 2 | H27: 243 | I27: 2025eb1100018@bitspilani-digital.edu.in | J27: 2025EB1100018 | K27: NIMMAGANTI SUMAHE | L27: 61 | M27: 86 | N27: 0 | O27: 16 | P27: 17 | Q27: 4 | R27: 0 | S27: 0 | T27: 2026-02-08T20:09:50.6830000Z | U27: 0 | W27: 25463 | X27: 2026-02-09T12:51:37.3100000Z | Y27: 2026-02-10T10:32:31.4130000Z | Z27: 324 | AB27: 2026-02-08T20:01:37.7070000Z | AC27: =LEFT(AB27,10) -> 2026-02-08 | AD27: 2026-02-08T20:01:57.0970000Z | AE27: 2026-02-08T20:01:57.0970000Z
A28: 7035 | B28: T2-25_BDSDF102 | C28: Data Preprocessing (BS) | D28: BS - Data Science &amp; AI | E28: dept_bs_dsai | F28: 6653 | G28: Trimester 2 | H28: 243 | I28: 2025eb1100018@bitspilani-digital.edu.in | J28: 2025EB1100018 | K28: NIMMAGANTI SUMAHE | L28: 81 | M28: 158 | N28: 0 | O28: 27 | P28: 27 | Q28: 0 | R28: 0 | S28: 0 | U28: 0 | W28: 28046 | X28: 2026-02-08T20:10:27.6930000Z | Y28: 2026-02-10T10:32:31.4130000Z | Z28: 324 | AB28: 2026-02-08T14:32:46.4930000Z | AC28: =LEFT(AB28,10) -> 2026-02-08
A29: 7034 | B29: T2-25_BDSDF106 | C29: Data Structures for Data Science | D29: BS - Data Science &amp; AI | E29: dept_bs_dsai | F29: 6653 | G29: Trimester 2 | H29: 243 | I29: 2025eb1100018@bitspilani-digital.edu.in | J29: 2025EB1100018 | K29: NIMMAGANTI SUMAHE | L29: 101 | M29: 154 | N29: 0 | O29: 33 | P29: 33 | Q29: 0 | R29: 0 | S29: 0 | U29: 0 | W29: 30678 | X29: 2026-02-10T11:01:21.4600000Z | Y29: 2026-02-10T10:32:31.4130000Z | Z29: 324 | AB29: 2026-02-10T11:01:16.6600000Z | AC29: =LEFT(AB29,10) -> 2026-02-10 | AD29: 2026-02-10T11:01:47.6670000Z | AE29: 2026-02-10T11:01:53.1170000Z
A30: 7022 | B30: T2-25_BDSDF114 | C30: Probability & Statistics | D30: BS - Data Science &amp; AI | E30: dept_bs_dsai | F30: 6653 | G30: Trimester 2 | H30: 244 | I30: 2025eb1100019@bitspilani-digital.edu.in | J30: 2025EB1100019 | K30: NITISH KUMAR | L30: 6 | M30: 326 | N30: 0 | O30: 1 | P30: 1 | Q30: 0 | R30: 0 | S30: 0 | U30: 0 | W30: 763 | X30: 2026-02-08T15:01:55.8400000Z | Y30: 2026-02-09T18:25:38.1170000Z | Z30: 124 | AB30: 2026-02-08T15:01:36.1370000Z | AC30: =LEFT(AB30,10) -> 2026-02-08
A31: 7025 | B31: T2-25_BDSDF108 | C31: Computing Systems | D31: BS - Data Science &amp; AI | E31: dept_bs_dsai | F31: 6653 | G31: Trimester 2 | H31: 244 | I31: 2025eb1100019@bitspilani-digital.edu.in | J31: 2025EB1100019 | K31: NITISH KUMAR | L31: 15 | M31: 267 | N31: 0 | O31: 4 | P31: 4 | Q31: 0 | R31: 0 | S31: 0 | U31: 0 | W31: 9984 | X31: 2026-02-09T20:04:12.7870000Z | Y31: 2026-02-09T18:25:38.1170000Z | Z31: 124 | AB31: 2026-02-09T20:04:02.3630000Z | AC31: =LEFT(AB31,10) -> 2026-02-09 | AD31: 2026-02-09T20:04:23.7470000Z | AE31: 2026-02-09T20:04:23.7400000Z
A32: 7025 | B32: T2-25_BDSDF108 | C32: Computing Systems | D32: BS - Data Science &amp; AI | E32: dept_bs_dsai | F32: 6653 | G32: Trimester 2 | H32: 245 | I32: 2025eb1100020@bitspilani-digital.edu.in | J32: 2025EB1100020 | K32: AYUSH JHA | L32: 5 | M32: 267 | N32: 0 | O32: 1 | P32: 1 | Q32: 0 | R32: 0 | S32: 0 | U32: 0 | W32: 66 | X32: 2026-02-08T13:56:05.5670000Z | Y32: 2026-02-09T07:21:41.8230000Z | Z32: 77 | AB32: 2026-02-08T13:55:34.7400000Z | AC32: =LEFT(AB32,10) -> 2026-02-08 | AD32: 2026-01-24T15:44:23.2600000Z | AE32: 2026-01-24T15:44:23.2670000Z
A33: 7022 | B33: T2-25_BDSDF114 | C33: Probability & Statistics | D33: BS - Data Science &amp; AI | E33: dept_bs_dsai | F33: 6653 | G33: Trimester 2 | H33: 245 | I33: 2025eb1100020@bitspilani-digital.edu.in | J33: 2025EB1100020 | K33: AYUSH JHA | L33: 1 | M33: 326 | N33: 0 | O33: 1 | P33: 1 | Q33: 0 | R33: 0 | S33: 0 | U33: 0 | W33: 0 | X33: 2026-02-08T13:45:37.9530000Z | Y33: 2026-02-09T07:21:41.8230000Z | Z33: 77 | AB33: 2026-02-08T13:45:25.1370000Z | AC33: =LEFT(AB33,10) -> 2026-02-08
A34: 7021 | B34: T2-25_BDSDF113 | C34: Computer Programming | D34: BS - Data Science &amp; AI | E34: dept_bs_dsai | F34: 6653 | G34: Trimester 2 | H34: 245 | I34: 2025eb1100020@bitspilani-digital.edu.in | J34: 2025EB1100020 | K34: AYUSH JHA | L34: 21 | M34: 356 | N34: 0 | O34: 6 | P34: 8 | Q34: 0 | R34: 0 | S34: 0 | U34: 0 | W34: 4646 | X34: 2026-02-09T07:22:11.7630000Z | Y34: 2026-02-09T07:21:41.8230000Z | Z34: 77 | AB34: 2026-02-08T13:37:04.5700000Z | AC34: =LEFT(AB34,10) -> 2026-02-08 | AD34: 2026-02-09T07:41:28.0400000Z | AE34: 2026-02-09T07:41:28.0400000Z
A35: 7034 | B35: T2-25_BDSDF106 | C35: Data Structures for Data Science | D35: BS - Data Science &amp; AI | E35: dept_bs_dsai | F35: 6653 | G35: Trimester 2 | H35: 246 | I35: 2025eb1100021@bitspilani-digital.edu.in | J35: 2025EB1100021 | K35: R KUSHAL MEHTA | L35: 23 | M35: 154 | N35: 0 | O35: 6 | P35: 7 | Q35: 0 | R35: 0 | S35: 0 | U35: 0 | W35: 7042 | X35: 2026-02-10T05:22:24.8300000Z | Y35: 2026-02-10T05:04:12.6300000Z | Z35: 274 | AB35: 2026-02-10T05:22:18.0230000Z | AC35: =LEFT(AB35,10) -> 2026-02-10 | AD35: 2026-02-04T11:22:17.7870000Z | AE35: 2026-02-05T12:29:06.3170000Z
A36: 7035 | B36: T2-25_BDSDF102 | C36: Data Preprocessing (BS) | D36: BS - Data Science &amp; AI | E36: dept_bs_dsai | F36: 6653 | G36: Trimester 2 | H36: 246 | I36: 2025eb1100021@bitspilani-digital.edu.in | J36: 2025EB1100021 | K36: R KUSHAL MEHTA | L36: 29 | M36: 158 | N36: 0 | O36: 8 | P36: 10 | Q36: 0 | R36: 0 | S36: 0 | U36: 0 | W36: 13207 | X36: 2026-02-10T05:27:57.6630000Z | Y36: 2026-02-10T05:04:12.6300000Z | Z36: 274 | AB36: 2026-02-10T05:27:09.6830000Z | AC36: =LEFT(AB36,10) -> 2026-02-10
A37: 7033 | B37: T2-25_BDSDF110 | C37: Linear Algebra | D37: BS - Data Science &amp; AI | E37: dept_bs_dsai | F37: 6653 | G37: Trimester 2 | H37: 246 | I37: 2025eb1100021@bitspilani-digital.edu.in | J37: 2025EB1100021 | K37: R KUSHAL MEHTA | L37: 7 | M37: 86 | N37: 0 | O37: 1 | P37: 1 | Q37: 0 | R37: 0 | S37: 0 | U37: 0 | W37: 1150 | X37: 2026-02-10T05:18:21.8000000Z | Y37: 2026-02-10T05:04:12.6300000Z | Z37: 274 | AB37: 2026-02-10T05:18:16.5670000Z | AC37: =LEFT(AB37,10) -> 2026-02-10 | AD37: 2026-01-29T13:05:35.3030000Z | AE37: 2026-01-29T13:05:35.3030000Z
A38: 7032 | B38: T2-25_BDSDF107 | C38: Fundamentals of Data Science and Engineering | D38: BS - Data Science &amp; AI | E38: dept_bs_dsai | F38: 6653 | G38: Trimester 2 | H38: 246 | I38: 2025eb1100021@bitspilani-digital.edu.in | J38: 2025EB1100021 | K38: R KUSHAL MEHTA | L38: 27 | M38: 112 | N38: 0 | O38: 4 | P38: 5 | Q38: 1 | R38: 0 | S38: 0 | T38: 2026-02-08T17:15:09.4430000Z | U38: 0 | W38: 4062 | X38: 2026-02-10T05:29:26.5130000Z | Y38: 2026-02-10T05:04:12.6300000Z | Z38: 274 | AB38: 2026-02-10T05:09:13.6330000Z | AC38: =LEFT(AB38,10) -> 2026-02-10
A39: 7021 | B39: T2-25_BDSDF113 | C39: Computer Programming | D39: BS - Data Science &amp; AI | E39: dept_bs_dsai | F39: 6653 | G39: Trimester 2 | H39: 249 | I39: 2025eb1100024@bitspilani-digital.edu.in | J39: 2025EB1100024 | K39: SHOORSEN THIRUNAVUKKARASU K | L39: 13 | M39: 356 | N39: 0 | O39: 4 | P39: 8 | Q39: 0 | R39: 0 | S39: 0 | U39: 0 | W39: 1785 | X39: 2026-02-08T06:56:25.9930000Z | Y39: 2026-02-08T06:51:55.3800000Z | Z39: 112 | AB39: 2026-02-08T06:55:52.9500000Z | AC39: =LEFT(AB39,10) -> 2026-02-08 | AD39: 2026-01-29T14:37:14.7270000Z | AE39: 2026-01-29T14:37:14.7370000Z
A40: 7033 | B40: T2-25_BDSDF110 | C40: Linear Algebra | D40: BS - Data Science &amp; AI | E40: dept_bs_dsai | F40: 6653 | G40: Trimester 2 | H40: 249 | I40: 2025eb1100024@bitspilani-digital.edu.in | J40: 2025EB1100024 | K40: SHOORSEN THIRUNAVUKKARASU K | L40: 9 | M40: 86 | N40: 0 | O40: 3 | P40: 3 | Q40: 0 | R40: 0 | S40: 0 | U40: 0 | W40: 4129 | X40: 2026-02-08T06:59:50.3870000Z | Y40: 2026-02-08T06:51:55.3800000Z | Z40: 112 | AB40: 2026-02-08T06:59:45.8830000Z | AC40: =LEFT(AB40,10) -> 2026-02-08 | AD40: 2026-01-27T13:34:45.6630000Z | AE40: 2026-01-27T13:34:45.6730000Z
...
