Workbook

Sheet Summary
A1: Old/New Student | B1: new | D1: Old/New Student | E1: new | G1: Old/New Student | H1: old | J1: Old/New Student | K1: old
A2: Parent Department Name | B2: BS | D2: Parent Department Name | E2: MS | G2: Parent Department Name | H2: BS | J2: Parent Department Name | K2: MS
A4: Course Name | B4: Student Count | D4: Course Name | E4: Student Count | G4: Course Name | H4: Student Count | J4: Course Name | K4: Student Count
A5: Computer Programming | B5: 109 | D5: Data Pre-processing (MSc) | E5: 356 | G5: Computer Programming | H5: 62 | J5: Artificial Neural Networks | K5: 353
A6: >10 % progress | B6: 71 | D6: >10 % progress | E6: 278 | G6: >10 % progress | H6: 17 | J6: >10 % progress | K6: 186
A7: 0 % progress | B7: 12 | D7: 0 % progress | E7: 39 | G7: 0 % progress | H7: 27 | J7: 0 % progress | K7: 44
A8: 0-10 % progress | B8: 26 | D8: 0-10 % progress | E8: 39 | G8: 0-10 % progress | H8: 18 | J8: 0-10 % progress | K8: 123
A9: Computing Systems | B9: 109 | D9: Data Visualization & Storytelling | E9: 356 | G9: Computing Systems | H9: 84 | J9: Cloud Services & Platforms | K9: 357
A10: >10 % progress | B10: 60 | D10: >10 % progress | E10: 271 | G10: >10 % progress | H10: 20 | J10: >10 % progress | K10: 192
A11: 0 % progress | B11: 17 | D11: 0 % progress | E11: 30 | G11: 0 % progress | H11: 27 | J11: 0 % progress | K11: 46
A12: 0-10 % progress | B12: 32 | D12: 0-10 % progress | E12: 55 | G12: 0-10 % progress | H12: 37 | J12: 0-10 % progress | K12: 119
A13: Data and the World | B13: 109 | D13: Feature Engineering | E13: 356 | G13: Data and the World | H13: 51 | J13: Data Pre-processing (MSc) | K13: 35
A14: >10 % progress | B14: 62 | D14: >10 % progress | E14: 157 | G14: >10 % progress | H14: 7 | J14: >10 % progress | K14: 7
A15: 0 % progress | B15: 26 | D15: 0 % progress | E15: 158 | G15: 0 % progress | H15: 33 | J15: 0 % progress | K15: 21
A16: 0-10 % progress | B16: 21 | D16: 0-10 % progress | E16: 41 | G16: 0-10 % progress | H16: 11 | J16: 0-10 % progress | K16: 7
... A21: Writing Practice | B21: 109 | D21: Grand Total | E21: 1424 | G21: Data Structures for Data Science | H21: 161 | J21: Data Visualization & Storytelling | K21: 36
A22: >10 % progress | B22: 53 | G22: >10 % progress | H22: 72 | J22: >10 % progress | K22: 8
A23: 0 % progress | B23: 19 | G23: 0 % progress | H23: 32 | J23: 0 % progress | K23: 14
A24: 0-10 % progress | B24: 37 | G24: 0-10 % progress | H24: 57 | J24: 0-10 % progress | K24: 14
A25: Grand Total | B25: 545 | G25: Fundamentals of Data Science and Engineering | H25: 178 | J25: Feature Engineering | K25: 35
G26: >10 % progress | H26: 105 | J26: >10 % progress | K26: 5
G27: 0 % progress | H27: 21 | J27: 0 % progress | K27: 25
G28: 0-10 % progress | H28: 52 | J28: 0-10 % progress | K28: 5
G29: Linear Algebra | H29: 190 | J29: Machine Learning | K29: 351
G30: >10 % progress | H30: 88 | J30: >10 % progress | K30: 190
G31: 0 % progress | H31: 37 | J31: 0 % progress | K31: 43
G32: 0-10 % progress | H32: 65 | J32: 0-10 % progress | K32: 118
G33: Probability & Statistics | H33: 69 | J33: Statistical Modelling & Inferencing | K33: 41
G34: >10 % progress | H34: 14 | J34: >10 % progress | K34: 7
G35: 0 % progress | H35: 32 | J35: 0 % progress | K35: 10
G36: 0-10 % progress | H36: 23 | J36: 0-10 % progress | K36: 24
G37: Writing Practice | H37: 25 | J37: Grand Total | K37: 1225
G38: >10 % progress | H38: 4
G39: 0 % progress | H39: 13
G40: 0-10 % progress | H40: 8
G41: Grand Total | H41: 976

Sheet Learners' Content Participation
A1: Course Offering Name | B1: (All) | D1: Until week 1, 2 | E1: 138
A2: Parent Department Name | B2: (All) | D2: present | E2: 78
A3: Old/New Student | B3: (All)
A5: Row Labels | B5: Total Courses (T2) | C5: Zero-Progress Courses (W1 2 3) | D5: Active Courses (W1,2,3)
A6: 2025eb1100001@bitspilani-digital.edu.in | B6: 5 | C6: 0 | D6: =B6-C6 -> 5
A7: 2025eb1100003@bitspilani-digital.edu.in | B7: 4 | C7: 0 | D7: =B7-C7 -> 4
A8: 2025eb1100004@bitspilani-digital.edu.in | B8: 4 | C8: 2 | D8: =B8-C8 -> 2
A9: 2025eb1100006@bitspilani-digital.edu.in | B9: 4 | C9: 1 | D9: =B9-C9 -> 3
A10: 2025eb1100007@bitspilani-digital.edu.in | B10: 4 | C10: 1 | D10: =B10-C10 -> 3
A11: 2025eb1100008@bitspilani-digital.edu.in | B11: 4 | C11: 2 | D11: =B11-C11 -> 2
A12: 2025eb1100009@bitspilani-digital.edu.in | B12: 5 | C12: 5 | D12: =B12-C12 -> 0
A13: 2025eb1100010@bitspilani-digital.edu.in | B13: 4 | C13: 1 | D13: =B13-C13 -> 3
A14: 2025eb1100012@bitspilani-digital.edu.in | B14: 2 | C14: 1 | D14: =B14-C14 -> 1
A15: 2025eb1100013@bitspilani-digital.edu.in | B15: 4 | C15: 4 | D15: =B15-C15 -> 0
A16: 2025eb1100014@bitspilani-digital.edu.in | B16: 2 | C16: 0 | D16: =B16-C16 -> 2
A17: 2025eb1100015@bitspilani-digital.edu.in | B17: 4 | C17: 0 | D17: =B17-C17 -> 4
... A1109: Grand Total | B1109: 4170 | C1109: 795 | D1109: =B1109-C1109 -> 3375
D1110: =B1110-C1110 -> 0
D1111: =B1111-C1111 -> 0
D1112: =B1112-C1112 -> 0
D1113: =B1113-C1113 -> 0
D1114: =B1114-C1114 -> 0

Sheet Learner Usage
A1: Course Offering Code | B1: Course Offering Name | C1: Parent Department Name | D1: Semester Name | E1: Username | F1: Username_for verification | G1: Org Defined Id | H1: Old/New Student | I1: First Name | J1: Is Active | K1: Content Completed | L1: Content Required W1,2,3 | M1: Usage% W1,2,3 | N1: W1,2,3 Active Flag | O1: Usage Category W1,2,3 | P1: Zero-Progress Flag | Q1: Total courses enrolled | R1: Learner with 0 participation | S1: Learner with 0 % participation | T1: Checklist Completed | U1: Quiz Completed | V1: Total Quiz Attempts | W1: Discussion Post Created | X1: Discussion Post Replies | Y1: Discussion Post Read | Z1: Last Discussion Post Date | AA1: Number Of Assignment Submissions | AB1: Last Assignment Submission Date | AC1: Total Time Spent In Content | AD1: Last Visited Date | AE1: Last System Login | AF1: Number Of Logins To The System | AG1: Auditor Name | AH1: Last Quiz Attempt Date | AI1: Last SCORM Completion Date | AJ1: Last SCORM Visit Date
A2: T2-25_BDSDF106 | B2: Data Structures for Data Science | C2: BS | D2: Trimester 2 | E2: 2025eb1100001@bitspilani-digital.edu.in | F2: =_xlfn.XLOOKUP(E2,Total_Enrolled!C:C,Total_Enrolled!C:C) -> 2025eb1100001@bitspilani-digital.edu.in | G2: 2025EB1100001 | H2: old | I2: RUDRA SHARMA | J2: TRUE | K2: 1 | L2: =_xlfn.XLOOKUP(B2,Courses!A:A,Courses!H:H) -> 93 | M2: =K2/L2 -> 0.010752688 | N2: =IF(M2>0,"Active","Not Active") -> Active | O2: {=_xlfn.IFS(M2=0,"0", M2<=10%,"0-10", TRUE,">10" )&" "&"% progress"} -> 0-10 % progress | P2: =IF(M2=0,1,0) -> 0 | Q2: =COUNTIFS($G:$G,$G2) -> 5 | R2: =P2/Q2 -> 0 | S2: =IF(R2=0, "no 0% progess", "no progress") -> no 0% progess | T2: 0 | U2: 1 | V2: 1 | W2: 0 | X2: 0 | Y2: 0 | AA2: 0 | AC2: 0 | AD2: 2026-02-08T09:13:59.9530000Z | AE2: 2026-02-08T08:54:36.2970000Z | AF2: 166 | AH2: 2026-02-08T09:04:03.4030000Z
A3: T2-25_BDSDF102 | B3: Data Preprocessing (BS) | C3: BS | D3: Trimester 2 | E3: 2025eb1100001@bitspilani-digital.edu.in | F3: =_xlfn.XLOOKUP(E3,Total_Enrolled!C:C,Total_Enrolled!C:C) -> 2025eb1100001@bitspilani-digital.edu.in | G3: 2025EB1100001 | H3: old | I3: RUDRA SHARMA | J3: TRUE | K3: 6 | L3: =_xlfn.XLOOKUP(B3,Courses!A:A,Courses!H:H) -> 84 | M3: =K3/L3 -> 0.071428571 | N3: =IF(M3>0,"Active","Not Active") -> Active | O3: {=_xlfn.IFS(M3=0,"0", M3<=10%,"0-10", TRUE,">10" )&" "&"% progress"} -> 0-10 % progress | P3: =IF(M3=0,1,0) -> 0 | Q3: =COUNTIFS($G:$G,$G3) -> 5 | R3: =P3/Q3 -> 0 | S3: =IF(R3=0, "no 0% progess", "no progress") -> no 0% progess | T3: 0 | U3: 2 | V3: 3 | W3: 0 | X3: 0 | Y3: 0 | AA3: 0 | AC3: 17096 | AD3: 2026-02-08T09:20:40.1530000Z | AE3: 2026-02-08T08:54:36.2970000Z | AF3: 166 | AH3: 2026-02-08T09:20:32.9730000Z
A4: T2-25_BDSDF107 | B4: Fundamentals of Data Science and Engineering | C4: BS | D4: Trimester 2 | E4: 2025eb1100001@bitspilani-digital.edu.in | F4: =_xlfn.XLOOKUP(E4,Total_Enrolled!C:C,Total_Enrolled!C:C) -> 2025eb1100001@bitspilani-digital.edu.in | G4: 2025EB1100001 | H4: old | I4: RUDRA SHARMA | J4: TRUE | K4: 45 | L4: =_xlfn.XLOOKUP(B4,Courses!A:A,Courses!H:H) -> 41 | M4: =K4/L4 -> 1.097561 | N4: =IF(M4>0,"Active","Not Active") -> Active | O4: {=_xlfn.IFS(M4=0,"0", M4<=10%,"0-10", TRUE,">10" )&" "&"% progress"} -> >10 % progress | P4: =IF(M4=0,1,0) -> 0 | Q4: =COUNTIFS($G:$G,$G4) -> 5 | R4: =P4/Q4 -> 0 | S4: =IF(R4=0, "no 0% progess", "no progress") -> no 0% progess | T4: 0 | U4: 7 | V4: 8 | W4: 0 | X4: 0 | Y4: 0 | AA4: 0 | AC4: 31534 | AD4: 2026-02-07T15:33:47.5000000Z | AE4: 2026-02-08T08:54:36.2970000Z | AF4: 166 | AH4: 2026-02-07T15:16:25.5370000Z
A5: T2-25_BDSDF110 | B5: Linear Algebra | C5: BS | D5: Trimester 2 | E5: 2025eb1100001@bitspilani-digital.edu.in | F5: =_xlfn.XLOOKUP(E5,Total_Enrolled!C:C,Total_Enrolled!C:C) -> 2025eb1100001@bitspilani-digital.edu.in | G5: 2025EB1100001 | H5: old | I5: RUDRA SHARMA | J5: TRUE | K5: 3 | L5: =_xlfn.XLOOKUP(B5,Courses!A:A,Courses!H:H) -> 46 | M5: =K5/L5 -> 0.065217391 | N5: =IF(M5>0,"Active","Not Active") -> Active | O5: {=_xlfn.IFS(M5=0,"0", M5<=10%,"0-10", TRUE,">10" )&" "&"% progress"} -> 0-10 % progress | P5: =IF(M5=0,1,0) -> 0 | Q5: =COUNTIFS($G:$G,$G5) -> 5 | R5: =P5/Q5 -> 0 | S5: =IF(R5=0, "no 0% progess", "no progress") -> no 0% progess | T5: 0 | U5: 1 | V5: 1 | W5: 0 | X5: 0 | Y5: 0 | AA5: 0 | AC5: 27 | AD5: 2026-02-08T09:12:57.6770000Z | AE5: 2026-02-08T08:54:36.2970000Z | AF5: 166 | AH5: 2026-02-08T09:12:53.8070000Z | AI5: 2026-01-23T15:01:45.2470000Z | AJ5: 2026-01-23T15:01:48.8770000Z
A6: T2-25_BDSDF108 | B6: Computing Systems | C6: BS | D6: Trimester 2 | E6: 2025eb1100001@bitspilani-digital.edu.in | F6: =_xlfn.XLOOKUP(E6,Total_Enrolled!C:C,Total_Enrolled!C:C) -> 2025eb1100001@bitspilani-digital.edu.in | G6: 2025EB1100001 | H6: old | I6: RUDRA SHARMA | J6: TRUE | K6: 92 | L6: =_xlfn.XLOOKUP(B6,Courses!A:A,Courses!H:H) -> 88 | M6: =K6/L6 -> 1.0454545 | N6: =IF(M6>0,"Active","Not Active") -> Active | O6: {=_xlfn.IFS(M6=0,"0", M6<=10%,"0-10", TRUE,">10" )&" "&"% progress"} -> >10 % progress | P6: =IF(M6=0,1,0) -> 0 | Q6: =COUNTIFS($G:$G,$G6) -> 5 | R6: =P6/Q6 -> 0 | S6: =IF(R6=0, "no 0% progess", "no progress") -> no 0% progess | T6: 0 | U6: 34 | V6: 56 | W6: 0 | X6: 0 | Y6: 0 | AA6: 0 | AC6: 1027 | AD6: 2026-02-08T08:57:34.8130000Z | AE6: 2026-02-08T08:54:36.2970000Z | AF6: 166 | AH6: 2026-02-08T08:57:30.2130000Z | AI6: 2026-01-23T14:59:58.6570000Z | AJ6: 2026-01-23T15:00:20.6770000Z
A7: T2-25_BDSDF114 | B7: Probability & Statistics | C7: BS | D7: Trimester 2 | E7: 2025eb1100003@bitspilani-digital.edu.in | F7: =_xlfn.XLOOKUP(E7,Total_Enrolled!C:C,Total_Enrolled!C:C) -> 2025eb1100003@bitspilani-digital.edu.in | G7: 2025EB1100003 | H7: old | I7: AJAYACHANDRAN.E | J7: TRUE | K7: 24 | L7: =_xlfn.XLOOKUP(B7,Courses!A:A,Courses!H:H) -> 61 | M7: =K7/L7 -> 0.39344262 | N7: =IF(M7>0,"Active","Not Active") -> Active | O7: {=_xlfn.IFS(M7=0,"0", M7<=10%,"0-10", TRUE,">10" )&" "&"% progress"} -> >10 % progress | P7: =IF(M7=0,1,0) -> 0 | Q7: =COUNTIFS($G:$G,$G7) -> 4 | R7: =P7/Q7 -> 0 | S7: =IF(R7=0, "no 0% progess", "no progress") -> no 0% progess | T7: 0 | U7: 3 | V7: 5 | W7: 2 | X7: 0 | Y7: 8 | Z7: 2026-01-30T21:48:45.6800000Z | AA7: 0 | AC7: 31222 | AD7: 2026-02-09T00:39:23.1430000Z | AE7: 2026-02-08T23:02:38.0030000Z | AF7: 115 | AH7: 2026-01-31T00:24:37.8630000Z | AI7: 2026-01-24T14:45:28.7000000Z | AJ7: 2026-01-31T00:25:02.4370000Z
A8: T2-25_BDSDF113 | B8: Computer Programming | C8: BS | D8: Trimester 2 | E8: 2025eb1100003@bitspilani-digital.edu.in | F8: =_xlfn.XLOOKUP(E8,Total_Enrolled!C:C,Total_Enrolled!C:C) -> 2025eb1100003@bitspilani-digital.edu.in | G8: 2025EB1100003 | H8: old | I8: AJAYACHANDRAN.E | J8: TRUE | K8: 44 | L8: =_xlfn.XLOOKUP(B8,Courses!A:A,Courses!H:H) -> 86 | M8: =K8/L8 -> 0.51162791 | N8: =IF(M8>0,"Active","Not Active") -> Active | O8: {=_xlfn.IFS(M8=0,"0", M8<=10%,"0-10", TRUE,">10" )&" "&"% progress"} -> >10 % progress | P8: =IF(M8=0,1,0) -> 0 | Q8: =COUNTIFS($G:$G,$G8) -> 4 | R8: =P8/Q8 -> 0 | S8: =IF(R8=0, "no 0% progess", "no progress") -> no 0% progess | T8: 0 | U8: 9 | V8: 18 | W8: 3 | X8: 0 | Y8: 1 | Z8: 2026-01-31T00:29:49.2300000Z | AA8: 0 | AC8: 49579 | AD8: 2026-02-09T00:39:46.6630000Z | AE8: 2026-02-08T23:02:38.0030000Z | AF8: 115 | AH8: 2026-01-31T23:46:19.5000000Z | AI8: 2026-01-31T12:03:07.5170000Z | AJ8: 2026-01-31T23:46:46.3370000Z
A9: T2-25_BDSDF107 | B9: Fundamentals of Data Science and Engineering | C9: BS | D9: Trimester 2 | E9: 2025eb1100003@bitspilani-digital.edu.in | F9: =_xlfn.XLOOKUP(E9,Total_Enrolled!C:C,Total_Enrolled!C:C) -> 2025eb1100003@bitspilani-digital.edu.in | G9: 2025EB1100003 | H9: old | I9: AJAYACHANDRAN.E | J9: TRUE | K9: 27 | L9: =_xlfn.XLOOKUP(B9,Courses!A:A,Courses!H:H) -> 41 | M9: =K9/L9 -> 0.65853659 | N9: =IF(M9>0,"Active","Not Active") -> Active | O9: {=_xlfn.IFS(M9=0,"0", M9<=10%,"0-10", TRUE,">10" )&" "&"% progress"} -> >10 % progress | P9: =IF(M9=0,1,0) -> 0 | Q9: =COUNTIFS($G:$G,$G9) -> 4 | R9: =P9/Q9 -> 0 | S9: =IF(R9=0, "no 0% progess", "no progress") -> no 0% progess | T9: 0 | U9: 3 | V9: 6 | W9: 0 | X9: 0 | Y9: 0 | AA9: 0 | AC9: 25900 | AD9: 2026-02-09T00:37:32.1300000Z | AE9: 2026-02-08T23:02:38.0030000Z | AF9: 115 | AH9: 2026-01-30T20:33:35.5230000Z
A10: T2-25_BDSDF102 | B10: Data Preprocessing (BS) | C10: BS | D10: Trimester 2 | E10: 2025eb1100003@bitspilani-digital.edu.in | F10: =_xlfn.XLOOKUP(E10,Total_Enrolled!C:C,Total_Enrolled!C:C) -> 2025eb1100003@bitspilani-digital.edu.in | G10: 2025EB1100003 | H10: old | I10: AJAYACHANDRAN.E | J10: TRUE | K10: 45 | L10: =_xlfn.XLOOKUP(B10,Courses!A:A,Courses!H:H) -> 84 | M10: =K10/L10 -> 0.53571429 | N10: =IF(M10>0,"Active","Not Active") -> Active | O10: {=_xlfn.IFS(M10=0,"0", M10<=10%,"0-10", TRUE,">10" )&" "&"% progress"} -> >10 % progress | P10: =IF(M10=0,1,0) -> 0 | Q10: =COUNTIFS($G:$G,$G10) -> 4 | R10: =P10/Q10 -> 0 | S10: =IF(R10=0, "no 0% progess", "no progress") -> no 0% progess | T10: 0 | U10: 6 | V10: 8 | W10: 3 | X10: 0 | Y10: 0 | Z10: 2026-02-07T23:08:17.5300000Z | AA10: 0 | AC10: 24234 | AD10: 2026-02-09T00:32:41.3400000Z | AE10: 2026-02-08T23:02:38.0030000Z | AF10: 115 | AH10: 2026-02-09T00:31:45.6730000Z
A11: T2-25_BDSDF102 | B11: Data Preprocessing (BS) | C11: BS | D11: Trimester 2 | E11: 2025eb1100004@bitspilani-digital.edu.in | F11: =_xlfn.XLOOKUP(E11,Total_Enrolled!C:C,Total_Enrolled!C:C) -> 2025eb1100004@bitspilani-digital.edu.in | G11: 2025EB1100004 | H11: old | I11: ARUNLAL P | J11: TRUE | K11: 1 | L11: =_xlfn.XLOOKUP(B11,Courses!A:A,Courses!H:H) -> 84 | M11: =K11/L11 -> 0.011904762 | N11: =IF(M11>0,"Active","Not Active") -> Active | O11: {=_xlfn.IFS(M11=0,"0", M11<=10%,"0-10", TRUE,">10" )&" "&"% progress"} -> 0-10 % progress | P11: =IF(M11=0,1,0) -> 0 | Q11: =COUNTIFS($G:$G,$G11) -> 4 | R11: =P11/Q11 -> 0 | S11: =IF(R11=0, "no 0% progess", "no progress") -> no 0% progess | T11: 0 | U11: 0 | V11: 0 | W11: 0 | X11: 0 | Y11: 0 | AA11: 0 | AC11: 0 | AD11: 2026-01-19T08:25:52.9870000Z | AE11: 2026-02-08T15:52:25.5800000Z | AF11: 151
A12: T2-25_BDSDF106 | B12: Data Structures for Data Science | C12: BS | D12: Trimester 2 | E12: 2025eb1100004@bitspilani-digital.edu.in | F12: =_xlfn.XLOOKUP(E12,Total_Enrolled!C:C,Total_Enrolled!C:C) -> 2025eb1100004@bitspilani-digital.edu.in | G12: 2025EB1100004 | H12: old | I12: ARUNLAL P | J12: TRUE | K12: 0 | L12: =_xlfn.XLOOKUP(B12,Courses!A:A,Courses!H:H) -> 93 | M12: =K12/L12 -> 0 | N12: =IF(M12>0,"Active","Not Active") -> Not Active | O12: {=_xlfn.IFS(M12=0,"0", M12<=10%,"0-10", TRUE,">10" )&" "&"% progress"} -> 0 % progress | P12: =IF(M12=0,1,0) -> 1 | Q12: =COUNTIFS($G:$G,$G12) -> 4 | R12: =P12/Q12 -> 0.25 | S12: =IF(R12=0, "no 0% progess", "no progress") -> no progress | T12: 0 | U12: 0 | V12: 0 | W12: 0 | X12: 0 | Y12: 0 | AA12: 0 | AC12: 0 | AD12: 2026-01-17T14:38:56.5370000Z | AE12: 2026-02-08T15:52:25.5800000Z | AF12: 151
A13: T2-25_BDSDF107 | B13: Fundamentals of Data Science and Engineering | C13: BS | D13: Trimester 2 | E13: 2025eb1100004@bitspilani-digital.edu.in | F13: =_xlfn.XLOOKUP(E13,Total_Enrolled!C:C,Total_Enrolled!C:C) -> 2025eb1100004@bitspilani-digital.edu.in | G13: 2025EB1100004 | H13: old | I13: ARUNLAL P | J13: TRUE | K13: 1 | L13: =_xlfn.XLOOKUP(B13,Courses!A:A,Courses!H:H) -> 41 | M13: =K13/L13 -> 0.024390244 | N13: =IF(M13>0,"Active","Not Active") -> Active | O13: {=_xlfn.IFS(M13=0,"0", M13<=10%,"0-10", TRUE,">10" )&" "&"% progress"} -> 0-10 % progress | P13: =IF(M13=0,1,0) -> 0 | Q13: =COUNTIFS($G:$G,$G13) -> 4 | R13: =P13/Q13 -> 0 | S13: =IF(R13=0, "no 0% progess", "no progress") -> no 0% progess | T13: 0 | U13: 1 | V13: 1 | W13: 0 | X13: 0 | Y13: 0 | AA13: 0 | AC13: 0 | AD13: 2026-02-08T15:58:42.1600000Z | AE13: 2026-02-08T15:52:25.5800000Z | AF13: 151 | AH13: 2026-02-08T15:58:35.0330000Z
A14: T2-25_BDSDF110 | B14: Linear Algebra | C14: BS | D14: Trimester 2 | E14: 2025eb1100004@bitspilani-digital.edu.in | F14: =_xlfn.XLOOKUP(E14,Total_Enrolled!C:C,Total_Enrolled!C:C) -> 2025eb1100004@bitspilani-digital.edu.in | G14: 2025EB1100004 | H14: old | I14: ARUNLAL P | J14: TRUE | K14: 0 | L14: =_xlfn.XLOOKUP(B14,Courses!A:A,Courses!H:H) -> 46 | M14: =K14/L14 -> 0 | N14: =IF(M14>0,"Active","Not Active") -> Not Active | O14: {=_xlfn.IFS(M14=0,"0", M14<=10%,"0-10", TRUE,">10" )&" "&"% progress"} -> 0 % progress | P14: =IF(M14=0,1,0) -> 1 | Q14: =COUNTIFS($G:$G,$G14) -> 4 | R14: =P14/Q14 -> 0.25 | S14: =IF(R14=0, "no 0% progess", "no progress") -> no progress | T14: 0 | U14: 0 | V14: 0 | W14: 0 | X14: 0 | Y14: 0 | AA14: 0 | AC14: 0 | AE14: 2026-02-08T15:52:25.5800000Z | AF14: 151
A15: T2-25_BDSDF110 | B15: Linear Algebra | C15: BS | D15: Trimester 2 | E15: 2025eb1100006@bitspilani-digital.edu.in | F15: =_xlfn.XLOOKUP(E15,Total_Enrolled!C:C,Total_Enrolled!C:C) -> 2025eb1100006@bitspilani-digital.edu.in | G15: 2025EB1100006 | H15: old | I15: JAL PATEL | J15: TRUE | K15: 1 | L15: =_xlfn.XLOOKUP(B15,Courses!A:A,Courses!H:H) -> 46 | M15: =K15/L15 -> 0.02173913 | N15: =IF(M15>0,"Active","Not Active") -> Active | O15: {=_xlfn.IFS(M15=0,"0", M15<=10%,"0-10", TRUE,">10" )&" "&"% progress"} -> 0-10 % progress | P15: =IF(M15=0,1,0) -> 0 | Q15: =COUNTIFS($G:$G,$G15) -> 4 | R15: =P15/Q15 -> 0 | S15: =IF(R15=0, "no 0% progess", "no progress") -> no 0% progess | T15: 0 | U15: 1 | V15: 1 | W15: 0 | X15: 0 | Y15: 0 | AA15: 0 | AC15: 0 | AD15: 2026-02-08T08:16:42.7600000Z | AE15: 2026-02-08T07:51:39.3430000Z | AF15: 73 | AH15: 2026-02-08T08:12:38.5830000Z
A16: T2-25_BDSDF107 | B16: Fundamentals of Data Science and Engineering | C16: BS | D16: Trimester 2 | E16: 2025eb1100006@bitspilani-digital.edu.in | F16: =_xlfn.XLOOKUP(E16,Total_Enrolled!C:C,Total_Enrolled!C:C) -> 2025eb1100006@bitspilani-digital.edu.in | G16: 2025EB1100006 | H16: old | I16: JAL PATEL | J16: TRUE | K16: 2 | L16: =_xlfn.XLOOKUP(B16,Courses!A:A,Courses!H:H) -> 41 | M16: =K16/L16 -> 0.048780488 | N16: =IF(M16>0,"Active","Not Active") -> Active | O16: {=_xlfn.IFS(M16=0,"0", M16<=10%,"0-10", TRUE,">10" )&" "&"% progress"} -> 0-10 % progress | P16: =IF(M16=0,1,0) -> 0 | Q16: =COUNTIFS($G:$G,$G16) -> 4 | R16: =P16/Q16 -> 0 | S16: =IF(R16=0, "no 0% progess", "no progress") -> no 0% progess | T16: 0 | U16: 2 | V16: 2 | W16: 0 | X16: 0 | Y16: 0 | AA16: 0 | AC16: 0 | AD16: 2026-02-08T08:17:07.8730000Z | AE16: 2026-02-08T07:51:39.3430000Z | AF16: 73 | AH16: 2026-02-08T08:02:33.4500000Z
A17: T2-25_BDSDF106 | B17: Data Structures for Data Science | C17: BS | D17: Trimester 2 | E17: 2025eb1100006@bitspilani-digital.edu.in | F17: =_xlfn.XLOOKUP(E17,Total_Enrolled!C:C,Total_Enrolled!C:C) -> 2025eb1100006@bitspilani-digital.edu.in | G17: 2025EB1100006 | H17: old | I17: JAL PATEL | J17: TRUE | K17: 1 | L17: =_xlfn.XLOOKUP(B17,Courses!A:A,Courses!H:H) -> 93 | M17: =K17/L17 -> 0.010752688 | N17: =IF(M17>0,"Active","Not Active") -> Active | O17: {=_xlfn.IFS(M17=0,"0", M17<=10%,"0-10", TRUE,">10" )&" "&"% progress"} -> 0-10 % progress | P17: =IF(M17=0,1,0) -> 0 | Q17: =COUNTIFS($G:$G,$G17) -> 4 | R17: =P17/Q17 -> 0 | S17: =IF(R17=0, "no 0% progess", "no progress") -> no 0% progess | T17: 0 | U17: 1 | V17: 1 | W17: 0 | X17: 0 | Y17: 0 | AA17: 0 | AC17: 0 | AD17: 2026-02-08T08:17:33.9070000Z | AE17: 2026-02-08T07:51:39.3430000Z | AF17: 73 | AH17: 2026-02-08T08:15:45.7230000Z
A18: T2-25_BDSDF102 | B18: Data Preprocessing (BS) | C18: BS | D18: Trimester 2 | E18: 2025eb1100006@bitspilani-digital.edu.in | F18: =_xlfn.XLOOKUP(E18,Total_Enrolled!C:C,Total_Enrolled!C:C) -> 2025eb1100006@bitspilani-digital.edu.in | G18: 2025EB1100006 | H18: old | I18: JAL PATEL | J18: TRUE | K18: 0 | L18: =_xlfn.XLOOKUP(B18,Courses!A:A,Courses!H:H) -> 84 | M18: =K18/L18 -> 0 | N18: =IF(M18>0,"Active","Not Active") -> Not Active | O18: {=_xlfn.IFS(M18=0,"0", M18<=10%,"0-10", TRUE,">10" )&" "&"% progress"} -> 0 % progress | P18: =IF(M18=0,1,0) -> 1 | Q18: =COUNTIFS($G:$G,$G18) -> 4 | R18: =P18/Q18 -> 0.25 | S18: =IF(R18=0, "no 0% progess", "no progress") -> no progress | T18: 0 | U18: 0 | V18: 0 | W18: 0 | X18: 0 | Y18: 0 | AA18: 0 | AC18: 0 | AD18: 2026-02-08T08:16:57.8270000Z | AE18: 2026-02-08T07:51:39.3430000Z | AF18: 73
A19: T2-25_BDSDF113 | B19: Computer Programming | C19: BS | D19: Trimester 2 | E19: 2025eb1100007@bitspilani-digital.edu.in | F19: =_xlfn.XLOOKUP(E19,Total_Enrolled!C:C,Total_Enrolled!C:C) -> 2025eb1100007@bitspilani-digital.edu.in | G19: 2025EB1100007 | H19: old | I19: HARSHVARDHAN SINGH | J19: TRUE | K19: 10 | L19: =_xlfn.XLOOKUP(B19,Courses!A:A,Courses!H:H) -> 86 | M19: =K19/L19 -> 0.11627907 | N19: =IF(M19>0,"Active","Not Active") -> Active | O19: {=_xlfn.IFS(M19=0,"0", M19<=10%,"0-10", TRUE,">10" )&" "&"% progress"} -> >10 % progress | P19: =IF(M19=0,1,0) -> 0 | Q19: =COUNTIFS($G:$G,$G19) -> 4 | R19: =P19/Q19 -> 0 | S19: =IF(R19=0, "no 0% progess", "no progress") -> no 0% progess | T19: 0 | U19: 4 | V19: 4 | W19: 0 | X19: 0 | Y19: 0 | AA19: 0 | AC19: 24662 | AD19: 2026-02-08T02:54:21.2930000Z | AE19: 2026-02-09T00:57:34.8670000Z | AF19: 67 | AH19: 2026-02-08T02:54:12.8470000Z | AI19: 2026-01-30T14:05:06.5370000Z | AJ19: 2026-02-05T07:23:03.0770000Z
A20: T2-25_BDSDF114 | B20: Probability & Statistics | C20: BS | D20: Trimester 2 | E20: 2025eb1100007@bitspilani-digital.edu.in | F20: =_xlfn.XLOOKUP(E20,Total_Enrolled!C:C,Total_Enrolled!C:C) -> 2025eb1100007@bitspilani-digital.edu.in | G20: 2025EB1100007 | H20: old | I20: HARSHVARDHAN SINGH | J20: TRUE | K20: 1 | L20: =_xlfn.XLOOKUP(B20,Courses!A:A,Courses!H:H) -> 61 | M20: =K20/L20 -> 0.016393443 | N20: =IF(M20>0,"Active","Not Active") -> Active | O20: {=_xlfn.IFS(M20=0,"0", M20<=10%,"0-10", TRUE,">10" )&" "&"% progress"} -> 0-10 % progress | P20: =IF(M20=0,1,0) -> 0 | Q20: =COUNTIFS($G:$G,$G20) -> 4 | R20: =P20/Q20 -> 0 | S20: =IF(R20=0, "no 0% progess", "no progress") -> no 0% progess | T20: 0 | U20: 1 | V20: 1 | W20: 0 | X20: 0 | Y20: 0 | AA20: 0 | AC20: 0 | AD20: 2026-02-08T02:56:47.4770000Z | AE20: 2026-02-09T00:57:34.8670000Z | AF20: 67 | AH20: 2026-02-08T02:56:43.8530000Z
A21: T2-25_BDSDF108 | B21: Computing Systems | C21: BS | D21: Trimester 2 | E21: 2025eb1100007@bitspilani-digital.edu.in | F21: =_xlfn.XLOOKUP(E21,Total_Enrolled!C:C,Total_Enrolled!C:C) -> 2025eb1100007@bitspilani-digital.edu.in | G21: 2025EB1100007 | H21: old | I21: HARSHVARDHAN SINGH | J21: TRUE | K21: 1 | L21: =_xlfn.XLOOKUP(B21,Courses!A:A,Courses!H:H) -> 88 | M21: =K21/L21 -> 0.011363636 | N21: =IF(M21>0,"Active","Not Active") -> Active | O21: {=_xlfn.IFS(M21=0,"0", M21<=10%,"0-10", TRUE,">10" )&" "&"% progress"} -> 0-10 % progress | P21: =IF(M21=0,1,0) -> 0 | Q21: =COUNTIFS($G:$G,$G21) -> 4 | R21: =P21/Q21 -> 0 | S21: =IF(R21=0, "no 0% progess", "no progress") -> no 0% progess | T21: 0 | U21: 1 | V21: 1 | W21: 0 | X21: 0 | Y21: 0 | AA21: 0 | AC21: 0 | AD21: 2026-02-08T03:02:53.3470000Z | AE21: 2026-02-09T00:57:34.8670000Z | AF21: 67 | AH21: 2026-02-08T03:02:49.6200000Z
A22: T2-25_BDSDF101 | B22: Data and the World | C22: BS | D22: Trimester 2 | E22: 2025eb1100007@bitspilani-digital.edu.in | F22: =_xlfn.XLOOKUP(E22,Total_Enrolled!C:C,Total_Enrolled!C:C) -> 2025eb1100007@bitspilani-digital.edu.in | G22: 2025EB1100007 | H22: old | I22: HARSHVARDHAN SINGH | J22: TRUE | K22: 0 | L22: =_xlfn.XLOOKUP(B22,Courses!A:A,Courses!H:H) -> 41 | M22: =K22/L22 -> 0 | N22: =IF(M22>0,"Active","Not Active") -> Not Active | O22: {=_xlfn.IFS(M22=0,"0", M22<=10%,"0-10", TRUE,">10" )&" "&"% progress"} -> 0 % progress | P22: =IF(M22=0,1,0) -> 1 | Q22: =COUNTIFS($G:$G,$G22) -> 4 | R22: =P22/Q22 -> 0.25 | S22: =IF(R22=0, "no 0% progess", "no progress") -> no progress | T22: 0 | U22: 0 | V22: 0 | W22: 0 | X22: 0 | Y22: 0 | AA22: 0 | AC22: 0 | AE22: 2026-02-09T00:57:34.8670000Z | AF22: 67
A23: T2-25_BDSDF102 | B23: Data Preprocessing (BS) | C23: BS | D23: Trimester 2 | E23: 2025eb1100008@bitspilani-digital.edu.in | F23: =_xlfn.XLOOKUP(E23,Total_Enrolled!C:C,Total_Enrolled!C:C) -> 2025eb1100008@bitspilani-digital.edu.in | G23: 2025EB1100008 | H23: old | I23: KALYANE VENKATESH NISHIKANT | J23: TRUE | K23: 4 | L23: =_xlfn.XLOOKUP(B23,Courses!A:A,Courses!H:H) -> 84 | M23: =K23/L23 -> 0.047619048 | N23: =IF(M23>0,"Active","Not Active") -> Active | O23: {=_xlfn.IFS(M23=0,"0", M23<=10%,"0-10", TRUE,">10" )&" "&"% progress"} -> 0-10 % progress | P23: =IF(M23=0,1,0) -> 0 | Q23: =COUNTIFS($G:$G,$G23) -> 4 | R23: =P23/Q23 -> 0 | S23: =IF(R23=0, "no 0% progess", "no progress") -> no 0% progess | T23: 0 | U23: 0 | V23: 0 | W23: 0 | X23: 0 | Y23: 0 | AA23: 0 | AC23: 6800 | AD23: 2026-02-07T15:35:16.0400000Z | AE23: 2026-02-07T15:26:57.4830000Z | AF23: 107
A24: T2-25_BDSDF106 | B24: Data Structures for Data Science | C24: BS | D24: Trimester 2 | E24: 2025eb1100008@bitspilani-digital.edu.in | F24: =_xlfn.XLOOKUP(E24,Total_Enrolled!C:C,Total_Enrolled!C:C) -> 2025eb1100008@bitspilani-digital.edu.in | G24: 2025EB1100008 | H24: old | I24: KALYANE VENKATESH NISHIKANT | J24: TRUE | K24: 0 | L24: =_xlfn.XLOOKUP(B24,Courses!A:A,Courses!H:H) -> 93 | M24: =K24/L24 -> 0 | N24: =IF(M24>0,"Active","Not Active") -> Not Active | O24: {=_xlfn.IFS(M24=0,"0", M24<=10%,"0-10", TRUE,">10" )&" "&"% progress"} -> 0 % progress | P24: =IF(M24=0,1,0) -> 1 | Q24: =COUNTIFS($G:$G,$G24) -> 4 | R24: =P24/Q24 -> 0.25 | S24: =IF(R24=0, "no 0% progess", "no progress") -> no progress | T24: 0 | U24: 0 | V24: 0 | W24: 0 | X24: 0 | Y24: 0 | AA24: 0 | AC24: 0 | AE24: 2026-02-07T15:26:57.4830000Z | AF24: 107
A25: T2-25_BDSDF107 | B25: Fundamentals of Data Science and Engineering | C25: BS | D25: Trimester 2 | E25: 2025eb1100008@bitspilani-digital.edu.in | F25: =_xlfn.XLOOKUP(E25,Total_Enrolled!C:C,Total_Enrolled!C:C) -> 2025eb1100008@bitspilani-digital.edu.in | G25: 2025EB1100008 | H25: old | I25: KALYANE VENKATESH NISHIKANT | J25: TRUE | K25: 5 | L25: =_xlfn.XLOOKUP(B25,Courses!A:A,Courses!H:H) -> 41 | M25: =K25/L25 -> 0.12195122 | N25: =IF(M25>0,"Active","Not Active") -> Active | O25: {=_xlfn.IFS(M25=0,"0", M25<=10%,"0-10", TRUE,">10" )&" "&"% progress"} -> >10 % progress | P25: =IF(M25=0,1,0) -> 0 | Q25: =COUNTIFS($G:$G,$G25) -> 4 | R25: =P25/Q25 -> 0 | S25: =IF(R25=0, "no 0% progess", "no progress") -> no 0% progess | T25: 0 | U25: 1 | V25: 1 | W25: 0 | X25: 0 | Y25: 0 | AA25: 0 | AC25: 3889 | AD25: 2026-02-07T15:34:29.9030000Z | AE25: 2026-02-07T15:26:57.4830000Z | AF25: 107 | AH25: 2026-02-07T15:34:10.0200000Z
A26: T2-25_BDSDF110 | B26: Linear Algebra | C26: BS | D26: Trimester 2 | E26: 2025eb1100008@bitspilani-digital.edu.in | F26: =_xlfn.XLOOKUP(E26,Total_Enrolled!C:C,Total_Enrolled!C:C) -> 2025eb1100008@bitspilani-digital.edu.in | G26: 2025EB1100008 | H26: old | I26: KALYANE VENKATESH NISHIKANT | J26: TRUE | K26: 0 | L26: =_xlfn.XLOOKUP(B26,Courses!A:A,Courses!H:H) -> 46 | M26: =K26/L26 -> 0 | N26: =IF(M26>0,"Active","Not Active") -> Not Active | O26: {=_xlfn.IFS(M26=0,"0", M26<=10%,"0-10", TRUE,">10" )&" "&"% progress"} -> 0 % progress | P26: =IF(M26=0,1,0) -> 1 | Q26: =COUNTIFS($G:$G,$G26) -> 4 | R26: =P26/Q26 -> 0.25 | S26: =IF(R26=0, "no 0% progess", "no progress") -> no progress | T26: 0 | U26: 0 | V26: 0 | W26: 0 | X26: 0 | Y26: 0 | AA26: 0 | AC26: 0 | AE26: 2026-02-07T15:26:57.4830000Z | AF26: 107
A27: T2-25_BDSDF101 | B27: Data and the World | C27: BS | D27: Trimester 2 | E27: 2025eb1100009@bitspilani-digital.edu.in | F27: =_xlfn.XLOOKUP(E27,Total_Enrolled!C:C,Total_Enrolled!C:C) -> 2025eb1100009@bitspilani-digital.edu.in | G27: 2025EB1100009 | H27: old | I27: ALI ZAFAR RIZVI | J27: TRUE | K27: 0 | L27: =_xlfn.XLOOKUP(B27,Courses!A:A,Courses!H:H) -> 41 | M27: =K27/L27 -> 0 | N27: =IF(M27>0,"Active","Not Active") -> Not Active | O27: {=_xlfn.IFS(M27=0,"0", M27<=10%,"0-10", TRUE,">10" )&" "&"% progress"} -> 0 % progress | P27: =IF(M27=0,1,0) -> 1 | Q27: =COUNTIFS($G:$G,$G27) -> 5 | R27: =P27/Q27 -> 0.2 | S27: =IF(R27=0, "no 0% progess", "no progress") -> no progress | T27: 0 | U27: 0 | V27: 0 | W27: 0 | X27: 0 | Y27: 0 | AA27: 0 | AC27: 0 | AE27: 2026-02-08T17:27:11.8430000Z | AF27: 7
A28: T2-25_BDSDF108 | B28: Computing Systems | C28: BS | D28: Trimester 2 | E28: 2025eb1100009@bitspilani-digital.edu.in | F28: =_xlfn.XLOOKUP(E28,Total_Enrolled!C:C,Total_Enrolled!C:C) -> 2025eb1100009@bitspilani-digital.edu.in | G28: 2025EB1100009 | H28: old | I28: ALI ZAFAR RIZVI | J28: TRUE | K28: 0 | L28: =_xlfn.XLOOKUP(B28,Courses!A:A,Courses!H:H) -> 88 | M28: =K28/L28 -> 0 | N28: =IF(M28>0,"Active","Not Active") -> Not Active | O28: {=_xlfn.IFS(M28=0,"0", M28<=10%,"0-10", TRUE,">10" )&" "&"% progress"} -> 0 % progress | P28: =IF(M28=0,1,0) -> 1 | Q28: =COUNTIFS($G:$G,$G28) -> 5 | R28: =P28/Q28 -> 0.2 | S28: =IF(R28=0, "no 0% progess", "no progress") -> no progress | T28: 0 | U28: 0 | V28: 0 | W28: 0 | X28: 0 | Y28: 0 | AA28: 0 | AC28: 0 | AE28: 2026-02-08T17:27:11.8430000Z | AF28: 7
A29: T2-25_BDSDF114 | B29: Probability & Statistics | C29: BS | D29: Trimester 2 | E29: 2025eb1100009@bitspilani-digital.edu.in | F29: =_xlfn.XLOOKUP(E29,Total_Enrolled!C:C,Total_Enrolled!C:C) -> 2025eb1100009@bitspilani-digital.edu.in | G29: 2025EB1100009 | H29: old | I29: ALI ZAFAR RIZVI | J29: TRUE | K29: 0 | L29: =_xlfn.XLOOKUP(B29,Courses!A:A,Courses!H:H) -> 61 | M29: =K29/L29 -> 0 | N29: =IF(M29>0,"Active","Not Active") -> Not Active | O29: {=_xlfn.IFS(M29=0,"0", M29<=10%,"0-10", TRUE,">10" )&" "&"% progress"} -> 0 % progress | P29: =IF(M29=0,1,0) -> 1 | Q29: =COUNTIFS($G:$G,$G29) -> 5 | R29: =P29/Q29 -> 0.2 | S29: =IF(R29=0, "no 0% progess", "no progress") -> no progress | T29: 0 | U29: 0 | V29: 0 | W29: 0 | X29: 0 | Y29: 0 | AA29: 0 | AC29: 0 | AE29: 2026-02-08T17:27:11.8430000Z | AF29: 7
A30: T2-25_BDSDF112 | B30: Writing Practice | C30: BS | D30: Trimester 2 | E30: 2025eb1100009@bitspilani-digital.edu.in | F30: =_xlfn.XLOOKUP(E30,Total_Enrolled!C:C,Total_Enrolled!C:C) -> 2025eb1100009@bitspilani-digital.edu.in | G30: 2025EB1100009 | H30: old | I30: ALI ZAFAR RIZVI | J30: TRUE | K30: 0 | L30: =_xlfn.XLOOKUP(B30,Courses!A:A,Courses!H:H) -> 77 | M30: =K30/L30 -> 0 | N30: =IF(M30>0,"Active","Not Active") -> Not Active | O30: {=_xlfn.IFS(M30=0,"0", M30<=10%,"0-10", TRUE,">10" )&" "&"% progress"} -> 0 % progress | P30: =IF(M30=0,1,0) -> 1 | Q30: =COUNTIFS($G:$G,$G30) -> 5 | R30: =P30/Q30 -> 0.2 | S30: =IF(R30=0, "no 0% progess", "no progress") -> no progress | T30: 0 | U30: 0 | V30: 0 | W30: 0 | X30: 0 | Y30: 0 | AA30: 0 | AC30: 0 | AE30: 2026-02-08T17:27:11.8430000Z | AF30: 7
A31: T2-25_BDSDF113 | B31: Computer Programming | C31: BS | D31: Trimester 2 | E31: 2025eb1100009@bitspilani-digital.edu.in | F31: =_xlfn.XLOOKUP(E31,Total_Enrolled!C:C,Total_Enrolled!C:C) -> 2025eb1100009@bitspilani-digital.edu.in | G31: 2025EB1100009 | H31: old | I31: ALI ZAFAR RIZVI | J31: TRUE | K31: 0 | L31: =_xlfn.XLOOKUP(B31,Courses!A:A,Courses!H:H) -> 86 | M31: =K31/L31 -> 0 | N31: =IF(M31>0,"Active","Not Active") -> Not Active | O31: {=_xlfn.IFS(M31=0,"0", M31<=10%,"0-10", TRUE,">10" )&" "&"% progress"} -> 0 % progress | P31: =IF(M31=0,1,0) -> 1 | Q31: =COUNTIFS($G:$G,$G31) -> 5 | R31: =P31/Q31 -> 0.2 | S31: =IF(R31=0, "no 0% progess", "no progress") -> no progress | T31: 0 | U31: 0 | V31: 0 | W31: 0 | X31: 0 | Y31: 0 | AA31: 0 | AC31: 0 | AE31: 2026-02-08T17:27:11.8430000Z | AF31: 7
A32: T2-25_BDSDF110 | B32: Linear Algebra | C32: BS | D32: Trimester 2 | E32: 2025eb1100010@bitspilani-digital.edu.in | F32: =_xlfn.XLOOKUP(E32,Total_Enrolled!C:C,Total_Enrolled!C:C) -> 2025eb1100010@bitspilani-digital.edu.in | G32: 2025EB1100010 | H32: old | I32: HARSHITA JAIN | J32: TRUE | K32: 0 | L32: =_xlfn.XLOOKUP(B32,Courses!A:A,Courses!H:H) -> 46 | M32: =K32/L32 -> 0 | N32: =IF(M32>0,"Active","Not Active") -> Not Active | O32: {=_xlfn.IFS(M32=0,"0", M32<=10%,"0-10", TRUE,">10" )&" "&"% progress"} -> 0 % progress | P32: =IF(M32=0,1,0) -> 1 | Q32: =COUNTIFS($G:$G,$G32) -> 4 | R32: =P32/Q32 -> 0.25 | S32: =IF(R32=0, "no 0% progess", "no progress") -> no progress | T32: 0 | U32: 0 | V32: 0 | W32: 0 | X32: 0 | Y32: 0 | AA32: 0 | AC32: 0 | AE32: 2026-02-08T14:34:30.4630000Z | AF32: 169
A33: T2-25_BDSDF107 | B33: Fundamentals of Data Science and Engineering | C33: BS | D33: Trimester 2 | E33: 2025eb1100010@bitspilani-digital.edu.in | F33: =_xlfn.XLOOKUP(E33,Total_Enrolled!C:C,Total_Enrolled!C:C) -> 2025eb1100010@bitspilani-digital.edu.in | G33: 2025EB1100010 | H33: old | I33: HARSHITA JAIN | J33: TRUE | K33: 4 | L33: =_xlfn.XLOOKUP(B33,Courses!A:A,Courses!H:H) -> 41 | M33: =K33/L33 -> 0.097560976 | N33: =IF(M33>0,"Active","Not Active") -> Active | O33: {=_xlfn.IFS(M33=0,"0", M33<=10%,"0-10", TRUE,">10" )&" "&"% progress"} -> 0-10 % progress | P33: =IF(M33=0,1,0) -> 0 | Q33: =COUNTIFS($G:$G,$G33) -> 4 | R33: =P33/Q33 -> 0 | S33: =IF(R33=0, "no 0% progess", "no progress") -> no 0% progess | T33: 0 | U33: 2 | V33: 2 | W33: 0 | X33: 0 | Y33: 0 | AA33: 0 | AC33: 14 | AD33: 2026-02-08T14:39:37.0530000Z | AE33: 2026-02-08T14:34:30.4630000Z | AF33: 169 | AH33: 2026-02-08T14:39:30.3800000Z
A34: T2-25_BDSDF106 | B34: Data Structures for Data Science | C34: BS | D34: Trimester 2 | E34: 2025eb1100010@bitspilani-digital.edu.in | F34: =_xlfn.XLOOKUP(E34,Total_Enrolled!C:C,Total_Enrolled!C:C) -> 2025eb1100010@bitspilani-digital.edu.in | G34: 2025EB1100010 | H34: old | I34: HARSHITA JAIN | J34: TRUE | K34: 3 | L34: =_xlfn.XLOOKUP(B34,Courses!A:A,Courses!H:H) -> 93 | M34: =K34/L34 -> 0.032258065 | N34: =IF(M34>0,"Active","Not Active") -> Active | O34: {=_xlfn.IFS(M34=0,"0", M34<=10%,"0-10", TRUE,">10" )&" "&"% progress"} -> 0-10 % progress | P34: =IF(M34=0,1,0) -> 0 | Q34: =COUNTIFS($G:$G,$G34) -> 4 | R34: =P34/Q34 -> 0 | S34: =IF(R34=0, "no 0% progess", "no progress") -> no 0% progess | T34: 0 | U34: 0 | V34: 0 | W34: 0 | X34: 0 | Y34: 0 | AA34: 0 | AC34: 22 | AD34: 2026-02-04T14:31:35.9470000Z | AE34: 2026-02-08T14:34:30.4630000Z | AF34: 169
A35: T2-25_BDSDF102 | B35: Data Preprocessing (BS) | C35: BS | D35: Trimester 2 | E35: 2025eb1100010@bitspilani-digital.edu.in | F35: =_xlfn.XLOOKUP(E35,Total_Enrolled!C:C,Total_Enrolled!C:C) -> 2025eb1100010@bitspilani-digital.edu.in | G35: 2025EB1100010 | H35: old | I35: HARSHITA JAIN | J35: TRUE | K35: 10 | L35: =_xlfn.XLOOKUP(B35,Courses!A:A,Courses!H:H) -> 84 | M35: =K35/L35 -> 0.11904762 | N35: =IF(M35>0,"Active","Not Active") -> Active | O35: {=_xlfn.IFS(M35=0,"0", M35<=10%,"0-10", TRUE,">10" )&" "&"% progress"} -> >10 % progress | P35: =IF(M35=0,1,0) -> 0 | Q35: =COUNTIFS($G:$G,$G35) -> 4 | R35: =P35/Q35 -> 0 | S35: =IF(R35=0, "no 0% progess", "no progress") -> no 0% progess | T35: 0 | U35: 0 | V35: 0 | W35: 0 | X35: 0 | Y35: 0 | AA35: 0 | AC35: 9593 | AD35: 2026-02-04T14:32:10.0600000Z | AE35: 2026-02-08T14:34:30.4630000Z | AF35: 169
A36: T2-25_BDSDF113 | B36: Computer Programming | C36: BS | D36: Trimester 2 | E36: 2025eb1100012@bitspilani-digital.edu.in | F36: =_xlfn.XLOOKUP(E36,Total_Enrolled!C:C,Total_Enrolled!C:C) -> 2025eb1100012@bitspilani-digital.edu.in | G36: 2025EB1100012 | H36: old | I36: SANTOSH SHRIKHANDE | J36: TRUE | K36: 0 | L36: =_xlfn.XLOOKUP(B36,Courses!A:A,Courses!H:H) -> 86 | M36: =K36/L36 -> 0 | N36: =IF(M36>0,"Active","Not Active") -> Not Active | O36: {=_xlfn.IFS(M36=0,"0", M36<=10%,"0-10", TRUE,">10" )&" "&"% progress"} -> 0 % progress | P36: =IF(M36=0,1,0) -> 1 | Q36: =COUNTIFS($G:$G,$G36) -> 2 | R36: =P36/Q36 -> 0.5 | S36: =IF(R36=0, "no 0% progess", "no progress") -> no progress | T36: 0 | U36: 0 | V36: 0 | W36: 0 | X36: 0 | Y36: 0 | AA36: 0 | AC36: 0 | AE36: 2026-02-07T05:52:24.4370000Z | AF36: 119
A37: T2-25_BDSDF114 | B37: Probability & Statistics | C37: BS | D37: Trimester 2 | E37: 2025eb1100012@bitspilani-digital.edu.in | F37: =_xlfn.XLOOKUP(E37,Total_Enrolled!C:C,Total_Enrolled!C:C) -> 2025eb1100012@bitspilani-digital.edu.in | G37: 2025EB1100012 | H37: old | I37: SANTOSH SHRIKHANDE | J37: TRUE | K37: 4 | L37: =_xlfn.XLOOKUP(B37,Courses!A:A,Courses!H:H) -> 61 | M37: =K37/L37 -> 0.06557377 | N37: =IF(M37>0,"Active","Not Active") -> Active | O37: {=_xlfn.IFS(M37=0,"0", M37<=10%,"0-10", TRUE,">10" )&" "&"% progress"} -> 0-10 % progress | P37: =IF(M37=0,1,0) -> 0 | Q37: =COUNTIFS($G:$G,$G37) -> 2 | R37: =P37/Q37 -> 0 | S37: =IF(R37=0, "no 0% progess", "no progress") -> no 0% progess | T37: 0 | U37: 0 | V37: 0 | W37: 0 | X37: 0 | Y37: 0 | AA37: 0 | AC37: 22 | AD37: 2026-02-07T05:55:07.9530000Z | AE37: 2026-02-07T05:52:24.4370000Z | AF37: 119 | AI37: 2026-02-07T05:55:22.3570000Z | AJ37: 2026-02-07T05:55:22.3570000Z
A38: T2-25_BDSDF113 | B38: Computer Programming | C38: BS | D38: Trimester 2 | E38: 2025eb1100013@bitspilani-digital.edu.in | F38: =_xlfn.XLOOKUP(E38,Total_Enrolled!C:C,Total_Enrolled!C:C) -> 2025eb1100013@bitspilani-digital.edu.in | G38: 2025EB1100013 | H38: old | I38: AKSHITHA IMMACULATE A | J38: TRUE | K38: 0 | L38: =_xlfn.XLOOKUP(B38,Courses!A:A,Courses!H:H) -> 86 | M38: =K38/L38 -> 0 | N38: =IF(M38>0,"Active","Not Active") -> Not Active | O38: {=_xlfn.IFS(M38=0,"0", M38<=10%,"0-10", TRUE,">10" )&" "&"% progress"} -> 0 % progress | P38: =IF(M38=0,1,0) -> 1 | Q38: =COUNTIFS($G:$G,$G38) -> 4 | R38: =P38/Q38 -> 0.25 | S38: =IF(R38=0, "no 0% progess", "no progress") -> no progress | T38: 0 | U38: 0 | V38: 0 | W38: 0 | X38: 0 | Y38: 0 | AA38: 0 | AC38: 0 | AE38: 2026-01-30T14:24:09.0330000Z | AF38: 100
A39: T2-25_BDSDF108 | B39: Computing Systems | C39: BS | D39: Trimester 2 | E39: 2025eb1100013@bitspilani-digital.edu.in | F39: =_xlfn.XLOOKUP(E39,Total_Enrolled!C:C,Total_Enrolled!C:C) -> 2025eb1100013@bitspilani-digital.edu.in | G39: 2025EB1100013 | H39: old | I39: AKSHITHA IMMACULATE A | J39: TRUE | K39: 0 | L39: =_xlfn.XLOOKUP(B39,Courses!A:A,Courses!H:H) -> 88 | M39: =K39/L39 -> 0 | N39: =IF(M39>0,"Active","Not Active") -> Not Active | O39: {=_xlfn.IFS(M39=0,"0", M39<=10%,"0-10", TRUE,">10" )&" "&"% progress"} -> 0 % progress | P39: =IF(M39=0,1,0) -> 1 | Q39: =COUNTIFS($G:$G,$G39) -> 4 | R39: =P39/Q39 -> 0.25 | S39: =IF(R39=0, "no 0% progess", "no progress") -> no progress | T39: 0 | U39: 0 | V39: 0 | W39: 0 | X39: 0 | Y39: 0 | AA39: 0 | AC39: 0 | AE39: 2026-01-30T14:24:09.0330000Z | AF39: 100
A40: T2-25_BDSDF107 | B40: Fundamentals of Data Science and Engineering | C40: BS | D40: Trimester 2 | E40: 2025eb1100013@bitspilani-digital.edu.in | F40: =_xlfn.XLOOKUP(E40,Total_Enrolled!C:C,Total_Enrolled!C:C) -> 2025eb1100013@bitspilani-digital.edu.in | G40: 2025EB1100013 | H40: old | I40: AKSHITHA IMMACULATE A | J40: TRUE | K40: 0 | L40: =_xlfn.XLOOKUP(B40,Courses!A:A,Courses!H:H) -> 41 | M40: =K40/L40 -> 0 | N40: =IF(M40>0,"Active","Not Active") -> Not Active | O40: {=_xlfn.IFS(M40=0,"0", M40<=10%,"0-10", TRUE,">10" )&" "&"% progress"} -> 0 % progress | P40: =IF(M40=0,1,0) -> 1 | Q40: =COUNTIFS($G:$G,$G40) -> 4 | R40: =P40/Q40 -> 0.25 | S40: =IF(R40=0, "no 0% progess", "no progress") -> no progress | T40: 0 | U40: 0 | V40: 0 | W40: 0 | X40: 0 | Y40: 0 | AA40: 0 | AC40: 0 | AD40: 2026-01-18T11:10:10.2200000Z | AE40: 2026-01-30T14:24:09.0330000Z | AF40: 100
...

Sheet Courses
A1: T2 | B1: WEEK 1 | C1: WEEK 2 | D1: WEEK 3 | E1: WEEK 4 | F1: WEEK 5 | G1: lab | H1: sum
A2: Artificial Neural Networks | B2: 25 | C2: 22 | D2: 24 | E2: 26 | F2: 28 | G2: - | H2: =SUM(B2:D2) -> 71
A3: Advanced Apex Project I | B3: 0 | C3: 0 | D3: 0 | E3: 0 | F3: 0 | G3: - | H3: =SUM(B3:D3) -> 0
A4: Basic Mathematics | B4: 12 | C4: 25 | G4: - | H4: =SUM(B4:D4) -> 37
A5: Cloud Services & Platforms | B5: 22 | C5: 23 | D5: 22 | E5: 20 | F5: 23 | G5: - | H5: =SUM(B5:D5) -> 67
A6: Computer Programming | B6: 25 | C6: 32 | D6: 29 | E6: 27 | F6: 25 | G6: - | H6: =SUM(B6:D6) -> 86
A7: Computing Systems | B7: 18 | C7: 33 | D7: 37 | E7: 23 | F7: 30 | G7: - | H7: =SUM(B7:D7) -> 88
A8: Data and the World | B8: 7 | C8: 17 | D8: 17 | E8: 11 | G8: - | H8: =SUM(B8:D8) -> 41
A9: Data Annotations and Labelling | B9: 12 | C9: 11 | D9: 13 | E9: 13 | F9: 12 | G9: - | H9: =SUM(B9:D9) -> 36
A10: Data Preprocessing (BS) | B10: 28 | C10: 27 | D10: 29 | E10: 26 | F10: 23 | G10: - | H10: =SUM(B10:D10) -> 84
A11: Data Pre-processing (MSc) | B11: 13 | C11: 11 | D11: 12 | E11: 15 | F11: 11 | G11: - | H11: =SUM(B11:D11) -> 36
A12: Data Stores & Pipelines | B12: 22 | C12: 19 | D12: 23 | E12: 23 | F12: 16 | G12: 9 | H12: =SUM(B12:D12) -> 64
A13: Data Structures for Data Science | B13: 29 | C13: 29 | D13: 35 | E13: 24 | F13: 32 | G13: - | H13: =SUM(B13:D13) -> 93
A14: Data Visualization & Storytelling | B14: 26 | C14: 31 | D14: 28 | E14: 28 | F14: 30 | G14: - | H14: =SUM(B14:D14) -> 85
A15: Feature Engineering | B15: 12 | C15: 12 | D15: 18 | E15: 11 | F15: 13 | G15: - | H15: =SUM(B15:D15) -> 42
A16: Fundamentals of Data Science and Engineering | B16: 13 | C16: 13 | D16: 15 | E16: 13 | F16: 13 | G16: - | H16: =SUM(B16:D16) -> 41
A17: Linear Algebra | B17: 16 | C17: 16 | D17: 14 | E17: 14 | F17: 11 | G17: - | H17: =SUM(B17:D17) -> 46
A18: Machine Learning | B18: 14 | C18: 14 | D18: 16 | E18: 12 | F18: 9 | G18: - | H18: =SUM(B18:D18) -> 44
A19: Probability & Statistics | B19: 22 | C19: 15 | D19: 24 | E19: 24 | F19: 33 | G19: - | H19: =SUM(B19:D19) -> 61
A20: Python Programming | B20: 21 | C20: 28 | G20: - | H20: =SUM(B20:D20) -> 49
A21: Statistical Modelling & Inferencing | B21: 23 | C21: 18 | D21: 27 | E21: 18 | F21: 12 | G21: - | H21: =SUM(B21:D21) -> 68
A22: Writing Practice | B22: 24 | C22: 23 | D22: 30 | E22: 25 | F22: 28 | G22: - | H22: =SUM(B22:D22) -> 77

Sheet Total_Enrolled
A1: PersonalEmailB3 | B1: IDB3 | C1: EmailB3 | D1: NameB3 | E1: passwordb3 | F1: Welcome Email Status
A2: JANCYJTG@GMAIL.COM | B2: 2025EM1200001 | C2: 2025em1200001@bitspilani-digital.edu.in | D2: JANCY C JOSHWA | E2: Ep$23012001 | F2: Sent
A3: OHILESWAR@GMAIL.COM | B3: 2025EM1200002 | C3: 2025em1200002@bitspilani-digital.edu.in | D3: OHILESWAR M N | E3: Ep$08061975 | F3: Sent
A4: TEJASLIMAYE37@GMAIL.COM | B4: 2025EM1200003 | C4: 2025em1200003@bitspilani-digital.edu.in | D4: TEJAS PRATAP LIMAYE | E4: Ep$19022002 | F4: Sent
A5: RAJANIDASTHRICE@YAHOO.CO.IN | B5: 2025EM1200005 | C5: 2025em1200005@bitspilani-digital.edu.in | D5: RAJANI DAS | E5: Ep$08091984 | F5: Sent
A6: ANEES.ASLAM.AI@GMAIL.COM | B6: 2025EM1200006 | C6: 2025em1200006@bitspilani-digital.edu.in | D6: ANEES A | E6: Ep$24102001 | F6: Sent
A7: GAURAVDATASCIENCE4438@GMAIL.COM | B7: 2025EM1200007 | C7: 2025em1200007@bitspilani-digital.edu.in | D7: GAURAV KUMAR SINGH | E7: Ep$23021993 | F7: Sent
A8: SAHI.VISTA@GMAIL.COM | B8: 2025EM1200008 | C8: 2025em1200008@bitspilani-digital.edu.in | D8: MOTUPALLI SURENDRA SAHI | E8: Ep$27051992 | F8: Sent
A9: ANASBISWAS@HOTMAIL.COM | B9: 2025EM1200009 | C9: 2025em1200009@bitspilani-digital.edu.in | D9: MD. ANAS BISWAS | E9: Ep$30081992 | F9: Sent
A10: SSK2410@GMAIL.COM | B10: 2025EM1200010 | C10: 2025em1200010@bitspilani-digital.edu.in | D10: KAMBLI SAURABH SANDEEP SWAPNA | E10: Ep$24101992 | F10: Sent
A11: ANKITA.SRIVASTAVA.01.09@GMAIL.COM | B11: 2025EM1200011 | C11: 2025em1200011@bitspilani-digital.edu.in | D11: ANKITA SRIVASTAVA | E11: Ep$27041995 | F11: Sent
A12: AMANABD98@GMAIL.COM | B12: 2025EM1200012 | C12: 2025em1200012@bitspilani-digital.edu.in | D12: AMAN ABDULLA | E12: Ep$16081998 | F12: Sent
... A1304: KHIMANSHU9953@GMAIL.COM | B1304: 2025EM1100509 | C1304: 2025em1100509@bitspilani-digital.edu.in | D1304: HIMANSHU PANDEY | E1304: Ep$19041999 | F1304: SENT
