Workbook

Sheet Learner Usage main dump
A1: Course Offering Code | B1: Course Offering Name | C1: Parent Department Name | D1: Parent Department Code | E1: Semester Code | F1: Semester Name | G1: Username | H1: Org Defined Id | I1: Old/New Student | J1: First Name | K1: Last Name | L1: Is Active | M1: Content Completed | N1: Content Required W1&2 | O1: Content Required | Q1: Checklist Completed | S1: Quiz Completed | T1: Total Quiz Attempts | U1: Discussion Post Created | V1: Discussion Post Replies | W1: Discussion Post Read | X1: Last Discussion Post Date | Y1: Number Of Assignment Submissions | Z1: Last Assignment Submission Date | AA1: Total Time Spent In Content | AB1: Last Visited Date | AC1: Last System Login | AD1: Number Of Logins To The System | AE1: Auditor Name | AF1: Last Quiz Attempt Date | AG1: Last SCORM Completion Date | AH1: Last SCORM Visit Date
A2: T1-25_BDSDF113 | B2: Computer Programming | C2: BS - Data Science &amp; AI | D2: dept_bs_dsai | E2: sem_trimester1 | F2: Trimester 1 | G2: 2025eb1100001@bitspilani-digital.edu.in | H2: 2025EB1100001 | I2: old | J2: RUDRA SHARMA | K2: . | L2: TRUE | M2: 177 | N2: =_xlfn.XLOOKUP(B2,Courses!A:A,Courses!E:E) -> 56 | O2: 387 | Q2: 0 | S2: 57 | T2: 78 | U2: 0 | V2: 0 | W2: 0 | Y2: 0 | AA2: 61717 | AB2: 2025-12-28T06:42:30.8300000Z | AC2: 2026-02-02T11:39:23.4370000Z | AD2: 153 | AF2: 2025-12-27T16:12:49.1700000Z | AG2: 2025-12-27T16:13:18.0270000Z | AH2: 2025-12-27T16:13:18.0400000Z
A3: T1-25_BDSDF108 | B3: Computing Systems | C3: BS - Data Science &amp; AI | D3: dept_bs_dsai | E3: sem_trimester1 | F3: Trimester 1 | G3: 2025eb1100001@bitspilani-digital.edu.in | H3: 2025EB1100001 | I3: old | J3: RUDRA SHARMA | K3: . | L3: TRUE | M3: 265 | N3: =_xlfn.XLOOKUP(B3,Courses!A:A,Courses!E:E) -> 47 | O3: 273 | Q3: 0 | S3: 82 | T3: 115 | U3: 0 | V3: 0 | W3: 0 | Y3: 1 | Z3: 2025-12-19T12:26:26.8400000Z | AA3: 60336 | AB3: 2026-01-17T15:39:46.5470000Z | AC3: 2026-02-02T11:39:23.4370000Z | AD3: 153 | AF3: 2025-12-26T17:16:16.8530000Z | AG3: 2025-12-26T17:10:58.1430000Z | AH3: 2025-12-26T17:14:06.8370000Z
A4: T1-25_BDSDF101 | B4: Data and the World | C4: BS - Data Science &amp; AI | D4: dept_bs_dsai | E4: sem_trimester1 | F4: Trimester 1 | G4: 2025eb1100001@bitspilani-digital.edu.in | H4: 2025EB1100001 | I4: old | J4: RUDRA SHARMA | K4: . | L4: TRUE | M4: 52 | N4: =_xlfn.XLOOKUP(B4,Courses!A:A,Courses!E:E) -> 24 | O4: 54 | Q4: 0 | S4: 9 | T4: 9 | U4: 0 | V4: 0 | W4: 0 | Y4: 1 | Z4: 2025-10-12T03:55:56.6870000Z | AA4: 1881 | AB4: 2025-12-27T06:20:37.9070000Z | AC4: 2026-02-02T11:39:23.4370000Z | AD4: 153 | AF4: 2025-10-29T12:35:24.4470000Z | AG4: 2025-10-29T11:50:49.4230000Z | AH4: 2025-10-29T11:50:54.8700000Z
A5: T1-25_BDSDF112 | B5: Writing Practice | C5: BS - Data Science &amp; AI | D5: dept_bs_dsai | E5: sem_trimester1 | F5: Trimester 1 | G5: 2025eb1100001@bitspilani-digital.edu.in | H5: 2025EB1100001 | I5: old | J5: RUDRA SHARMA | K5: . | L5: TRUE | M5: 208 | N5: =_xlfn.XLOOKUP(B5,Courses!A:A,Courses!E:E) -> 46 | O5: 220 | Q5: 0 | S5: 85 | T5: 115 | U5: 0 | V5: 0 | W5: 0 | Y5: 0 | AA5: 3642 | AB5: 2025-12-30T08:13:40.6200000Z | AC5: 2026-02-02T11:39:23.4370000Z | AD5: 153 | AF5: 2025-12-25T17:41:14.2300000Z
A6: T1-25_BDSDF114 | B6: Probability & Statistics | C6: BS - Data Science &amp; AI | D6: dept_bs_dsai | E6: sem_trimester1 | F6: Trimester 1 | G6: 2025eb1100001@bitspilani-digital.edu.in | H6: 2025EB1100001 | I6: old | J6: RUDRA SHARMA | K6: . | L6: TRUE | M6: 23 | N6: =_xlfn.XLOOKUP(B6,Courses!A:A,Courses!E:E) -> 35 | O6: 332 | Q6: 0 | S6: 6 | T6: 9 | U6: 0 | V6: 0 | W6: 0 | Y6: 0 | AA6: 9944 | AB6: 2025-12-28T00:37:37.9300000Z | AC6: 2026-02-02T11:39:23.4370000Z | AD6: 153 | AF6: 2025-12-27T13:55:18.8630000Z | AG6: 2025-09-26T06:32:55.6800000Z | AH6: 2025-12-27T13:55:35.0670000Z
A7: T2-25_BDSDF106 | B7: Data Structures for Data Science | C7: BS - Data Science &amp; AI | D7: dept_bs_dsai | E7: sem_trimester 2 | F7: Trimester 2 | G7: 2025eb1100001@bitspilani-digital.edu.in | H7: 2025EB1100001 | I7: old | J7: RUDRA SHARMA | K7: . | L7: TRUE | M7: 0 | N7: =_xlfn.XLOOKUP(B7,Courses!A:A,Courses!E:E) -> 58 | O7: 119 | Q7: 0 | S7: 0 | T7: 0 | U7: 0 | V7: 0 | W7: 0 | Y7: 0 | AA7: 0 | AB7: 2026-01-20T11:51:15.2100000Z | AC7: 2026-02-02T11:39:23.4370000Z | AD7: 153
A8: T2-25_BDSDF102 | B8: Data Preprocessing (BS) | C8: BS - Data Science &amp; AI | D8: dept_bs_dsai | E8: sem_trimester 2 | F8: Trimester 2 | G8: 2025eb1100001@bitspilani-digital.edu.in | H8: 2025EB1100001 | I8: old | J8: RUDRA SHARMA | K8: . | L8: TRUE | M8: 2 | N8: =_xlfn.XLOOKUP(B8,Courses!A:A,Courses!E:E) -> 54 | O8: 106 | Q8: 0 | S8: 0 | T8: 0 | U8: 0 | V8: 0 | W8: 0 | Y8: 0 | AA8: 16859 | AB8: 2026-02-02T11:39:50.9000000Z | AC8: 2026-02-02T11:39:23.4370000Z | AD8: 153
A9: T2-25_BDSDF107 | B9: Fundamentals of Data Science and Engineering | C9: BS - Data Science &amp; AI | D9: dept_bs_dsai | E9: sem_trimester 2 | F9: Trimester 2 | G9: 2025eb1100001@bitspilani-digital.edu.in | H9: 2025EB1100001 | I9: old | J9: RUDRA SHARMA | K9: . | L9: TRUE | M9: 40 | N9: =_xlfn.XLOOKUP(B9,Courses!A:A,Courses!E:E) -> 25 | O9: 71 | Q9: 0 | S9: 5 | T9: 6 | U9: 0 | V9: 0 | W9: 0 | Y9: 0 | AA9: 29839 | AB9: 2026-01-30T15:21:22.0970000Z | AC9: 2026-02-02T11:39:23.4370000Z | AD9: 153 | AF9: 2026-01-28T11:35:29.7270000Z
A10: T2-25_BDSDF110 | B10: Linear Algebra | C10: BS - Data Science &amp; AI | D10: dept_bs_dsai | E10: sem_trimester 2 | F10: Trimester 2 | G10: 2025eb1100001@bitspilani-digital.edu.in | H10: 2025EB1100001 | I10: old | J10: RUDRA SHARMA | K10: . | L10: TRUE | M10: 2 | N10: =_xlfn.XLOOKUP(B10,Courses!A:A,Courses!E:E) -> 30 | O10: 61 | Q10: 0 | S10: 0 | T10: 0 | U10: 0 | V10: 0 | W10: 0 | Y10: 0 | AA10: 27 | AB10: 2026-01-23T15:02:12.0900000Z | AC10: 2026-02-02T11:39:23.4370000Z | AD10: 153 | AG10: 2026-01-23T15:01:45.2470000Z | AH10: 2026-01-23T15:01:48.8770000Z
A11: T2-25_BDSDF108 | B11: Computing Systems | C11: BS - Data Science &amp; AI | D11: dept_bs_dsai | E11: sem_trimester 2 | F11: Trimester 2 | G11: 2025eb1100001@bitspilani-digital.edu.in | H11: 2025EB1100001 | I11: old | J11: RUDRA SHARMA | K11: . | L11: TRUE | M11: 91 | N11: =_xlfn.XLOOKUP(B11,Courses!A:A,Courses!E:E) -> 47 | O11: 263 | Q11: 0 | S11: 33 | T11: 55 | U11: 0 | V11: 0 | W11: 0 | Y11: 0 | AA11: 1027 | AB11: 2026-01-23T15:00:49.2930000Z | AC11: 2026-02-02T11:39:23.4370000Z | AD11: 153 | AF11: 2026-01-18T07:48:14.9500000Z | AG11: 2026-01-23T14:59:58.6570000Z | AH11: 2026-01-23T15:00:20.6770000Z
A12: T1-25_BDSDF114 | B12: Probability & Statistics | C12: BS - Data Science &amp; AI | D12: dept_bs_dsai | E12: sem_trimester1 | F12: Trimester 1 | G12: 2025eb1100002@bitspilani-digital.edu.in | H12: 2025EB1100002 | I12: old | J12: BANDREDDY BHAWIN SAI KOUSHIK | K12: . | L12: TRUE | M12: 12 | N12: =_xlfn.XLOOKUP(B12,Courses!A:A,Courses!E:E) -> 35 | O12: 329 | Q12: 0 | S12: 0 | T12: 0 | U12: 0 | V12: 0 | W12: 0 | Y12: 0 | AA12: 6010 | AB12: 2025-11-18T06:22:50.9800000Z | AC12: 2026-01-21T12:03:24.3400000Z | AD12: 85 | AG12: 2025-10-03T07:25:46.2670000Z | AH12: 2025-10-23T15:59:37.7770000Z
A13: T1-25_BDSDF112 | B13: Writing Practice | C13: BS - Data Science &amp; AI | D13: dept_bs_dsai | E13: sem_trimester1 | F13: Trimester 1 | G13: 2025eb1100002@bitspilani-digital.edu.in | H13: 2025EB1100002 | I13: old | J13: BANDREDDY BHAWIN SAI KOUSHIK | K13: . | L13: TRUE | M13: 50 | N13: =_xlfn.XLOOKUP(B13,Courses!A:A,Courses!E:E) -> 46 | O13: 203 | Q13: 0 | S13: 10 | T13: 10 | U13: 0 | V13: 0 | W13: 3 | Y13: 0 | AA13: 26346 | AB13: 2025-12-15T02:07:29.1670000Z | AC13: 2026-01-21T12:03:24.3400000Z | AD13: 85 | AF13: 2025-10-05T13:15:47.9630000Z
A14: T1-25_BDSDF101 | B14: Data and the World | C14: BS - Data Science &amp; AI | D14: dept_bs_dsai | E14: sem_trimester1 | F14: Trimester 1 | G14: 2025eb1100002@bitspilani-digital.edu.in | H14: 2025EB1100002 | I14: old | J14: BANDREDDY BHAWIN SAI KOUSHIK | K14: . | L14: TRUE | M14: 27 | N14: =_xlfn.XLOOKUP(B14,Courses!A:A,Courses!E:E) -> 24 | O14: 51 | Q14: 0 | S14: 1 | T14: 2 | U14: 0 | V14: 0 | W14: 0 | Y14: 1 | Z14: 2025-10-12T15:06:41.4870000Z | AA14: 14489 | AB14: 2025-12-13T16:28:04.8330000Z | AC14: 2026-01-21T12:03:24.3400000Z | AD14: 85 | AF14: 2025-09-17T05:26:10.0730000Z | AG14: 2025-10-09T15:11:30.0670000Z | AH14: 2025-10-10T03:21:00.8100000Z
A15: T1-25_BDSDF108 | B15: Computing Systems | C15: BS - Data Science &amp; AI | D15: dept_bs_dsai | E15: sem_trimester1 | F15: Trimester 1 | G15: 2025eb1100002@bitspilani-digital.edu.in | H15: 2025EB1100002 | I15: old | J15: BANDREDDY BHAWIN SAI KOUSHIK | K15: . | L15: TRUE | M15: 18 | N15: =_xlfn.XLOOKUP(B15,Courses!A:A,Courses!E:E) -> 47 | O15: 238 | Q15: 0 | S15: 1 | T15: 1 | U15: 0 | V15: 0 | W15: 0 | Y15: 0 | AA15: 5360 | AB15: 2025-11-18T06:29:05.1200000Z | AC15: 2026-01-21T12:03:24.3400000Z | AD15: 85 | AF15: 2025-10-06T04:41:38.2870000Z | AG15: 2025-10-06T04:53:09.1500000Z | AH15: 2025-11-18T06:30:38.3200000Z
A16: T1-25_BDSDF113 | B16: Computer Programming | C16: BS - Data Science &amp; AI | D16: dept_bs_dsai | E16: sem_trimester1 | F16: Trimester 1 | G16: 2025eb1100002@bitspilani-digital.edu.in | H16: 2025EB1100002 | I16: old | J16: BANDREDDY BHAWIN SAI KOUSHIK | K16: . | L16: TRUE | M16: 58 | N16: =_xlfn.XLOOKUP(B16,Courses!A:A,Courses!E:E) -> 56 | O16: 362 | Q16: 0 | S16: 13 | T16: 15 | U16: 0 | V16: 0 | W16: 0 | Y16: 0 | AA16: 23143 | AB16: 2025-12-07T13:09:45.0830000Z | AC16: 2026-01-21T12:03:24.3400000Z | AD16: 85 | AF16: 2025-11-18T06:21:35.4270000Z | AG16: 2025-10-05T11:36:16.5570000Z | AH16: 2025-10-05T11:36:16.5400000Z
A17: T1-25_BDSDF113 | B17: Computer Programming | C17: BS - Data Science &amp; AI | D17: dept_bs_dsai | E17: sem_trimester1 | F17: Trimester 1 | G17: 2025eb1100003@bitspilani-digital.edu.in | H17: 2025EB1100003 | I17: old | J17: AJAYACHANDRAN.E | K17: . | L17: TRUE | M17: 45 | N17: =_xlfn.XLOOKUP(B17,Courses!A:A,Courses!E:E) -> 56 | O17: 354 | Q17: 0 | S17: 4 | T17: 6 | U17: 1 | V17: 0 | W17: 17 | X17: 2025-12-01T10:50:52.5870000Z | Y17: 0 | AA17: 27721 | AB17: 2026-01-22T21:49:50.0400000Z | AC17: 2026-02-01T13:37:18.9730000Z | AD17: 107 | AF17: 2025-10-04T20:29:51.7530000Z | AG17: 2025-11-09T08:09:15.8970000Z | AH17: 2026-01-22T17:07:37.4170000Z
A18: T1-25_BDSDF108 | B18: Computing Systems | C18: BS - Data Science &amp; AI | D18: dept_bs_dsai | E18: sem_trimester1 | F18: Trimester 1 | G18: 2025eb1100003@bitspilani-digital.edu.in | H18: 2025EB1100003 | I18: old | J18: AJAYACHANDRAN.E | K18: . | L18: TRUE | M18: 91 | N18: =_xlfn.XLOOKUP(B18,Courses!A:A,Courses!E:E) -> 47 | O18: 259 | Q18: 0 | S18: 18 | T18: 29 | U18: 0 | V18: 0 | W18: 0 | Y18: 2 | Z18: 2025-11-14T15:41:49.7570000Z | AA18: 95876 | AB18: 2026-01-23T14:15:58.3870000Z | AC18: 2026-02-01T13:37:18.9730000Z | AD18: 107 | AF18: 2025-11-27T20:26:03.2830000Z | AG18: 2025-11-27T18:44:00.7630000Z | AH18: 2025-11-27T20:24:31.5000000Z
A19: T1-25_BDSDF101 | B19: Data and the World | C19: BS - Data Science &amp; AI | D19: dept_bs_dsai | E19: sem_trimester1 | F19: Trimester 1 | G19: 2025eb1100003@bitspilani-digital.edu.in | H19: 2025EB1100003 | I19: old | J19: AJAYACHANDRAN.E | K19: . | L19: TRUE | M19: 43 | N19: =_xlfn.XLOOKUP(B19,Courses!A:A,Courses!E:E) -> 24 | O19: 54 | Q19: 0 | S19: 7 | T19: 7 | U19: 0 | V19: 1 | W19: 19 | X19: 2025-10-03T17:03:24.8270000Z | Y19: 1 | Z19: 2025-10-11T19:08:16.7730000Z | AA19: 22938 | AB19: 2026-01-22T21:49:36.7300000Z | AC19: 2026-02-01T13:37:18.9730000Z | AD19: 107 | AF19: 2025-10-03T18:33:26.4400000Z | AG19: 2025-10-16T18:35:41.7400000Z | AH19: 2025-10-16T18:35:41.7270000Z
A20: T1-25_BDSDF112 | B20: Writing Practice | C20: BS - Data Science &amp; AI | D20: dept_bs_dsai | E20: sem_trimester1 | F20: Trimester 1 | G20: 2025eb1100003@bitspilani-digital.edu.in | H20: 2025EB1100003 | I20: old | J20: AJAYACHANDRAN.E | K20: . | L20: TRUE | M20: 80 | N20: =_xlfn.XLOOKUP(B20,Courses!A:A,Courses!E:E) -> 46 | O20: 198 | Q20: 0 | S20: 22 | T20: 37 | U20: 2 | V20: 0 | W20: 11 | X20: 2025-12-01T10:55:10.6430000Z | Y20: 0 | AA20: 29430 | AB20: 2026-01-05T19:05:39.5630000Z | AC20: 2026-02-01T13:37:18.9730000Z | AD20: 107 | AF20: 2025-10-28T14:30:09.3030000Z
A21: T1-25_BDSDF114 | B21: Probability & Statistics | C21: BS - Data Science &amp; AI | D21: dept_bs_dsai | E21: sem_trimester1 | F21: Trimester 1 | G21: 2025eb1100003@bitspilani-digital.edu.in | H21: 2025EB1100003 | I21: old | J21: AJAYACHANDRAN.E | K21: . | L21: TRUE | M21: 27 | N21: =_xlfn.XLOOKUP(B21,Courses!A:A,Courses!E:E) -> 35 | O21: 329 | Q21: 0 | S21: 4 | T21: 4 | U21: 0 | V21: 0 | W21: 14 | Y21: 0 | AA21: 28793 | AB21: 2026-01-05T19:24:58.6070000Z | AC21: 2026-02-01T13:37:18.9730000Z | AD21: 107 | AF21: 2025-12-01T10:11:06.3800000Z | AG21: 2025-11-04T13:55:01.5170000Z | AH21: 2025-11-05T13:29:27.7070000Z
A22: T2-25_BDSDF114 | B22: Probability & Statistics | C22: BS - Data Science &amp; AI | D22: dept_bs_dsai | E22: sem_trimester 2 | F22: Trimester 2 | G22: 2025eb1100003@bitspilani-digital.edu.in | H22: 2025EB1100003 | I22: old | J22: AJAYACHANDRAN.E | K22: . | L22: TRUE | M22: 23 | N22: =_xlfn.XLOOKUP(B22,Courses!A:A,Courses!E:E) -> 35 | O22: 321 | Q22: 0 | S22: 3 | T22: 5 | U22: 2 | V22: 0 | W22: 8 | X22: 2026-01-30T21:48:45.6800000Z | Y22: 0 | AA22: 22772 | AB22: 2026-02-01T11:23:20.9230000Z | AC22: 2026-02-01T13:37:18.9730000Z | AD22: 107 | AF22: 2026-01-31T00:24:37.8630000Z | AG22: 2026-01-24T14:45:28.7000000Z | AH22: 2026-01-31T00:25:02.4370000Z
A23: T2-25_BDSDF113 | B23: Computer Programming | C23: BS - Data Science &amp; AI | D23: dept_bs_dsai | E23: sem_trimester 2 | F23: Trimester 2 | G23: 2025eb1100003@bitspilani-digital.edu.in | H23: 2025EB1100003 | I23: old | J23: AJAYACHANDRAN.E | K23: . | L23: TRUE | M23: 43 | N23: =_xlfn.XLOOKUP(B23,Courses!A:A,Courses!E:E) -> 56 | O23: 351 | Q23: 0 | S23: 9 | T23: 18 | U23: 3 | V23: 0 | W23: 1 | X23: 2026-01-31T00:29:49.2300000Z | Y23: 0 | AA23: 49496 | AB23: 2026-02-01T11:24:44.1100000Z | AC23: 2026-02-01T13:37:18.9730000Z | AD23: 107 | AF23: 2026-01-31T23:46:19.5000000Z | AG23: 2026-01-31T12:03:07.5170000Z | AH23: 2026-01-31T23:46:46.3370000Z
A24: T2-25_BDSDF107 | B24: Fundamentals of Data Science and Engineering | C24: BS - Data Science &amp; AI | D24: dept_bs_dsai | E24: sem_trimester 2 | F24: Trimester 2 | G24: 2025eb1100003@bitspilani-digital.edu.in | H24: 2025EB1100003 | I24: old | J24: AJAYACHANDRAN.E | K24: . | L24: TRUE | M24: 26 | N24: =_xlfn.XLOOKUP(B24,Courses!A:A,Courses!E:E) -> 25 | O24: 71 | Q24: 0 | S24: 3 | T24: 6 | U24: 0 | V24: 0 | W24: 0 | Y24: 0 | AA24: 19503 | AB24: 2026-01-31T15:31:13.7430000Z | AC24: 2026-02-01T13:37:18.9730000Z | AD24: 107 | AF24: 2026-01-30T20:33:35.5230000Z
A25: T2-25_BDSDF102 | B25: Data Preprocessing (BS) | C25: BS - Data Science &amp; AI | D25: dept_bs_dsai | E25: sem_trimester 2 | F25: Trimester 2 | G25: 2025eb1100003@bitspilani-digital.edu.in | H25: 2025EB1100003 | I25: old | J25: AJAYACHANDRAN.E | K25: . | L25: TRUE | M25: 35 | N25: =_xlfn.XLOOKUP(B25,Courses!A:A,Courses!E:E) -> 54 | O25: 106 | Q25: 0 | S25: 0 | T25: 0 | U25: 0 | V25: 0 | W25: 0 | Y25: 0 | AA25: 12547 | AB25: 2026-01-31T15:35:12.7370000Z | AC25: 2026-02-01T13:37:18.9730000Z | AD25: 107
A26: T2-25_BDSDF102 | B26: Data Preprocessing (BS) | C26: BS - Data Science &amp; AI | D26: dept_bs_dsai | E26: sem_trimester 2 | F26: Trimester 2 | G26: 2025eb1100004@bitspilani-digital.edu.in | H26: 2025EB1100004 | I26: old | J26: ARUNLAL P | K26: . | L26: TRUE | M26: 1 | N26: =_xlfn.XLOOKUP(B26,Courses!A:A,Courses!E:E) -> 54 | O26: 106 | Q26: 0 | S26: 0 | T26: 0 | U26: 0 | V26: 0 | W26: 0 | Y26: 0 | AA26: 0 | AB26: 2026-01-19T08:25:52.9870000Z | AC26: 2026-01-19T08:25:10.8100000Z | AD26: 149
A27: T2-25_BDSDF106 | B27: Data Structures for Data Science | C27: BS - Data Science &amp; AI | D27: dept_bs_dsai | E27: sem_trimester 2 | F27: Trimester 2 | G27: 2025eb1100004@bitspilani-digital.edu.in | H27: 2025EB1100004 | I27: old | J27: ARUNLAL P | K27: . | L27: TRUE | M27: 0 | N27: =_xlfn.XLOOKUP(B27,Courses!A:A,Courses!E:E) -> 58 | O27: 119 | Q27: 0 | S27: 0 | T27: 0 | U27: 0 | V27: 0 | W27: 0 | Y27: 0 | AA27: 0 | AB27: 2026-01-17T14:38:56.5370000Z | AC27: 2026-01-19T08:25:10.8100000Z | AD27: 149
A28: T2-25_BDSDF107 | B28: Fundamentals of Data Science and Engineering | C28: BS - Data Science &amp; AI | D28: dept_bs_dsai | E28: sem_trimester 2 | F28: Trimester 2 | G28: 2025eb1100004@bitspilani-digital.edu.in | H28: 2025EB1100004 | I28: old | J28: ARUNLAL P | K28: . | L28: TRUE | M28: 0 | N28: =_xlfn.XLOOKUP(B28,Courses!A:A,Courses!E:E) -> 25 | O28: 71 | Q28: 0 | S28: 0 | T28: 0 | U28: 0 | V28: 0 | W28: 0 | Y28: 0 | AA28: 0 | AC28: 2026-01-19T08:25:10.8100000Z | AD28: 149
A29: T2-25_BDSDF110 | B29: Linear Algebra | C29: BS - Data Science &amp; AI | D29: dept_bs_dsai | E29: sem_trimester 2 | F29: Trimester 2 | G29: 2025eb1100004@bitspilani-digital.edu.in | H29: 2025EB1100004 | I29: old | J29: ARUNLAL P | K29: . | L29: TRUE | M29: 0 | N29: =_xlfn.XLOOKUP(B29,Courses!A:A,Courses!E:E) -> 30 | O29: 61 | Q29: 0 | S29: 0 | T29: 0 | U29: 0 | V29: 0 | W29: 0 | Y29: 0 | AA29: 0 | AC29: 2026-01-19T08:25:10.8100000Z | AD29: 149
A30: T1-25_BDSDF114 | B30: Probability & Statistics | C30: BS - Data Science &amp; AI | D30: dept_bs_dsai | E30: sem_trimester1 | F30: Trimester 1 | G30: 2025eb1100004@bitspilani-digital.edu.in | H30: 2025EB1100004 | I30: old | J30: ARUNLAL P | K30: . | L30: TRUE | M30: 59 | N30: =_xlfn.XLOOKUP(B30,Courses!A:A,Courses!E:E) -> 35 | O30: 351 | Q30: 0 | S30: 20 | T30: 20 | U30: 0 | V30: 0 | W30: 0 | Y30: 1 | Z30: 2025-12-05T16:59:07.8500000Z | AA30: 25059 | AB30: 2025-12-20T00:59:22.4200000Z | AC30: 2026-01-19T08:25:10.8100000Z | AD30: 149 | AF30: 2025-12-20T00:59:13.9870000Z | AG30: 2025-12-20T00:59:28.3330000Z | AH30: 2025-12-20T00:59:28.3430000Z
A31: T1-25_BDSDF112 | B31: Writing Practice | C31: BS - Data Science &amp; AI | D31: dept_bs_dsai | E31: sem_trimester1 | F31: Trimester 1 | G31: 2025eb1100004@bitspilani-digital.edu.in | H31: 2025EB1100004 | I31: old | J31: ARUNLAL P | K31: . | L31: TRUE | M31: 47 | N31: =_xlfn.XLOOKUP(B31,Courses!A:A,Courses!E:E) -> 46 | O31: 188 | Q31: 0 | S31: 16 | T31: 17 | U31: 0 | V31: 0 | W31: 0 | Y31: 2 | Z31: 2025-11-28T17:22:22.3800000Z | AA31: 48593 | AB31: 2025-12-30T07:59:00.5530000Z | AC31: 2026-01-19T08:25:10.8100000Z | AD31: 149 | AF31: 2025-12-20T15:34:23.3170000Z
A32: T1-25_BDSDF101 | B32: Data and the World | C32: BS - Data Science &amp; AI | D32: dept_bs_dsai | E32: sem_trimester1 | F32: Trimester 1 | G32: 2025eb1100004@bitspilani-digital.edu.in | H32: 2025EB1100004 | I32: old | J32: ARUNLAL P | K32: . | L32: TRUE | M32: 6 | N32: =_xlfn.XLOOKUP(B32,Courses!A:A,Courses!E:E) -> 24 | O32: 46 | Q32: 0 | S32: 0 | T32: 0 | U32: 0 | V32: 0 | W32: 0 | Y32: 1 | Z32: 2025-10-12T13:47:08.8530000Z | AA32: 2306 | AB32: 2025-12-11T16:49:27.0600000Z | AC32: 2026-01-19T08:25:10.8100000Z | AD32: 149 | AG32: 2025-10-18T12:06:57.9300000Z | AH32: 2025-10-18T12:06:57.8830000Z
A33: T1-25_BDSDF108 | B33: Computing Systems | C33: BS - Data Science &amp; AI | D33: dept_bs_dsai | E33: sem_trimester1 | F33: Trimester 1 | G33: 2025eb1100004@bitspilani-digital.edu.in | H33: 2025EB1100004 | I33: old | J33: ARUNLAL P | K33: . | L33: TRUE | M33: 16 | N33: =_xlfn.XLOOKUP(B33,Courses!A:A,Courses!E:E) -> 47 | O33: 235 | Q33: 0 | S33: 3 | T33: 3 | U33: 0 | V33: 0 | W33: 0 | Y33: 2 | Z33: 2025-11-14T17:10:10.2630000Z | AA33: 24817 | AB33: 2025-12-27T00:29:55.4000000Z | AC33: 2026-01-19T08:25:10.8100000Z | AD33: 149 | AF33: 2025-12-15T16:57:51.3570000Z | AG33: 2025-12-27T00:30:00.8370000Z | AH33: 2025-12-27T00:30:00.8470000Z
A34: T1-25_BDSDF113 | B34: Computer Programming | C34: BS - Data Science &amp; AI | D34: dept_bs_dsai | E34: sem_trimester1 | F34: Trimester 1 | G34: 2025eb1100004@bitspilani-digital.edu.in | H34: 2025EB1100004 | I34: old | J34: ARUNLAL P | K34: . | L34: TRUE | M34: 26 | N34: =_xlfn.XLOOKUP(B34,Courses!A:A,Courses!E:E) -> 56 | O34: 353 | Q34: 0 | S34: 4 | T34: 5 | U34: 0 | V34: 0 | W34: 0 | Y34: 1 | Z34: 2025-12-08T17:27:21.7500000Z | AA34: 15779 | AB34: 2025-12-28T00:50:26.9530000Z | AC34: 2026-01-19T08:25:10.8100000Z | AD34: 149 | AF34: 2025-11-23T17:01:29.7230000Z | AG34: 2025-09-16T17:29:45.4430000Z | AH34: 2025-09-16T17:30:57.4930000Z
A35: T1-25_BDSDF113 | B35: Computer Programming | C35: BS - Data Science &amp; AI | D35: dept_bs_dsai | E35: sem_trimester1 | F35: Trimester 1 | G35: 2025eb1100005@bitspilani-digital.edu.in | H35: 2025EB1100005 | I35: old | J35: RUPEN TAK | K35: . | L35: TRUE | M35: 1 | N35: =_xlfn.XLOOKUP(B35,Courses!A:A,Courses!E:E) -> 56 | O35: 347 | Q35: 0 | S35: 0 | T35: 0 | U35: 0 | V35: 0 | W35: 0 | Y35: 0 | AA35: 0 | AB35: 2025-12-17T11:52:49.3730000Z | AC35: 2026-01-17T15:59:38.7600000Z | AD35: 40
A36: T1-25_BDSDF108 | B36: Computing Systems | C36: BS - Data Science &amp; AI | D36: dept_bs_dsai | E36: sem_trimester1 | F36: Trimester 1 | G36: 2025eb1100005@bitspilani-digital.edu.in | H36: 2025EB1100005 | I36: old | J36: RUPEN TAK | K36: . | L36: TRUE | M36: 62 | N36: =_xlfn.XLOOKUP(B36,Courses!A:A,Courses!E:E) -> 47 | O36: 258 | Q36: 0 | S36: 13 | T36: 24 | U36: 0 | V36: 0 | W36: 0 | Y36: 1 | Z36: 2025-12-14T16:47:22.3600000Z | AA36: 8521 | AB36: 2025-12-26T04:43:43.3770000Z | AC36: 2026-01-17T15:59:38.7600000Z | AD36: 40 | AF36: 2025-12-14T16:21:23.5270000Z | AG36: 2025-10-03T09:19:10.1670000Z | AH36: 2025-10-03T09:19:15.4800000Z
A37: T1-25_BDSDF101 | B37: Data and the World | C37: BS - Data Science &amp; AI | D37: dept_bs_dsai | E37: sem_trimester1 | F37: Trimester 1 | G37: 2025eb1100005@bitspilani-digital.edu.in | H37: 2025EB1100005 | I37: old | J37: RUPEN TAK | K37: . | L37: TRUE | M37: 35 | N37: =_xlfn.XLOOKUP(B37,Courses!A:A,Courses!E:E) -> 24 | O37: 54 | Q37: 0 | S37: 0 | T37: 0 | U37: 0 | V37: 0 | W37: 0 | Y37: 1 | Z37: 2025-10-03T09:42:12.3400000Z | AA37: 135 | AB37: 2025-12-14T16:50:17.1870000Z | AC37: 2026-01-17T15:59:38.7600000Z | AD37: 40 | AG37: 2025-10-03T09:23:44.4100000Z | AH37: 2025-10-03T09:23:50.0130000Z
A38: T1-25_BDSDF112 | B38: Writing Practice | C38: BS - Data Science &amp; AI | D38: dept_bs_dsai | E38: sem_trimester1 | F38: Trimester 1 | G38: 2025eb1100005@bitspilani-digital.edu.in | H38: 2025EB1100005 | I38: old | J38: RUPEN TAK | K38: . | L38: TRUE | M38: 8 | N38: =_xlfn.XLOOKUP(B38,Courses!A:A,Courses!E:E) -> 46 | O38: 186 | Q38: 0 | S38: 3 | T38: 3 | U38: 0 | V38: 0 | W38: 0 | Y38: 0 | AA38: 903 | AB38: 2025-12-30T07:53:54.2130000Z | AC38: 2026-01-17T15:59:38.7600000Z | AD38: 40 | AF38: 2025-11-24T05:36:41.9400000Z
A39: T1-25_BDSDF114 | B39: Probability & Statistics | C39: BS - Data Science &amp; AI | D39: dept_bs_dsai | E39: sem_trimester1 | F39: Trimester 1 | G39: 2025eb1100005@bitspilani-digital.edu.in | H39: 2025EB1100005 | I39: old | J39: RUPEN TAK | K39: . | L39: TRUE | M39: 2 | N39: =_xlfn.XLOOKUP(B39,Courses!A:A,Courses!E:E) -> 35 | O39: 327 | Q39: 0 | S39: 1 | T39: 1 | U39: 0 | V39: 0 | W39: 0 | Y39: 0 | AA39: 28 | AB39: 2025-12-14T16:53:28.5530000Z | AC39: 2026-01-17T15:59:38.7600000Z | AD39: 40 | AF39: 2025-10-05T10:33:20.0570000Z
A40: T1-25_BDSDF114 | B40: Probability & Statistics | C40: BS - Data Science &amp; AI | D40: dept_bs_dsai | E40: sem_trimester1 | F40: Trimester 1 | G40: 2025eb1100006@bitspilani-digital.edu.in | H40: 2025EB1100006 | I40: old | J40: JAL PATEL | K40: . | L40: TRUE | M40: 27 | N40: =_xlfn.XLOOKUP(B40,Courses!A:A,Courses!E:E) -> 35 | O40: 337 | Q40: 0 | S40: 8 | T40: 11 | U40: 0 | V40: 0 | W40: 0 | Y40: 1 | Z40: 2025-12-01T15:05:07.2070000Z | AA40: 3175 | AB40: 2026-01-12T19:37:22.8530000Z | AC40: 2026-01-19T09:41:37.4630000Z | AD40: 70 | AF40: 2025-12-05T06:58:21.1430000Z | AG40: 2025-12-04T07:48:54.9270000Z | AH40: 2025-12-05T06:58:46.1170000Z
...

Sheet Summary
A1: Old/New Student | B1: new | D1: Old/New Student | E1: new | G1: Old/New Student | H1: old | J1: Old/New Student | K1: old
A2: Parent Department Name | B2: BS | D2: Parent Department Name | E2: MS | G2: Parent Department Name | H2: BS | J2: Parent Department Name | K2: MS
A4: Course Name | B4: Student Count | D4: Course Name | E4: Student Count | G4: Course Name | H4: Student Count | J4: Course Name | K4: Student Count
A5: Computer Programming | B5: 109 | D5: Data Pre-processing (MSc) | E5: 361 | G5: Computer Programming | H5: 64 | J5: Artificial Neural Networks | K5: 353
A6: 0 % progress | B6: 17 | D6: 0 % progress | E6: 57 | G6: 0 % progress | H6: 39 | J6: 0 % progress | K6: 86
A7: 0-10 % progress | B7: 24 | D7: 0-10 % progress | E7: 47 | G7: 0-10 % progress | H7: 9 | J7: 0-10 % progress | K7: 84
A8: >10 % progress | B8: 68 | D8: >10 % progress | E8: 257 | G8: >10 % progress | H8: 16 | J8: >10 % progress | K8: 183
A9: Computing Systems | B9: 109 | D9: Data Visualization & Storytelling | E9: 361 | G9: Computing Systems | H9: 85 | J9: Cloud Services & Platforms | K9: 356
A10: 0 % progress | B10: 24 | D10: 0 % progress | E10: 42 | G10: 0 % progress | H10: 40 | J10: 0 % progress | K10: 80
A11: 0-10 % progress | B11: 22 | D11: 0-10 % progress | E11: 60 | G11: 0-10 % progress | H11: 22 | J11: 0-10 % progress | K11: 96
A12: >10 % progress | B12: 63 | D12: >10 % progress | E12: 259 | G12: >10 % progress | H12: 23 | J12: >10 % progress | K12: 180
A13: Data and the World | B13: 109 | D13: Feature Engineering | E13: 361 | G13: Data and the World | H13: 51 | J13: Data Pre-processing (MSc) | K13: 35
A14: 0 % progress | B14: 30 | D14: 0 % progress | E14: 174 | G14: 0 % progress | H14: 36 | J14: 0 % progress | K14: 24
A15: 0-10 % progress | B15: 19 | D15: 0-10 % progress | E15: 29 | G15: 0-10 % progress | H15: 7 | J15: 0-10 % progress | K15: 5
A16: >10 % progress | B16: 60 | D16: >10 % progress | E16: 158 | G16: >10 % progress | H16: 8 | J16: >10 % progress | K16: 6
... A21: Writing Practice | B21: 109 | D21: Grand Total | E21: 1444 | G21: Data Structures for Data Science | H21: 158 | J21: Data Visualization & Storytelling | K21: 36
A22: 0 % progress | B22: 29 | G22: 0 % progress | H22: 55 | J22: 0 % progress | K22: 25
A23: 0-10 % progress | B23: 26 | G23: 0-10 % progress | H23: 33 | J23: 0-10 % progress | K23: 5
A24: >10 % progress | B24: 54 | G24: >10 % progress | H24: 70 | J24: >10 % progress | K24: 6
A25: Grand Total | B25: 545 | G25: Fundamentals of Data Science and Engineering | H25: 175 | J25: Feature Engineering | K25: 35
G26: 0 % progress | H26: 54 | J26: 0 % progress | K26: 26
G27: 0-10 % progress | H27: 23 | J27: 0-10 % progress | K27: 4
G28: >10 % progress | H28: 98 | J28: >10 % progress | K28: 5
G29: Linear Algebra | H29: 186 | J29: Machine Learning | K29: 351
G30: 0 % progress | H30: 62 | J30: 0 % progress | K30: 88
G31: 0-10 % progress | H31: 42 | J31: 0-10 % progress | K31: 60
G32: >10 % progress | H32: 82 | J32: >10 % progress | K32: 203
G33: Probability & Statistics | H33: 71 | J33: Statistical Modelling & Inferencing | K33: 41
G34: 0 % progress | H34: 40 | J34: 0 % progress | K34: 19
G35: 0-10 % progress | H35: 16 | J35: 0-10 % progress | K35: 13
G36: >10 % progress | H36: 15 | J36: >10 % progress | K36: 9
G37: Writing Practice | H37: 28 | J37: Grand Total | K37: 1224
G38: 0 % progress | H38: 16
G39: 0-10 % progress | H39: 9
G40: >10 % progress | H40: 3
G41: Grand Total | H41: 971

Sheet Learners' Content Participation
A1: Parent Department Name | B1: (All)
A2: Old/New Student | B2: (All)
A4: Student ID | B4: Total Courses (T2) | C4: Zero-Progress Courses (W1&2) | D4: Not viewed any Content
A5: 2025eb1100001@bitspilani-digital.edu.in | B5: 5 | C5: 1 | D5: =B5-C5 -> 4
A6: 2025eb1100003@bitspilani-digital.edu.in | B6: 4 | C6: 0 | D6: =B6-C6 -> 4
A7: 2025eb1100004@bitspilani-digital.edu.in | B7: 4 | C7: 3 | D7: =B7-C7 -> 1
A8: 2025eb1100007@bitspilani-digital.edu.in | B8: 4 | C8: 3 | D8: =B8-C8 -> 1
A9: 2025eb1100008@bitspilani-digital.edu.in | B9: 4 | C9: 2 | D9: =B9-C9 -> 2
A10: 2025eb1100009@bitspilani-digital.edu.in | B10: 5 | C10: 5 | D10: =B10-C10 -> 0
A11: 2025eb1100010@bitspilani-digital.edu.in | B11: 4 | C11: 3 | D11: =B11-C11 -> 1
A12: 2025eb1100012@bitspilani-digital.edu.in | B12: 2 | C12: 2 | D12: =B12-C12 -> 0
A13: 2025eb1100013@bitspilani-digital.edu.in | B13: 4 | C13: 4 | D13: =B13-C13 -> 0
A14: 2025eb1100014@bitspilani-digital.edu.in | B14: 2 | C14: 0 | D14: =B14-C14 -> 2
A15: 2025eb1100015@bitspilani-digital.edu.in | B15: 4 | C15: 0 | D15: =B15-C15 -> 4
A16: 2025eb1100016@bitspilani-digital.edu.in | B16: 2 | C16: 0 | D16: =B16-C16 -> 2
... A1110: 2025em1200369@bitspilani-digital.edu.in | B1110: 4 | C1110: 3 | D1110: =B1110-C1110 -> 1
A1111: Grand Total | B1111: 4184 | C1111: 1167

Sheet Analysis Dump
A1: Course Offering Code | B1: Course Offering Name | C1: Parent Department Name | D1: Parent Department Code | E1: Semester Name | F1: Username | G1: Org Defined Id | H1: Old/New Student | I1: First Name | J1: Is Active | K1: Content Completed | L1: Content Required W1&2 | M1: Usage% W1&2 | N1: W1&2 Active Flag | O1: Usage Category W1&2 | P1: Zero-Progress Flag | Q1: Total courses enrolled | R1: Learner with 0 participation | S1: Learner with 0 % participation
A2: T2-25_BDSDF106 | B2: Data Structures for Data Science | C2: BS | D2: dept_bs_dsai | E2: Trimester 2 | F2: 2025eb1100001@bitspilani-digital.edu.in | G2: 2025EB1100001 | H2: old | I2: RUDRA SHARMA | J2: TRUE | K2: 0 | L2: 58 | M2: =K2/L2 -> 0 | N2: =IF(M2>0,"Active","Not Active") -> Not Active | O2: {=_xlfn.IFS(M2=0,"0", M2<=10%,"0-10", TRUE,">10" )&" "&"% progress"} -> 0 % progress | P2: =IF(M2=0,1,0) -> 1 | Q2: =COUNTIFS($G:$G,$G2) -> 5 | R2: =P2/Q2 -> 0.2 | S2: =IF(R2=0, "no 0% progess", "no progress") -> no progress
A3: T2-25_BDSDF102 | B3: Data Preprocessing (BS) | C3: BS | D3: dept_bs_dsai | E3: Trimester 2 | F3: 2025eb1100001@bitspilani-digital.edu.in | G3: 2025EB1100001 | H3: old | I3: RUDRA SHARMA | J3: TRUE | K3: 2 | L3: 54 | M3: =K3/L3 -> 0.037037037 | N3: =IF(M3>0,"Active","Not Active") -> Active | O3: {=_xlfn.IFS(M3=0,"0", M3<=10%,"0-10", TRUE,">10" )&" "&"% progress"} -> 0-10 % progress | P3: =IF(M3=0,1,0) -> 0 | Q3: =COUNTIFS($G:$G,$G3) -> 5 | R3: =P3/Q3 -> 0 | S3: =IF(R3=0, "no 0% progess", "no progress") -> no 0% progess
A4: T2-25_BDSDF107 | B4: Fundamentals of Data Science and Engineering | C4: BS | D4: dept_bs_dsai | E4: Trimester 2 | F4: 2025eb1100001@bitspilani-digital.edu.in | G4: 2025EB1100001 | H4: old | I4: RUDRA SHARMA | J4: TRUE | K4: 40 | L4: 25 | M4: =K4/L4 -> 1.6 | N4: =IF(M4>0,"Active","Not Active") -> Active | O4: {=_xlfn.IFS(M4=0,"0", M4<=10%,"0-10", TRUE,">10" )&" "&"% progress"} -> >10 % progress | P4: =IF(M4=0,1,0) -> 0 | Q4: =COUNTIFS($G:$G,$G4) -> 5 | R4: =P4/Q4 -> 0 | S4: =IF(R4=0, "no 0% progess", "no progress") -> no 0% progess
A5: T2-25_BDSDF110 | B5: Linear Algebra | C5: BS | D5: dept_bs_dsai | E5: Trimester 2 | F5: 2025eb1100001@bitspilani-digital.edu.in | G5: 2025EB1100001 | H5: old | I5: RUDRA SHARMA | J5: TRUE | K5: 2 | L5: 30 | M5: =K5/L5 -> 0.066666667 | N5: =IF(M5>0,"Active","Not Active") -> Active | O5: {=_xlfn.IFS(M5=0,"0", M5<=10%,"0-10", TRUE,">10" )&" "&"% progress"} -> 0-10 % progress | P5: =IF(M5=0,1,0) -> 0 | Q5: =COUNTIFS($G:$G,$G5) -> 5 | R5: =P5/Q5 -> 0 | S5: =IF(R5=0, "no 0% progess", "no progress") -> no 0% progess
A6: T2-25_BDSDF108 | B6: Computing Systems | C6: BS | D6: dept_bs_dsai | E6: Trimester 2 | F6: 2025eb1100001@bitspilani-digital.edu.in | G6: 2025EB1100001 | H6: old | I6: RUDRA SHARMA | J6: TRUE | K6: 91 | L6: 47 | M6: =K6/L6 -> 1.9361702 | N6: =IF(M6>0,"Active","Not Active") -> Active | O6: {=_xlfn.IFS(M6=0,"0", M6<=10%,"0-10", TRUE,">10" )&" "&"% progress"} -> >10 % progress | P6: =IF(M6=0,1,0) -> 0 | Q6: =COUNTIFS($G:$G,$G6) -> 5 | R6: =P6/Q6 -> 0 | S6: =IF(R6=0, "no 0% progess", "no progress") -> no 0% progess
A7: T2-25_BDSDF114 | B7: Probability & Statistics | C7: BS | D7: dept_bs_dsai | E7: Trimester 2 | F7: 2025eb1100003@bitspilani-digital.edu.in | G7: 2025EB1100003 | H7: old | I7: AJAYACHANDRAN.E | J7: TRUE | K7: 23 | L7: 35 | M7: =K7/L7 -> 0.65714286 | N7: =IF(M7>0,"Active","Not Active") -> Active | O7: {=_xlfn.IFS(M7=0,"0", M7<=10%,"0-10", TRUE,">10" )&" "&"% progress"} -> >10 % progress | P7: =IF(M7=0,1,0) -> 0 | Q7: =COUNTIFS($G:$G,$G7) -> 4 | R7: =P7/Q7 -> 0 | S7: =IF(R7=0, "no 0% progess", "no progress") -> no 0% progess
A8: T2-25_BDSDF113 | B8: Computer Programming | C8: BS | D8: dept_bs_dsai | E8: Trimester 2 | F8: 2025eb1100003@bitspilani-digital.edu.in | G8: 2025EB1100003 | H8: old | I8: AJAYACHANDRAN.E | J8: TRUE | K8: 43 | L8: 56 | M8: =K8/L8 -> 0.76785714 | N8: =IF(M8>0,"Active","Not Active") -> Active | O8: {=_xlfn.IFS(M8=0,"0", M8<=10%,"0-10", TRUE,">10" )&" "&"% progress"} -> >10 % progress | P8: =IF(M8=0,1,0) -> 0 | Q8: =COUNTIFS($G:$G,$G8) -> 4 | R8: =P8/Q8 -> 0 | S8: =IF(R8=0, "no 0% progess", "no progress") -> no 0% progess
A9: T2-25_BDSDF107 | B9: Fundamentals of Data Science and Engineering | C9: BS | D9: dept_bs_dsai | E9: Trimester 2 | F9: 2025eb1100003@bitspilani-digital.edu.in | G9: 2025EB1100003 | H9: old | I9: AJAYACHANDRAN.E | J9: TRUE | K9: 26 | L9: 25 | M9: =K9/L9 -> 1.04 | N9: =IF(M9>0,"Active","Not Active") -> Active | O9: {=_xlfn.IFS(M9=0,"0", M9<=10%,"0-10", TRUE,">10" )&" "&"% progress"} -> >10 % progress | P9: =IF(M9=0,1,0) -> 0 | Q9: =COUNTIFS($G:$G,$G9) -> 4 | R9: =P9/Q9 -> 0 | S9: =IF(R9=0, "no 0% progess", "no progress") -> no 0% progess
A10: T2-25_BDSDF102 | B10: Data Preprocessing (BS) | C10: BS | D10: dept_bs_dsai | E10: Trimester 2 | F10: 2025eb1100003@bitspilani-digital.edu.in | G10: 2025EB1100003 | H10: old | I10: AJAYACHANDRAN.E | J10: TRUE | K10: 35 | L10: 54 | M10: =K10/L10 -> 0.64814815 | N10: =IF(M10>0,"Active","Not Active") -> Active | O10: {=_xlfn.IFS(M10=0,"0", M10<=10%,"0-10", TRUE,">10" )&" "&"% progress"} -> >10 % progress | P10: =IF(M10=0,1,0) -> 0 | Q10: =COUNTIFS($G:$G,$G10) -> 4 | R10: =P10/Q10 -> 0 | S10: =IF(R10=0, "no 0% progess", "no progress") -> no 0% progess
A11: T2-25_BDSDF102 | B11: Data Preprocessing (BS) | C11: BS | D11: dept_bs_dsai | E11: Trimester 2 | F11: 2025eb1100004@bitspilani-digital.edu.in | G11: 2025EB1100004 | H11: old | I11: ARUNLAL P | J11: TRUE | K11: 1 | L11: 54 | M11: =K11/L11 -> 0.018518519 | N11: =IF(M11>0,"Active","Not Active") -> Active | O11: {=_xlfn.IFS(M11=0,"0", M11<=10%,"0-10", TRUE,">10" )&" "&"% progress"} -> 0-10 % progress | P11: =IF(M11=0,1,0) -> 0 | Q11: =COUNTIFS($G:$G,$G11) -> 4 | R11: =P11/Q11 -> 0 | S11: =IF(R11=0, "no 0% progess", "no progress") -> no 0% progess
A12: T2-25_BDSDF106 | B12: Data Structures for Data Science | C12: BS | D12: dept_bs_dsai | E12: Trimester 2 | F12: 2025eb1100004@bitspilani-digital.edu.in | G12: 2025EB1100004 | H12: old | I12: ARUNLAL P | J12: TRUE | K12: 0 | L12: 58 | M12: =K12/L12 -> 0 | N12: =IF(M12>0,"Active","Not Active") -> Not Active | O12: {=_xlfn.IFS(M12=0,"0", M12<=10%,"0-10", TRUE,">10" )&" "&"% progress"} -> 0 % progress | P12: =IF(M12=0,1,0) -> 1 | Q12: =COUNTIFS($G:$G,$G12) -> 4 | R12: =P12/Q12 -> 0.25 | S12: =IF(R12=0, "no 0% progess", "no progress") -> no progress
A13: T2-25_BDSDF107 | B13: Fundamentals of Data Science and Engineering | C13: BS | D13: dept_bs_dsai | E13: Trimester 2 | F13: 2025eb1100004@bitspilani-digital.edu.in | G13: 2025EB1100004 | H13: old | I13: ARUNLAL P | J13: TRUE | K13: 0 | L13: 25 | M13: =K13/L13 -> 0 | N13: =IF(M13>0,"Active","Not Active") -> Not Active | O13: {=_xlfn.IFS(M13=0,"0", M13<=10%,"0-10", TRUE,">10" )&" "&"% progress"} -> 0 % progress | P13: =IF(M13=0,1,0) -> 1 | Q13: =COUNTIFS($G:$G,$G13) -> 4 | R13: =P13/Q13 -> 0.25 | S13: =IF(R13=0, "no 0% progess", "no progress") -> no progress
... A4185: T2-25_MDSDF402 | B4185: Data Pre-processing (MSc) | C4185: MS | D4185: dept_msc_dsai | E4185: Trimester 2 | F4185: 2025em1200369@bitspilani-digital.edu.in | G4185: 2025EM1200369 | H4185: new | I4185: NEHA GUPTA | J4185: TRUE | K4185: 0 | L4185: 22 | M4185: =K4185/L4185 -> 0 | N4185: =IF(M4185>0,"Active","Not Active") -> Not Active | O4185: {=_xlfn.IFS(M4185=0,"0", M4185<=10%,"0-10", TRUE,">10" )&" "&"% progress"} -> 0 % progress | P4185: =IF(M4185=0,1,0) -> 1 | Q4185: =COUNTIFS($G:$G,$G4185) -> 4 | R4185: =P4185/Q4185 -> 0.25 | S4185: =IF(R4185=0, "no 0% progess", "no progress") -> no progress

Sheet Courses
A1: T2 | B1: WEEK 1 | C1: WEEK 2 | D1: lab | E1: sum | G1: T1 | H1: WEEK 1 | I1: WEEK 2 | J1: lab | K1: sum
A2: Artificial Neural Networks | B2: 25 | C2: 20 | D2: - | E2: =SUM(B2:C2) -> 45 | G2: Computing Systems | H2: 16 | I2: 30 | J2: - | K2: =SUM(H2:J2) -> 46
A3: Advanced Apex Project I | B3: 0 | C3: 0 | D3: - | E3: =SUM(B3:C3) -> 0 | G3: Computer Programming | H3: 25 | I3: 32 | J3: - | K3: =SUM(H3:J3) -> 57
A4: Basic Mathematics | B4: 12 | C4: 25 | D4: - | E4: =SUM(B4:C4) -> 37 | G4: Probability & Statistics | H4: 21 | I4: 15 | J4: - | K4: =SUM(H4:J4) -> 36
A5: Cloud Services & Platforms | B5: 21 | C5: 20 | D5: - | E5: =SUM(B5:C5) -> 41 | G5: Basic Mathematics | H5: 12 | I5: 25 | J5: - | K5: =SUM(H5:J5) -> 37
A6: Computer Programming | B6: 25 | C6: 31 | D6: - | E6: =SUM(B6:C6) -> 56 | G6: Writing Practice | H6: 23 | I6: 22 | J6: - | K6: =SUM(H6:J6) -> 45
A7: Computing Systems | B7: 17 | C7: 30 | D7: - | E7: =SUM(B7:C7) -> 47 | G7: Data Stores & Pipelines | H7: 23 | I7: 18 | J7: 9 | K7: =SUM(H7:I7) -> 41
A8: Data and the World | B8: 7 | C8: 17 | D8: - | E8: =SUM(B8:C8) -> 24 | G8: Data and the World | H8: 7 | I8: 17 | J8: - | K8: =SUM(H8:J8) -> 24
A9: Data Annotations and Labelling | B9: 12 | C9: 11 | D9: - | E9: =SUM(B9:C9) -> 23 | G9: Advanced Apex Project I | H9: 3 | I9: 7 | J9: - | K9: =SUM(H9:J9) -> 10
A10: Data Preprocessing (BS) | B10: 28 | C10: 26 | D10: - | E10: =SUM(B10:C10) -> 54 | G10: Computer Architecture | H10: 0 | I10: 0 | J10: - | K10: =SUM(H10:J10) -> 0
A11: Data Pre-processing (MSc) | B11: 12 | C11: 10 | D11: - | E11: =SUM(B11:C11) -> 22 | G11: Data Pre-processing | H11: 13 | I11: 12 | J11: - | K11: =SUM(H11:J11) -> 25
A12: Data Stores & Pipelines | B12: 22 | C12: 18 | D12: 9 | E12: =SUM(B12:C12) -> 40 | G12: Data Visualization & Storytelling | H12: 23 | I12: 30 | J12: - | K12: =SUM(H12:J12) -> 53
A13: Data Structures for Data Science | B13: 29 | C13: 29 | D13: - | E13: =SUM(B13:C13) -> 58 | G13: Feature Engineering | H13: 12 | I13: 12 | J13: - | K13: =SUM(H13:J13) -> 24
A14: Data Visualization & Storytelling | B14: 26 | C14: 29 | D14: - | E14: =SUM(B14:C14) -> 55 | G14: Statistical Modelling & Inferencing | H14: 22 | I14: 18 | J14: - | K14: =SUM(H14:J14) -> 40
A15: Feature Engineering | B15: 12 | C15: 12 | D15: - | E15: =SUM(B15:C15) -> 24
A16: Fundamentals of Data Science and Engineering | B16: 13 | C16: 12 | D16: - | E16: =SUM(B16:C16) -> 25
A17: Linear Algebra | B17: 16 | C17: 14 | D17: - | E17: =SUM(B17:C17) -> 30
A18: Machine Learning | B18: 14 | C18: 12 | D18: - | E18: =SUM(B18:C18) -> 26
A19: Probability & Statistics | B19: 22 | C19: 13 | D19: - | E19: =SUM(B19:C19) -> 35
A20: Python Programming | B20: 21 | C20: 28 | D20: - | E20: =SUM(B20:C20) -> 49
A21: Statistical Modelling & Inferencing | B21: 23 | C21: 15 | D21: - | E21: =SUM(B21:C21) -> 38
A22: Writing Practice | B22: 24 | C22: 22 | D22: - | E22: =SUM(B22:C22) -> 46
